Workbook

Sheet Cover
A16: TIMES-Ireland Model
A19: Document type: | B19: Base Year Template
A20: Sector(s): | B20: Transport sector (TRA)
A21: Purpose: | B21: Transport structure in Ireland and the base year simulation
A23: Original developer(s): | B23: Vahid Aryanpur (UCC, vahid.aryanpur@ucc.ie)
B24: James Glynn (UCC, james.glynn@ucc.ie)
A26: Current maintainer(s): | B26: Vahid Aryanpur (UCC, vahid.aryanpur@ucc.ie)
A29: Part of TIM version: | B29: 1
A30: Model repository: | B30: https://github.com/MaREI-EPMG/TIMES-Ireland-model
A31: Licence: | B31: CC BY-NC-SA 4.0 (unless specified otherwise)
B32: https://creativecommons.org/licenses/by-nc-sa/4.0/

Sheet Intro
B2: Table of contents
B3: Sheet | C3: Description
B4: EB2018 | C4: SEAI 2018 energy balance in ktoe
B5: Commodities | C5: TIMES commodities list for the sector
B6: TRA_FuelTechs | C6: Fuel sectoral technologies/infrastructure
B7: TRA_FuelBlending | C7: Fuel blending
B8: Demands | C8: Energy service demands for the transport sector
B9: Emi | C9: Emission coefficients for the transport sector
B10: CAR | C10: TIMES inputs for Cars
B11: MOTO | C11: TIMES inputs for Moto
B12: FREH | C12: TIMES inputs for Freight
B13: PUB | C13: TIMES inputs for Public
B14: NAV | C14: TIMES inputs for Navigation
... B16: … | C16: Data elaboration sheets
B18: Tab colour legend
C19: General inputs
C20: Private cars
C21: Motorcycles
C22: Freight
C23: Public
C24: Navigation
C25: Aviation
B27: Units
B28: Capacity | C28: V or PJa
B29: Consumption | C29: PJ
B30: Currency (year) | C30: Milion Euro 2018
B31: Base year | C31: 2018

Sheet EB2018
A1: 2018 Units = ktoe | B1: NACE (Rev 2) | C1: Coal | D1: Bituminous Coal | E1: Anthracite + Manufactured Ovoids | F1: Coke | G1: Lignite \ Brown Coal Briquettes | H1: Peat | I1: Milled Peat | J1: Sod Peat | K1: Briquettes | L1: Oil | M1: Crude | N1: Refinery Feedstocks | O1: Refinery Gas | P1: Gasoline | Q1: Kerosene | R1: Jet Kerosene | S1: Fueloil | T1: LPG | U1: Gasoil / Diesel /DERV | V1: Petroleum Coke | W1: Naphta | X1: Bitumen | Y1: White Spirit | Z1: Lubricants | AA1: Natural Gas | AB1: Renewables | AC1: Hydro | AD1: Wind | AE1: Biomass | AF1: Renewable Waste | AG1: Landfill Gas | AH1: Biogas | AI1: Biodiesel | AJ1: Bioethanol | AK1: Solar Photovoltaic | AL1: Solar Thermal | AM1: Ambient Heat | AN1: Non-Renewable Waste | AO1: Electricity | AP1: Heat | AQ1: TOTAL
A2: Indigenous Production | C2: =SUM(D2:G2) -> 0 | D2: 0 | H2: =SUM(I2:K2) -> 815.92435 | I2: 688.22035 | J2: 127.704 | L2: =SUM(M2:Z2) -> 0 | AA2: 2751.9192 | AB2: =SUM(AC2:AM2) -> 1334.6583 | AC2: 59.691709 | AD2: 743.01992 | AE2: 248.9086 | AF2: 139.99993 | AG2: 33.531819 | AH2: 16.813133 | AI2: 31.064468 | AJ2: 2.6691993 | AK2: 1.8899881 | AL2: 13.546086 | AM2: 43.523448 | AN2: 145.4371 | AQ2: =C2+H2+L2+AA2+AB2+AN2+AO2+AP2 -> 5047.9389
A3: Imports | C3: =SUM(D3:G3) -> 903.49466 | D3: 829.5746 | E3: 61.722868 | G3: 12.197194 | H3: =SUM(I3:K3) -> 0 | L3: =SUM(M3:Z3) -> 9138.5578 | M3: 3053.4743 | N3: 16.633377 | O3: 0 | P3: 564.23641 | Q3: 369.14639 | R3: 1542.2444 | S3: 82.827949 | T3: 157.54636 | U3: 2932.6956 | V3: 166.37648 | W3: 7.5616539 | X3: 200.83222 | Y3: 1.228147 | Z3: 43.754533 | AA3: 1728.3381 | AB3: =SUM(AC3:AM3) -> 151.93356 | AE3: 24.282116 | AI3: 104.81441 | AJ3: 22.83703 | AO3: 139.45062 | AQ3: =C3+H3+L3+AA3+AB3+AN3+AO3+AP3 -> 12061.775
A4: Exports | C4: =SUM(D4:G4) -> 15.186581 | D4: 0 | E4: 14.097722 | G4: 1.0888587 | H4: =SUM(I4:K4) -> 7.033068 | K4: 7.033068 | L4: =SUM(M4:Z4) -> 1717.0625 | M4: 0 | N4: 0 | P4: 364.52222 | Q4: 21.672508 | R4: 156.2938 | S4: 986.60612 | T4: 35.289733 | U4: 102.14625 | V4: 0.0029088438 | W4: 36.297317 | X4: 5.469469 | Y4: 0.018500298 | Z4: 8.7436483 | AA4: 0 | AB4: =SUM(AC4:AM4) -> 9.4476585 | AE4: 0.4126464 | AI4: 9.0350121 | AJ4: 0 | AO4: 141.83539 | AQ4: =C4+H4+L4+AA4+AB4+AN4+AO4+AP4 -> 1890.5652
A5: Mar. Bunkers | C5: =SUM(D5:G5) -> 0 | H5: =SUM(I5:K5) -> 0 | L5: =SUM(M5:Z5) -> 172.71259 | S5: 15.730078 | U5: 156.98251 | AB5: =SUM(AC5:AM5) -> 0 | AQ5: =C5+H5+L5+AA5+AB5+AN5+AO5+AP5 -> 172.71259
A6: Stock Change | C6: =SUM(D6:G6) -> -101.25635 | D6: -101.86989 | E6: -0.80797667 | G6: 1.421516 | H6: =SUM(I6:K6) -> -122.93905 | I6: -136.53827 | J6: 0 | K6: 13.599214 | L6: =SUM(M6:Z6) -> 151.33981 | M6: 38.730965 | N6: -8.875152 | P6: -9.6980083 | Q6: 12.883202 | R6: 82.120249 | S6: 23.6376 | T6: 1.4659197 | U6: 8.3874136 | V6: 3.2040911 | W6: -0.51646779 | X6: 0 | Y6: 0 | Z6: 0 | AA6: 0 | AB6: =SUM(AC6:AM6) -> 4.4601014 | AE6: 0.26707428 | AI6: 1.7828522 | AJ6: 2.410175 | AQ6: =C6+H6+L6+AA6+AB6+AN6+AO6+AP6 -> -68.395488
A7: Primary Energy Supply (incl non-energy) | C7: =C2+C3-C4-C5+C6 -> 787.05173 | D7: =D2+D3-D4-D5+D6 -> 727.70471 | E7: =E2+E3-E4-E5+E6 -> 46.817169 | F7: =F2+F3-F4-F5+F6 -> 0 | G7: =G2+G3-G4-G5+G6 -> 12.529851 | H7: =H2+H3-H4-H5+H6 -> 685.95223 | I7: =I2+I3-I4-I5+I6 -> 551.68208 | J7: =J2+J3-J4-J5+J6 -> 127.704 | ... AP7: =AP2+AP3-AP4-AP5+AP6 -> 0 | AQ7: =C7+H7+L7+AA7+AB7+AN7+AO7+AP7 -> 14978.04
A8: Primary Energy Requirement (excl. non-energy) | C8: =C7-C27 -> 787.05173 | D8: =D7-D27 -> 727.70471 | E8: =E7-E27 -> 46.817169 | F8: =F7-F27 -> 0 | G8: =G7-G27 -> 12.529851 | H8: =H7-H27 -> 685.95223 | I8: =I7-I27 -> 551.68208 | J8: =J7-J27 -> 127.704 | ... AP8: =AP7-AP27 -> 0 | AQ8: =C8+H8+L8+AA8+AB8+AN8+AO8+AP8 -> 14746.457
A9: Transformation Input | C9: =SUM(C10:C14) -> 489.1342 | D9: =SUM(D10:D14) -> 489.1342 | E9: =SUM(E10:E14) -> 0 | F9: =SUM(F10:F14) -> 0 | G9: =SUM(G10:G14) -> 0 | H9: =SUM(H10:H14) -> 541.02658 | I9: =SUM(I10:I14) -> 541.02658 | J9: =SUM(J10:J14) -> 0 | ... AP9: =SUM(AP10:AP14) -> 0 | AQ9: =C9+H9+L9+AA9+AB9+AN9+AO9+AP9 -> 7058.1841
A10: Public Thermal Power Plants (Input) | C10: =SUM(D10:G10) -> 489.1342 | D10: 489.1342 | H10: =SUM(I10:K10) -> 467.10846 | I10: 467.10846 | J10: 0 | L10: =SUM(M10:Z10) -> 34.094789 | S10: 25.868327 | U10: 8.2264622 | AA10: 2187.6034 | AB10: =SUM(AC10:AM10) -> 205.3059 | AE10: 72.46706 | AF10: 99.307023 | AG10: 33.531819 | AN10: 90.714163 | AQ10: =C10+H10+L10+AA10+AB10+AN10+AO10+AP10 -> 3473.9609
A11: Combined Heat and Power Plants (Input) | C11: =SUM(D11:G11) -> 0 | D11: 0 | H11: =SUM(I11:K11) -> 5.8425469 | I11: 5.8425469 | L11: =SUM(M11:Z11) -> 0.63499472 | O11: 0 | S11: 0 | T11: 0.63499472 | U11: 0 | AA11: 272.96145 | AB11: =SUM(AC11:AM11) -> 10.597627 | AE11: 3.561556 | AH11: 7.0360715 | AQ11: =C11+H11+L11+AA11+AB11+AN11+AO11+AP11 -> 290.03662
A12: Pumped Storage Consumption (Input) | AO12: 42.94206 | AQ12: =C12+H12+L12+AA12+AB12+AN12+AO12+AP12 -> 42.94206
A13: Briquetting Plants (Input) | C13: =SUM(D13:G13) -> 0 | H13: =SUM(I13:K13) -> 68.075577 | I13: 68.075577 | L13: =SUM(M13:Z13) -> 0 | AB13: =SUM(AC13:AM13) -> 0 | AQ13: =C13+H13+L13+AA13+AB13+AN13+AO13+AP13 -> 68.075577
A14: Oil Refineries & other energy sector (Input) | C14: =SUM(D14:G14) -> 0 | H14: =SUM(I14:K14) -> 0 | L14: =SUM(M14:Z14) -> 3130.9919 | M14: 3092.2053 | N14: 38.786602 | AA14: 40.734585 | AB14: =SUM(AC14:AM14) -> 0 | AO14: 11.442472 | AQ14: =C14+H14+L14+AA14+AB14+AN14+AO14+AP14 -> 3183.1689
A15: Transformation Output | C15: =SUM(C16:C20) -> 0 | D15: =SUM(D16:D20) -> 0 | E15: =SUM(E16:E20) -> 0 | F15: =SUM(F16:F20) -> 0 | G15: =SUM(G16:G20) -> 0 | H15: =SUM(H16:H20) -> 64.671798 | I15: =SUM(I16:I20) -> 0 | J15: =SUM(J16:J20) -> 0 | ... AP15: =SUM(AP16:AP20) -> 0 | AQ15: =C15+H15+L15+AA15+AB15+AN15+AO15+AP15 -> 5104.8192
A16: Public Thermal Power Plants (Output) | C16: =SUM(D16:G16) -> 0 | H16: =SUM(I16:K16) -> 0 | L16: =SUM(M16:Z16) -> 0 | AB16: =SUM(AC16:AL16) -> 0 | AO16: 1667.7866 | AQ16: =C16+H16+L16+AA16+AO16+AP16 -> 1667.7866
A17: Combined Heat and Power Plants (Output) | C17: =SUM(D17:G17) -> 0 | H17: =SUM(I17:K17) -> 0 | L17: =SUM(M17:Z17) -> 0 | AB17: =SUM(AC17:AL17) -> 0 | AO17: 185.14396 | AQ17: =C17+H17+L17+AA17+AO17+AP17 -> 185.14396
A18: Pumped Storage Generation (Output) | AO18: 20.430939 | AQ18: =C18+H18+L18+AA18+AB18+AN18+AO18+AP18 -> 20.430939
A19: Briquetting Plants (Output) | H19: =SUM(I19:K19) -> 64.671798 | K19: 64.671798 | L19: =SUM(M19:Z19) -> 0 | AB19: =SUM(AC19:AL19) -> 0 | AQ19: =C19+H19+L19+AA19+AB19+AN19+AO19+AP19 -> 64.671798
A20: Oil Refineries & other energy sector (Output) | H20: =SUM(I20:K20) -> 0 | L20: =SUM(M20:Z20) -> 3166.7859 | O20: 90.017984 | P20: 640.5368 | Q20: 226.77459 | R20: 0 | S20: 960.95018 | T20: 64.797463 | U20: 1146.9502 | W20: 36.758644 | AB20: =SUM(AC20:AL20) -> 0 | AQ20: =C20+H20+L20+AA20+AB20+AN20+AO20+AP20 -> 3166.7859
A21: Exchanges and transfers | C21: =SUM(C22:C24) -> 22.240062 | D21: =SUM(D22:D24) -> -17.141361 | E21: =SUM(E22:E24) -> 39.381423 | F21: =SUM(F22:F24) -> 0 | G21: =SUM(G22:G24) -> 0 | H21: =SUM(I21:K21) -> 0 | I21: =SUM(I22:I24) -> 0 | J21: =SUM(J22:J24) -> 0 | K21: =SUM(K22:K24) -> 0 | L21: =SUM(M21:Z21) -> -24.684016 | M21: =SUM(M22:M24) -> 0 | N21: =SUM(N22:N24) -> 30.880435 | O21: =SUM(O22:O24) -> 0 | P21: =SUM(P22:P24) -> -31.331711 | Q21: =SUM(Q22:Q24) -> 361.9108 | R21: =SUM(R22:R24) -> -361.12225 | S21: =SUM(S22:S24) -> -0.17168421 | T21: =SUM(T22:T24) -> 0 | ... AQ21: =SUM(AQ22:AQ24) -> -2.4439548
A22: Electricity Exchange & Transfers | AB22: =SUM(AC22:AM22) -> -804.60162 | AC22: =-AC2 -> -59.691709 | AD22: =-AD2 -> -743.01992 | AK22: -1.8899881 | AO22: =-(C22+H22+L22+AA22+AB22) -> 804.60162 | AQ22: =C22+H22+L22+AA22+AB22+AN22+AO22+AP22 -> 0
A23: Heat Exchange & Transfers | AQ23: =C23+H23+L23+AA23+AB23+AN23+AO23+AP23 -> 0
A24: Other Exchange & Transfers | C24: =SUM(D24:G24) -> 22.240062 | D24: -17.141361 | E24: =-D24-V24 -> 39.381423 | L24: =SUM(N24:Z24) -> -24.684016 | N24: 30.880435 | P24: -31.331711 | Q24: 361.9108 | R24: -361.12225 | S24: -0.17168421 | U24: -2.6095464 | V24: -22.240062 | W24: 0 | AB24: =SUM(AC24:AM24) -> 0 | AQ24: =C24+H24+L24+AA24+AB24+AN24+AO24+AP24 -> -2.4439548
A25: Own Use and Distribution Losses | C25: =SUM(D25:G25) -> 0 | H25: =SUM(I25:K25) -> 10.283248 | I25: 10.283248 | L25: =SUM(O25:Z25) -> 98.284658 | O25: 95.274692 | S25: 0 | T25: 0.0041693256 | U25: 3.0057963 | AA25: 57.5286 | AB25: =SUM(AC25:AI25) -> 0 | AO25: 259.46681 | AQ25: =C25+H25+L25+AA25+AB25+AN25+AO25+AP25 -> 425.56332
A26: Available Final Energy Consumption | C26: =C7-C9+C15+C21-C25 -> 320.1576 | D26: =D7-D9+D15+D21-D25 -> 221.42916 | E26: =E7-E9+E15+E21-E25 -> 86.198592 | F26: =F7-F9+F15+F21-F25 -> 0 | G26: =G7-G9+G15+G21-G25 -> 12.529851 | H26: =H7-H9+H15+H21-H25 -> 199.3142 | I26: =I7-I9+I15+I21-I25 -> 0.37225107 | J26: =J7-J9+J15+J21-J25 -> 127.704 | ... AP26: =AP7-AP9+AP15+AP21-AP25 -> 0 | AQ26: =C26+H26+L26+AA26+AB26+AN26+AO26+AP26 -> 12596.668
A27: Non-Energy Consumption | C27: =C28 -> 0 | D27: =D28 -> 0 | E27: =E28 -> 0 | F27: =F28 -> 0 | G27: =G28 -> 0 | H27: =H28 -> 0 | I27: =I28 -> 0 | J27: =J28 -> 0 | ... V27: =V28 -> 0 | X27: =X28 -> 195.36275 | Y27: =Y28 -> 1.2096467 | Z27: =Z28 -> 35.010885 | AA27: =AA28 -> 0 | AB27: =AB28 -> 0 | AC27: =AC28 -> 0 | AD27: =AD28 -> 0 | AE27: =AE28 -> 0 | ... AQ27: =AQ28 -> 231.58328
A28: Final non-Energy Consumption (Feedstocks) | C28: =SUM(D28:G28) -> 0 | H28: =SUM(I28:K28) -> 0 | L28: =SUM(M28:Z28) -> 231.58328 | X28: =X26 -> 195.36275 | Y28: =Y26 -> 1.2096467 | Z28: =Z26 -> 35.010885 | AA28: 0 | AB28: =SUM(AC28:AI28) -> 0 | AQ28: =C28+H28+L28+AA28+AB28+AN28+AO28+AP28 -> 231.58328
A29: Total Final Energy Consumption | C29: =C30+C45+C56+C58+C65+C70+C71 -> 322.73713 | D29: =D30+D45+D56+D58+D65+D70+D71 -> 221.25199 | E29: =E30+E45+E56+E58+E65+E70+E71 -> 89.64728 | F29: =F30+F45+F56+F58+F65+F70+F71 -> 0 | G29: =G30+G45+G56+G58+G65+G70+G71 -> 11.837385 | H29: =H30+H45+H56+H58+H65+H70+H71 -> 197.36847 | I29: =I30+I45+I56+I58+I65+I70+I71 -> 0.82966372 | J29: =J30+J45+J56+J58+J65+J70+J71 -> 127.704 | ... AQ29: =AQ30+AQ45+AQ56+AQ58+AQ65+AQ70+AQ71 -> 12441.76
A30: Industry* | C30: =SUM(C31:C44) -> 105.42503 | D30: 105.42455 | E30: 0 | H30: =SUM(H31:H44) -> 0.82966372 | I30: =SUM(I31:I44) -> 0.82966372 | J30: =SUM(J31:J44) -> 0 | K30: =SUM(K31:K44) -> 0 | L30: =SUM(L31:L44) -> 333.21701 | M30: =SUM(M31:M44) -> 0 | N30: =SUM(N31:N44) -> 0 | O30: =SUM(O31:O44) -> 0 | P30: =SUM(P31:P44) -> 0 | Q30: 5.8273118 | R30: =SUM(R31:R44) -> 0 | S30: 30.396553 | T30: 55.10581 | U30: 100.77893 | V30: 141.1084 | W30: =SUM(W31:W44) -> 0 | X30: =SUM(X31:X44) -> 0 | Y30: =SUM(Y31:Y44) -> 0 | Z30: =SUM(Z31:Z44) -> 0 | AA30: 1006.4294 | AB30: =SUM(AB31:AB44) -> 198.81521 | AC30: =SUM(AC31:AC44) -> 0 | AD30: =SUM(AD31:AD44) -> 0 | AE30: =SUM(AE31:AE44) -> 153.96699 | AF30: =SUM(AF31:AF44) -> 40.692904 | AG30: =SUM(AG31:AG44) -> 0 | AH30: =SUM(AH31:AH44) -> 4.1553164 | AI30: =SUM(AI31:AI44) -> 0 | ... AN30: =SUM(AN31:AN44) -> 54.72294 | AO30: 562.37095 | AP30: =SUM(AP31:AP44) -> 0 | AQ30: =C30+H30+L30+AA30+AB30+AN30+AO30+AP30 -> 2261.8102
A31: Non-Energy Mining | B31: 05-09 | C31: =SUM(D31:G31) -> 0 | D31: 0 | H31: =SUM(I31:K31) -> 0 | L31: =SUM(M31:Z31) -> 15.076944 | Q31: 0.252 | S31: 0 | T31: 0.090944232 | U31: 14.734 | V31: 0 | AA31: 11.321518 | AB31: =SUM(AC31:AM31) -> 0 | AO31: 18.942945 | AQ31: =C31+H31+L31+AA31+AB31+AN31+AO31+AP31 -> 45.341408
A32: Food & beverages | B32: 10-11 | C32: =SUM(D32:G32) -> 18.505816 | D32: 18.505816 | H32: =SUM(I32:K32) -> 0.82966372 | I32: 0.82966372 | L32: =SUM(M32:Z32) -> 65.081235 | Q32: 1.514 | S32: 22.968462 | T32: 29.495772 | U32: 11.103 | V32: 0 | AA32: 272.71139 | AB32: =SUM(AC32:AM32) -> 27.983335 | AE32: 23.828019 | AH32: 4.1553164 | AO32: 95.275089 | AQ32: =C32+H32+L32+AA32+AB32+AN32+AO32+AP32 -> 480.38653
A33: Textiles and textile products | B33: 13-14 | C33: =SUM(D33:G33) -> 0 | D33: 0 | H33: =SUM(I33:K33) -> 0 | L33: =SUM(M33:Z33) -> 4.25876 | Q33: 0.077 | S33: 0 | T33: 3.90776 | U33: 0.274 | V33: 0 | AA33: 3.3044502 | AB33: =SUM(AC33:AM33) -> 0 | AO33: 2.6521774 | AQ33: =C33+H33+L33+AA33+AB33+AN33+AO33+AP33 -> 10.215388
A34: Wood and wood products | B34: 16 | C34: =SUM(D34:G34) -> 0 | D34: 0 | H34: =SUM(I34:K34) -> 0 | L34: =SUM(M34:Z34) -> 3.2131896 | Q34: 0.177 | S34: 0 | T34: 0.60818955 | U34: 2.428 | V34: 0 | AA34: 9.6605546 | AB34: =SUM(AC34:AM34) -> 127.9132 | AE34: 127.9132 | AO34: 24.722009 | AQ34: =C34+H34+L34+AA34+AB34+AN34+AO34+AP34 -> 165.50895
A35: Pulp, paper, publishing and printing | B35: 17-18 | C35: =SUM(D35:G35) -> 0 | D35: 0 | H35: =SUM(I35:K35) -> 0 | L35: =SUM(M35:Z35) -> 1.6055046 | Q35: 0.096 | S35: 0 | T35: 0.6295046 | U35: 0.88 | V35: 0 | AA35: 14.125994 | AB35: =SUM(AC35:AM35) -> 0 | AO35: 10.336268 | AQ35: =C35+H35+L35+AA35+AB35+AN35+AO35+AP35 -> 26.067767
A36: Chemicals & man-made fibres | B36: 20-21 | C36: =SUM(D36:G36) -> 0 | D36: 0 | H36: =SUM(I36:K36) -> 0 | L36: =SUM(M36:Z36) -> 21.418897 | Q36: 0.306 | S36: 2.7458234 | T36: 3.9702841 | U36: 4.579 | V36: 9.8177897 | AA36: 129.58451 | AB36: =SUM(AC36:AM36) -> 0 | AE36: 0 | AO36: 76.140196 | AQ36: =C36+H36+L36+AA36+AB36+AN36+AO36+AP36 -> 227.1436
A37: Rubber and plastic products | B37: 22 | C37: =SUM(D37:G37) -> 0 | D37: 0 | H37: =SUM(I37:K37) -> 0 | L37: =SUM(M37:Z37) -> 4.1927666 | Q37: 0.535 | S37: 0 | T37: 2.1897666 | U37: 1.468 | V37: 0 | AA37: 17.456036 | AB37: =SUM(AC37:AM37) -> 0 | AO37: 25.060497 | AQ37: =C37+H37+L37+AA37+AB37+AN37+AO37+AP37 -> 46.7093
A38: Other non-metallic mineral products | B38: 23 | C38: =SUM(D38:G38) -> 86.919212 | D38: 86.919212 | H38: =SUM(I38:K38) -> 0 | L38: =SUM(M38:Z38) -> 160.32357 | Q38: 1.144 | S38: 0 | T38: 2.6359617 | U38: 25.253 | V38: 131.29061 | AA38: 46.760405 | AB38: =SUM(AC38:AM38) -> 42.918678 | AE38: 2.2257741 | AF38: 40.692904 | AN38: 54.72294 | AO38: 73.686158 | AQ38: =C38+H38+L38+AA38+AB38+AN38+AO38+AP38 -> 465.33096
A39: Basic metals and fabricated metal products | B39: 24-25 | C39: =SUM(D39:G39) -> 0 | D39: 0 | H39: =SUM(I39:K39) -> 0 | L39: =SUM(M39:Z39) -> 5.6776554 | Q39: 0.338 | S39: 1.0397615 | T39: 1.5488939 | U39: 2.751 | V39: 0 | AA39: 411.95146 | AB39: =SUM(AC39:AM39) -> 0 | AO39: 67.595438 | AQ39: =C39+H39+L39+AA39+AB39+AN39+AO39+AP39 -> 485.22456
A40: Machinery and equipment n.e.c. | B40: 28 | C40: =SUM(D40:G40) -> 0 | D40: 0 | H40: =SUM(I40:K40) -> 0 | L40: =SUM(M40:Z40) -> 4.0583976 | Q40: 0.144 | S40: 0 | T40: 2.2053976 | U40: 1.709 | V40: 0 | AA40: 14.088543 | AB40: =SUM(AC40:AM40) -> 0 | AO40: 17.03379 | AQ40: =C40+H40+L40+AA40+AB40+AN40+AO40+AP40 -> 35.180731
...

Sheet Regions
C3: {=IF(LEFT(INDEX(C5:C7,$A$4),1)<>"*",INDEX(C5:C7,$A$4),"")} -> IE | D3: {=IF(LEFT(INDEX(D5:D7,$A$4),1)<>"*",INDEX(D5:D7,$A$4),"")} | E3: {=IF(LEFT(INDEX(E5:E7,$A$4),1)<>"*",INDEX(E5:E7,$A$4),"")} -> IE-CW | F3: {=IF(LEFT(INDEX(F5:F7,$A$4),1)<>"*",INDEX(F5:F7,$A$4),"")} -> IE-D | G3: {=IF(LEFT(INDEX(G5:G7,$A$4),1)<>"*",INDEX(G5:G7,$A$4),"")} -> IE-KE | H3: {=IF(LEFT(INDEX(H5:H7,$A$4),1)<>"*",INDEX(H5:H7,$A$4),"")} -> IE-KK | I3: {=IF(LEFT(INDEX(I5:I7,$A$4),1)<>"*",INDEX(I5:I7,$A$4),"")} -> IE-LS | J3: {=IF(LEFT(INDEX(J5:J7,$A$4),1)<>"*",INDEX(J5:J7,$A$4),"")} -> IE-LD | ... AD3: {=IF(LEFT(INDEX(AD5:AD7,$A$4),1)<>"*",INDEX(AD5:AD7,$A$4),"")} -> IE-MN
A4: 1
A5: Development | C5: IE | D5: *National | E5: =Regions!A11 -> IE-CW | F5: =Regions!A16 -> IE-D | G5: =Regions!A19 -> IE-KE | H5: =Regions!A20 -> IE-KK | I5: =Regions!A21 -> IE-LS | J5: =Regions!A24 -> IE-LD | K5: =Regions!A25 -> IE-LH | L5: =Regions!A27 -> IE-MH | M5: =Regions!A29 -> IE-OY | N5: =Regions!A34 -> IE-WH | O5: =Regions!A35 -> IE-WX | P5: =Regions!A36 -> IE-WW | Q5: =Regions!A13 -> IE-CE | R5: =Regions!A14 -> IE-CO | S5: =Regions!A18 -> IE-KY | T5: =Regions!A23 -> IE-LK | U5: =Regions!A32 -> IE-TA | V5: =Regions!A33 -> IE-WD | W5: =Regions!A17 -> IE-G | X5: =Regions!A22 -> IE-LM | Y5: =Regions!A26 -> IE-MO | Z5: =Regions!A30 -> IE-RN | AA5: =Regions!A31 -> IE-SO | AB5: =Regions!A12 -> IE-CN | AC5: =Regions!A15 -> IE-DL | AD5: =Regions!A28 -> IE-MN
A6: Single-region | C6: =C5 -> IE | D6: =IF(LEFT(D5,1)<>"*","*"&D5,D5) -> *National | E6: =IF(LEFT(E5,1)<>"*","*"&E5,E5) -> *IE-CW | F6: =IF(LEFT(F5,1)<>"*","*"&F5,F5) -> *IE-D | G6: =IF(LEFT(G5,1)<>"*","*"&G5,G5) -> *IE-KE | H6: =IF(LEFT(H5,1)<>"*","*"&H5,H5) -> *IE-KK | I6: =IF(LEFT(I5,1)<>"*","*"&I5,I5) -> *IE-LS | J6: =IF(LEFT(J5,1)<>"*","*"&J5,J5) -> *IE-LD | K6: =IF(LEFT(K5,1)<>"*","*"&K5,K5) -> *IE-LH | ... AD6: =IF(LEFT(AD5,1)<>"*","*"&AD5,AD5) -> *IE-MN
A7: Multi-region | C7: ="*"&C5 -> *IE | D7: =D5 -> *National | E7: =E5 -> IE-CW | F7: =F5 -> IE-D | G7: =G5 -> IE-KE | H7: =H5 -> IE-KK | I7: =I5 -> IE-LS | J7: =J5 -> IE-LD | K7: =K5 -> IE-LH | ... AD7: =AD5 -> IE-MN
A10: Code | B10: County name
A11: IE-CW | B11: Carlow
A12: IE-CN | B12: Cavan
A13: IE-CE | B13: Clare
A14: IE-CO | B14: Cork
A15: IE-DL | B15: Donegal
A16: IE-D | B16: Dublin
A17: IE-G | B17: Galway
A18: IE-KY | B18: Kerry
A19: IE-KE | B19: Kildare
A20: IE-KK | B20: Kilkenny
A21: IE-LS | B21: Laois
... A36: IE-WW | B36: Wicklow
A37: Source: https://en.wikipedia.org/wiki/ISO_3166-2:IE

Sheet Commodities
A1: Commodities
A3: ~FI_Comm
A4: Csets | B4: Region | C4: CommName | D4: CommDesc | E4: Unit | F4: LimType | G4: CTSLvl | H4: PeakTS | I4: Ctype
A5: *Commodity Set Membership | B5: Region | C5: Commodity Name | D5: Commodity Description | E5: Unit | F5: Balance equation | G5: Timeslice Level | H5: Peak Monitoring | I5: Electricity Indicator
A6: NRG | B6: =_xlfn.TEXTJOIN(",",TRUE,Regions!$C$3:'Regions'!$AD$3) -> IE,IE-CW,IE-D,IE-KE,IE-KK,IE-LS,IE-LD,IE-LH,IE-MH,IE-OY,IE-WH,IE-WX,IE-WW,IE-CE,IE-CO,IE-KY,IE-LK,IE-TA,IE-WD,IE-G,IE-LM,IE-MO,IE-RN,IE-SO,IE-CN,IE-DL,IE-MN | C6: TRAWLK | D6: Walking (TRA) | E6: PJ
B7: =_xlfn.TEXTJOIN(",",TRUE,Regions!$C$3:'Regions'!$AD$3) -> IE,IE-CW,IE-D,IE-KE,IE-KK,IE-LS,IE-LD,IE-LH,IE-MH,IE-OY,IE-WH,IE-WX,IE-WW,IE-CE,IE-CO,IE-KY,IE-LK,IE-TA,IE-WD,IE-G,IE-LM,IE-MO,IE-RN,IE-SO,IE-CN,IE-DL,IE-MN | C7: TRACYC | D7: Cycling (TRA) | E7: PJ
B8: =_xlfn.TEXTJOIN(",",TRUE,Regions!$C$3:'Regions'!$AD$3) -> IE,IE-CW,IE-D,IE-KE,IE-KK,IE-LS,IE-LD,IE-LH,IE-MH,IE-OY,IE-WH,IE-WX,IE-WW,IE-CE,IE-CO,IE-KY,IE-LK,IE-TA,IE-WD,IE-G,IE-LM,IE-MO,IE-RN,IE-SO,IE-CN,IE-DL,IE-MN | C8: TRAGSL | D8: Gasoline (TRA) | E8: PJ | F8: FX
B9: =_xlfn.TEXTJOIN(",",TRUE,Regions!$C$3:'Regions'!$AD$3) -> IE,IE-CW,IE-D,IE-KE,IE-KK,IE-LS,IE-LD,IE-LH,IE-MH,IE-OY,IE-WH,IE-WX,IE-WW,IE-CE,IE-CO,IE-KY,IE-LK,IE-TA,IE-WD,IE-G,IE-LM,IE-MO,IE-RN,IE-SO,IE-CN,IE-DL,IE-MN | C9: TRADST | D9: Diesel (TRA) | E9: PJ | F9: FX
B10: =_xlfn.TEXTJOIN(",",TRUE,Regions!$C$3:'Regions'!$AD$3) -> IE,IE-CW,IE-D,IE-KE,IE-KK,IE-LS,IE-LD,IE-LH,IE-MH,IE-OY,IE-WH,IE-WX,IE-WW,IE-CE,IE-CO,IE-KY,IE-LK,IE-TA,IE-WD,IE-G,IE-LM,IE-MO,IE-RN,IE-SO,IE-CN,IE-DL,IE-MN | C10: TRAETH | D10: BioEthanol (TRA) | E10: PJ | F10: FX
B11: =_xlfn.TEXTJOIN(",",TRUE,Regions!$C$3:'Regions'!$AD$3) -> IE,IE-CW,IE-D,IE-KE,IE-KK,IE-LS,IE-LD,IE-LH,IE-MH,IE-OY,IE-WH,IE-WX,IE-WW,IE-CE,IE-CO,IE-KY,IE-LK,IE-TA,IE-WD,IE-G,IE-LM,IE-MO,IE-RN,IE-SO,IE-CN,IE-DL,IE-MN | C11: TRABDL | D11: BioDiesel (TRA) | E11: PJ | F11: FX
B12: =_xlfn.TEXTJOIN(",",TRUE,Regions!$C$3:'Regions'!$AD$3) -> IE,IE-CW,IE-D,IE-KE,IE-KK,IE-LS,IE-LD,IE-LH,IE-MH,IE-OY,IE-WH,IE-WX,IE-WW,IE-CE,IE-CO,IE-KY,IE-LK,IE-TA,IE-WD,IE-G,IE-LM,IE-MO,IE-RN,IE-SO,IE-CN,IE-DL,IE-MN | C12: TRABJK | D12: Bio Jet Kerosene (TRA) | E12: PJ | F12: FX
B13: =_xlfn.TEXTJOIN(",",TRUE,Regions!$C$3:'Regions'!$AD$3) -> IE,IE-CW,IE-D,IE-KE,IE-KK,IE-LS,IE-LD,IE-LH,IE-MH,IE-OY,IE-WH,IE-WX,IE-WW,IE-CE,IE-CO,IE-KY,IE-LK,IE-TA,IE-WD,IE-G,IE-LM,IE-MO,IE-RN,IE-SO,IE-CN,IE-DL,IE-MN | C13: TRACNG | D13: CNG (TRA) | E13: PJ | F13: FX
B14: =_xlfn.TEXTJOIN(",",TRUE,Regions!$C$3:'Regions'!$AD$3) -> IE,IE-CW,IE-D,IE-KE,IE-KK,IE-LS,IE-LD,IE-LH,IE-MH,IE-OY,IE-WH,IE-WX,IE-WW,IE-CE,IE-CO,IE-KY,IE-LK,IE-TA,IE-WD,IE-G,IE-LM,IE-MO,IE-RN,IE-SO,IE-CN,IE-DL,IE-MN | C14: TRABNG | D14: BioCNG (TRA) | E14: PJ | F14: FX
B15: =_xlfn.TEXTJOIN(",",TRUE,Regions!$C$3:'Regions'!$AD$3) -> IE,IE-CW,IE-D,IE-KE,IE-KK,IE-LS,IE-LD,IE-LH,IE-MH,IE-OY,IE-WH,IE-WX,IE-WW,IE-CE,IE-CO,IE-KY,IE-LK,IE-TA,IE-WD,IE-G,IE-LM,IE-MO,IE-RN,IE-SO,IE-CN,IE-DL,IE-MN | C15: TRAELC | D15: Electricity (TRA) | E15: PJ | F15: FX | G15: DAYNITE | I15: ELC
B16: =_xlfn.TEXTJOIN(",",TRUE,Regions!$C$3:'Regions'!$AD$3) -> IE,IE-CW,IE-D,IE-KE,IE-KK,IE-LS,IE-LD,IE-LH,IE-MH,IE-OY,IE-WH,IE-WX,IE-WW,IE-CE,IE-CO,IE-KY,IE-LK,IE-TA,IE-WD,IE-G,IE-LM,IE-MO,IE-RN,IE-SO,IE-CN,IE-DL,IE-MN | C16: TRALNG | D16: LNG (TRA) | E16: PJ | F16: FX
B17: =_xlfn.TEXTJOIN(",",TRUE,Regions!$C$3:'Regions'!$AD$3) -> IE,IE-CW,IE-D,IE-KE,IE-KK,IE-LS,IE-LD,IE-LH,IE-MH,IE-OY,IE-WH,IE-WX,IE-WW,IE-CE,IE-CO,IE-KY,IE-LK,IE-TA,IE-WD,IE-G,IE-LM,IE-MO,IE-RN,IE-SO,IE-CN,IE-DL,IE-MN | C17: TRAH2 | D17: Hydrogen (TRA) | E17: PJ | F17: FX
B18: =_xlfn.TEXTJOIN(",",TRUE,Regions!$C$3:'Regions'!$AD$3) -> IE,IE-CW,IE-D,IE-KE,IE-KK,IE-LS,IE-LD,IE-LH,IE-MH,IE-OY,IE-WH,IE-WX,IE-WW,IE-CE,IE-CO,IE-KY,IE-LK,IE-TA,IE-WD,IE-G,IE-LM,IE-MO,IE-RN,IE-SO,IE-CN,IE-DL,IE-MN | C18: TRAKER | D18: Kerosene (TRA) | E18: PJ | F18: FX
B19: =B18 -> IE,IE-CW,IE-D,IE-KE,IE-KK,IE-LS,IE-LD,IE-LH,IE-MH,IE-OY,IE-WH,IE-WX,IE-WW,IE-CE,IE-CO,IE-KY,IE-LK,IE-TA,IE-WD,IE-G,IE-LM,IE-MO,IE-RN,IE-SO,IE-CN,IE-DL,IE-MN | C19: TRAPtLKER | D19: Power to Liquid, pure synthetic kerosene (TRA) | E19: PJ | F19: FX
B20: =B19 -> IE,IE-CW,IE-D,IE-KE,IE-KK,IE-LS,IE-LD,IE-LH,IE-MH,IE-OY,IE-WH,IE-WX,IE-WW,IE-CE,IE-CO,IE-KY,IE-LK,IE-TA,IE-WD,IE-G,IE-LM,IE-MO,IE-RN,IE-SO,IE-CN,IE-DL,IE-MN | C20: AVIKER | D20: Kerosene for Aviation | E20: PJ | F20: FX
B21: =B20 -> IE,IE-CW,IE-D,IE-KE,IE-KK,IE-LS,IE-LD,IE-LH,IE-MH,IE-OY,IE-WH,IE-WX,IE-WW,IE-CE,IE-CO,IE-KY,IE-LK,IE-TA,IE-WD,IE-G,IE-LM,IE-MO,IE-RN,IE-SO,IE-CN,IE-DL,IE-MN | C21: AVIBJK | D21: Biojet kerosene or SAF for Aviation | E21: PJ | F21: FX
B22: =B21 -> IE,IE-CW,IE-D,IE-KE,IE-KK,IE-LS,IE-LD,IE-LH,IE-MH,IE-OY,IE-WH,IE-WX,IE-WW,IE-CE,IE-CO,IE-KY,IE-LK,IE-TA,IE-WD,IE-G,IE-LM,IE-MO,IE-RN,IE-SO,IE-CN,IE-DL,IE-MN | C22: AVIELC | D22: Electricity for Aviation | E22: PJ | F22: FX
B23: =B22 -> IE,IE-CW,IE-D,IE-KE,IE-KK,IE-LS,IE-LD,IE-LH,IE-MH,IE-OY,IE-WH,IE-WX,IE-WW,IE-CE,IE-CO,IE-KY,IE-LK,IE-TA,IE-WD,IE-G,IE-LM,IE-MO,IE-RN,IE-SO,IE-CN,IE-DL,IE-MN | C23: AVIH2 | D23: Hydrogen for Aviation | E23: PJ | F23: FX
B24: =B23 -> IE,IE-CW,IE-D,IE-KE,IE-KK,IE-LS,IE-LD,IE-LH,IE-MH,IE-OY,IE-WH,IE-WX,IE-WW,IE-CE,IE-CO,IE-KY,IE-LK,IE-TA,IE-WD,IE-G,IE-LM,IE-MO,IE-RN,IE-SO,IE-CN,IE-DL,IE-MN | C24: AVIPtL | D24: Syntethic fuel for Aviation | E24: PJ | F24: FX
A25: DEM | B25: =_xlfn.TEXTJOIN(",",TRUE,Regions!$C$3:'Regions'!$AD$3) -> IE,IE-CW,IE-D,IE-KE,IE-KK,IE-LS,IE-LD,IE-LH,IE-MH,IE-OY,IE-WH,IE-WX,IE-WW,IE-CE,IE-CO,IE-KY,IE-LK,IE-TA,IE-WD,IE-G,IE-LM,IE-MO,IE-RN,IE-SO,IE-CN,IE-DL,IE-MN | C25: TRAPS | D25: Transport Demand: Short-range passenger travels | E25: Bpkm
B26: =_xlfn.TEXTJOIN(",",TRUE,Regions!$C$3:'Regions'!$AD$3) -> IE,IE-CW,IE-D,IE-KE,IE-KK,IE-LS,IE-LD,IE-LH,IE-MH,IE-OY,IE-WH,IE-WX,IE-WW,IE-CE,IE-CO,IE-KY,IE-LK,IE-TA,IE-WD,IE-G,IE-LM,IE-MO,IE-RN,IE-SO,IE-CN,IE-DL,IE-MN | C26: TRAPM | D26: Transport Demand: Medium-range passenger travels | E26: Bpkm
B27: =_xlfn.TEXTJOIN(",",TRUE,Regions!$C$3:'Regions'!$AD$3) -> IE,IE-CW,IE-D,IE-KE,IE-KK,IE-LS,IE-LD,IE-LH,IE-MH,IE-OY,IE-WH,IE-WX,IE-WW,IE-CE,IE-CO,IE-KY,IE-LK,IE-TA,IE-WD,IE-G,IE-LM,IE-MO,IE-RN,IE-SO,IE-CN,IE-DL,IE-MN | C27: TRAPL | D27: Transport Demand: Long-range passenger travels | E27: Bpkm
B28: =_xlfn.TEXTJOIN(",",TRUE,Regions!$C$3:'Regions'!$AD$3) -> IE,IE-CW,IE-D,IE-KE,IE-KK,IE-LS,IE-LD,IE-LH,IE-MH,IE-OY,IE-WH,IE-WX,IE-WW,IE-CE,IE-CO,IE-KY,IE-LK,IE-TA,IE-WD,IE-G,IE-LM,IE-MO,IE-RN,IE-SO,IE-CN,IE-DL,IE-MN | C28: TRAF | D28: Transport Demand: Goods vehicle for freight | E28: Btkm
B29: =_xlfn.TEXTJOIN(",",TRUE,Regions!$C$3:'Regions'!$AD$3) -> IE,IE-CW,IE-D,IE-KE,IE-KK,IE-LS,IE-LD,IE-LH,IE-MH,IE-OY,IE-WH,IE-WX,IE-WW,IE-CE,IE-CO,IE-KY,IE-LK,IE-TA,IE-WD,IE-G,IE-LM,IE-MO,IE-RN,IE-SO,IE-CN,IE-DL,IE-MN | C29: TTURS | D29: Transport Demand: Turism fuel | E29: PJ
B30: =_xlfn.TEXTJOIN(",",TRUE,Regions!$C$3:'Regions'!$AD$3) -> IE,IE-CW,IE-D,IE-KE,IE-KK,IE-LS,IE-LD,IE-LH,IE-MH,IE-OY,IE-WH,IE-WX,IE-WW,IE-CE,IE-CO,IE-KY,IE-LK,IE-TA,IE-WD,IE-G,IE-LM,IE-MO,IE-RN,IE-SO,IE-CN,IE-DL,IE-MN | C30: TNAV | D30: Transport Demand: Navigation fuel | E30: PJ
B31: =_xlfn.TEXTJOIN(",",TRUE,Regions!$C$3:'Regions'!$AD$3) -> IE,IE-CW,IE-D,IE-KE,IE-KK,IE-LS,IE-LD,IE-LH,IE-MH,IE-OY,IE-WH,IE-WX,IE-WW,IE-CE,IE-CO,IE-KY,IE-LK,IE-TA,IE-WD,IE-G,IE-LM,IE-MO,IE-RN,IE-SO,IE-CN,IE-DL,IE-MN | C31: TOTH | D31: Transport Demand: Unspecified fuel | E31: PJ
B32: =_xlfn.TEXTJOIN(",",TRUE,Regions!$C$3:'Regions'!$AD$3) -> IE,IE-CW,IE-D,IE-KE,IE-KK,IE-LS,IE-LD,IE-LH,IE-MH,IE-OY,IE-WH,IE-WX,IE-WW,IE-CE,IE-CO,IE-KY,IE-LK,IE-TA,IE-WD,IE-G,IE-LM,IE-MO,IE-RN,IE-SO,IE-CN,IE-DL,IE-MN | C32: TAVIDOM | D32: Transport Demand: Aviation domestic | E32: PJ
B33: =_xlfn.TEXTJOIN(",",TRUE,Regions!$C$3:'Regions'!$AD$3) -> IE,IE-CW,IE-D,IE-KE,IE-KK,IE-LS,IE-LD,IE-LH,IE-MH,IE-OY,IE-WH,IE-WX,IE-WW,IE-CE,IE-CO,IE-KY,IE-LK,IE-TA,IE-WD,IE-G,IE-LM,IE-MO,IE-RN,IE-SO,IE-CN,IE-DL,IE-MN | C33: TAVIINT | D33: Transport Demand: Aviation international | E33: PJ
B34: =_xlfn.TEXTJOIN(",",TRUE,Regions!$C$3:'Regions'!$AD$3) -> IE,IE-CW,IE-D,IE-KE,IE-KK,IE-LS,IE-LD,IE-LH,IE-MH,IE-OY,IE-WH,IE-WX,IE-WW,IE-CE,IE-CO,IE-KY,IE-LK,IE-TA,IE-WD,IE-G,IE-LM,IE-MO,IE-RN,IE-SO,IE-CN,IE-DL,IE-MN | C34: TAVIINTS | D34: Transport Demand: Aviation international_Short | E34: Bpkm
B35: =_xlfn.TEXTJOIN(",",TRUE,Regions!$C$3:'Regions'!$AD$3) -> IE,IE-CW,IE-D,IE-KE,IE-KK,IE-LS,IE-LD,IE-LH,IE-MH,IE-OY,IE-WH,IE-WX,IE-WW,IE-CE,IE-CO,IE-KY,IE-LK,IE-TA,IE-WD,IE-G,IE-LM,IE-MO,IE-RN,IE-SO,IE-CN,IE-DL,IE-MN | C35: TAVIINTM | D35: Transport Demand: Aviation international_Medium | E35: Bpkm
B36: =_xlfn.TEXTJOIN(",",TRUE,Regions!$C$3:'Regions'!$AD$3) -> IE,IE-CW,IE-D,IE-KE,IE-KK,IE-LS,IE-LD,IE-LH,IE-MH,IE-OY,IE-WH,IE-WX,IE-WW,IE-CE,IE-CO,IE-KY,IE-LK,IE-TA,IE-WD,IE-G,IE-LM,IE-MO,IE-RN,IE-SO,IE-CN,IE-DL,IE-MN | C36: TAVIINTL | D36: Transport Demand: Aviation international_Long | E36: Bpkm
A37: ENV | B37: =_xlfn.TEXTJOIN(",",TRUE,Regions!$C$3:'Regions'!$AD$3) -> IE,IE-CW,IE-D,IE-KE,IE-KK,IE-LS,IE-LD,IE-LH,IE-MH,IE-OY,IE-WH,IE-WX,IE-WW,IE-CE,IE-CO,IE-KY,IE-LK,IE-TA,IE-WD,IE-G,IE-LM,IE-MO,IE-RN,IE-SO,IE-CN,IE-DL,IE-MN | C37: TRACO2N | D37: Carbon Dioxide - Combustion (TRA) | E37: kt
B38: =_xlfn.TEXTJOIN(",",TRUE,Regions!$C$3:'Regions'!$AD$3) -> IE,IE-CW,IE-D,IE-KE,IE-KK,IE-LS,IE-LD,IE-LH,IE-MH,IE-OY,IE-WH,IE-WX,IE-WW,IE-CE,IE-CO,IE-KY,IE-LK,IE-TA,IE-WD,IE-G,IE-LM,IE-MO,IE-RN,IE-SO,IE-CN,IE-DL,IE-MN | C38: TRACH4N | D38: Methane (TRA) | E38: kt
B39: =_xlfn.TEXTJOIN(",",TRUE,Regions!$C$3:'Regions'!$AD$3) -> IE,IE-CW,IE-D,IE-KE,IE-KK,IE-LS,IE-LD,IE-LH,IE-MH,IE-OY,IE-WH,IE-WX,IE-WW,IE-CE,IE-CO,IE-KY,IE-LK,IE-TA,IE-WD,IE-G,IE-LM,IE-MO,IE-RN,IE-SO,IE-CN,IE-DL,IE-MN | C39: TRASO2N | D39: Sulphur Oxides (TRA) | E39: kt
B40: =_xlfn.TEXTJOIN(",",TRUE,Regions!$C$3:'Regions'!$AD$3) -> IE,IE-CW,IE-D,IE-KE,IE-KK,IE-LS,IE-LD,IE-LH,IE-MH,IE-OY,IE-WH,IE-WX,IE-WW,IE-CE,IE-CO,IE-KY,IE-LK,IE-TA,IE-WD,IE-G,IE-LM,IE-MO,IE-RN,IE-SO,IE-CN,IE-DL,IE-MN | C40: TRANOXN | D40: Nitrogen Oxide (TRA) | E40: kt
B41: =_xlfn.TEXTJOIN(",",TRUE,Regions!$C$3:'Regions'!$AD$3) -> IE,IE-CW,IE-D,IE-KE,IE-KK,IE-LS,IE-LD,IE-LH,IE-MH,IE-OY,IE-WH,IE-WX,IE-WW,IE-CE,IE-CO,IE-KY,IE-LK,IE-TA,IE-WD,IE-G,IE-LM,IE-MO,IE-RN,IE-SO,IE-CN,IE-DL,IE-MN | C41: TRAPM10 | D41: Particulate Matter <10 µm (TRA) | E41: kt
...

Sheet Processes
B2: ~FI_Process
B3: Sets | C3: Region | D3: TechName | E3: TechDesc | F3: Tact | G3: Tcap | H3: Tslvl | I3: PrimaryCG | J3: Vintage
B4: *Passengers
B5: *Active modes
B6: DMD | C6: =_xlfn.TEXTJOIN(",",TRUE,Regions!$C$3:'Regions'!$AD$3) -> IE,IE-CW,IE-D,IE-KE,IE-KK,IE-LS,IE-LD,IE-LH,IE-MH,IE-OY,IE-WH,IE-WX,IE-WW,IE-CE,IE-CO,IE-KY,IE-LK,IE-TA,IE-WD,IE-G,IE-LM,IE-MO,IE-RN,IE-SO,IE-CN,IE-DL,IE-MN | D6: T-WLK_WLK | E6: TRA Walking | F6: Bpkm | G6: kUnits
B7: DMD | C7: =_xlfn.TEXTJOIN(",",TRUE,Regions!$C$3:'Regions'!$AD$3) -> IE,IE-CW,IE-D,IE-KE,IE-KK,IE-LS,IE-LD,IE-LH,IE-MH,IE-OY,IE-WH,IE-WX,IE-WW,IE-CE,IE-CO,IE-KY,IE-LK,IE-TA,IE-WD,IE-G,IE-LM,IE-MO,IE-RN,IE-SO,IE-CN,IE-DL,IE-MN | D7: T-CYC_CYC | E7: TRA Cycling | F7: Bpkm | G7: kUnits
B8: *Two-wheelers
B9: DMD | C9: =_xlfn.TEXTJOIN(",",TRUE,Regions!$C$3:'Regions'!$AD$3) -> IE,IE-CW,IE-D,IE-KE,IE-KK,IE-LS,IE-LD,IE-LH,IE-MH,IE-OY,IE-WH,IE-WX,IE-WW,IE-CE,IE-CO,IE-KY,IE-LK,IE-TA,IE-WD,IE-G,IE-LM,IE-MO,IE-RN,IE-SO,IE-CN,IE-DL,IE-MN | D9: T-MOT-ICE_GSL00 | E9: TRA Motorcycles: Gasoline ICEs - Existing | F9: Bpkm | G9: kUnits
B10: *Private cars
B11: DMD | C11: =_xlfn.TEXTJOIN(",",TRUE,Regions!$C$3:'Regions'!$AD$3) -> IE,IE-CW,IE-D,IE-KE,IE-KK,IE-LS,IE-LD,IE-LH,IE-MH,IE-OY,IE-WH,IE-WX,IE-WW,IE-CE,IE-CO,IE-KY,IE-LK,IE-TA,IE-WD,IE-G,IE-LM,IE-MO,IE-RN,IE-SO,IE-CN,IE-DL,IE-MN | D11: T-CAR-ICE_GSL00 | E11: TRA Cars: Gasoline ICEs - Existing | F11: Bpkm | G11: kUnits
B12: DMD | C12: =_xlfn.TEXTJOIN(",",TRUE,Regions!$C$3:'Regions'!$AD$3) -> IE,IE-CW,IE-D,IE-KE,IE-KK,IE-LS,IE-LD,IE-LH,IE-MH,IE-OY,IE-WH,IE-WX,IE-WW,IE-CE,IE-CO,IE-KY,IE-LK,IE-TA,IE-WD,IE-G,IE-LM,IE-MO,IE-RN,IE-SO,IE-CN,IE-DL,IE-MN | D12: T-CAR-ICE_DST00 | E12: TRA Cars: Diesel ICEs - Existing | F12: Bpkm | G12: kUnits
B13: DMD | C13: =_xlfn.TEXTJOIN(",",TRUE,Regions!$C$3:'Regions'!$AD$3) -> IE,IE-CW,IE-D,IE-KE,IE-KK,IE-LS,IE-LD,IE-LH,IE-MH,IE-OY,IE-WH,IE-WX,IE-WW,IE-CE,IE-CO,IE-KY,IE-LK,IE-TA,IE-WD,IE-G,IE-LM,IE-MO,IE-RN,IE-SO,IE-CN,IE-DL,IE-MN | D13: T-CAR-ICE_DF00 | E13: TRA Cars: Dual fuel ICEs - Existing | F13: Bpkm | G13: kUnits
B14: DMD | C14: =_xlfn.TEXTJOIN(",",TRUE,Regions!$C$3:'Regions'!$AD$3) -> IE,IE-CW,IE-D,IE-KE,IE-KK,IE-LS,IE-LD,IE-LH,IE-MH,IE-OY,IE-WH,IE-WX,IE-WW,IE-CE,IE-CO,IE-KY,IE-LK,IE-TA,IE-WD,IE-G,IE-LM,IE-MO,IE-RN,IE-SO,IE-CN,IE-DL,IE-MN | D14: T-CAR-ICE_E8500 | E14: TRA Cars: Flex fuel ICEs - Existing | F14: Bpkm | G14: kUnits
B15: DMD | C15: =_xlfn.TEXTJOIN(",",TRUE,Regions!$C$3:'Regions'!$AD$3) -> IE,IE-CW,IE-D,IE-KE,IE-KK,IE-LS,IE-LD,IE-LH,IE-MH,IE-OY,IE-WH,IE-WX,IE-WW,IE-CE,IE-CO,IE-KY,IE-LK,IE-TA,IE-WD,IE-G,IE-LM,IE-MO,IE-RN,IE-SO,IE-CN,IE-DL,IE-MN | D15: T-CAR-HEV_GSL00 | E15: TRA Cars: Gasoline HEV - Existing | F15: Bpkm | G15: kUnits
B16: DMD | C16: =_xlfn.TEXTJOIN(",",TRUE,Regions!$C$3:'Regions'!$AD$3) -> IE,IE-CW,IE-D,IE-KE,IE-KK,IE-LS,IE-LD,IE-LH,IE-MH,IE-OY,IE-WH,IE-WX,IE-WW,IE-CE,IE-CO,IE-KY,IE-LK,IE-TA,IE-WD,IE-G,IE-LM,IE-MO,IE-RN,IE-SO,IE-CN,IE-DL,IE-MN | D16: T-CAR-HEV_DST00 | E16: TRA Cars: Diesel HEV - Existing | F16: Bpkm | G16: kUnits
B17: DMD | C17: =_xlfn.TEXTJOIN(",",TRUE,Regions!$C$3:'Regions'!$AD$3) -> IE,IE-CW,IE-D,IE-KE,IE-KK,IE-LS,IE-LD,IE-LH,IE-MH,IE-OY,IE-WH,IE-WX,IE-WW,IE-CE,IE-CO,IE-KY,IE-LK,IE-TA,IE-WD,IE-G,IE-LM,IE-MO,IE-RN,IE-SO,IE-CN,IE-DL,IE-MN | D17: T-CAR-PHEV_GSL00 | E17: TRA Cars: Gasoline PHEV - Existing | F17: Bpkm | G17: kUnits
B18: DMD | C18: =_xlfn.TEXTJOIN(",",TRUE,Regions!$C$3:'Regions'!$AD$3) -> IE,IE-CW,IE-D,IE-KE,IE-KK,IE-LS,IE-LD,IE-LH,IE-MH,IE-OY,IE-WH,IE-WX,IE-WW,IE-CE,IE-CO,IE-KY,IE-LK,IE-TA,IE-WD,IE-G,IE-LM,IE-MO,IE-RN,IE-SO,IE-CN,IE-DL,IE-MN | D18: T-CAR-PHEV_DST00 | E18: TRA Cars: Diesel PHEV - Existing | F18: Bpkm | G18: kUnits
B19: DMD | C19: =_xlfn.TEXTJOIN(",",TRUE,Regions!$C$3:'Regions'!$AD$3) -> IE,IE-CW,IE-D,IE-KE,IE-KK,IE-LS,IE-LD,IE-LH,IE-MH,IE-OY,IE-WH,IE-WX,IE-WW,IE-CE,IE-CO,IE-KY,IE-LK,IE-TA,IE-WD,IE-G,IE-LM,IE-MO,IE-RN,IE-SO,IE-CN,IE-DL,IE-MN | D19: T-CAR-BEV_ELC00 | E19: TRA Cars: Battery Electric Vehicle - Existing | F19: Bpkm | G19: kUnits
B20: *Small sevice vehicle
B21: DMD | C21: =_xlfn.TEXTJOIN(",",TRUE,Regions!$C$3:'Regions'!$AD$3) -> IE,IE-CW,IE-D,IE-KE,IE-KK,IE-LS,IE-LD,IE-LH,IE-MH,IE-OY,IE-WH,IE-WX,IE-WW,IE-CE,IE-CO,IE-KY,IE-LK,IE-TA,IE-WD,IE-G,IE-LM,IE-MO,IE-RN,IE-SO,IE-CN,IE-DL,IE-MN | D21: T-TAX-ICE_GSL00 | E21: TRA Taxis: Gasoline ICEs - Existing | F21: Bpkm | G21: kUnits
B22: DMD | C22: =_xlfn.TEXTJOIN(",",TRUE,Regions!$C$3:'Regions'!$AD$3) -> IE,IE-CW,IE-D,IE-KE,IE-KK,IE-LS,IE-LD,IE-LH,IE-MH,IE-OY,IE-WH,IE-WX,IE-WW,IE-CE,IE-CO,IE-KY,IE-LK,IE-TA,IE-WD,IE-G,IE-LM,IE-MO,IE-RN,IE-SO,IE-CN,IE-DL,IE-MN | D22: T-TAX-ICE_DST00 | E22: TRA Taxis: Diesel ICEs - Existing | F22: Bpkm | G22: kUnits
B23: DMD | C23: =_xlfn.TEXTJOIN(",",TRUE,Regions!$C$3:'Regions'!$AD$3) -> IE,IE-CW,IE-D,IE-KE,IE-KK,IE-LS,IE-LD,IE-LH,IE-MH,IE-OY,IE-WH,IE-WX,IE-WW,IE-CE,IE-CO,IE-KY,IE-LK,IE-TA,IE-WD,IE-G,IE-LM,IE-MO,IE-RN,IE-SO,IE-CN,IE-DL,IE-MN | D23: T-TAX-HEV_GSL00 | E23: TRA Taxis: Gasoline HEVs - Existing | F23: Bpkm | G23: kUnits
B24: *Large sevice vehicle
B25: DMD | C25: =_xlfn.TEXTJOIN(",",TRUE,Regions!$C$3:'Regions'!$AD$3) -> IE,IE-CW,IE-D,IE-KE,IE-KK,IE-LS,IE-LD,IE-LH,IE-MH,IE-OY,IE-WH,IE-WX,IE-WW,IE-CE,IE-CO,IE-KY,IE-LK,IE-TA,IE-WD,IE-G,IE-LM,IE-MO,IE-RN,IE-SO,IE-CN,IE-DL,IE-MN | D25: T-BUS-ICE_DST00 | E25: TRA BUS: Diesel ICEs - Existing | F25: Bpkm | G25: kUnits
B26: *Rail
B27: DMD | C27: =_xlfn.TEXTJOIN(",",TRUE,Regions!$C$3:'Regions'!$AD$3) -> IE,IE-CW,IE-D,IE-KE,IE-KK,IE-LS,IE-LD,IE-LH,IE-MH,IE-OY,IE-WH,IE-WX,IE-WW,IE-CE,IE-CO,IE-KY,IE-LK,IE-TA,IE-WD,IE-G,IE-LM,IE-MO,IE-RN,IE-SO,IE-CN,IE-DL,IE-MN | D27: T-LPT-BEV_ELC00 | E27: TRA Light Passenger Train: Electric - Existing | F27: Bpkm | G27: kUnits
B28: DMD | C28: =_xlfn.TEXTJOIN(",",TRUE,Regions!$C$3:'Regions'!$AD$3) -> IE,IE-CW,IE-D,IE-KE,IE-KK,IE-LS,IE-LD,IE-LH,IE-MH,IE-OY,IE-WH,IE-WX,IE-WW,IE-CE,IE-CO,IE-KY,IE-LK,IE-TA,IE-WD,IE-G,IE-LM,IE-MO,IE-RN,IE-SO,IE-CN,IE-DL,IE-MN | D28: T-HPT-BEV_ELC00 | E28: TRA Heavy Passenger Train: Electric - Existing | F28: Bpkm | G28: kUnits
B29: DMD | C29: =_xlfn.TEXTJOIN(",",TRUE,Regions!$C$3:'Regions'!$AD$3) -> IE,IE-CW,IE-D,IE-KE,IE-KK,IE-LS,IE-LD,IE-LH,IE-MH,IE-OY,IE-WH,IE-WX,IE-WW,IE-CE,IE-CO,IE-KY,IE-LK,IE-TA,IE-WD,IE-G,IE-LM,IE-MO,IE-RN,IE-SO,IE-CN,IE-DL,IE-MN | D29: T-HPT-ICE_DST00 | E29: TRA Heavy Passenger Train: Diesel - Existing | F29: Bpkm | G29: kUnits
B30: *Freight
B31: *Trucks and Rail
B32: DMD | C32: =_xlfn.TEXTJOIN(",",TRUE,Regions!$C$3:'Regions'!$AD$3) -> IE,IE-CW,IE-D,IE-KE,IE-KK,IE-LS,IE-LD,IE-LH,IE-MH,IE-OY,IE-WH,IE-WX,IE-WW,IE-CE,IE-CO,IE-KY,IE-LK,IE-TA,IE-WD,IE-G,IE-LM,IE-MO,IE-RN,IE-SO,IE-CN,IE-DL,IE-MN | D32: T-LGT-ICE_GSL00 | E32: TRA Light Goods Truck: Gasoline ICEs - Existing | F32: Btkm | G32: kUnits
B33: DMD | C33: =_xlfn.TEXTJOIN(",",TRUE,Regions!$C$3:'Regions'!$AD$3) -> IE,IE-CW,IE-D,IE-KE,IE-KK,IE-LS,IE-LD,IE-LH,IE-MH,IE-OY,IE-WH,IE-WX,IE-WW,IE-CE,IE-CO,IE-KY,IE-LK,IE-TA,IE-WD,IE-G,IE-LM,IE-MO,IE-RN,IE-SO,IE-CN,IE-DL,IE-MN | D33: T-LGT-ICE_DST00 | E33: TRA Light Goods Truck: Diesel ICEs - Existing | F33: Btkm | G33: kUnits
B34: DMD | C34: =_xlfn.TEXTJOIN(",",TRUE,Regions!$C$3:'Regions'!$AD$3) -> IE,IE-CW,IE-D,IE-KE,IE-KK,IE-LS,IE-LD,IE-LH,IE-MH,IE-OY,IE-WH,IE-WX,IE-WW,IE-CE,IE-CO,IE-KY,IE-LK,IE-TA,IE-WD,IE-G,IE-LM,IE-MO,IE-RN,IE-SO,IE-CN,IE-DL,IE-MN | D34: T-MGT-ICE_DST00 | E34: TRA Medium Goods Truck: Diesel ICEs - Existing | F34: Btkm | G34: kUnits
B35: DMD | C35: =_xlfn.TEXTJOIN(",",TRUE,Regions!$C$3:'Regions'!$AD$3) -> IE,IE-CW,IE-D,IE-KE,IE-KK,IE-LS,IE-LD,IE-LH,IE-MH,IE-OY,IE-WH,IE-WX,IE-WW,IE-CE,IE-CO,IE-KY,IE-LK,IE-TA,IE-WD,IE-G,IE-LM,IE-MO,IE-RN,IE-SO,IE-CN,IE-DL,IE-MN | D35: T-HGT-ICE_DST00 | E35: TRA Heavy Goods Truck: Diesel ICEs - Existing | F35: Btkm | G35: kUnits
B36: DMD | C36: =_xlfn.TEXTJOIN(",",TRUE,Regions!$C$3:'Regions'!$AD$3) -> IE,IE-CW,IE-D,IE-KE,IE-KK,IE-LS,IE-LD,IE-LH,IE-MH,IE-OY,IE-WH,IE-WX,IE-WW,IE-CE,IE-CO,IE-KY,IE-LK,IE-TA,IE-WD,IE-G,IE-LM,IE-MO,IE-RN,IE-SO,IE-CN,IE-DL,IE-MN | D36: T-GTR-ICE_DST00 | E36: TRA Goods Train: ICE Diesel Train - Existing | F36: Btkm | G36: kUnits
B37: *Turism, Navigation & Others
B38: DMD | C38: =_xlfn.TEXTJOIN(",",TRUE,Regions!$C$3:'Regions'!$AD$3) -> IE,IE-CW,IE-D,IE-KE,IE-KK,IE-LS,IE-LD,IE-LH,IE-MH,IE-OY,IE-WH,IE-WX,IE-WW,IE-CE,IE-CO,IE-KY,IE-LK,IE-TA,IE-WD,IE-G,IE-LM,IE-MO,IE-RN,IE-SO,IE-CN,IE-DL,IE-MN | D38: T-TUR_CON00 | E38: TRA Tourism: Conventional Tourism Vehicles - Existing | F38: PJ | G38: PJa
B39: DMD | C39: =_xlfn.TEXTJOIN(",",TRUE,Regions!$C$3:'Regions'!$AD$3) -> IE,IE-CW,IE-D,IE-KE,IE-KK,IE-LS,IE-LD,IE-LH,IE-MH,IE-OY,IE-WH,IE-WX,IE-WW,IE-CE,IE-CO,IE-KY,IE-LK,IE-TA,IE-WD,IE-G,IE-LM,IE-MO,IE-RN,IE-SO,IE-CN,IE-DL,IE-MN | D39: T-NAV_CON00 | E39: TRA Navigation: Conventional Navigation Vehicles - Existing | F39: PJ | G39: PJa
B40: DMD | C40: =_xlfn.TEXTJOIN(",",TRUE,Regions!$C$3:'Regions'!$AD$3) -> IE,IE-CW,IE-D,IE-KE,IE-KK,IE-LS,IE-LD,IE-LH,IE-MH,IE-OY,IE-WH,IE-WX,IE-WW,IE-CE,IE-CO,IE-KY,IE-LK,IE-TA,IE-WD,IE-G,IE-LM,IE-MO,IE-RN,IE-SO,IE-CN,IE-DL,IE-MN | D40: T-OTH_CON00 | E40: TRA Unspecified: Conventional Unspecified Vehicles - Existing | F40: PJ | G40: PJa
B41: *Aviation
...

Sheet FT
E2: ~FI_T
B3: Region | C3: TechName | D3: Comm-IN | E3: Comm-OUT | F3: EFF | G3: LIFE | H3: DELIV~2018 | I3: DELIV~2025 | J3: DELIV~2050 | K3: DELIV~0 | L3: ACT_BND~2030 | M3: ACT_BND~2045 | N3: ACT_BND~2050 | O3: ACT_BND~2070 | P3: ACT_BND~0
B4: Region | C4: *Technology Name | D4: Input Commodity | E4: Output Commodity | F4: Efficiency | G4: Lifetime
B5: *Units | G5: Years | H5: MEuro2018/PJ | I5: MEuro2018/PJ | J5: MEuro2018/PJ | K5: MEuro2018/PJ | L5: Maximum | M5: Maximum | N5: Maximum | O5: Maximum
B6: =Processes!C45 -> IE,IE-CW,IE-D,IE-KE,IE-KK,IE-LS,IE-LD,IE-LH,IE-MH,IE-OY,IE-WH,IE-WX,IE-WW,IE-CE,IE-CO,IE-KY,IE-LK,IE-TA,IE-WD,IE-G,IE-LM,IE-MO,IE-RN,IE-SO,IE-CN,IE-DL,IE-MN | C6: =Processes!D45 -> FT-TRAWLK | D6: WLK | E6: =Commodities!C6 -> TRAWLK | F6: 1 | G6: 50 | H6: 0.01 | I6: 0.01 | J6: 0.01 | K6: 5
B7: =Processes!C46 -> IE,IE-CW,IE-D,IE-KE,IE-KK,IE-LS,IE-LD,IE-LH,IE-MH,IE-OY,IE-WH,IE-WX,IE-WW,IE-CE,IE-CO,IE-KY,IE-LK,IE-TA,IE-WD,IE-G,IE-LM,IE-MO,IE-RN,IE-SO,IE-CN,IE-DL,IE-MN | C7: =Processes!D46 -> FT-TRACYC | D7: CYC | E7: =Commodities!C7 -> TRACYC | F7: 1 | G7: 50 | H7: 0.01 | I7: 0.01 | J7: 0.01 | K7: 5
B8: =Processes!C47 -> IE,IE-CW,IE-D,IE-KE,IE-KK,IE-LS,IE-LD,IE-LH,IE-MH,IE-OY,IE-WH,IE-WX,IE-WW,IE-CE,IE-CO,IE-KY,IE-LK,IE-TA,IE-WD,IE-G,IE-LM,IE-MO,IE-RN,IE-SO,IE-CN,IE-DL,IE-MN | C8: =Processes!D47 -> FT-TRAGSL | D8: OILGSL | E8: =Commodities!C8 -> TRAGSL | F8: 1 | G8: 50 | H8: 0.01 | I8: 0.01 | J8: 0.01 | K8: 5
B9: =Processes!C48 -> IE,IE-CW,IE-D,IE-KE,IE-KK,IE-LS,IE-LD,IE-LH,IE-MH,IE-OY,IE-WH,IE-WX,IE-WW,IE-CE,IE-CO,IE-KY,IE-LK,IE-TA,IE-WD,IE-G,IE-LM,IE-MO,IE-RN,IE-SO,IE-CN,IE-DL,IE-MN | C9: =Processes!D48 -> FT-TRADST | D9: OILDST | E9: =Commodities!C9 -> TRADST | F9: 1 | G9: 50 | H9: 0.01 | I9: 0.01 | J9: 0.01 | K9: 5
B10: =Processes!C49 -> IE,IE-CW,IE-D,IE-KE,IE-KK,IE-LS,IE-LD,IE-LH,IE-MH,IE-OY,IE-WH,IE-WX,IE-WW,IE-CE,IE-CO,IE-KY,IE-LK,IE-TA,IE-WD,IE-G,IE-LM,IE-MO,IE-RN,IE-SO,IE-CN,IE-DL,IE-MN | C10: =Processes!D49 -> FT-TRAETH | D10: BIOETH1G,BIOETH2G | E10: =Commodities!C10 -> TRAETH | F10: 1 | G10: 50 | H10: 0.01 | I10: 0.01 | J10: 0.01 | K10: 5
B11: =Processes!C50 -> IE,IE-CW,IE-D,IE-KE,IE-KK,IE-LS,IE-LD,IE-LH,IE-MH,IE-OY,IE-WH,IE-WX,IE-WW,IE-CE,IE-CO,IE-KY,IE-LK,IE-TA,IE-WD,IE-G,IE-LM,IE-MO,IE-RN,IE-SO,IE-CN,IE-DL,IE-MN | C11: =Processes!D50 -> FT-TRABDL | D11: BIODST1G,BIODST2G | E11: =Commodities!C11 -> TRABDL | F11: 1 | G11: 50 | H11: 0.01 | I11: 0.01 | J11: 0.01 | K11: 5
B12: =Processes!C51 -> IE,IE-CW,IE-D,IE-KE,IE-KK,IE-LS,IE-LD,IE-LH,IE-MH,IE-OY,IE-WH,IE-WX,IE-WW,IE-CE,IE-CO,IE-KY,IE-LK,IE-TA,IE-WD,IE-G,IE-LM,IE-MO,IE-RN,IE-SO,IE-CN,IE-DL,IE-MN | C12: =Processes!D51 -> FT-TRABJK | D12: BIOJKR | E12: =Commodities!C12 -> TRABJK | F12: 1 | G12: 50 | H12: 0.01 | I12: 0.01 | J12: 0.01 | K12: 5
B13: =Processes!C52 -> IE,IE-CW,IE-D,IE-KE,IE-KK,IE-LS,IE-LD,IE-LH,IE-MH,IE-OY,IE-WH,IE-WX,IE-WW,IE-CE,IE-CO,IE-KY,IE-LK,IE-TA,IE-WD,IE-G,IE-LM,IE-MO,IE-RN,IE-SO,IE-CN,IE-DL,IE-MN | C13: =Processes!D52 -> FT-TRACNG | D13: GASNAT | E13: =Commodities!C13 -> TRACNG | F13: 1 | G13: 50 | H13: 4 | I13: 80 | J13: =I13 -> 80 | K13: 5
B14: =Processes!C53 -> IE,IE-CW,IE-D,IE-KE,IE-KK,IE-LS,IE-LD,IE-LH,IE-MH,IE-OY,IE-WH,IE-WX,IE-WW,IE-CE,IE-CO,IE-KY,IE-LK,IE-TA,IE-WD,IE-G,IE-LM,IE-MO,IE-RN,IE-SO,IE-CN,IE-DL,IE-MN | C14: =Processes!D53 -> FT-TRABNG | D14: BIOGAS1G,BIOGAS2G | E14: =Commodities!C14 -> TRABNG | F14: 1 | G14: 50 | H14: 4 | I14: 80 | J14: =I14 -> 80 | K14: 5
B15: =Processes!C54 -> IE,IE-CW,IE-D,IE-KE,IE-KK,IE-LS,IE-LD,IE-LH,IE-MH,IE-OY,IE-WH,IE-WX,IE-WW,IE-CE,IE-CO,IE-KY,IE-LK,IE-TA,IE-WD,IE-G,IE-LM,IE-MO,IE-RN,IE-SO,IE-CN,IE-DL,IE-MN | C15: =Processes!D54 -> FT-TRAELC | D15: ELCD | E15: =Commodities!C15 -> TRAELC | F15: 1 | G15: 50 | H15: 0.01 | I15: 0.01 | J15: 0.01 | K15: 5
B16: =Processes!C55 -> IE,IE-CW,IE-D,IE-KE,IE-KK,IE-LS,IE-LD,IE-LH,IE-MH,IE-OY,IE-WH,IE-WX,IE-WW,IE-CE,IE-CO,IE-KY,IE-LK,IE-TA,IE-WD,IE-G,IE-LM,IE-MO,IE-RN,IE-SO,IE-CN,IE-DL,IE-MN | C16: =Processes!D55 -> FT-TRALNG | D16: GASLNG | E16: =Commodities!C16 -> TRALNG | F16: 1 | G16: 50 | H16: 80 | I16: 80 | J16: 80 | K16: 5
B17: =Processes!C56 -> IE,IE-CW,IE-D,IE-KE,IE-KK,IE-LS,IE-LD,IE-LH,IE-MH,IE-OY,IE-WH,IE-WX,IE-WW,IE-CE,IE-CO,IE-KY,IE-LK,IE-TA,IE-WD,IE-G,IE-LM,IE-MO,IE-RN,IE-SO,IE-CN,IE-DL,IE-MN | C17: =Processes!D56 -> FT-TRAH2 | D17: SUPH2GD | E17: =Commodities!C17 -> TRAH2 | F17: 1 | G17: 50 | H17: 4 | I17: 4 | J17: 4 | K17: 5
B18: =Processes!C57 -> IE,IE-CW,IE-D,IE-KE,IE-KK,IE-LS,IE-LD,IE-LH,IE-MH,IE-OY,IE-WH,IE-WX,IE-WW,IE-CE,IE-CO,IE-KY,IE-LK,IE-TA,IE-WD,IE-G,IE-LM,IE-MO,IE-RN,IE-SO,IE-CN,IE-DL,IE-MN | C18: =Processes!D57 -> FT-TRAKER | D18: OILKER | E18: =Commodities!C18 -> TRAKER | F18: 1 | G18: 50 | H18: 0.01 | I18: 0.01 | J18: 0.01 | K18: 5
B19: =B18 -> IE,IE-CW,IE-D,IE-KE,IE-KK,IE-LS,IE-LD,IE-LH,IE-MH,IE-OY,IE-WH,IE-WX,IE-WW,IE-CE,IE-CO,IE-KY,IE-LK,IE-TA,IE-WD,IE-G,IE-LM,IE-MO,IE-RN,IE-SO,IE-CN,IE-DL,IE-MN | C19: =Processes!D58 -> FT-TRAPtLKER | D19: PtLKER | E19: =Commodities!C19 -> TRAPtLKER | F19: 1 | G19: 50 | H19: 0.01 | K19: 5
B20: =B19 -> IE,IE-CW,IE-D,IE-KE,IE-KK,IE-LS,IE-LD,IE-LH,IE-MH,IE-OY,IE-WH,IE-WX,IE-WW,IE-CE,IE-CO,IE-KY,IE-LK,IE-TA,IE-WD,IE-G,IE-LM,IE-MO,IE-RN,IE-SO,IE-CN,IE-DL,IE-MN | C20: =Processes!D59 -> FT-AVIKER | D20: =Commodities!C18 -> TRAKER | E20: =Commodities!C20 -> AVIKER | F20: 1 | G20: 100 | H20: 0.01 | K20: 5
B21: =B20 -> IE,IE-CW,IE-D,IE-KE,IE-KK,IE-LS,IE-LD,IE-LH,IE-MH,IE-OY,IE-WH,IE-WX,IE-WW,IE-CE,IE-CO,IE-KY,IE-LK,IE-TA,IE-WD,IE-G,IE-LM,IE-MO,IE-RN,IE-SO,IE-CN,IE-DL,IE-MN | C21: =Processes!D60 -> FT-AVIBJK | D21: =Commodities!C12 -> TRABJK | E21: =Commodities!C21 -> AVIBJK | F21: 1 | G21: 100 | H21: 0.01 | K21: 5
B22: =B21 -> IE,IE-CW,IE-D,IE-KE,IE-KK,IE-LS,IE-LD,IE-LH,IE-MH,IE-OY,IE-WH,IE-WX,IE-WW,IE-CE,IE-CO,IE-KY,IE-LK,IE-TA,IE-WD,IE-G,IE-LM,IE-MO,IE-RN,IE-SO,IE-CN,IE-DL,IE-MN | C22: =Processes!D61 -> FT-AVIELC | D22: =Commodities!C15 -> TRAELC | E22: =Commodities!C22 -> AVIELC | F22: 1 | G22: 100 | H22: 0.01 | K22: 5 | L22: =0.05*Q35/L61/H61 -> 0.32054829 | N22: =AK35/L61/I61 -> 7.173431 | O22: =N22+(0.5*BE36/I62/L62) -> 20.289794 | P22: 5 | R22: *from 5% of existing fleet to 100% by 2050 for short-range flights and 50% of medium-range flights by 2070
B23: =B22 -> IE,IE-CW,IE-D,IE-KE,IE-KK,IE-LS,IE-LD,IE-LH,IE-MH,IE-OY,IE-WH,IE-WX,IE-WW,IE-CE,IE-CO,IE-KY,IE-LK,IE-TA,IE-WD,IE-G,IE-LM,IE-MO,IE-RN,IE-SO,IE-CN,IE-DL,IE-MN | C23: =Processes!D62 -> FT-AVIH2 | D23: =Commodities!C17 -> TRAH2 | E23: =Commodities!C23 -> AVIH2 | F23: 1 | G23: 100 | H23: 0.01 | K23: 5 | L23: 0 | M23: =0.01*SUM(AF35:AF37)/I64/L64 -> 0.44416387 | O23: =0.25*SUM(BE35:BE37)/L64/I64 -> 11.499396 | P23: 5 | R23: *from 1% of existing fleet in 2045 to 25% by 2070 for all ranges
B24: =B23 -> IE,IE-CW,IE-D,IE-KE,IE-KK,IE-LS,IE-LD,IE-LH,IE-MH,IE-OY,IE-WH,IE-WX,IE-WW,IE-CE,IE-CO,IE-KY,IE-LK,IE-TA,IE-WD,IE-G,IE-LM,IE-MO,IE-RN,IE-SO,IE-CN,IE-DL,IE-MN | C24: =Processes!D63 -> FT-AVIPtL | D24: =Commodities!C19 -> TRAPtLKER | E24: =Commodities!C24 -> AVIPtL | F24: 1 | G24: 100 | H24: 0.01 | K24: 5
C32: Cset_CN | D32: *Description | E32: 2018 | F32: 2019 | G32: 2020 | H32: 2021 | I32: 2022 | J32: 2023 | K32: 2024 | L32: 2025 | M32: 2026 | N32: 2027 | O32: 2028 | P32: 2029 | Q32: 2030 | R32: 2031 | S32: 2032 | T32: 2033 | U32: 2034 | V32: 2035 | W32: 2036 | X32: 2037 | Y32: 2038 | Z32: 2039 | AA32: 2040 | AB32: 2041 | AC32: 2042 | AD32: 2043 | AE32: 2044 | AF32: 2045 | AG32: 2046 | AH32: 2047 | AI32: 2048 | AJ32: 2049 | AK32: 2050 | AL32: 2051 | AM32: 2052 | AN32: 2053 | AO32: 2054 | AP32: 2055 | AQ32: 2056 | AR32: 2057 | AS32: 2058 | AT32: 2059 | AU32: 2060 | AV32: 2061 | AW32: 2062 | AX32: 2063 | AY32: 2064 | AZ32: 2065 | BA32: 2066 | BB32: 2067 | BC32: 2068 | BD32: 2069 | BE32: 2070 | BF32: 2071 | BG32: 2072 | BH32: 2073 | BI32: 2074 | BJ32: 2075 | BK32: 2076 | BL32: 2077 | BM32: 2078 | BN32: 2079 | BO32: 2080 | BP32: 2081 | BQ32: 2082 | BR32: 2083 | BS32: 2084 | BT32: 2085 | BU32: 2086 | BV32: 2087 | BW32: 2088 | BX32: 2089 | BY32: 2090 | BZ32: 2091 | CA32: 2092 | CB32: 2093 | CC32: 2094 | CD32: 2095 | CE32: 2096 | CF32: 2097 | CG32: 2098 | CH32: 2099 | CI32: 2100
C33: TAVIDOM | D33: Transport Demand: Aviation domestic | E33: 0.2334932 | F33: 0.2509092 | G33: 0.11004689 | H33: 0.12006442 | I33: 0.23 | J33: 0.23 | K33: 0.23 | L33: 0.23 | M33: 0.23 | N33: 0.23 | O33: 0.23 | P33: 0.23 | Q33: 0.23 | R33: 0.23 | S33: 0.23 | T33: 0.23 | U33: 0.23 | V33: 0.23 | W33: 0.23 | X33: 0.23 | Y33: 0.23 | Z33: 0.23 | AA33: 0.23 | AB33: 0.23 | AC33: 0.23 | AD33: 0.23 | AE33: 0.23 | AF33: 0.23 | AG33: 0.23 | AH33: 0.23 | AI33: 0.23 | AJ33: 0.23 | AK33: 0.23 | AL33: 0.23 | AM33: 0.23 | AN33: 0.23 | AO33: 0.23 | AP33: 0.23 | AQ33: 0.23 | AR33: 0.23 | AS33: 0.23 | AT33: 0.23 | AU33: 0.23 | AV33: 0.23 | AW33: 0.23 | AX33: 0.23 | AY33: 0.23 | AZ33: 0.23 | BA33: 0.23 | BB33: 0.23 | BC33: 0.23 | BD33: 0.23 | BE33: 0.23 | BF33: 0.23 | BG33: 0.23 | BH33: 0.23 | BI33: 0.23 | BJ33: 0.23 | BK33: 0.23 | BL33: 0.23 | BM33: 0.23 | BN33: 0.23 | BO33: 0.23 | BP33: 0.23 | BQ33: 0.23 | BR33: 0.23 | BS33: 0.23 | BT33: 0.23 | BU33: 0.23 | BV33: 0.23 | BW33: 0.23 | BX33: 0.23 | BY33: 0.23 | BZ33: 0.23 | CA33: 0.23 | CB33: 0.23 | CC33: 0.23 | CD33: 0.23 | CE33: 0.23 | CF33: 0.23 | CG33: 0.23 | CH33: 0.23 | CI33: 0.23
C34: TAVIINT | D34: Transport Demand: Aviation international | E34: 45.968364 | F34: 46.490628 | G34: 16.580491 | H34: 18.57572 | I34: 48.192397 | J34: 48.860779 | K34: 49.515792 | L34: 0 | M34: 0 | N34: 0 | O34: 0 | P34: 0 | Q34: 0 | R34: 0 | S34: 0 | T34: 0 | U34: 0 | V34: 0 | W34: 0 | X34: 0 | Y34: 0 | Z34: 0 | AA34: 0 | AB34: 0 | AC34: 0 | AD34: 0 | AE34: 0 | AF34: 0 | AG34: 0 | AH34: 0 | AI34: 0 | AJ34: 0 | AK34: 0 | AL34: 0 | AM34: 0 | AN34: 0 | AO34: 0 | AP34: 0 | AQ34: 0 | AR34: 0 | AS34: 0 | AT34: 0 | AU34: 0 | AV34: 0 | AW34: 0 | AX34: 0 | AY34: 0 | AZ34: 0 | BA34: 0 | BB34: 0 | BC34: 0 | BD34: 0 | BE34: 0 | BF34: 0 | BG34: 0 | BH34: 0 | BI34: 0 | BJ34: 0 | BK34: 0 | BL34: 0 | BM34: 0 | BN34: 0 | BO34: 0 | BP34: 0 | BQ34: 0 | BR34: 0 | BS34: 0 | BT34: 0 | BU34: 0 | BV34: 0 | BW34: 0 | BX34: 0 | BY34: 0 | BZ34: 0 | CA34: 0 | CB34: 0 | CC34: 0 | CD34: 0 | CE34: 0 | CF34: 0 | CG34: 0 | CH34: 0 | CI34: 0
C35: TAVIINTS | D35: Transport Demand: Aviation international_Short | E35: 0 | F35: 0 | G35: 0 | H35: 0 | I35: 0 | J35: 0 | K35: 0 | L35: 2.9392746 | M35: 2.9833143 | N35: 3.027354 | O35: 3.0713937 | P35: 3.1154334 | Q35: 3.1594731 | R35: 3.2035128 | S35: 3.2475525 | T35: 3.2915922 | U35: 3.3356319 | V35: 3.3796716 | W35: 3.4237113 | X35: 3.467751 | Y35: 3.5117907 | Z35: 3.5558304 | AA35: 3.5998701 | AB35: 3.6439098 | AC35: 3.6879495 | AD35: 3.7319892 | AE35: 3.7760289 | AF35: 3.8200686 | AG35: 3.8641083 | AH35: 3.908148 | AI35: 3.9521876 | AJ35: 3.9962273 | AK35: 4.040267 | AL35: 4.040267 | AM35: 4.040267 | AN35: 4.040267 | AO35: 4.040267 | AP35: 4.040267 | AQ35: 4.040267 | AR35: 4.040267 | AS35: 4.040267 | AT35: 4.040267 | AU35: 4.040267 | AV35: 4.040267 | AW35: 4.040267 | AX35: 4.040267 | AY35: 4.040267 | AZ35: 4.040267 | BA35: 4.040267 | BB35: 4.040267 | BC35: 4.040267 | BD35: 4.040267 | BE35: 4.040267 | BF35: 4.040267 | BG35: 4.040267 | BH35: 4.040267 | BI35: 4.040267 | BJ35: 4.040267 | BK35: 4.040267 | BL35: 4.040267 | BM35: 4.040267 | BN35: 4.040267 | BO35: 4.040267 | BP35: 4.040267 | BQ35: 4.040267 | BR35: 4.040267 | BS35: 4.040267 | BT35: 4.040267 | BU35: 4.040267 | BV35: 4.040267 | BW35: 4.040267 | BX35: 4.040267 | BY35: 4.040267 | BZ35: 4.040267 | CA35: 4.040267 | CB35: 4.040267 | CC35: 4.040267 | CD35: 4.040267 | CE35: 4.040267 | CF35: 4.040267 | CG35: 4.040267 | CH35: 4.040267 | CI35: 4.040267
C36: TAVIINTM | D36: Transport Demand: Aviation international_Medium | E36: 0 | F36: 0 | G36: 0 | H36: 0 | I36: 0 | J36: 0 | K36: 0 | L36: 15.777791 | M36: 15.900361 | N36: 16.022932 | O36: 16.145502 | P36: 16.268073 | Q36: 16.390643 | R36: 16.513213 | S36: 16.635784 | T36: 16.758354 | U36: 16.880925 | V36: 17.003495 | W36: 17.126065 | X36: 17.248636 | Y36: 17.371206 | Z36: 17.493777 | AA36: 17.616347 | AB36: 17.738917 | AC36: 17.861488 | AD36: 17.984058 | AE36: 18.106629 | AF36: 18.229199 | AG36: 18.351769 | AH36: 18.47434 | AI36: 18.59691 | AJ36: 18.719481 | AK36: 18.842051 | AL36: 18.842051 | AM36: 18.842051 | AN36: 18.842051 | AO36: 18.842051 | AP36: 18.842051 | AQ36: 18.842051 | AR36: 18.842051 | AS36: 18.842051 | AT36: 18.842051 | AU36: 18.842051 | AV36: 18.842051 | AW36: 18.842051 | AX36: 18.842051 | AY36: 18.842051 | AZ36: 18.842051 | BA36: 18.842051 | BB36: 18.842051 | BC36: 18.842051 | BD36: 18.842051 | BE36: 18.842051 | BF36: 18.842051 | BG36: 18.842051 | BH36: 18.842051 | BI36: 18.842051 | BJ36: 18.842051 | BK36: 18.842051 | BL36: 18.842051 | BM36: 18.842051 | BN36: 18.842051 | BO36: 18.842051 | BP36: 18.842051 | BQ36: 18.842051 | BR36: 18.842051 | BS36: 18.842051 | BT36: 18.842051 | BU36: 18.842051 | BV36: 18.842051 | BW36: 18.842051 | BX36: 18.842051 | BY36: 18.842051 | BZ36: 18.842051 | CA36: 18.842051 | CB36: 18.842051 | CC36: 18.842051 | CD36: 18.842051 | CE36: 18.842051 | CF36: 18.842051 | CG36: 18.842051 | CH36: 18.842051 | CI36: 18.842051
C37: TAVIINTL | D37: Transport Demand: Aviation international_Long | E37: 0 | F37: 0 | G37: 0 | H37: 0 | I37: 0 | J37: 0 | K37: 0 | L37: 13.766068 | M37: 13.869136 | N37: 13.972203 | O37: 14.07527 | P37: 14.178337 | Q37: 14.281405 | R37: 14.384472 | S37: 14.487539 | T37: 14.590607 | U37: 14.693674 | V37: 14.796741 | W37: 14.899808 | X37: 15.002876 | Y37: 15.105943 | Z37: 15.20901 | AA37: 15.312078 | AB37: 15.415145 | AC37: 15.518212 | AD37: 15.621279 | AE37: 15.724347 | AF37: 15.827414 | AG37: 15.930481 | AH37: 16.033549 | AI37: 16.136616 | AJ37: 16.239683 | AK37: 16.34275 | AL37: 16.34275 | AM37: 16.34275 | AN37: 16.34275 | AO37: 16.34275 | AP37: 16.34275 | AQ37: 16.34275 | AR37: 16.34275 | AS37: 16.34275 | AT37: 16.34275 | AU37: 16.34275 | AV37: 16.34275 | AW37: 16.34275 | AX37: 16.34275 | AY37: 16.34275 | AZ37: 16.34275 | BA37: 16.34275 | BB37: 16.34275 | BC37: 16.34275 | BD37: 16.34275 | BE37: 16.34275 | BF37: 16.34275 | BG37: 16.34275 | BH37: 16.34275 | BI37: 16.34275 | BJ37: 16.34275 | BK37: 16.34275 | BL37: 16.34275 | BM37: 16.34275 | BN37: 16.34275 | BO37: 16.34275 | BP37: 16.34275 | BQ37: 16.34275 | BR37: 16.34275 | BS37: 16.34275 | BT37: 16.34275 | BU37: 16.34275 | BV37: 16.34275 | BW37: 16.34275 | BX37: 16.34275 | BY37: 16.34275 | BZ37: 16.34275 | CA37: 16.34275 | CB37: 16.34275 | CC37: 16.34275 | CD37: 16.34275 | CE37: 16.34275 | CF37: 16.34275 | CG37: 16.34275 | CH37: 16.34275 | CI37: 16.34275
C46: TechName | D46: Comm-IN | E46: Comm-OUT | F46: START | G46: EFF~2018 | H46: EFF~2030 | I46: EFF~2050 | J46: INVCOST~2018 | K46: AFA~2018 | L46: ACTFLO~DEMO | M46: LIFE | N46: CAP2ACT
C47: *Technology Name | D47: Input Commodity | E47: Output Commodity | G47: Efficiency | H47: Efficiency | I47: Efficiency | J47: Purchase price | K47: Utilisation Factor | L47: Activity to Flo | M47: Lifetime | N47: Capacity to Activity Factor
C48: *Units | G48: BV*km/PJ | H48: BV*km/PJ | I48: BV*km/PJ | J48: M€2018/000_units | K48: '000 km | L48: Passenger or tonnage/Vehicle | M48: Years | N48: bvkm/mvkm
C49: *Aviation
C50: T-AVI_DOM_NEW | D50: AVIKER,AVIBJK | E50: TAVIDOM | F50: 2019 | G50: 1 | H50: 1.05 | I50: 1.2 | N50: 1
C51: T-AVI_INT_NEW | D51: AVIKER,AVIBJK | E51: TAVIINT | F51: 2019 | G51: 1 | H51: 1.05 | I51: 1.2 | N51: 1
C52: T-SAVI_INT_JETK_NEW | D52: AVIKER | E52: TAVIINTS | F52: 2024 | G52: 0.0027498626 | H52: 0.0028873557 | I52: 0.0032998351 | J52: 63300 | K52: 2800 | L52: 117.34854 | M52: 30 | N52: 0.001
C53: T-MAVI_INT_JETK_NEW | D53: AVIKER | E53: TAVIINTM | F53: 2024 | G53: 0.004748628 | H53: 0.0049860594 | I53: 0.0056983536 | J53: 81410 | K53: 2800 | L53: 149.65089 | M53: 30 | N53: 0.001
C54: T-LAVI_INT_JETK_NEW | D54: AVIKER | E54: TAVIINTL | F54: 2024 | G54: 0.002924603 | H54: 0.0030708332 | I54: 0.0035095236 | J54: 224140 | K54: 2800 | L54: 220.27434 | M54: 30 | N54: 0.001
C55: T-SAVI_INT_SAF_NEW | D55: AVIKER,AVIBJK,AVIPtL | E55: TAVIINTS | F55: 2024 | G55: 0.0027498626 | H55: 0.0028873557 | I55: 0.0032998351 | J55: 69630 | K55: 2800 | L55: 117.34854 | M55: 30 | N55: 0.001
C56: T-MAVI_INT_SAF_NEW | D56: AVIKER,AVIBJK,AVIPtL | E56: TAVIINTM | F56: 2024 | G56: 0.004748628 | H56: 0.0049860594 | I56: 0.0056983536 | J56: 89551 | K56: 2800 | L56: 149.65089 | M56: 30 | N56: 0.001
...

Sheet Stock
AI2: Passenger | BM2: Freight
F3: ~FI_T: Stock~2018 | AI3: Total available supply (Bpkm) | BM3: Total available supply (Btkm)
C4: TechName | D4: *Unit | E4: Comm-IN | F4: Comm-OUT | G4: =Regions!C3 -> IE | H4: =Regions!E3 -> IE-CW | I4: =Regions!F3 -> IE-D | J4: =Regions!G3 -> IE-KE | K4: =Regions!H3 -> IE-KK | L4: =Regions!I3 -> IE-LS | M4: =Regions!J3 -> IE-LD | N4: =Regions!K3 -> IE-LH | O4: =Regions!L3 -> IE-MH | ... AG4: =Regions!AD3 -> IE-MN | AJ4: =G4 -> IE | AK4: =H4 -> IE-CW | AL4: =I4 -> IE-D | AM4: =J4 -> IE-KE | AN4: =K4 -> IE-KK | AO4: =L4 -> IE-LS | AP4: =M4 -> IE-LD | AQ4: =N4 -> IE-LH | ... BJ4: =AG4 -> IE-MN | BM4: Technology | BN4: =AJ4 -> IE | BO4: =AK4 -> IE-CW | BP4: =AL4 -> IE-D | BQ4: =AM4 -> IE-KE | BR4: =AN4 -> IE-KK | BS4: =AO4 -> IE-LS | BT4: =AP4 -> IE-LD | BU4: =AQ4 -> IE-LH | ... CN4: =BJ4 -> IE-MN
C5: *Two-wheelers | AI5: =C5 -> *Two-wheelers | BM5: Goods Vehicles
C6: =Processes!D9 -> T-MOT-ICE_GSL00 | D6: kUnits | E6: =Commodities!C8&","&Commodities!C10 -> TRAGSL,TRAETH | F6: =Commodities!C25&","&Commodities!C26 -> TRAPS,TRAPM | G6: =SUM(H6:AG6) -> 39.852 | H6: =F185/1000 -> 0.563 | I6: =G185/1000 -> 12.616 | J6: =H185/1000 -> 2.168 | K6: =I185/1000 -> 0.872 | L6: =J185/1000 -> 0.513 | M6: =K185/1000 -> 0.213 | N6: =L185/1000 -> 0.855 | O6: =M185/1000 -> 1.684 | ... AG6: =AE185/1000 -> 0.301 | AI6: =C6 -> T-MOT-ICE_GSL00 | AJ6: =G6*AF!D6*ACT2FLO!E52/1000 -> 0.11971939 | AK6: =H6*AF!E6*ACT2FLO!F52/1000 -> 0.0016330941 | AL6: =I6*AF!F6*ACT2FLO!G52/1000 -> 0.038829525 | AM6: =J6*AF!G6*ACT2FLO!H52/1000 -> 0.0065057344 | AN6: =K6*AF!H6*ACT2FLO!I52/1000 -> 0.0025437984 | AO6: =L6*AF!I6*ACT2FLO!J52/1000 -> 0.001529253 | AP6: =M6*AF!J6*ACT2FLO!K52/1000 -> 0.0006253467 | AQ6: =N6*AF!K6*ACT2FLO!L52/1000 -> 0.002593899 | ... BJ6: =AG6*AF!AD6*ACT2FLO!AE52/1000 -> 0.000920458 | BM6: =C28 -> T-LGT-ICE_GSL00 | BN6: =G28*AF!D23*ACT2FLO!E70/1000 -> 0.00079580552 | BO6: =H28*AF!E23*ACT2FLO!F70/1000 -> 8.879285e-06 | BP6: =I28*AF!F23*ACT2FLO!G70/1000 -> 0.00026747075 | BQ6: =J28*AF!G23*ACT2FLO!H70/1000 -> 4.5203578e-05 | BR6: =K28*AF!H23*ACT2FLO!I70/1000 -> 1.2900645e-05 | BS6: =L28*AF!I23*ACT2FLO!J70/1000 -> 1.8639274e-05 | BT6: =M28*AF!J23*ACT2FLO!K70/1000 -> 7.00212e-06 | BU6: =N28*AF!K23*ACT2FLO!L70/1000 -> 1.3527585e-05 | ... CN6: =AG28*AF!AD23*ACT2FLO!AE70/1000 -> 1.0767888e-05
C7: *Private cars | AI7: =C7 -> *Private cars | BM7: =C31 -> T-HGT-ICE_DST00 | BN7: =G31*AF!D26*ACT2FLO!E73/1000 -> 10.105241 | BO7: =H31*AF!E26*ACT2FLO!F73/1000 -> 0.17478036 | BP7: =I31*AF!F26*ACT2FLO!G73/1000 -> 1.7660123 | BQ7: =J31*AF!G26*ACT2FLO!H73/1000 -> 0.55782975 | BR7: =K31*AF!H26*ACT2FLO!I73/1000 -> 0.38957272 | BS7: =L31*AF!I26*ACT2FLO!J73/1000 -> 0.21890466 | BT7: =M31*AF!J26*ACT2FLO!K73/1000 -> 0.12980282 | BU7: =N31*AF!K26*ACT2FLO!L73/1000 -> 0.2927574 | ... CN7: =AG31*AF!AD26*ACT2FLO!AE73/1000 -> 0.5420726
C8: =Processes!D11 -> T-CAR-ICE_GSL00 | D8: kUnits | E8: =Commodities!C8&","&Commodities!C10 -> TRAGSL,TRAETH | F8: =Commodities!C25&","&Commodities!C26&","&Commodities!C27 -> TRAPS,TRAPM,TRAPL | G8: =SUM(H8:AG8) -> 946.86 | H8: =F186/1000 -> 10.796 | I8: =G186/1000 -> 299.408 | J8: =H186/1000 -> 44.521 | K8: =I186/1000 -> 17.346 | L8: =J186/1000 -> 12.391 | M8: =K186/1000 -> 5.804 | N8: =L186/1000 -> 20.722 | O8: =M186/1000 -> 34.216 | ... AG8: =AE186/1000 -> 7.85 | AI8: =C8 -> T-CAR-ICE_GSL00 | AJ8: =G8*AF!D7*ACT2FLO!E53/1000 -> 18.10691 | AK8: =H8*AF!E7*ACT2FLO!F53/1000 -> 0.21806681 | AL8: =I8*AF!F7*ACT2FLO!G53/1000 -> 4.9233032 | AM8: =J8*AF!G7*ACT2FLO!H53/1000 -> 0.89867526 | AN8: =K8*AF!H7*ACT2FLO!I53/1000 -> 0.35621826 | AO8: =L8*AF!I7*ACT2FLO!J53/1000 -> 0.26035967 | AP8: =M8*AF!J7*ACT2FLO!K53/1000 -> 0.1214254 | AQ8: =N8*AF!K7*ACT2FLO!L53/1000 -> 0.40758491 | ... BJ8: =AG8*AF!AD7*ACT2FLO!AE53/1000 -> 0.16140707 | BM8: =C32 -> T-GTR-ICE_DST00 | BN8: =G32*AF!D27*ACT2FLO!E74/1000 -> 0.090839 | BO8: =H32*AF!E27*ACT2FLO!F74/1000 -> 0 | BP8: =I32*AF!F27*ACT2FLO!G74/1000 -> 0.090839 | BQ8: =J32*AF!G27*ACT2FLO!H74/1000 -> 0 | BR8: =K32*AF!H27*ACT2FLO!I74/1000 -> 0 | BS8: =L32*AF!I27*ACT2FLO!J74/1000 -> 0 | BT8: =M32*AF!J27*ACT2FLO!K74/1000 -> 0 | BU8: =N32*AF!K27*ACT2FLO!L74/1000 -> 0 | ... CN8: =AG32*AF!AD27*ACT2FLO!AE74/1000 -> 0
C9: =Processes!D12 -> T-CAR-ICE_DST00 | D9: kUnits | E9: =Commodities!C9&","&Commodities!C11 -> TRADST,TRABDL | F9: =Commodities!C25&","&Commodities!C26&","&Commodities!C27 -> TRAPS,TRAPM,TRAPL | G9: =SUM(H9:AG9) -> 1129.404 | H9: =F187/1000 -> 17.385 | I9: =G187/1000 -> 225.706 | J9: =H187/1000 -> 56.834 | K9: =I187/1000 -> 26.674 | L9: =J187/1000 -> 22.058 | M9: =K187/1000 -> 11.27 | N9: =L187/1000 -> 29.947 | O9: =M187/1000 -> 52.424 | ... AG9: =AE187/1000 -> 17.634 | AI9: =C9 -> T-CAR-ICE_DST00 | AJ9: =G9*AF!D8*ACT2FLO!E54/1000 -> 34.741372 | AK9: =H9*AF!E8*ACT2FLO!F54/1000 -> 0.56367216 | AL9: =I9*AF!F8*ACT2FLO!G54/1000 -> 6.0973033 | AM9: =J9*AF!G8*ACT2FLO!H54/1000 -> 1.7730201 | AN9: =K9*AF!H8*ACT2FLO!I54/1000 -> 0.86560466 | AO9: =L9*AF!I8*ACT2FLO!J54/1000 -> 0.73387771 | AP9: =M9*AF!J8*ACT2FLO!K54/1000 -> 0.38208656 | AQ9: =N9*AF!K8*ACT2FLO!L54/1000 -> 0.921015 | ... BJ9: =AG9*AF!AD8*ACT2FLO!AE54/1000 -> 0.56787787
