Workbook

Sheet Cover
A16: TIMES-Ireland Model
A19: Document type: | B19: Base Year Template
A20: Sector(s): | B20: Residential sector (RSD)
A21: Purpose: | B21: Specify base year (2018) data and define sector structure
A23: Original developer(s): | B23: Jason Mc Guire ( MaREI, jason.mcguire@ucc.ie)
B24: Alessandro Chiodi ( E4SMA, alessandro.chiodi@e4sma.com)
B25: Maurizio Gargiulo ( E4SMA, maurizio.gargiulo@e4sma.com)
A26: Current maintainer(s): | B26: Jason Mc Guire ( MaREI, jason.mcguire@ucc.ie)
B27: Olexandr Balyk ( MaREI, olexandr.balyk@ucc.ie)
A29: Part of TIM version: | B29: 1
A30: Model repository: | B30: https://github.com/MaREI-EPMG/TIMES-Ireland-model
A31: Licence: | B31: CC BY-NC-SA 4.0 (unless specified otherwise)
B32: https://creativecommons.org/licenses/by-nc-sa/4.0/

Sheet Intro
B2: Table of contents | G2: Colour code
B3: Sheet | C3: Description | D3: Updated | E3: By | H3: Referenced data (columns and rows headers)
B4: Regions | C4: County Level ( Mulit-Region ) or National Region Model Selection | D4: 44136 | E4: Olex | H4: Own calculations (columns and rows headers)
B5: RES | C5: Sector Reference Energy System | D5: 44169 | E5: JMcG | H5: Own assumptions (columns and rows headers)
B6: Setup | C6: Used for Automatic Naming Conenvtion | D6: 44166 | E6: JMcG | H6: Energy Balance Data
B7: EnergyBalance | C7: SEAI 2018 energy balance in ktoe | D7: 43862 | E7: JMcG | H7: Filtered Data
B8: RSD_Balance | C8: Description of the existing uses of energy in the residential sector, used for BY calibration | D8: 44166 | E8: JMcG
B9: Fuel-Age Adjustment | C9: Uses CSO data and BER data, to find probablilty of BER Rating for Age of dwelling | D9: 44044 | E9: JMcG
B10: COMM | C10: TIMES commodities list for the residential sector | D10: 44136 | E10: JMcG
B11: EMIS | C11: Emission coefficients for the residential sector | D11: 44013 | E11: JMcG | G11: Units
B12: Sector_Fuels | C12: Description of the fuel sectoral technologies for the residential sector | D12: 44136 | E12: Olex | G12: Capacity | H12: 000units or PJa
B13: Archetype Drivers | C13: The Share of Energy Service Drivers and projected demands assoicated with Archetypes | D13: 44136 | E13: JMcG | G13: Consumption | H13: PJ
B14: Non-Archetype Drivers | C14: projected demands NOT assoicated with Archetypes | D14: 44105 | E14: JMcG | G14: Currency (year) | H14: 2018M€
B15: DwellingStocks | C15: Description of the residential building stocks | D15: 44105 | E15: JMcG | G15: Base year | H15: 2018
B16: RHWLP-APT | C16: Description of space heat, water heat and lighting technologies in apartments | D16: 44166 | E16: JMcG
B17: RHWLP-Ter | C17: Description of space heat, water heat and lighting technologies in terrace dwellings | D17: 44166 | E17: JMcG
B18: RHWLP-Det | C18: Description of space heat, water heat and lighting technologies in detached dwellings | D18: 44166 | E18: JMcG | G18: Assumptions
G19: Value | H19: Comment
B27: Data Sources
B28: Sheet | C28: Description | D28: Updated | E28: By | F28: Open Source
B29: ArDEM | C29: ArDEM SQL | F29: ü
B30: LEAP | C30: Irish LEAP | F30: N/A
B31: JRC_EU_TIMES | C31: European TIMES | D31: Nov-19 | E31: JMcG | F31: ü | G31: Anybody can directly and anonymously access the data, without being required to register or authenticate + Attribution 4.0 International (CC BY 4.0)
B32: PET_IE | C32: Irish TIMES 1.0 | D32: 44044 | E32: JMcG | F32: N/A
B33: BER Database | C33: https://ndber.seai.ie/pass/ber/search.aspx | D33: 43952 | E33: JMcG | F33: ü
B34: Energy Balance 2018 | C34: https://www.seai.ie/data-and-insights/seai-statistics/key-publications/national-energy-balance/ | D34: 43952 | E34: JMcG | F34: ü | G34: Eurostat has a policy of encouraging free re-use of its data, both for non-commercial and commercial purposes
B35: CSO 2016 | C35: https://www.cso.ie/en/csolatestnews/presspages/2017/census2016profile1-housinginireland/ | D35: 43983 | E35: JMcG | F35: JMcG
B36: TopTen | C36: EU Appliances Data https://storage.topten.eu/source/files/WhiteGoods_in_Europe_June15.pdf | D36: 43983 | E36: JMcG | F36: JMcG
B37: SEAI Residential | C37: https://www.seai.ie/publications/Energy-in-the-Residential-Sector-2018-Final.pdf | D37: 43983 | E37: JMcG | F37: ü | G37: Reproduction of the contents is permissible provided the source is acknowledged.
B38: SEAI Emissions | C38: https://www.seai.ie/publications/Energy-Emissions-Report-2020.pdf | D38: 43983 | E38: JMcG | F38: ü | G38: Reproduction of the contents is permissible provided the source is acknowledged.
B39: EPA | C39: https://www.epa.ie/publications/monitoring--assessment/climate-change/air-emissions/Ireland-NIR-2018.pdf(Table 3.1.1)) | D39: 43983 | E39: JMcG | F39: ü | G39: Parts of this publication may be reproduced without further permission, provided the source is acknowledged.
B40: SEAI Data | C40: https://www.seai.ie/data-and-insights/seai-statistics/conversion-factors/ | D40: 43983 | E40: JMcG | F40: ü
B41: Central Bank | C41: vol-2019-no-14-population-change-and-housing-demand-in-ireland-(conefrey-and-staunton) | D41: 44044 | E41: JMcG | F41: ü
B42: HDD Projection | C42: http://www.epa.ie/pubs/reports/research/climate/researchreport339/Research_Report_339_Part3.pdf | D42: 44044 | E42: JMcG | F42: N/A
B43: HDD Projection | C43: http://www.epa.ie/pubs/reports/research/climate/researchreport339/Research_Report_339_Part3.pdf | D43: 44044 | E43: JMcG | F43: N/A
B44: TopTen | C44: https://storage.topten.eu/source/files/Market-Monitoring-2016-EN-Topten.eu.pdf | D44: 44044 | E44: JMcG | F44: ü | G44: Citation : Anette Michel, Sophie Attali, Eric Bush. Topten 2016. Energy efficiency of White Goods in Europe: monitoring the market with sales data – Final report. ADEME, 72 pages.
B46: Verision Control
B47: Verision | C47: Description | D47: Updated | E47: By
B48: 1 | C48: JMcG continue from Alessandro Chiodi BY template in 2018 - Initial Release | D48: 44166 | E48: JMcG | G48: E4SMA referenced

Sheet Regions
C3: {=INDEX(C5:C7,$A$4)} -> IE | D3: {=INDEX(D5:D7,$A$4)} -> National | E3: {=INDEX(E5:E7,$A$4)} -> IE-CW | F3: {=INDEX(F5:F7,$A$4)} -> IE-D | G3: {=INDEX(G5:G7,$A$4)} -> IE-KE | H3: {=INDEX(H5:H7,$A$4)} -> IE-KK | I3: {=INDEX(I5:I7,$A$4)} -> IE-LS | J3: {=INDEX(J5:J7,$A$4)} -> IE-LD | ... AD3: {=INDEX(AD5:AD7,$A$4)} -> IE-MN
A4: 1
A5: Development | C5: IE | D5: National | E5: =A11 -> IE-CW | F5: =A16 -> IE-D | G5: =A19 -> IE-KE | H5: =A20 -> IE-KK | I5: =A21 -> IE-LS | J5: =A24 -> IE-LD | K5: =A25 -> IE-LH | L5: =A27 -> IE-MH | M5: =A29 -> IE-OY | N5: =A34 -> IE-WH | O5: =A35 -> IE-WX | P5: =A36 -> IE-WW | Q5: =A13 -> IE-CE | R5: =A14 -> IE-CO | S5: =A18 -> IE-KY | T5: =A23 -> IE-LK | U5: =A32 -> IE-TA | V5: =A33 -> IE-WD | W5: =A17 -> IE-G | X5: =A22 -> IE-LM | Y5: =A26 -> IE-MO | Z5: =A30 -> IE-RN | AA5: =A31 -> IE-SO | AB5: =A12 -> IE-CN | AC5: =A15 -> IE-DL | AD5: =A28 -> IE-MN
A6: Single-region | C6: =C5 -> IE | D6: ="*"&D5 -> *National | E6: ="*"&E5 -> *IE-CW | F6: ="*"&F5 -> *IE-D | G6: ="*"&G5 -> *IE-KE | H6: ="*"&H5 -> *IE-KK | I6: ="*"&I5 -> *IE-LS | J6: ="*"&J5 -> *IE-LD | K6: ="*"&K5 -> *IE-LH | ... AD6: ="*"&AD5 -> *IE-MN
A7: Multi-region | C7: ="*"&C5 -> *IE | D7: =D5 -> National | E7: =E5 -> IE-CW | F7: =F5 -> IE-D | G7: =G5 -> IE-KE | H7: =H5 -> IE-KK | I7: =I5 -> IE-LS | J7: =J5 -> IE-LD | K7: =K5 -> IE-LH | ... AD7: =AD5 -> IE-MN
A10: Code | B10: County name
A11: IE-CW | B11: Carlow
A12: IE-CN | B12: Cavan
A13: IE-CE | B13: Clare
A14: IE-CO | B14: Cork
A15: IE-DL | B15: Donegal
A16: IE-D | B16: Dublin
A17: IE-G | B17: Galway
A18: IE-KY | B18: Kerry
A19: IE-KE | B19: Kildare
A20: IE-KK | B20: Kilkenny
A21: IE-LS | B21: Laois
... A36: IE-WW | B36: Wicklow
A37: Source: https://en.wikipedia.org/wiki/ISO_3166-2:IE

Sheet SETUP
A1: Automatic Naming Convention
A2: ( * = 0PJ, ie. unused commodity in BY ) | B2: TIMES | C2: Description
B3: RSD | C3: Residential
B4: FT | C4: Fuel Tech
B5: DISTN | C5: Distribution
B6: TIMES | C6: Description
A7: * Energy Carriers
B8: =B3&"COA" -> RSDCOA | C8: =TRIM("Coal"&" to "&C3) -> Coal to Residential
A9: =IF(RSD_Balance!C10>0," ",IF(ISBLANK('EB2018'!C13)," ","*")) | B9: =B3&RSD_Balance!A10 -> RSDPEA | C9: =TRIM(RSD_Balance!B10&" to "&C3) -> Peat to Residential
A10: =IF(RSD_Balance!C11>0," ",IF(ISBLANK('EB2018'!C14)," ","*")) | B10: =B3&RSD_Balance!A11 -> RSDLPG | C10: =TRIM(RSD_Balance!B11&" to "&C3) -> LPG to Residential
A11: =IF(RSD_Balance!C12>0," ",IF(ISBLANK('EB2018'!C15)," ","*")) -> * | B11: =B3&RSD_Balance!A12 -> RSDGSL | C11: =TRIM(RSD_Balance!B12&" to "&C3) -> Gasoline to Residential
A12: =IF(RSD_Balance!C13>0," ",IF(ISBLANK('EB2018'!C16)," ","*")) | B12: =B3&RSD_Balance!A13 -> RSDKER | C12: =TRIM(RSD_Balance!B13&" to "&C3) -> Kerosene to Residential
A13: =IF(RSD_Balance!C14>0," ",IF(ISBLANK('EB2018'!C17)," ","*")) | B13: =B3&RSD_Balance!A14 -> RSDDST | C13: =TRIM(RSD_Balance!B14&" to "&C3) -> Gasoil / Diesel /DERV to Residential
A14: =IF(RSD_Balance!C15>0," ",IF(ISBLANK('EB2018'!#REF!)," ","*")) -> * | B14: =B3&RSD_Balance!A15 -> RSDHFO | C14: =TRIM(RSD_Balance!B15&" to "&C3) -> Fueloil to Residential
A15: =IF(RSD_Balance!C16>0," ",IF(ISBLANK('EB2018'!C18)," ","*")) | B15: =B3&RSD_Balance!A16 -> RSDCOK | C15: =TRIM(RSD_Balance!B16&" to "&C3) -> Petroleum Coke to Residential
A16: =IF(RSD_Balance!C17>0," ",IF(ISBLANK('EB2018'!C19)," ","*")) | B16: =B3&RSD_Balance!A17 -> RSDGAS | C16: =TRIM(RSD_Balance!B17&" to "&C3) -> Natural Gas to Residential
A17: =IF(RSD_Balance!C18>0," ",IF(ISBLANK('EB2018'!C20)," ","*")) | B17: =B3&RSD_Balance!A18 -> RSDSOL | C17: =TRIM(RSD_Balance!B18&" to "&C3) -> Solar Thermal to Residential
A18: =IF(RSD_Balance!C19>0," ",IF(ISBLANK('EB2018'!C21)," ","*")) | B18: =B3&RSD_Balance!A19 -> RSDWOO | C18: =TRIM(RSD_Balance!B19&" to "&C3) -> Biomass to Residential
A19: =IF(RSD_Balance!C20>0," ",IF(ISBLANK('EB2018'!C22)," ","*")) | B19: =B3&RSD_Balance!A20 -> RSDBGS | C19: =TRIM(RSD_Balance!B20&" to "&C3) -> Biogas to Residential
A20: =IF(RSD_Balance!C21>0," ",IF(ISBLANK('EB2018'!C23)," ","*")) | B20: =B3&RSD_Balance!A21 -> RSDBIOMUN | C20: =TRIM(RSD_Balance!B21&" to "&C3) -> Landfill Gas to Residential
A21: =IF(RSD_Balance!C22>0," ",IF(ISBLANK('EB2018'!C24)," ","*")) | B21: =B3&RSD_Balance!A22 -> RSDAHT | C21: =TRIM(RSD_Balance!B22&" to "&C3) -> Ambient Heat to Residential
B22: =B3&RSD_Balance!A23 -> RSDETH | C22: =TRIM(RSD_Balance!B23&" to "&C3) -> Ethanol to Residential
B23: =B3&RSD_Balance!A24 -> RSDBDL | C23: =TRIM(RSD_Balance!B24&" to "&C3) -> Biodiesel to Residential
B24: =B3&RSD_Balance!A25 -> RSDBIOSLU | C24: =TRIM(RSD_Balance!B25&" to "&C3) -> Non-Renewable Waste to Residential
B25: RSDSMF | C25: Solid Multi-Fuel
A26: =IF(RSD_Balance!C26>0," ",IF(ISBLANK('EB2018'!C27)," ","*")) | B26: =B3&RSD_Balance!A26 -> RSDELC | C26: =TRIM(RSD_Balance!B26&" to "&C3) -> Electricity to Residential
B27: =B3&RSD_Balance!A27 -> RSDHET | C27: =TRIM(RSD_Balance!B27&" to "&C3) -> Heat to Residential
A28: * Emissions
B29: RSDCO2 | C29: Carbon Dioxide - Combustion (RSD)
B30: RSDCH4 | C30: Methane (RSD)
B31: RSDN2O | C31: Nitrogen Oxide (RSD)
B32: RSDSO2N | C32: Sulphur Oxides (RSD)
B33: RSDPM10 | C33: Particulate Matter <10 µm (RSD)
B34: RSDPM25 | C34: Particulate Matter <2.5 µm (RSD)
A35: * Building Types
B36: Apt | C36: Apartment
B37: Att | C37: Attached
B38: Det | C38: Detached
A39: * Building Energy Rating
B40: A | C40: -200 kWh/m2/yr to 75 kWh/m2/yr
...

Sheet EB2018
A1: 2018 Units = ktoe | B1: NACE (Rev 2) | C1: Coal | D1: Bituminous Coal | E1: Anthracite + Manufactured Ovoids | F1: Coke | G1: Lignite \ Brown Coal Briquettes | H1: Peat | I1: Milled Peat | J1: Sod Peat | K1: Briquettes | L1: Oil | M1: Crude | N1: Refinery Feedstocks | O1: Refinery Gas | P1: Gasoline | Q1: Kerosene | R1: Jet Kerosene | S1: Fueloil | T1: LPG | U1: Gasoil / Diesel /DERV | V1: Petroleum Coke | W1: Naphta | X1: Bitumen | Y1: White Spirit | Z1: Lubricants | AA1: Natural Gas | AB1: Renewables | AC1: Hydro | AD1: Wind | AE1: Biomass | AF1: Renewable Waste | AG1: Landfill Gas | AH1: Biogas | AI1: Biodiesel | AJ1: Bioethanol | AK1: Solar Photovoltaic | AL1: Solar Thermal | AM1: Ambient Heat | AN1: Non-Renewable Waste | AO1: Electricity | AP1: Heat | AQ1: TOTAL
A2: Indigenous Production | C2: =SUM(D2:G2) -> 0 | D2: 0 | H2: =SUM(I2:K2) -> 815.92435 | I2: 688.22035 | J2: 127.704 | L2: =SUM(M2:Z2) -> 0 | AA2: 2751.9192 | AB2: =SUM(AC2:AM2) -> 1334.6583 | AC2: 59.691709 | AD2: 743.01992 | AE2: 248.9086 | AF2: 139.99993 | AG2: 33.531819 | AH2: 16.813133 | AI2: 31.064468 | AJ2: 2.6691993 | AK2: 1.8899881 | AL2: 13.546086 | AM2: 43.523448 | AN2: 145.4371 | AQ2: =C2+H2+L2+AA2+AB2+AN2+AO2+AP2 -> 5047.9389
A3: Imports | C3: =SUM(D3:G3) -> 903.49466 | D3: 829.5746 | E3: 61.722868 | G3: 12.197194 | H3: =SUM(I3:K3) -> 0 | L3: =SUM(M3:Z3) -> 9138.5578 | M3: 3053.4743 | N3: 16.633377 | O3: 0 | P3: 564.23641 | Q3: 369.14639 | R3: 1542.2444 | S3: 82.827949 | T3: 157.54636 | U3: 2932.6956 | V3: 166.37648 | W3: 7.5616539 | X3: 200.83222 | Y3: 1.228147 | Z3: 43.754533 | AA3: 1728.3381 | AB3: =SUM(AC3:AM3) -> 151.93356 | AE3: 24.282116 | AI3: 104.81441 | AJ3: 22.83703 | AO3: 139.45062 | AQ3: =C3+H3+L3+AA3+AB3+AN3+AO3+AP3 -> 12061.775
A4: Exports | C4: =SUM(D4:G4) -> 15.186581 | D4: 0 | E4: 14.097722 | G4: 1.0888587 | H4: =SUM(I4:K4) -> 7.033068 | K4: 7.033068 | L4: =SUM(M4:Z4) -> 1717.0625 | M4: 0 | N4: 0 | P4: 364.52222 | Q4: 21.672508 | R4: 156.2938 | S4: 986.60612 | T4: 35.289733 | U4: 102.14625 | V4: 0.0029088438 | W4: 36.297317 | X4: 5.469469 | Y4: 0.018500298 | Z4: 8.7436483 | AA4: 0 | AB4: =SUM(AC4:AM4) -> 9.4476585 | AE4: 0.4126464 | AI4: 9.0350121 | AJ4: 0 | AO4: 141.83539 | AQ4: =C4+H4+L4+AA4+AB4+AN4+AO4+AP4 -> 1890.5652
A5: Mar. Bunkers | C5: =SUM(D5:G5) -> 0 | H5: =SUM(I5:K5) -> 0 | L5: =SUM(M5:Z5) -> 172.71259 | S5: 15.730078 | U5: 156.98251 | AB5: =SUM(AC5:AM5) -> 0 | AQ5: =C5+H5+L5+AA5+AB5+AN5+AO5+AP5 -> 172.71259
A6: Stock Change | C6: =SUM(D6:G6) -> -101.25635 | D6: -101.86989 | E6: -0.80797667 | G6: 1.421516 | H6: =SUM(I6:K6) -> -122.93905 | I6: -136.53827 | J6: 0 | K6: 13.599214 | L6: =SUM(M6:Z6) -> 151.33981 | M6: 38.730965 | N6: -8.875152 | P6: -9.6980083 | Q6: 12.883202 | R6: 82.120249 | S6: 23.6376 | T6: 1.4659197 | U6: 8.3874136 | V6: 3.2040911 | W6: -0.51646779 | X6: 0 | Y6: 0 | Z6: 0 | AA6: 0 | AB6: =SUM(AC6:AM6) -> 4.4601014 | AE6: 0.26707428 | AI6: 1.7828522 | AJ6: 2.410175 | AQ6: =C6+H6+L6+AA6+AB6+AN6+AO6+AP6 -> -68.395488
A7: Primary Energy Supply (incl non-energy) | C7: =C2+C3-C4-C5+C6 -> 787.05173 | D7: =D2+D3-D4-D5+D6 -> 727.70471 | E7: =E2+E3-E4-E5+E6 -> 46.817169 | F7: =F2+F3-F4-F5+F6 -> 0 | G7: =G2+G3-G4-G5+G6 -> 12.529851 | H7: =H2+H3-H4-H5+H6 -> 685.95223 | I7: =I2+I3-I4-I5+I6 -> 551.68208 | J7: =J2+J3-J4-J5+J6 -> 127.704 | ... AP7: =AP2+AP3-AP4-AP5+AP6 -> 0 | AQ7: =C7+H7+L7+AA7+AB7+AN7+AO7+AP7 -> 14978.04
A8: Primary Energy Requirement (excl. non-energy) | C8: =C7-C27 -> 787.05173 | D8: =D7-D27 -> 727.70471 | E8: =E7-E27 -> 46.817169 | F8: =F7-F27 -> 0 | G8: =G7-G27 -> 12.529851 | H8: =H7-H27 -> 685.95223 | I8: =I7-I27 -> 551.68208 | J8: =J7-J27 -> 127.704 | ... AP8: =AP7-AP27 -> 0 | AQ8: =C8+H8+L8+AA8+AB8+AN8+AO8+AP8 -> 14746.457
A9: Transformation Input | C9: =SUM(C10:C14) -> 489.1342 | D9: =SUM(D10:D14) -> 489.1342 | E9: =SUM(E10:E14) -> 0 | F9: =SUM(F10:F14) -> 0 | G9: =SUM(G10:G14) -> 0 | H9: =SUM(H10:H14) -> 541.02658 | I9: =SUM(I10:I14) -> 541.02658 | J9: =SUM(J10:J14) -> 0 | ... AP9: =SUM(AP10:AP14) -> 0 | AQ9: =C9+H9+L9+AA9+AB9+AN9+AO9+AP9 -> 7058.1841
A10: Public Thermal Power Plants | C10: =SUM(D10:G10) -> 489.1342 | D10: 489.1342 | H10: =SUM(I10:K10) -> 467.10846 | I10: 467.10846 | J10: 0 | L10: =SUM(M10:Z10) -> 34.094789 | S10: 25.868327 | U10: 8.2264622 | AA10: 2187.6034 | AB10: =SUM(AC10:AM10) -> 205.3059 | AE10: 72.46706 | AF10: 99.307023 | AG10: 33.531819 | AN10: 90.714163 | AQ10: =C10+H10+L10+AA10+AB10+AN10+AO10+AP10 -> 3473.9609
A11: Combined Heat and Power Plants | C11: =SUM(D11:G11) -> 0 | D11: 0 | H11: =SUM(I11:K11) -> 5.8425469 | I11: 5.8425469 | L11: =SUM(M11:Z11) -> 0.63499472 | O11: 0 | S11: 0 | T11: 0.63499472 | U11: 0 | AA11: 272.96145 | AB11: =SUM(AC11:AM11) -> 10.597627 | AE11: 3.561556 | AH11: 7.0360715 | AQ11: =C11+H11+L11+AA11+AB11+AN11+AO11+AP11 -> 290.03662
A12: Pumped Storage Consumption | AO12: 42.94206 | AQ12: =C12+H12+L12+AA12+AB12+AN12+AO12+AP12 -> 42.94206
A13: Briquetting Plants | C13: =SUM(D13:G13) -> 0 | H13: =SUM(I13:K13) -> 68.075577 | I13: 68.075577 | L13: =SUM(M13:Z13) -> 0 | AB13: =SUM(AC13:AM13) -> 0 | AQ13: =C13+H13+L13+AA13+AB13+AN13+AO13+AP13 -> 68.075577
A14: Oil Refineries & other energy sector | C14: =SUM(D14:G14) -> 0 | H14: =SUM(I14:K14) -> 0 | L14: =SUM(M14:Z14) -> 3130.9919 | M14: 3092.2053 | N14: 38.786602 | AA14: 40.734585 | AB14: =SUM(AC14:AM14) -> 0 | AO14: 11.442472 | AQ14: =C14+H14+L14+AA14+AB14+AN14+AO14+AP14 -> 3183.1689
A15: Transformation Output | C15: =SUM(C16:C20) -> 0 | D15: =SUM(D16:D20) -> 0 | E15: =SUM(E16:E20) -> 0 | F15: =SUM(F16:F20) -> 0 | G15: =SUM(G16:G20) -> 0 | H15: =SUM(H16:H20) -> 64.671798 | I15: =SUM(I16:I20) -> 0 | J15: =SUM(J16:J20) -> 0 | ... AP15: =SUM(AP16:AP20) -> 0 | AQ15: =C15+H15+L15+AA15+AB15+AN15+AO15+AP15 -> 5104.8192
A16: Public Thermal Power Plants | C16: =SUM(D16:G16) -> 0 | H16: =SUM(I16:K16) -> 0 | L16: =SUM(M16:Z16) -> 0 | AB16: =SUM(AC16:AL16) -> 0 | AO16: 1667.7866 | AQ16: =C16+H16+L16+AA16+AO16+AP16 -> 1667.7866
A17: Combined Heat and Power Plants | C17: =SUM(D17:G17) -> 0 | H17: =SUM(I17:K17) -> 0 | L17: =SUM(M17:Z17) -> 0 | AB17: =SUM(AC17:AL17) -> 0 | AO17: 185.14396 | AQ17: =C17+H17+L17+AA17+AO17+AP17 -> 185.14396
A18: Pumped Storage Generation | AO18: 20.430939 | AQ18: =C18+H18+L18+AA18+AB18+AN18+AO18+AP18 -> 20.430939
A19: Briquetting Plants | H19: =SUM(I19:K19) -> 64.671798 | K19: 64.671798 | L19: =SUM(M19:Z19) -> 0 | AB19: =SUM(AC19:AL19) -> 0 | AQ19: =C19+H19+L19+AA19+AB19+AN19+AO19+AP19 -> 64.671798
A20: Oil Refineries | H20: =SUM(I20:K20) -> 0 | L20: =SUM(M20:Z20) -> 3166.7859 | O20: 90.017984 | P20: 640.5368 | Q20: 226.77459 | R20: 0 | S20: 960.95018 | T20: 64.797463 | U20: 1146.9502 | W20: 36.758644 | AB20: =SUM(AC20:AL20) -> 0 | AQ20: =C20+H20+L20+AA20+AB20+AN20+AO20+AP20 -> 3166.7859
A21: Exchanges and transfers | C21: =SUM(C22:C24) -> 22.240062 | D21: =SUM(D22:D24) -> -17.141361 | E21: =SUM(E22:E24) -> 39.381423 | F21: =SUM(F22:F24) -> 0 | G21: =SUM(G22:G24) -> 0 | H21: =SUM(I21:K21) -> 0 | I21: =SUM(I22:I24) -> 0 | J21: =SUM(J22:J24) -> 0 | K21: =SUM(K22:K24) -> 0 | L21: =SUM(M21:Z21) -> -24.684016 | M21: =SUM(M22:M24) -> 0 | N21: =SUM(N22:N24) -> 30.880435 | O21: =SUM(O22:O24) -> 0 | P21: =SUM(P22:P24) -> -31.331711 | Q21: =SUM(Q22:Q24) -> 361.9108 | R21: =SUM(R22:R24) -> -361.12225 | S21: =SUM(S22:S24) -> -0.17168421 | T21: =SUM(T22:T24) -> 0 | ... AQ21: =SUM(AQ22:AQ24) -> -2.4439548
A22: Electricity | AB22: =SUM(AC22:AM22) -> -804.60162 | AC22: =-AC2 -> -59.691709 | AD22: =-AD2 -> -743.01992 | AK22: -1.8899881 | AO22: =-(C22+H22+L22+AA22+AB22) -> 804.60162 | AQ22: =C22+H22+L22+AA22+AB22+AN22+AO22+AP22 -> 0
A23: Heat | AQ23: =C23+H23+L23+AA23+AB23+AN23+AO23+AP23 -> 0
A24: Other | C24: =SUM(D24:G24) -> 22.240062 | D24: -17.141361 | E24: =-D24-V24 -> 39.381423 | L24: =SUM(N24:Z24) -> -24.684016 | N24: 30.880435 | P24: -31.331711 | Q24: 361.9108 | R24: -361.12225 | S24: -0.17168421 | U24: -2.6095464 | V24: -22.240062 | W24: 0 | AB24: =SUM(AC24:AM24) -> 0 | AQ24: =C24+H24+L24+AA24+AB24+AN24+AO24+AP24 -> -2.4439548
A25: Own Use and Distribution Losses | C25: =SUM(D25:G25) -> 0 | H25: =SUM(I25:K25) -> 10.283248 | I25: 10.283248 | L25: =SUM(O25:Z25) -> 98.284658 | O25: 95.274692 | S25: 0 | T25: 0.0041693256 | U25: 3.0057963 | AA25: 57.5286 | AB25: =SUM(AC25:AI25) -> 0 | AO25: 259.46681 | AQ25: =C25+H25+L25+AA25+AB25+AN25+AO25+AP25 -> 425.56332
A26: Available Final Energy Consumption | C26: =C7-C9+C15+C21-C25 -> 320.1576 | D26: =D7-D9+D15+D21-D25 -> 221.42916 | E26: =E7-E9+E15+E21-E25 -> 86.198592 | F26: =F7-F9+F15+F21-F25 -> 0 | G26: =G7-G9+G15+G21-G25 -> 12.529851 | H26: =H7-H9+H15+H21-H25 -> 199.3142 | I26: =I7-I9+I15+I21-I25 -> 0.37225107 | J26: =J7-J9+J15+J21-J25 -> 127.704 | ... AP26: =AP7-AP9+AP15+AP21-AP25 -> 0 | AQ26: =C26+H26+L26+AA26+AB26+AN26+AO26+AP26 -> 12596.668
A27: Non-Energy Consumption | C27: =C28 -> 0 | D27: =D28 -> 0 | E27: =E28 -> 0 | F27: =F28 -> 0 | G27: =G28 -> 0 | H27: =H28 -> 0 | I27: =I28 -> 0 | J27: =J28 -> 0 | ... V27: =V28 -> 0 | X27: =X28 -> 195.36275 | Y27: =Y28 -> 1.2096467 | Z27: =Z28 -> 35.010885 | AA27: =AA28 -> 0 | AB27: =AB28 -> 0 | AC27: =AC28 -> 0 | AD27: =AD28 -> 0 | AE27: =AE28 -> 0 | ... AQ27: =AQ28 -> 231.58328
A28: Final non-Energy Consumption (Feedstocks) | C28: =SUM(D28:G28) -> 0 | H28: =SUM(I28:K28) -> 0 | L28: =SUM(M28:Z28) -> 231.58328 | X28: =X26 -> 195.36275 | Y28: =Y26 -> 1.2096467 | Z28: =Z26 -> 35.010885 | AA28: 0 | AB28: =SUM(AC28:AI28) -> 0 | AQ28: =C28+H28+L28+AA28+AB28+AN28+AO28+AP28 -> 231.58328
A29: Total Final Energy Consumption | C29: =C30+C45+C56+C58+C65+C70+C71 -> 322.73713 | D29: =D30+D45+D56+D58+D65+D70+D71 -> 221.25199 | E29: =E30+E45+E56+E58+E65+E70+E71 -> 89.64728 | F29: =F30+F45+F56+F58+F65+F70+F71 -> 0 | G29: =G30+G45+G56+G58+G65+G70+G71 -> 11.837385 | H29: =H30+H45+H56+H58+H65+H70+H71 -> 197.36847 | I29: =I30+I45+I56+I58+I65+I70+I71 -> 0.82966372 | J29: =J30+J45+J56+J58+J65+J70+J71 -> 127.704 | ... AQ29: =AQ30+AQ45+AQ56+AQ58+AQ65+AQ70+AQ71 -> 12441.76
A30: Industry* | C30: =SUM(C31:C44) -> 105.42503 | D30: 105.42455 | E30: 0 | H30: =SUM(H31:H44) -> 0.82966372 | I30: =SUM(I31:I44) -> 0.82966372 | J30: =SUM(J31:J44) -> 0 | K30: =SUM(K31:K44) -> 0 | L30: =SUM(L31:L44) -> 333.21701 | M30: =SUM(M31:M44) -> 0 | N30: =SUM(N31:N44) -> 0 | O30: =SUM(O31:O44) -> 0 | P30: =SUM(P31:P44) -> 0 | Q30: 5.8273118 | R30: =SUM(R31:R44) -> 0 | S30: 30.396553 | T30: 55.10581 | U30: 100.77893 | V30: 141.1084 | W30: =SUM(W31:W44) -> 0 | X30: =SUM(X31:X44) -> 0 | Y30: =SUM(Y31:Y44) -> 0 | Z30: =SUM(Z31:Z44) -> 0 | AA30: 1006.4294 | AB30: =SUM(AB31:AB44) -> 198.81521 | AC30: =SUM(AC31:AC44) -> 0 | AD30: =SUM(AD31:AD44) -> 0 | AE30: =SUM(AE31:AE44) -> 153.96699 | AF30: =SUM(AF31:AF44) -> 40.692904 | AG30: =SUM(AG31:AG44) -> 0 | AH30: =SUM(AH31:AH44) -> 4.1553164 | AI30: =SUM(AI31:AI44) -> 0 | ... AN30: =SUM(AN31:AN44) -> 54.72294 | AO30: 562.37095 | AP30: =SUM(AP31:AP44) -> 0 | AQ30: =C30+H30+L30+AA30+AB30+AN30+AO30+AP30 -> 2261.8102
A31: Non-Energy Mining | B31: 05-09 | C31: =SUM(D31:G31) -> 0 | D31: 0 | H31: =SUM(I31:K31) -> 0 | L31: =SUM(M31:Z31) -> 15.076944 | Q31: 0.252 | S31: 0 | T31: 0.090944232 | U31: 14.734 | V31: 0 | AA31: 11.321518 | AB31: =SUM(AC31:AM31) -> 0 | AO31: 18.942945 | AQ31: =C31+H31+L31+AA31+AB31+AN31+AO31+AP31 -> 45.341408
A32: Food & beverages | B32: 10-11 | C32: =SUM(D32:G32) -> 18.505816 | D32: 18.505816 | H32: =SUM(I32:K32) -> 0.82966372 | I32: 0.82966372 | L32: =SUM(M32:Z32) -> 65.081235 | Q32: 1.514 | S32: 22.968462 | T32: 29.495772 | U32: 11.103 | V32: 0 | AA32: 272.71139 | AB32: =SUM(AC32:AM32) -> 27.983335 | AE32: 23.828019 | AH32: 4.1553164 | AO32: 95.275089 | AQ32: =C32+H32+L32+AA32+AB32+AN32+AO32+AP32 -> 480.38653
A33: Textiles and textile products | B33: 13-14 | C33: =SUM(D33:G33) -> 0 | D33: 0 | H33: =SUM(I33:K33) -> 0 | L33: =SUM(M33:Z33) -> 4.25876 | Q33: 0.077 | S33: 0 | T33: 3.90776 | U33: 0.274 | V33: 0 | AA33: 3.3044502 | AB33: =SUM(AC33:AM33) -> 0 | AO33: 2.6521774 | AQ33: =C33+H33+L33+AA33+AB33+AN33+AO33+AP33 -> 10.215388
A34: Wood and wood products | B34: 16 | C34: =SUM(D34:G34) -> 0 | D34: 0 | H34: =SUM(I34:K34) -> 0 | L34: =SUM(M34:Z34) -> 3.2131896 | Q34: 0.177 | S34: 0 | T34: 0.60818955 | U34: 2.428 | V34: 0 | AA34: 9.6605546 | AB34: =SUM(AC34:AM34) -> 127.9132 | AE34: 127.9132 | AO34: 24.722009 | AQ34: =C34+H34+L34+AA34+AB34+AN34+AO34+AP34 -> 165.50895
A35: Pulp, paper, publishing and printing | B35: 17-18 | C35: =SUM(D35:G35) -> 0 | D35: 0 | H35: =SUM(I35:K35) -> 0 | L35: =SUM(M35:Z35) -> 1.6055046 | Q35: 0.096 | S35: 0 | T35: 0.6295046 | U35: 0.88 | V35: 0 | AA35: 14.125994 | AB35: =SUM(AC35:AM35) -> 0 | AO35: 10.336268 | AQ35: =C35+H35+L35+AA35+AB35+AN35+AO35+AP35 -> 26.067767
A36: Chemicals & man-made fibres | B36: 20-21 | C36: =SUM(D36:G36) -> 0 | D36: 0 | H36: =SUM(I36:K36) -> 0 | L36: =SUM(M36:Z36) -> 21.418897 | Q36: 0.306 | S36: 2.7458234 | T36: 3.9702841 | U36: 4.579 | V36: 9.8177897 | AA36: 129.58451 | AB36: =SUM(AC36:AM36) -> 0 | AE36: 0 | AO36: 76.140196 | AQ36: =C36+H36+L36+AA36+AB36+AN36+AO36+AP36 -> 227.1436
A37: Rubber and plastic products | B37: 22 | C37: =SUM(D37:G37) -> 0 | D37: 0 | H37: =SUM(I37:K37) -> 0 | L37: =SUM(M37:Z37) -> 4.1927666 | Q37: 0.535 | S37: 0 | T37: 2.1897666 | U37: 1.468 | V37: 0 | AA37: 17.456036 | AB37: =SUM(AC37:AM37) -> 0 | AO37: 25.060497 | AQ37: =C37+H37+L37+AA37+AB37+AN37+AO37+AP37 -> 46.7093
A38: Other non-metallic mineral products | B38: 23 | C38: =SUM(D38:G38) -> 86.919212 | D38: 86.919212 | H38: =SUM(I38:K38) -> 0 | L38: =SUM(M38:Z38) -> 160.32357 | Q38: 1.144 | S38: 0 | T38: 2.6359617 | U38: 25.253 | V38: 131.29061 | AA38: 46.760405 | AB38: =SUM(AC38:AM38) -> 42.918678 | AE38: 2.2257741 | AF38: 40.692904 | AN38: 54.72294 | AO38: 73.686158 | AQ38: =C38+H38+L38+AA38+AB38+AN38+AO38+AP38 -> 465.33096
A39: Basic metals and fabricated metal products | B39: 24-25 | C39: =SUM(D39:G39) -> 0 | D39: 0 | H39: =SUM(I39:K39) -> 0 | L39: =SUM(M39:Z39) -> 5.6776554 | Q39: 0.338 | S39: 1.0397615 | T39: 1.5488939 | U39: 2.751 | V39: 0 | AA39: 411.95146 | AB39: =SUM(AC39:AM39) -> 0 | AO39: 67.595438 | AQ39: =C39+H39+L39+AA39+AB39+AN39+AO39+AP39 -> 485.22456
A40: Machinery and equipment n.e.c. | B40: 28 | C40: =SUM(D40:G40) -> 0 | D40: 0 | H40: =SUM(I40:K40) -> 0 | L40: =SUM(M40:Z40) -> 4.0583976 | Q40: 0.144 | S40: 0 | T40: 2.2053976 | U40: 1.709 | V40: 0 | AA40: 14.088543 | AB40: =SUM(AC40:AM40) -> 0 | AO40: 17.03379 | AQ40: =C40+H40+L40+AA40+AB40+AN40+AO40+AP40 -> 35.180731
...

Sheet RSD_Balance
A1: ~Country | B1: IE | F1: SMF - Components | H1: SHARE
A2: Sector | B2: Residential | F2: COA | H2: 0.194
A3: ~Year | B3: 2018 | F3: PEA | H3: 0.744
A4: ~Unit conversion | B4: 0.041868 | F4: BIOWOO | H4: 0.062
F5: SMF | H5: =SUM(H2:H4) -> 1 | AN5: Light
AN6: APT | AO6: 0.33 | AQ6: ELC | AR6: 2.05
A7: Base-year energy consumption from SEAI (PJ) | F7: Space Heating | I7: Water Heating | L7: Lighting | O7: Pumps & Fans | R7: Cooking | S7: Appliances | Y7: TIMES-Ireland Total | Z7: SEAI Energy Balance 2018 | AA7: Excel Error | AD7: VEDA | AE7: VEDA Error | AI7: SH | AN7: ATT | AO7: 1.75 | AQ7: Gas | AR7: 0.67
A8: Fuel | B8: Description | C8: PJ | F8: Apartment | G8: Attached | H8: Detached | I8: Apartment | J8: Attached | K8: Detached | L8: Apartment | M8: Attached | N8: Detached | O8: Apartment | P8: Attached | Q8: Detached | S8: Refrigeration | T8: Cloth Washing | U8: Cloth Drying | V8: Dish Washing | W8: Other Electric | X8: Other Energy | AA8: Error | AE8: Error | AI8: RSDAHT | AJ8: 1.1516523 | AN8: DET | AO8: 2.73 | AQ8: LPG | AR8: 0.04
A9: COA | B9: Coal | C9: =SUM('EB2018'!C56)*RSD_Balance!B4 -> 9.0766551 | E9: COA | F9: ='SHWLP-Apt'!$AC$7+'SHWLP-Apt'!AC20 -> 0 | G9: ='SHWLP-Att'!$AC$7+'SHWLP-Att'!$AC$20 -> 5.0701051 | H9: ='SHWLP-Det'!$AC$7+'SHWLP-Det'!$AC$20 -> 4.428656 | I9: ='SHWLP-Apt'!$AC$33+'SHWLP-Apt'!$AC$46 -> 0 | J9: ='SHWLP-Att'!$AC$33+'SHWLP-Att'!$AC$46 -> 0.40856217 | K9: ='SHWLP-Det'!$AC$33+'SHWLP-Det'!$AC$46 -> 0.10058759 | Y9: =SUM(F9:X9) -> 10.007911 | Z9: =C9 -> 9.0766551 | AA9: =ABS(Z9-Y9)/Z9 -> 0.102599 | AD9: =AJ9+AJ20 -> 10.269076 | AE9: =ABS(AD9-Y9)/AD9 -> 0.025432157 | AI9: RSDCOA | AJ9: 9.659974 | AN9: P&F
A10: PEA | B10: ='EB2018'!H1 -> Peat | C10: ='EB2018'!H56*RSD_Balance!B4 -> 8.2286867 | E10: PEA | F10: ='SHWLP-Apt'!$AC$18+'SHWLP-Apt'!$AC$21 -> 0.0032061499 | G10: ='SHWLP-Att'!$AC$18+'SHWLP-Att'!$AC$21 -> 2.0071676 | H10: ='SHWLP-Det'!$AC$18+'SHWLP-Det'!$AC$21 -> 5.3563325 | I10: ='SHWLP-Apt'!$AC$44+'SHWLP-Apt'!$AC$47 -> 0 | J10: ='SHWLP-Att'!$AC$44+'SHWLP-Att'!$AC$47 -> 0.36088384 | K10: ='SHWLP-Det'!$AC$44+'SHWLP-Det'!$AC$47 -> 0.38575861 | Y10: =SUM(F10:X10) -> 8.1133487 | Z10: =C10 -> 8.2286867 | AA10: =ABS(Z10-Y10)/Z10 -> 0.014016576 | AD10: =AJ14+AJ27 -> 8.1954076 | AE10: =ABS(AD10-Y10)/AD10 -> 0.010012791 | AI10: RSDELC | AJ10: 4.4337734 | AN10: APT | AO10: 0.07
A11: LPG | B11: ='EB2018'!T1 -> LPG | C11: ='EB2018'!T56*RSD_Balance!B4 -> 2.2542369 | E11: OILLPG | F11: ='SHWLP-Apt'!$AC$10 -> 0 | G11: ='SHWLP-Att'!$AC$10 -> 0.33080594 | H11: ='SHWLP-Det'!$AC$10 -> 1.2958226 | I11: ='SHWLP-Apt'!$AC$36 -> 0 | J11: ='SHWLP-Att'!$AC$36 -> 0 | K11: ='SHWLP-Det'!$AC$36 -> 0 | R11: 0.039492406 | Y11: =SUM(F11:X11) -> 1.6661209 | Z11: =C11 -> 2.2542369 | AA11: =ABS(Z11-Y11)/Z11 -> 0.2608936 | AD11: =AJ13+AJ26+AR8 -> 2.1294859 | AE11: =ABS(AD11-Y11)/AD11 -> 0.21759477 | AI11: RSDGAS | AJ11: 16.539193 | AN11: ATT | AO11: 0.49
A12: GSL | B12: ='EB2018'!P1 -> Gasoline | C12: ='EB2018'!P56*B4 -> 0 | E12: OILGSL | Y12: =SUM(F12:X12) -> 0 | Z12: =C12 -> 0 | AI12: RSDKER | AJ12: 33.821001 | AN12: DET | AO12: 0.57
A13: KER | B13: ='EB2018'!Q1 -> Kerosene | C13: ='EB2018'!Q56*RSD_Balance!B4 -> 36.243918 | E13: OILKER | F13: ='SHWLP-Apt'!$AC$14 -> 0.23973747 | G13: ='SHWLP-Att'!$AC$14 -> 8.555665 | H13: ='SHWLP-Det'!$AC$14 -> 31.600518 | I13: ='SHWLP-Apt'!$AC$40 -> 0 | J13: ='SHWLP-Att'!$AC$40 -> 3.1609218 | K13: ='SHWLP-Det'!$AC$40 -> 8.4233865 | Y13: =SUM(F13:X13) -> 51.980229 | Z13: =C13 -> 36.243918 | AA13: =ABS(Z13+Z14+Z16-Y13)/(Z13+Z14+Z16) -> 0.033757693 | AD13: =AJ12+AJ25 -> 43.727301 | AE13: =ABS(AD13-Y13)/AD13 -> 0.18873628 | AI13: RSDLPG | AJ13: 1.6238402
A14: DST | B14: ='EB2018'!U1 -> Gasoil / Diesel /DERV | C14: ='EB2018'!U56*RSD_Balance!B4 -> 13.81263 | E14: OILDST | Y14: =SUM(F14:X14) -> 0 | Z14: =C14 -> 13.81263 | AA14: =ABS(Z13+Z14+Z16-Y13)/(Z13+Z14+Z16) -> 0.033757693 | AI14: RSDPEA | AJ14: 7.3969701
A15: HFO | B15: ='EB2018'!S1 -> Fueloil | C15: ='EB2018'!S56*RSD_Balance!B4 -> 0 | E15: OILHFO | Y15: =SUM(F15:X15) -> 0 | Z15: =C15 -> 0 | AA15: =ABS(Z13+Z14+Z16-Y13)/(Z13+Z14+Z16) -> 0.033757693 | AI15: RSDWOO | AJ15: 1.1222132 | AQ15: CD | AR15: 1.71
A16: COK | B16: ='EB2018'!V1 -> Petroleum Coke | C16: ='EB2018'!V56*RSD_Balance!B4 -> 0.2262493 | E16: OILCOK | Y16: =SUM(F16:X16) -> 0 | Z16: =C16 -> 0.2262493 | AA16: =ABS(Z13+Z14+Z16-Y13)/(Z13+Z14+Z16) -> 0.033757693 | AQ16: CW | AR16: 1.1
A17: GAS | B17: ='EB2018'!AA1 -> Natural Gas | C17: ='EB2018'!AA56*RSD_Balance!B4 -> 25.292197 | E17: GASNAT | F17: ='SHWLP-Apt'!$AC$16 -> 1.2906334 | G17: ='SHWLP-Att'!$AC$16 -> 11.879486 | H17: ='SHWLP-Det'!$AC$16 -> 5.2345577 | I17: ='SHWLP-Apt'!$AC$42 -> 0.60716402 | J17: ='SHWLP-Att'!$AC$42 -> 4.1120335 | K17: ='SHWLP-Det'!$AC$42 -> 1.4948266 | R17: 0.66992893 | Y17: =SUM(F17:X17) -> 25.28863 | Z17: =C17 -> 25.292197 | AA17: =ABS(Z17-Y17)/Z17 -> 0.00014104055 | AD17: =AJ11+AJ23+AR7 -> 23.522734 | AE17: =ABS(AD17-Y17)/AD17 -> 0.075071888 | AI17: WH | AQ17: DW | AR17: 1.19
A18: SOL | B18: ='EB2018'!AL1 -> Solar Thermal | C18: ='EB2018'!AL56*RSD_Balance!B4 -> 0.56017671 | E18: RENSOL | I18: =($C$18*0.05) -> 0.028008836 | J18: =($C$18*0.475) -> 0.26608394 | K18: =($C$18*0.475) -> 0.26608394 | Y18: =SUM(F18:X18) -> 0.56017671 | Z18: =C18 -> 0.56017671 | AA18: =ABS(Z18-Y18)/Z18 -> 1.9819157e-16 | AD18: =AJ28 -> 0.56017671 | AE18: =ABS(AD18-Y18)/AD18 -> 9.9095785e-16 | AI18: RSDAHT2 | AJ18: 1.05138 | AQ18: OE | AR18: 10.84
A19: WOO | B19: ='EB2018'!AE1 -> Biomass | C19: ='EB2018'!AE56*RSD_Balance!B4 -> 1.246665 | E19: BIOWOO | F19: ='SHWLP-Apt'!$AC$22+'SHWLP-Apt'!$AC$23 -> 0 | G19: ='SHWLP-Att'!$AC$22+'SHWLP-Att'!$AC$23 -> 0.15910158 | H19: ='SHWLP-Det'!$AC$22+'SHWLP-Det'!$AC$23 -> 0.86316679 | I19: ='SHWLP-Apt'!$AC$49+'SHWLP-Apt'!$AC$48 -> 0 | J19: ='SHWLP-Att'!$AC$49+'SHWLP-Att'!$AC$48 -> 0.030073653 | K19: ='SHWLP-Det'!$AC$49+'SHWLP-Det'!$AC$48 -> 0.032146551 | Y19: =SUM(F19:X19) -> 1.0844886 | Z19: =C19 -> 1.246665 | AA19: =ABS(Z19-Y19)/Z19 -> 0.13008822 | AD19: =AJ29+AJ15 -> 1.2689595 | AE19: =ABS(AD19-Y19)/AD19 -> 0.14537179 | AI19: RSDBDL | AJ19: 7.8153182e-05 | AQ19: RF | AR19: 1.41
A20: BGS | B20: ='EB2018'!AH1 -> Biogas | C20: ='EB2018'!AH56*RSD_Balance!B4 -> 0 | E20: BIOGAS | Y20: =SUM(F20:X20) -> 0 | Z20: =C20 -> 0 | AI20: RSDCOA | AJ20: 0.60910161
A21: BIOMUN | B21: ='EB2018'!AG1 -> Landfill Gas | C21: ='EB2018'!AG56*RSD_Balance!B4 -> 0 | E21: BIOMUN | Y21: =SUM(F21:X21) -> 0 | Z21: =C21 -> 0 | AI21: RSDELC | AJ21: 2.3626994
A22: AHT | B22: ='EB2018'!AM1 -> Ambient Heat | C22: ='EB2018'!AM56*RSD_Balance!B4 -> 1.1669029 | E22: RENAHT | F22: =('SHWLP-Apt'!$AC$12/('SHWLP-Apt'!$AC$12+'SHWLP-Att'!$AC$12+'SHWLP-Det'!$AC$12+'SHWLP-Apt'!$AC$38+'SHWLP-Att'!$AC$38+'SHWLP-Det'!$AC$38+'SHWLP-Apt'!AC24+'SHWLP-Apt'!AC50+'SHWLP-Att'!AC24+'SHWLP-Att'!AC50+'SHWLP-Det'!AC24+'SHWLP-Det'!AC50)) -> 0.21442628 | G22: =('SHWLP-Att'!$AC$12/('SHWLP-Apt'!$AC$12+'SHWLP-Att'!$AC$12+'SHWLP-Det'!$AC$12+'SHWLP-Apt'!$AC$38+'SHWLP-Att'!$AC$38+'SHWLP-Det'!$AC$38+'SHWLP-Apt'!AC24+'SHWLP-Apt'!AC50+'SHWLP-Att'!AC24+'SHWLP-Att'!AC50+'SHWLP-Det'!AC24+'SHWLP-Det'!AC50)) -> 0.13280396 | H22: =('SHWLP-Det'!$AC$12/('SHWLP-Apt'!$AC$12+'SHWLP-Att'!$AC$12+'SHWLP-Det'!$AC$12+'SHWLP-Apt'!$AC$38+'SHWLP-Att'!$AC$38+'SHWLP-Det'!$AC$38+'SHWLP-Apt'!AC24+'SHWLP-Apt'!AC50+'SHWLP-Att'!AC24+'SHWLP-Att'!AC50+'SHWLP-Det'!AC24+'SHWLP-Det'!AC50)) -> 0.1494104 | I22: =('SHWLP-Apt'!$AC$38/('SHWLP-Apt'!$AC$12+'SHWLP-Att'!$AC$12+'SHWLP-Det'!$AC$12+'SHWLP-Apt'!$AC$38+'SHWLP-Att'!$AC$38+'SHWLP-Det'!$AC$38+'SHWLP-Apt'!AC50)) -> 0.34644334 | J22: =('SHWLP-Att'!$AC$38/('SHWLP-Apt'!$AC$12+'SHWLP-Att'!$AC$12+'SHWLP-Det'!$AC$12+'SHWLP-Apt'!$AC$38+'SHWLP-Att'!$AC$38+'SHWLP-Det'!$AC$38+'SHWLP-Att'!AC50)) -> 0.15691601 | K22: =('SHWLP-Det'!$AC$38/('SHWLP-Apt'!$AC$12+'SHWLP-Att'!$AC$12+'SHWLP-Det'!$AC$12+'SHWLP-Apt'!$AC$38+'SHWLP-Att'!$AC$38+'SHWLP-Det'!$AC$38+'SHWLP-Det'!AC50)) -> 0 | Y22: =SUM(F22:X22) -> 1 | Z22: =C22 -> 1.1669029 | AA22: =ABS(Z22+Z27-Y22-Y27)/(Z22+Z27) -> 0.14303065 | AD22: =AJ8+AJ18+AJ24 -> 2.2054176 | AE22: =ABS(AD22-Y22)/SUM(AD22+AD27) -> 0.54657113 | AI22: RSDETH | AJ22: 2.1879413e-05
A23: ETH | B23: Ethanol | C23: ='EB2018'!AI56*RSD_Balance!B4*0.5 -> 0 | E23: BIOETH | F23: ='SHWLP-Apt'!$AC$9 -> 0 | G23: ='SHWLP-Att'!$AC$9 -> 0 | H23: ='SHWLP-Det'!$AC$9 -> 0 | I23: ='SHWLP-Apt'!$AC$35 -> 0 | J23: ='SHWLP-Att'!$AC$35 -> 0 | K23: ='SHWLP-Det'!$AC$35 -> 0 | Y23: =SUM(F23:X23) -> 0 | Z23: =C23 -> 0 | AI23: RSDGAS | AJ23: 6.313541
A24: BDL | B24: Biodiesel | C24: ='EB2018'!AI56*RSD_Balance!B4*0.5 -> 0 | E24: BIODST | F24: ='SHWLP-Apt'!$AC$8 -> 0 | G24: ='SHWLP-Att'!$AC$8 -> 0 | H24: ='SHWLP-Det'!$AC$8 -> 0 | I24: ='SHWLP-Apt'!$AC$34 -> 0 | J24: ='SHWLP-Att'!$AC$34 -> 0 | K24: ='SHWLP-Det'!$AC$34 -> 0 | Y24: =SUM(F24:X24) -> 0 | Z24: =C24 -> 0 | AI24: RSDHET | AJ24: 0.002385329
A25: BIOSLU | B25: ='EB2018'!AN1 -> Non-Renewable Waste | C25: ='EB2018'!AN56*RSD_Balance!B4 -> 0 | E25: BIOSLU | Y25: =SUM(F25:X25) -> 0 | Z25: =C25 -> 0 | AI25: RSDKER | AJ25: 9.9062996
A26: ELC | B26: ='EB2018'!AO1 -> Electricity | C26: ='EB2018'!AO56*RSD_Balance!B4 -> 29.43089 | E26: ELC | F26: ='SHWLP-Apt'!$AC$11+'SHWLP-Apt'!$AC$13 -> 0.66757192 | G26: ='SHWLP-Att'!$AC$11+'SHWLP-Att'!$AC$13 -> 1.0838903 | H26: ='SHWLP-Det'!$AC$11+'SHWLP-Det'!$AC$13 -> 1.589426 | I26: ='SHWLP-Apt'!$AC$37+'SHWLP-Apt'!$AC$39 -> 0.69372778 | J26: ='SHWLP-Att'!$AC$37+'SHWLP-Att'!$AC$39 -> 0.56457084 | K26: ='SHWLP-Det'!$AC$37+'SHWLP-Det'!$AC$39 -> 0 | L26: ='SHWLP-Apt'!$AC$59 -> 0.34353539 | M26: ='SHWLP-Att'!$AC$59 -> 1.8080719 | N26: ='SHWLP-Det'!$AC$59 -> 2.7736752 | O26: ='SHWLP-Apt'!$AC$60 -> 0.070788487 | P26: ='SHWLP-Att'!$AC$60 -> 0.5006851 | Q26: ='SHWLP-Det'!$AC$60 -> 0.57732325 | R26: 2.0517341 | S26: =(T38*0.0000000036)*(DwellingStocks!L28*RSD_Balance!U38) -> 1.4430683 | T26: =(T36*0.0000000036)*(DwellingStocks!L28*RSD_Balance!U36) -> 1.1268114 | U26: =(T37*0.0000000036)*(DwellingStocks!L28*RSD_Balance!U37) -> 1.7528219 | V26: =(T39*0.0000000036)*(DwellingStocks!L28*RSD_Balance!U39) -> 1.2125522 | W26: 10.843444 | X26: 0 | Y26: =SUM(F26:X26) -> 29.103698 | Z26: =C26 -> 29.43089 | AA26: =ABS(Z26-Y26)/Z26 -> 0.011117318 | AD26: =AJ10+AJ21+AO6+AO7+AO8+AO10+AO11+AO12+AR6+AR15+AR16+AR17+AR18+AR19 -> 31.036473 | AE26: =ABS(AD26-Y26)/AD26 -> 0.062274316 | AI26: RSDLPG | AJ26: 0.46564568
A27: HET | B27: ='EB2018'!AP1 -> Heat | C27: ='EB2018'!AP56*RSD_Balance!B4 -> 0 | E27: HET | F27: ='SHWLP-Apt'!$AC$24 -> 0 | G27: ='SHWLP-Att'!$AC$24 -> 0 | H27: ='SHWLP-Det'!$AC$24 -> 0 | I27: ='SHWLP-Apt'!$AC$50 -> 0 | J27: ='SHWLP-Att'!$AC$50 -> 0 | K27: ='SHWLP-Det'!$AC$50 -> 0 | Y27: =SUM(F27:X27) -> 0 | Z27: =C27 -> 0 | AA27: =ABS(Z22+Z27-Y22-Y27)/(Z22+Z27) -> 0.14303065 | AI27: RSDPEA | AJ27: 0.79843754
B28: Total | C28: =SUM(C9:C27) -> 127.53921 | E28: SMF | F28: =SUM('SHWLP-Apt'!AC20:AC22) -> 0 | G28: =SUM('SHWLP-Att'!AC20:AC22) -> 2.5661545 | H28: =SUM('SHWLP-Det'!AC20:AC22) -> 6.694108 | I28: =SUM('SHWLP-Apt'!AC46:AC48) -> 0 | J28: =SUM('SHWLP-Att'!AC46:AC48) -> 0.48505892 | K28: =SUM('SHWLP-Det'!AC46:AC48) -> 0.51849275 | Y28: =SUM(F28:K28) -> 10.263814 | AI28: RSDSOL | AJ28: 0.56017671
F29: =SUM(F9:F27) -> 2.4155752 | G29: =SUM(G9:G27) -> 29.219026 | H29: =SUM(H9:H27) -> 50.51789 | I29: =SUM(I9:I27) -> 1.675344 | J29: =SUM(J9:J27) -> 9.0600458 | K29: =SUM(K9:K27) -> 10.70279 | L29: =SUM(L9:L27) -> 0.34353539 | M29: =SUM(M9:M27) -> 1.8080719 | ... Z29: =SUM(Z9:Z27) -> 127.53921 | AA29: =ABS(Z29-Y29)/Z29 -> 0.0099216072 | AD29: =SUM(AD9:AD27) -> 122.91503 | AI29: RSDWOO | AJ29: 0.14674631
F30: =SUM(F29:H29) -> 82.152491 | G30: =F30/$Y$29 -> 0.63780711 | I30: =SUM(I29:K29) -> 21.43818 | J30: =I30/$Y$29 -> 0.16643955 | L30: =SUM(L29:N29) -> 4.9252825 | M30: =L30/$Y$29 -> 0.038238404 | O30: =SUM(O29:Q29) -> 1.1487968 | P30: =O30/$Y$29 -> 0.0089189114 | R30: =R29/$Y$29 -> 0.021436776 | S30: =SUM(S29:X29) -> 16.378697 | T30: =S30/$Y$29 -> 0.12715926 | Y30: =T30+R30+P30++M30+J30+G30 -> 1
Y33: =F7 -> Space Heating | Z33: =F30 -> 82.152491
Y34: =I7 -> Water Heating | Z34: =I30 -> 21.43818
S35: Item | T35: kWh/yr/unit | U35: Ownership | Y35: =O7 -> Pumps & Fans | Z35: =O30 -> 1.1487968
R36: Cloth Washing | T36: 185 | U36: 0.975 | Y36: =L7 -> Lighting | Z36: =L30 -> 4.9252825
R37: Cloth Drying | T37: 433 | U37: 0.648 | Y37: =R7 -> Cooking | Z37: =R29 -> 2.7611555
R38: Refrigeration | T38: 231 | U38: 1 | Y38: =S7 -> Appliances | Z38: =S30 -> 16.378697
R39: Dish Washing | T39: 300 | U39: 0.647

Sheet Fuel-Age_Adj
B3: Summary without Fuels | CA3: E1055: | CI3: E1008
B4: BER Database (Fuel-Age) | O4: CSO Database 2016 (Fuel-Age) | CA4: CSO Database 2016
B6: Year_of_Construction (group) | C6: Apartments | D6: Attached | E6: Detached | O6: Year_of_Construction (group) | P6: Apartments | Q6: Attached | R6: Detached | CA6: Private Households in Permanent Housing Units 2011 to 2016 (Number) by | CI6: Private Households in Permanent Housing Units 2011 to 2016 (Number) by | CQ6: Private Households in Permanent Housing Units 2011 to 2016 (Number) by
B7: Before_1919 | C7: 6094 | D7: 22883 | E7: 21159 | F7: =SUM(C7:E7) -> 50136 | O7: Before 1919 | P7: =CE76+CE64+CE88 -> 13706 | Q7: =CE39+CE52 -> 52434 | R7: =CE27 -> 74125 | S7: =SUM(P7:R7) -> 140265 | CA7: Persons per Household, Aggregate Town or Rural Area, Type of Private | CI7: Persons per Household, Aggregate Town or Rural Area, Type of Private | CQ7: Aggregate Town or Rural Area, Period in which Built, Type of Private
B8: 1919-1945 | C8: 2800 | D8: 26844 | E8: 16032 | F8: =SUM(C8:E8) -> 45676 | O8: 1919 to 1945 | P8: =CE77+CE65+CE89 -> 5393 | Q8: =CE40+CE53 -> 56743 | R8: =CE28 -> 46847 | S8: =SUM(P8:R8) -> 108983 | CA8: Accommodation, Period in which Built and Census Year | CI8: Accommodation, Type of Central Heating and Census Year | CQ8: Accommodation, Type of Central Heating and Census Year
B9: 1946-1960 | C9: 2187 | D9: 33473 | E9: 14682 | F9: =SUM(C9:E9) -> 50342 | O9: 1946 to 1960 | P9: =CE78+CE66+CE90 -> 5389 | Q9: =CE42+CE54 -> 77531 | R9: =CE29 -> 42427 | S9: =SUM(P9:R9) -> 125347
B10: 1961-1970 | C10: 2486 | D10: 24851 | E10: 14478 | F10: =SUM(C10:E10) -> 41815 | O10: 1961 to 1970 | P10: =CE79+CE67+CE91 -> 5420 | Q10: =CE43+CE55 -> 67734 | R10: =CE30 -> 42221 | S10: =SUM(P10:R10) -> 115375 | CE10: 2016 | CM10: 2016 | CU10: 2016
B11: 1971-1980 | C11: 3677 | D11: 51695 | E11: 35579 | F11: =SUM(C11:E11) -> 90951 | O11: 1971 to 1980 | P11: =CE80+CE68+CE92 -> 7201 | Q11: =CE44+CE56 -> 107453 | R11: =CE31 -> 97698 | S11: =SUM(P11:R11) -> 212352 | CA11: All private households | CI11: All private households | CQ11: State
B12: 1981-1990 | C12: 6342 | D12: 43624 | E12: 33190 | F12: =SUM(C12:E12) -> 83156 | O12: 1981 to 1990 | P12: =CE81+CE69+CE93 -> 10485 | Q12: =CE45+CE57 -> 73079 | R12: =CE32 -> 86491 | S12: =SUM(P12:R12) -> 170055 | CB12: State | CJ12: State | CR12: Before 1919
B13: 1991-2000 | C13: 25354 | D13: 64118 | E13: 50159 | F13: =SUM(C13:E13) -> 139631 | O13: 1991 to 2000 | P13: =CE82+CE70+CE94 -> 28780 | Q13: =CE46+CE58 -> 99598 | R13: =CE33 -> 111455 | S13: =SUM(P13:R13) -> 239833 | CC13: All households | CK13: All households | CR13: Before 1919 | CS13: All households
B14: 2001-2010 | C14: 78381 | D14: 115507 | E14: 69518 | F14: =SUM(C14:E14) -> 263406 | O14: 2001 to 2010 | P14: =CE83+CE71+CE95 -> 86920 | Q14: =CE47+CE59 -> 167551 | R14: =CE34 -> 175223 | S14: =SUM(P14:R14) -> 429694 | CD14: All years | CE14: 1697665 | CL14: All households | CM14: 1697665 | CR14: Before 1919 | CT14: All households | CU14: 141200
B15: Later_2010 | C15: 7476 | D15: 31963 | E15: 10694 | F15: =SUM(C15:E15) -> 50133 | O15: 2011 or later | P15: =CE84+CE72+CE96 -> 6124 | Q15: =CE48+CE60 -> 9027 | R15: =CE35 -> 18050 | S15: =SUM(P15:R15) -> 33201 | CD15: Before 1919 | CE15: 141200 | CL15: No central heating | CM15: 23174 | CR15: Before 1919 | CT15: No central heating | CU15: 6507
B16: Total | C16: =SUM(C7:C15) -> 134797 | D16: =SUM(D7:D15) -> 414958 | E16: =SUM(E7:E15) -> 265491 | F16: =SUM(C16:E16) -> 815246 | O16: Total | P16: =SUM(P7:P15) -> 169418 | Q16: =SUM(Q7:Q15) -> 711150 | R16: =SUM(R7:R15) -> 694537 | S16: =SUM(P16:R16) -> 1575105 | CD16: 1919 to 1945 | CE16: 109668 | CL16: Oil | CM16: 686004 | CR16: Before 1919 | CT16: Oil | CU16: 59339
CD17: 1946 to 1960 | CE17: 126107 | CL17: Natural Gas | CM17: 569166 | CR17: Before 1919 | CT17: Natural Gas | CU17: 32118
B18: Summary with Fuels | AB18: Data from Tableau | AY18: Data used in DwellingStocks Tab | BL18: Data only used to crosscheck in SHWLP-*** Tabs | CD18: 1961 to 1970 | CE18: 116041 | CL18: Electricity | CM18: 146302 | CR18: Before 1919 | CT18: Electricity | CU18: 13175
B19: BER Database (Fuel-Age) | O19: CSO Database 2016 (Fuel-Age) | AB19: BER Database (Rating to Age) | AN19: Correlation (Rating to Age) | AY19: Housing Stock based upon Age to BER correlation index | BL19: BER Rating/Fuel Type | CD19: 1971 to 1980 | CE19: 213473 | CL19: Coal (incl. Anthracite_Coal) | CM19: 86611 | CR19: Before 1919 | CT19: Coal (incl. Anthracite_Coal) | CU19: 10093
B20: Summary with Fuels | CD20: 1981 to 1990 | CE20: 171044 | CL20: Peat (incl. turf) | CM20: 90029 | CR20: Before 1919 | CT20: Peat (incl. turf) | CU20: 10892
B21: Apartments | C21: No central heating | D21: Oil | E21: Natural Gas | F21: Electricity | G21: Coal (incl. Anthracite_Coal) | H21: Peat (incl. turf) | I21: Liquid Petroleum Gas (LPG) | J21: Wood (incl. wood pellets) | K21: Other fuels | L21: Not stated | M21: Totals | O21: Apartments | P21: No central heating | Q21: Oil | R21: Natural Gas | S21: Electricity | T21: Coal (incl. Anthracite_Coal) | U21: Peat (incl. turf) | V21: Liquid Petroleum Gas (LPG) | W21: Wood (incl. wood pellets) | X21: Other fuels | Y21: Not stated | AC21: A | AD21: B1 | AE21: B2 | AF21: B3 | AG21: C | AH21: D | AI21: E | AJ21: F | AK21: G | AN21: Apartments | AO21: A | AP21: B1 | AQ21: B2 | AR21: B3 | AS21: C | AT21: D | AU21: E | AV21: F | AW21: G | AY21: Apartments | AZ21: A | BA21: B1 | BB21: B2 | BC21: B3 | BD21: C | BE21: D | BF21: E | BG21: F | BH21: G | BL21: Apartments | BM21: No central heating | BN21: Oil | BO21: Natural Gas | BP21: Electricity | BQ21: Coal (incl. Anthracite_Coal) | BR21: Peat (incl. turf) | BS21: Liquid Petroleum Gas (LPG) | BT21: Wood (incl. wood pellets) | BU21: Other fuels | BV21: Not stated | BW21: Solid Multi Fuel | CD21: 1991 to 2000 | CE21: 240811 | CL21: Liquid Petroleum Gas (LPG) | CM21: 9990 | CR21: Before 1919 | CT21: Liquid Petroleum Gas (LPG) | CU21: 830
B22: Before_1919 | D22: =SUMIFS(INDEX(Table5[],,MATCH(B21,Table5[#Headers],0)),Table5[MainSpaceHeatingFuel],"*Oil",Table5[Year_of_Construction (group)],B22) -> 469 | E22: =SUMIFS(INDEX(Table5[],,MATCH(B21,Table5[#Headers],0)),Table5[MainSpaceHeatingFuel],"Mains Gas",Table5[Year_of_Construction (group)],B22) -> 1700 | F22: =SUMIFS(INDEX(Table5[],,MATCH(B21,Table5[#Headers],0)),Table5[MainSpaceHeatingFuel],F21,Table5[Year_of_Construction (group)],B22) -> 3428 | G22: =SUMIFS(INDEX(Table5[],,MATCH(B21,Table5[#Headers],0)),Table5[MainSpaceHeatingFuel],"*Coal",Table5[Year_of_Construction (group)],B22) -> 41 | H22: =SUMIFS(INDEX(Table5[],,MATCH(B21,Table5[#Headers],0)),Table5[MainSpaceHeatingFuel],"*Peat*",Table5[Year_of_Construction (group)],B22) -> 6 | I22: =SUMIFS(INDEX(Table5[],,MATCH(B21,Table5[#Headers],0)),Table5[MainSpaceHeatingFuel],"*LPG*",Table5[Year_of_Construction (group)],B22) -> 31 | J22: =SUMIFS(INDEX(Table5[],,MATCH(B21,Table5[#Headers],0)),Table5[MainSpaceHeatingFuel],"*Wood*",Table5[Year_of_Construction (group)],B22) -> 4 | K22: =SUMIFS(INDEX(Table5[],,MATCH(B21,Table5[#Headers],0)),Table5[MainSpaceHeatingFuel],"*Multi-Fuel*",Table5[Year_of_Construction (group)],B22) -> 52 | L22: =SUMIFS(INDEX(Table5[],,MATCH(B21,Table5[#Headers],0)),Table5[MainSpaceHeatingFuel],"",Table5[Year_of_Construction (group)],B22) -> 363 | M22: =SUM(C22:L22) -> 6094 | O22: Before_1919 | P22: =SUMIFS( CU14:CU96,CT14:CT96, P21, CS14:CS96, O21) -> 941 | Q22: =SUMIFS( CU14:CU96,CT14:CT96, Q21, CS14:CS96, O21) -> 1622 | R22: =SUMIFS( CU14:CU96,CT14:CT96, R21, CS14:CS96, O21) -> 3653 | S22: =SUMIFS( CU14:CU96,CT14:CT96, S21, CS14:CS96, O21) -> 6835 | T22: =SUMIFS( CU14:CU96,CT14:CT96, T21, CS14:CS96, O21) -> 163 | U22: =SUMIFS( CU14:CU96,CT14:CT96, U21, CS14:CS96, O21) -> 75 | V22: =SUMIFS( CU14:CU96,CT14:CT96, V21, CS14:CS96, O21) -> 56 | W22: =SUMIFS( CU14:CU96,CT14:CT96, W21, CS14:CS96, O21) -> 88 | X22: =SUMIFS( CU14:CU96,CT14:CT96, X21, CS14:CS96, O21) -> 92 | Y22: =SUMIFS( CU14:CU96,CT14:CT96, Y21, CS14:CS96, O21) -> 181 | Z22: =SUM(P22:Y22) -> 13706 | AB22: Before_1919 | AC22: 3 | AD22: 13 | AE22: 40 | AF22: 85 | AG22: 527 | AH22: 986 | AI22: 1151 | AJ22: 882 | AK22: 2407 | AL22: =SUM(AC22:AK22) -> 6094 | AN22: Before_1919 | AO22: =AC22/AL22 -> 0.0004922875 | AP22: =AD22/AL22 -> 0.0021332458 | AQ22: =AE22/AL22 -> 0.0065638333 | AR22: =AF22/AL22 -> 0.013948146 | AS22: =AG22/AL22 -> 0.086478503 | AT22: =AH22/AL22 -> 0.16179849 | AU22: =AI22/AL22 -> 0.1888743 | AV22: =AJ22/AL22 -> 0.14473252 | AW22: =AK22/AL22 -> 0.39497867 | AZ22: =AO22*Z22 -> 6.7472924 | BA22: =AP22*$Z$22 -> 29.238267 | BB22: =AQ22*$Z$22 -> 89.963899 | BC22: =AR22*$Z$22 -> 191.17329 | BD22: =AS22*$Z$22 -> 1185.2744 | BE22: =AT22*$Z$22 -> 2217.6101 | BF22: =AU22*$Z$22 -> 2588.7112 | BG22: =AV22*$Z$22 -> 1983.704 | BH22: =AW22*$Z$22 -> 5413.5776 | BL22: A | BM22: =(P22*AO22+P23*AO23+P24*AO24+P25*AO25+P26*AO26+P27*AO27+P28*AO28+P29*AO29+P30*AO30+P31/9)*BX31 -> 183.89796 | BN22: =(Q22*AO22+Q23*AO23+Q24*AO24+Q25*AO25+Q26*AO26+Q27*AO27+Q28*AO28+Q29*AO29+Q30*AO30+Q31/9)*BX31 -> 369.35841 | BO22: =(R22*AO22+R23*AO23+R24*AO24+R25*AO25+R26*AO26+R27*AO27+R28*AO28+R29*AO29+R30*AO30+R31/9)*BX31 -> 3828.3051 | BP22: =(S22*AO22+S23*AO23+S24*AO24+S25*AO25+S26*AO26+S27*AO27+S28*AO28+S29*AO29+S30*AO30+S31/9)*BX31 -> 3682.2436 | BQ22: =(T22*AO22+T23*AO23+T24*AO24+T25*AO25+T26*AO26+T27*AO27+T28*AO28+T29*AO29+T30*AO30+T31/9)*BX31 -> 41.327709 | BR22: =(U22*AO22+U23*AO23+U24*AO24+U25*AO25+U26*AO26+U27*AO27+U28*AO28+U29*AO29+U30*AO30+U31/9)*BX31 -> 22.365812 | BS22: =(V22*AO22+V23*AO23+V24*AO24+V25*AO25+V26*AO26+V27*AO27+V28*AO28+V29*AO29+V30*AO30+V31/9)*BX31 -> 41.233455 | BT22: =(W22*AO22+W23*AO23+W24*AO24+W25*AO25+W26*AO26+W27*AO27+W28*AO28+W29*AO29+W30*AO30+W31/9)*BX31 -> 33.528461 | BU22: =(X22*AO22+X23*AO23+X24*AO24+X25*AO25+X26*AO26+X27*AO27+X28*AO28+X29*AO29+X30*AO30+X31/9)*BX31 -> 120.73024 | BV22: =(Y22*AO22+Y23*AO23+Y24*AO24+Y25*AO25+Y26*AO26+Y27*AO27+Y28*AO28+Y29*AO29+Y30*AO30+Y31/9)*BX31 -> 1335.6949 | BW22: =AVERAGE(BQ22,BR22,BT22)/3 -> 10.802442 | CD22: 2001 to 2010 | CE22: 431763 | CL22: Wood (incl. wood pellets) | CM22: 33976 | CR22: Before 1919 | CT22: Wood (incl. wood pellets) | CU22: 6539
B23: 1919-1945 | D23: =SUMIFS(INDEX(Table5[],,MATCH(B21,Table5[#Headers],0)),Table5[MainSpaceHeatingFuel],"*Oil",Table5[Year_of_Construction (group)],B23) -> 266 | E23: =SUMIFS(INDEX(Table5[],,MATCH(B21,Table5[#Headers],0)),Table5[MainSpaceHeatingFuel],"Mains Gas",Table5[Year_of_Construction (group)],B23) -> 1447 | F23: =SUMIFS(INDEX(Table5[],,MATCH(B21,Table5[#Headers],0)),Table5[MainSpaceHeatingFuel],F21,Table5[Year_of_Construction (group)],B23) -> 952 | G23: =SUMIFS(INDEX(Table5[],,MATCH(B21,Table5[#Headers],0)),Table5[MainSpaceHeatingFuel],"*Coal",Table5[Year_of_Construction (group)],B23) -> 18 | H23: =SUMIFS(INDEX(Table5[],,MATCH(B21,Table5[#Headers],0)),Table5[MainSpaceHeatingFuel],"*Peat*",Table5[Year_of_Construction (group)],B23) -> 1 | I23: =SUMIFS(INDEX(Table5[],,MATCH(B21,Table5[#Headers],0)),Table5[MainSpaceHeatingFuel],"*LPG*",Table5[Year_of_Construction (group)],B23) -> 21 | J23: =SUMIFS(INDEX(Table5[],,MATCH(B21,Table5[#Headers],0)),Table5[MainSpaceHeatingFuel],"*Wood*",Table5[Year_of_Construction (group)],B23) -> 0 | K23: =SUMIFS(INDEX(Table5[],,MATCH(B21,Table5[#Headers],0)),Table5[MainSpaceHeatingFuel],"*Multi-Fuel*",Table5[Year_of_Construction (group)],B23) -> 36 | L23: =SUMIFS(INDEX(Table5[],,MATCH(B21,Table5[#Headers],0)),Table5[MainSpaceHeatingFuel],"",Table5[Year_of_Construction (group)],B23) -> 59 | M23: =SUM(C23:L23) -> 2800 | O23: 1919-1945 | P23: =SUMIFS( CU110:CU181,CT110:CT181, P21, CS110:CS181, O21) -> 234 | Q23: =SUMIFS( CU110:CU181,CT110:CT181, Q21, CS110:CS181, O21) -> 575 | R23: =SUMIFS( CU110:CU181,CT110:CT181, R21, CS110:CS181, O21) -> 2069 | S23: =SUMIFS( CU110:CU181,CT110:CT181, S21, CS110:CS181, O21) -> 2235 | T23: =SUMIFS( CU110:CU181,CT110:CT181, T21, CS110:CS181, O21) -> 99 | U23: =SUMIFS( CU110:CU181,CT110:CT181, U21, CS110:CS181, O21) -> 43 | V23: =SUMIFS( CU110:CU181,CT110:CT181, V21, CS110:CS181, O21) -> 11 | W23: =SUMIFS( CU110:CU181,CT110:CT181, W21, CS110:CS181, O21) -> 29 | X23: =SUMIFS( CU110:CU181,CT110:CT181, X21, CS110:CS181, O21) -> 39 | Y23: =SUMIFS( CU110:CU181,CT110:CT181, Y21, CS110:CS181, O21) -> 59 | Z23: =SUM(P23:Y23) -> 5393 | AB23: 1919-1945 | AC23: 2 | AD23: 21 | AE23: 128 | AF23: 193 | AG23: 461 | AH23: 497 | AI23: 452 | AJ23: 308 | AK23: 738 | AL23: =SUM(AC23:AK23) -> 2800 | AN23: 1919-1945 | AO23: =AC23/AL23 -> 0.00071428571 | AP23: =AD23/AL23 -> 0.0075 | AQ23: =AE23/AL23 -> 0.045714286 | AR23: =AF23/AL23 -> 0.068928571 | AS23: =AG23/AL23 -> 0.16464286 | AT23: =AH23/AL23 -> 0.1775 | AU23: =AI23/AL23 -> 0.16142857 | AV23: =AJ23/AL23 -> 0.11 | AW23: =AK23/AL23 -> 0.26357143 | AZ23: =AO23*$Z23 -> 3.8521429 | BA23: =AP23*$Z$23 -> 40.4475 | BB23: =AQ23*$Z$23 -> 246.53714 | BC23: =AR23*$Z$23 -> 371.73179 | BD23: =AS23*$Z$23 -> 887.91893 | BE23: =AT23*$Z$23 -> 957.2575 | BF23: =AU23*$Z$23 -> 870.58429 | BG23: =AV23*$Z$23 -> 593.23 | BH23: =AW23*$Z$23 -> 1421.4407 | BL23: B1 | BM23: =(P22*AP22+P23*AP23+P24*AP24+P25*AP25+P26*AP26+P27*AP27+P28*AP28+P29*AP29+P30*AP30+P31/9)*BX31 -> 166.32489 | BN23: =(Q22*AP22+Q23*AP23+Q24*AP24+Q25*AP25+Q26*AP26+Q27*AP27+Q28*AP28+Q29*AP29+Q30*AP30+Q31/9)*BX31 -> 252.2461 | BO23: =(R22*AP22+R23*AP23+R24*AP24+R25*AP25+R26*AP26+R27*AP27+R28*AP28+R29*AP29+R30*AP30+R31/9)*BX31 -> 2661.9095 | BP23: =(S22*AP22+S23*AP23+S24*AP24+S25*AP25+S26*AP26+S27*AP27+S28*AP28+S29*AP29+S30*AP30+S31/9)*BX31 -> 3140.8766 | BQ23: =(T22*AP22+T23*AP23+T24*AP24+T25*AP25+T26*AP26+T27*AP27+T28*AP28+T29*AP29+T30*AP30+T31/9)*BX31 -> 37.24799 | BR23: =(U22*AP22+U23*AP23+U24*AP24+U25*AP25+U26*AP26+U27*AP27+U28*AP28+U29*AP29+U30*AP30+U31/9)*BX31 -> 13.343719 | BS23: =(V22*AP22+V23*AP23+V24*AP24+V25*AP25+V26*AP26+V27*AP27+V28*AP28+V29*AP29+V30*AP30+V31/9)*BX31 -> 25.546659 | BT23: =(W22*AP22+W23*AP23+W24*AP24+W25*AP25+W26*AP26+W27*AP27+W28*AP28+W29*AP29+W30*AP30+W31/9)*BX31 -> 14.5357 | BU23: =(X22*AP22+X23*AP23+X24*AP24+X25*AP25+X26*AP26+X27*AP27+X28*AP28+X29*AP29+X30*AP30+X31/9)*BX31 -> 51.13593 | BV23: =(Y22*AP22+Y23*AP23+Y24*AP24+Y25*AP25+Y26*AP26+Y27*AP27+Y28*AP28+Y29*AP29+Y30*AP30+Y31/9)*BX31 -> 1286.0232 | BW23: =AVERAGE(BQ23,BR23,BT23)/3 -> 7.2363787 | CD23: 2011 or later | CE23: 33436 | CL23: Other fuels | CM23: 11068 | CR23: Before 1919 | CT23: Other fuels | CU23: 744
B24: 1946-1960 | D24: =SUMIFS(INDEX(Table5[],,MATCH(B21,Table5[#Headers],0)),Table5[MainSpaceHeatingFuel],"*Oil",Table5[Year_of_Construction (group)],B24) -> 241 | E24: =SUMIFS(INDEX(Table5[],,MATCH(B21,Table5[#Headers],0)),Table5[MainSpaceHeatingFuel],"Mains Gas",Table5[Year_of_Construction (group)],B24) -> 1283 | F24: =SUMIFS(INDEX(Table5[],,MATCH(B21,Table5[#Headers],0)),Table5[MainSpaceHeatingFuel],F21,Table5[Year_of_Construction (group)],B24) -> 561 | G24: =SUMIFS(INDEX(Table5[],,MATCH(B21,Table5[#Headers],0)),Table5[MainSpaceHeatingFuel],"*Coal",Table5[Year_of_Construction (group)],B24) -> 16 | H24: =SUMIFS(INDEX(Table5[],,MATCH(B21,Table5[#Headers],0)),Table5[MainSpaceHeatingFuel],"*Peat*",Table5[Year_of_Construction (group)],B24) -> 1 | I24: =SUMIFS(INDEX(Table5[],,MATCH(B21,Table5[#Headers],0)),Table5[MainSpaceHeatingFuel],"*LPG*",Table5[Year_of_Construction (group)],B24) -> 15 | J24: =SUMIFS(INDEX(Table5[],,MATCH(B21,Table5[#Headers],0)),Table5[MainSpaceHeatingFuel],"*Wood*",Table5[Year_of_Construction (group)],B24) -> 3 | K24: =SUMIFS(INDEX(Table5[],,MATCH(B21,Table5[#Headers],0)),Table5[MainSpaceHeatingFuel],"*Multi-Fuel*",Table5[Year_of_Construction (group)],B24) -> 24 | L24: =SUMIFS(INDEX(Table5[],,MATCH(B21,Table5[#Headers],0)),Table5[MainSpaceHeatingFuel],"",Table5[Year_of_Construction (group)],B24) -> 43 | M24: =SUM(C24:L24) -> 2187 | O24: 1946-1960 | P24: =SUMIFS( CU195:CU266,CT195:CT266, P21, CS195:CS266, O21) -> 212 | Q24: =SUMIFS( CU195:CU266,CT195:CT266, Q21, CS195:CS266, O21) -> 505 | R24: =SUMIFS( CU195:CU266,CT195:CT266, R21, CS195:CS266, O21) -> 2730 | S24: =SUMIFS( CU195:CU266,CT195:CT266, S21, CS195:CS266, O21) -> 1710 | T24: =SUMIFS( CU195:CU266,CT195:CT266, T21, CS195:CS266, O21) -> 98 | U24: =SUMIFS( CU195:CU266,CT195:CT266, U21, CS195:CS266, O21) -> 37 | V24: =SUMIFS( CU195:CU266,CT195:CT266, V21, CS195:CS266, O21) -> 12 | W24: =SUMIFS( CU195:CU266,CT195:CT266, W21, CS195:CS266, O21) -> 19 | X24: =SUMIFS( CU195:CU266,CT195:CT266, X21, CS195:CS266, O21) -> 30 | Y24: =SUMIFS( CU195:CU266,CT195:CT266, Y21, CS195:CS266, O21) -> 36 | Z24: =SUM(P24:Y24) -> 5389 | AB24: 1946-1960 | AC24: 15 | AD24: 32 | AE24: 95 | AF24: 121 | AG24: 352 | AH24: 456 | AI24: 403 | AJ24: 249 | AK24: 464 | AL24: =SUM(AC24:AK24) -> 2187 | AN24: 1946-1960 | AO24: =AC24/AL24 -> 0.0068587106 | AP24: =AD24/AL24 -> 0.014631916 | AQ24: =AE24/AL24 -> 0.0434385 | AR24: =AF24/AL24 -> 0.055326932 | AS24: =AG24/AL24 -> 0.16095107 | AT24: =AH24/AL24 -> 0.2085048 | AU24: =AI24/AL24 -> 0.18427069 | AV24: =AJ24/AL24 -> 0.1138546 | AW24: =AK24/AL24 -> 0.21216278 | AZ24: =AO24*$Z$24 -> 36.961591 | BA24: =AP24*$Z$24 -> 78.851395 | BB24: =AQ24*$Z$24 -> 234.09008 | BC24: =AR24*$Z$24 -> 298.15684 | BD24: =AS24*$Z$24 -> 867.36534 | BE24: =AT24*$Z$24 -> 1123.6324 | BF24: =AU24*$Z$24 -> 993.03475 | BG24: =AV24*$Z$24 -> 613.56241 | BH24: =AW24*$Z$24 -> 1143.3452 | BL24: B2 | BM24: =(P22*AQ22+P23*AQ23+P24*AQ24+P25*AQ25+P26*AQ26+P27*AQ27+P28*AQ28+P29*AQ29+P30*AQ30+P31/9)*BX31 -> 278.21519 | BN24: =(Q22*AQ22+Q23*AQ23+Q24*AQ24+Q25*AQ25+Q26*AQ26+Q27*AQ27+Q28*AQ28+Q29*AQ29+Q30*AQ30+Q31/9)*BX31 -> 484.56021 | BO24: =(R22*AQ22+R23*AQ23+R24*AQ24+R25*AQ25+R26*AQ26+R27*AQ27+R28*AQ28+R29*AQ29+R30*AQ30+R31/9)*BX31 -> 6017.8273 | BP24: =(S22*AQ22+S23*AQ23+S24*AQ24+S25*AQ25+S26*AQ26+S27*AQ27+S28*AQ28+S29*AQ29+S30*AQ30+S31/9)*BX31 -> 5996.2801 | BQ24: =(T22*AQ22+T23*AQ23+T24*AQ24+T25*AQ25+T26*AQ26+T27*AQ27+T28*AQ28+T29*AQ29+T30*AQ30+T31/9)*BX31 -> 73.446016 | BR24: =(U22*AQ22+U23*AQ23+U24*AQ24+U25*AQ25+U26*AQ26+U27*AQ27+U28*AQ28+U29*AQ29+U30*AQ30+U31/9)*BX31 -> 25.961706 | BS24: =(V22*AQ22+V23*AQ23+V24*AQ24+V25*AQ25+V26*AQ26+V27*AQ27+V28*AQ28+V29*AQ29+V30*AQ30+V31/9)*BX31 -> 54.156589 | BT24: =(W22*AQ22+W23*AQ23+W24*AQ24+W25*AQ25+W26*AQ26+W27*AQ27+W28*AQ28+W29*AQ29+W30*AQ30+W31/9)*BX31 -> 30.357224 | BU24: =(X22*AQ22+X23*AQ23+X24*AQ24+X25*AQ25+X26*AQ26+X27*AQ27+X28*AQ28+X29*AQ29+X30*AQ30+X31/9)*BX31 -> 96.863308 | BV24: =(Y22*AQ22+Y23*AQ23+Y24*AQ24+Y25*AQ25+Y26*AQ26+Y27*AQ27+Y28*AQ28+Y29*AQ29+Y30*AQ30+Y31/9)*BX31 -> 1341.6578 | BW24: =AVERAGE(BQ24,BR24,BT24)/3 -> 14.418327 | CD24: Not stated | CE24: 114122 | CL24: Not stated | CM24: 41345 | CR24: Before 1919 | CT24: Not stated | CU24: 963
