Workbook

Sheet Cover
A16: TIMES-Ireland Model
A19: Document type: | B19: Base Year Template
A20: Sector(s): | B20: Service sector (SRV)
A21: Purpose: | B21: Specify base year data and define sector structure
A23: Original developer(s):
A26: Current maintainer(s): | B26: Olexandr Balyk (UCC, olexandr.balyk@ucc.ie)
A29: Part of TIM version: | B29: 1
A30: Model repository: | B30: https://github.com/MaREI-EPMG/TIMES-Ireland-model
A31: Licence: | B31: CC BY-NC-SA 4.0 (unless specified otherwise)
B32: https://creativecommons.org/licenses/by-nc-sa/4.0/

Sheet Legend
A3: Ragion: | B3: Ireland | C3: IE
A4: Sector: | B4: Services | C4: SRV
A5: Base-year | B5: 2018
A8: Cell colour legend
A9: aaa | B9: Model input
A10: aaa | B10: Model input based on own assumptions
B11: Calculated value (not recommended to directly modify)
A13: Tab colour legend
B14: VEDA-TIMES data input tables
B15: Energy balance breakdown and other elaborations
B16: External data sources
A18: Codes for processes and commodities names
A19: Dimension | B19: Short code | C19: Full code
A20: Sub-sectors
A21: Commercial Services | C21: CS
A22: Public Services | C22: PU
A23: Thermal uses
A24: Space heating | C24: SH
A25: Water heating | C25: WH
A26: Space cooling | C26: SC
A27: Other uses
A28: Cooking | C28: CK
A29: Building lighting | C29: LIG
A30: Refrigeration | C30: REF
A31: Other appliances | C31: OEL
A32: Data centers | C32: DCE
A33: Public lighting | C33: PLIG
A34: Other services | C34: OTS
A35: Fuels
A36: Solids | B36: COA | C36: =$C$4&B36 -> SRVCOA
A37: LPG | B37: LPG | C37: =$C$4&B37 -> SRVLPG
A38: Oil | B38: OIL | C38: =$C$4&B38 -> SRVOIL
A39: Natural Gas | B39: GAS | C39: =$C$4&B39 -> SRVGAS
A40: Biomass | B40: BIO | C40: =$C$4&B40 -> SRVBIO
A41: Biogas | B41: BGS | C41: =$C$4&B41 -> SRVBGS
A42: Solar | B42: SOL | C42: =$C$4&B42 -> SRVSOL
A43: Electricity | B43: ELC | C43: =$C$4&B43 -> SRVELC
A44: Ambient Heat | B44: AHT | C44: =$C$4&B44 -> SRVAHT
A45: Ambient Heat 2 | B45: AHT2 | C45: =$C$4&B45 -> SRVAHT2
A46: District heating | B46: HET | C46: =$C$4&B46 -> SRVHET
...

Sheet Regions
C3: {=INDEX(C5:C7,$A$4)} -> IE | D3: {=INDEX(D5:D7,$A$4)} -> National | E3: {=INDEX(E5:E7,$A$4)} -> IE-CW | F3: {=INDEX(F5:F7,$A$4)} -> IE-D | G3: {=INDEX(G5:G7,$A$4)} -> IE-KE | H3: {=INDEX(H5:H7,$A$4)} -> IE-KK | I3: {=INDEX(I5:I7,$A$4)} -> IE-LS | J3: {=INDEX(J5:J7,$A$4)} -> IE-LD | ... AD3: {=INDEX(AD5:AD7,$A$4)} -> IE-MN
A4: 1
A5: Development | C5: IE | D5: National | E5: =A11 -> IE-CW | F5: =A16 -> IE-D | G5: =A19 -> IE-KE | H5: =A20 -> IE-KK | I5: =A21 -> IE-LS | J5: =A24 -> IE-LD | K5: =A25 -> IE-LH | L5: =A27 -> IE-MH | M5: =A29 -> IE-OY | N5: =A34 -> IE-WH | O5: =A35 -> IE-WX | P5: =A36 -> IE-WW | Q5: =A13 -> IE-CE | R5: =A14 -> IE-CO | S5: =A18 -> IE-KY | T5: =A23 -> IE-LK | U5: =A32 -> IE-TA | V5: =A33 -> IE-WD | W5: =A17 -> IE-G | X5: =A22 -> IE-LM | Y5: =A26 -> IE-MO | Z5: =A30 -> IE-RN | AA5: =A31 -> IE-SO | AB5: =A12 -> IE-CN | AC5: =A15 -> IE-DL | AD5: =A28 -> IE-MN
A6: Single-region | C6: =C5 -> IE | D6: ="*"&D5 -> *National | E6: ="*"&E5 -> *IE-CW | F6: ="*"&F5 -> *IE-D | G6: ="*"&G5 -> *IE-KE | H6: ="*"&H5 -> *IE-KK | I6: ="*"&I5 -> *IE-LS | J6: ="*"&J5 -> *IE-LD | K6: ="*"&K5 -> *IE-LH | ... AD6: ="*"&AD5 -> *IE-MN
A7: Multi-region | C7: ="*"&C5 -> *IE | D7: =D5 -> National | E7: =E5 -> IE-CW | F7: =F5 -> IE-D | G7: =G5 -> IE-KE | H7: =H5 -> IE-KK | I7: =I5 -> IE-LS | J7: =J5 -> IE-LD | K7: =K5 -> IE-LH | ... AD7: =AD5 -> IE-MN
A10: Code | B10: County name
A11: IE-CW | B11: Carlow
A12: IE-CN | B12: Cavan
A13: IE-CE | B13: Clare
A14: IE-CO | B14: Cork
A15: IE-DL | B15: Donegal
A16: IE-D | B16: Dublin
A17: IE-G | B17: Galway
A18: IE-KY | B18: Kerry
A19: IE-KE | B19: Kildare
A20: IE-KK | B20: Kilkenny
A21: IE-LS | B21: Laois
... A36: IE-WW | B36: Wicklow
A37: Source: https://en.wikipedia.org/wiki/ISO_3166-2:IE

Sheet EB_SRV
B1: Energy Balance breakdown
B3: Table 1 | C3: Energy Balance 2018 (ktoe)
D4: Coal | E4: Bituminous Coal | F4: Anthracite + Manufactured Ovoids | G4: Coke | H4: Lignite \ Brown Coal Briquettes | I4: Peat | J4: Milled Peat | K4: Sod Peat | L4: Briquettes | M4: Oil | N4: Crude | O4: Refinery Feedstocks | P4: Refinery Gas | Q4: Gasoline | R4: Kerosene | S4: Jet Kerosene | T4: Fueloil | U4: LPG | V4: Gasoil / Diesel /DERV | W4: Petroleum Coke | X4: Naphta | Y4: Bitumen | Z4: White Spirit | AA4: Lubricants | AB4: Natural Gas | AC4: Renewables | AD4: Hydro | AE4: Wind | AF4: Biomass | AG4: Renewable Waste | AH4: Landfill Gas | AI4: Biogas | AJ4: Biodiesel | AK4: Bioethanol | AL4: Solar Photovoltaic | AM4: Solar Thermal | AN4: Ambient Heat | AO4: Non-Renewable Waste | AP4: Electricity | AQ4: Heat | AR4: TOTAL
B5: Services | D5: ='EB2018'!C57 -> 0.56291534 | E5: ='EB2018'!D57 -> 0.56291534 | F5: ='EB2018'!E57 -> 0 | G5: ='EB2018'!F57 -> 0 | H5: ='EB2018'!G57 -> 0 | I5: ='EB2018'!H57 -> 0 | J5: ='EB2018'!I57 -> 0 | K5: ='EB2018'!J57 -> 0 | ... AR5: ='EB2018'!AQ57 -> 1702.2928
B6: Commercial Services | D6: ='EB2018'!C58 -> 0.56091564 | E6: ='EB2018'!D58 -> 0.56091564 | F6: ='EB2018'!E58 -> 0 | G6: ='EB2018'!F58 -> 0 | H6: ='EB2018'!G58 -> 0 | I6: ='EB2018'!H58 -> 0 | J6: ='EB2018'!I58 -> 0 | K6: ='EB2018'!J58 -> 0 | ... AR6: ='EB2018'!AQ58 -> 1198.9419
B7: Public Services | D7: ='EB2018'!C65 -> 0.0019996992 | E7: ='EB2018'!D65 -> 0.0019996992 | F7: ='EB2018'!E65 -> 0 | G7: ='EB2018'!F65 -> 0 | H7: ='EB2018'!G65 -> 0 | I7: ='EB2018'!H65 -> 0 | J7: ='EB2018'!I65 -> 0 | K7: ='EB2018'!J65 -> 0 | ... AR7: ='EB2018'!AQ65 -> 503.35096
B10: Table 2 | C10: Energy Balance 2018 (PJ)
D11: =Legend!$A$36 -> Solids | E11: =Legend!$A$37 -> LPG | F11: =Legend!$A$38 -> Oil | G11: =Legend!$A$39 -> Natural Gas | H11: =Legend!$A$40 -> Biomass | I11: =Legend!$A$41 -> Biogas | J11: =Legend!$A$42 -> Solar | K11: =Legend!$A$43 -> Electricity | L11: =Legend!$A$44 -> Ambient Heat | M11: Total
B12: Services | D12: =SUM(D5,I5)*Legend!$B$65 -> 0.023568139 | E12: =U5*Legend!$B$65 -> 2.7842199 | F12: =SUM(R5,T5,V5)*Legend!$B$65 -> 7.0394279 | G12: =AB5*Legend!$B$65 -> 14.401641 | H12: =AF5*Legend!$B$65 -> 0.75333608 | I12: =AI5*Legend!$B$65 -> 0.23537121 | J12: =AM5*Legend!$B$65 -> 0.0069707985 | K12: =AP5*Legend!$B$65 -> 45.371724 | L12: =AN5*Legend!$B$65 -> 0.65533684 | M12: =SUM(D12:L12) -> 71.271597
B13: =Legend!$A$21 -> Commercial Services | D13: =SUM(D6,I6)*Legend!$B$65 -> 0.023484416 | E13: =U6*Legend!$B$65 -> 1.862077 | F13: =SUM(R6,T6,V6)*Legend!$B$65 -> 2.8363477 | G13: =AB6*Legend!$B$65 -> 9.094157 | H13: =AF6*Legend!$B$65 -> 0.29850706 | I13: =AI6*Legend!$B$65 -> 0.033679907 | J13: =AM6*Legend!$B$65 -> 0.0069707985 | K13: =AP6*Legend!$B$65 -> 35.386738 | L13: =AN6*Legend!$B$65 -> 0.65533684 | M13: =SUM(D13:L13) -> 50.197298
B14: =Legend!$A$32 -> Data centers | K14: ='Key Inputs'!$I$114 -> 5.629176 | M14: =SUM(D14:L14) -> 5.629176
B15: =Legend!$A$22 -> Public Services | D15: =SUM(D7,I7)*Legend!$B$65 -> 8.3723408e-05 | E15: =U7*Legend!$B$65 -> 0.92214284 | F15: =SUM(R7,T7,V7)*Legend!$B$65 -> 4.2030803 | G15: =AB7*Legend!$B$65 -> 5.3074842 | H15: =AF7*Legend!$B$65 -> 0.45482902 | I15: =AI7*Legend!$B$65 -> 0.2016913 | J15: =AM7*Legend!$B$65 -> 0 | K15: =AP7*Legend!$B$65 -> 9.9849868 | L15: =AN7*Legend!$B$65 -> 0 | M15: =SUM(D15:L15) -> 21.074298
B16: =Legend!$A$33 -> Public lighting | K16: ='Public SEAI'!C29*Legend!$B$66 -> 1.4472 | M16: =SUM(D16:L16) -> 1.4472
B17: =Legend!$A$21&" (excl. "&B14&")" -> Commercial Services (excl. Data centers) | D17: =D13-D14 -> 0.023484416 | E17: =E13-E14 -> 1.862077 | F17: =F13-F14 -> 2.8363477 | G17: =G13-G14 -> 9.094157 | H17: =H13-H14 -> 0.29850706 | I17: =I13-I14 -> 0.033679907 | J17: =J13-J14 -> 0.0069707985 | K17: =K13-K14 -> 29.757562 | ... M17: =M13-M14 -> 44.568122
B18: =Legend!$A$22&" (excl. "&B16&")" -> Public Services (excl. Public lighting) | D18: =D15-D16 -> 8.3723408e-05 | E18: =E15-E16 -> 0.92214284 | F18: =F15-F16 -> 4.2030803 | G18: =G15-G16 -> 5.3074842 | H18: =H15-H16 -> 0.45482902 | I18: =I15-I16 -> 0.2016913 | J18: =J15-J16 -> 0 | K18: =K15-K16 -> 8.5377868 | ... M18: =M15-M16 -> 19.627098
B21: Table 3 | C21: ="Energy Balance breakdown for "&B25 -> Energy Balance breakdown for Commercial Services (excl. Data centers)
B22: Sub-sector | C22: Energy service | D22: Fuel | E22: Sub-type | F22: Consumption shares | G22: Consumption
B23: Sources: | F23: JRC-IDEES
F24: % | G24: PJ
B25: =$B$17 -> Commercial Services (excl. Data centers) | C25: =Legend!$A$24 -> Space heating | D25: =Legend!$A$36 -> Solids | F25: 1 | G25: =SUMIFS($D$17:$L$17,$D$11:$L$11,$D25)*F25 -> 0.023484416
B26: =$B$17 -> Commercial Services (excl. Data centers) | C26: =Legend!$A$24 -> Space heating | D26: =Legend!$A$37 -> LPG | F26: 0 | G26: =SUMIFS($D$17:$L$17,$D$11:$L$11,$D26)*F26 -> 0
B27: =$B$17 -> Commercial Services (excl. Data centers) | C27: =Legend!$A$24 -> Space heating | D27: =Legend!$A$38 -> Oil | F27: 0.77148995 | G27: =SUMIFS($D$17:$L$17,$D$11:$L$11,$D27)*F27 -> 2.1882137
B28: =$B$17 -> Commercial Services (excl. Data centers) | C28: =Legend!$A$24 -> Space heating | D28: =Legend!$A$39 -> Natural Gas | F28: 0.57925203 | G28: =SUMIFS($D$17:$L$17,$D$11:$L$11,$D28)*F28 -> 5.2678089
B29: =$B$17 -> Commercial Services (excl. Data centers) | C29: =Legend!$A$24 -> Space heating | D29: =Legend!$A$40 -> Biomass | F29: 1 | G29: =SUMIFS($D$17:$L$17,$D$11:$L$11,$D29)*F29 -> 0.29850706
B30: =$B$17 -> Commercial Services (excl. Data centers) | C30: =Legend!$A$24 -> Space heating | D30: =Legend!$A$41 -> Biogas | F30: 1 | G30: =SUMIFS($D$17:$L$17,$D$11:$L$11,$D30)*F30 -> 0.033679907
B31: =$B$17 -> Commercial Services (excl. Data centers) | C31: =Legend!$A$24 -> Space heating | D31: =Legend!$A$42 -> Solar | F31: 0 | G31: =SUMIFS($D$17:$L$17,$D$11:$L$11,$D31)*F31 -> 0
B32: =$B$17 -> Commercial Services (excl. Data centers) | C32: =Legend!$A$24 -> Space heating | D32: =Legend!$A$43 -> Electricity | E32: HP | F32: 0.02097908 | G32: =SUMIFS($D$17:$L$17,$D$11:$L$11,$D32)*F32 -> 0.62428626
B33: =$B$17 -> Commercial Services (excl. Data centers) | C33: =Legend!$A$24 -> Space heating | D33: =Legend!$A$43 -> Electricity | E33: Conventional | F33: 0.090683292 | G33: =SUMIFS($D$17:$L$17,$D$11:$L$11,$D33)*F33 -> 2.6985137
B34: =$B$17 -> Commercial Services (excl. Data centers) | C34: =Legend!$A$24 -> Space heating | D34: =Legend!$A$44 -> Ambient Heat | F34: 1 | G34: =SUMIFS($D$17:$L$17,$D$11:$L$11,$D34)*F34 -> 0.65533684
B35: =$B$17 -> Commercial Services (excl. Data centers) | C35: =Legend!$A$24 -> Space heating | D35: All fuels | G35: =SUM(G25:G34) -> 11.789831
B36: =$B$17 -> Commercial Services (excl. Data centers) | C36: =Legend!$A$25 -> Water heating | D36: =Legend!$A$36 -> Solids | F36: 0 | G36: =SUMIFS($D$17:$L$17,$D$11:$L$11,$D36)*F36 -> 0
B37: =$B$17 -> Commercial Services (excl. Data centers) | C37: =Legend!$A$25 -> Water heating | D37: =Legend!$A$37 -> LPG | F37: 0 | G37: =SUMIFS($D$17:$L$17,$D$11:$L$11,$D37)*F37 -> 0
B38: =$B$17 -> Commercial Services (excl. Data centers) | C38: =Legend!$A$25 -> Water heating | D38: =Legend!$A$38 -> Oil | F38: 0.22851005 | G38: =SUMIFS($D$17:$L$17,$D$11:$L$11,$D38)*F38 -> 0.64813396
B39: =$B$17 -> Commercial Services (excl. Data centers) | C39: =Legend!$A$25 -> Water heating | D39: =Legend!$A$39 -> Natural Gas | F39: 0.17174852 | G39: =SUMIFS($D$17:$L$17,$D$11:$L$11,$D39)*F39 -> 1.561908
B40: =$B$17 -> Commercial Services (excl. Data centers) | C40: =Legend!$A$25 -> Water heating | D40: =Legend!$A$40 -> Biomass | F40: 0 | G40: =SUMIFS($D$17:$L$17,$D$11:$L$11,$D40)*F40 -> 0
B41: =$B$17 -> Commercial Services (excl. Data centers) | C41: =Legend!$A$25 -> Water heating | D41: =Legend!$A$41 -> Biogas | F41: 0 | G41: =SUMIFS($D$17:$L$17,$D$11:$L$11,$D41)*F41 -> 0
B42: =$B$17 -> Commercial Services (excl. Data centers) | C42: =Legend!$A$25 -> Water heating | D42: =Legend!$A$43 -> Electricity | F42: 0.051446558 | G42: =SUMIFS($D$17:$L$17,$D$11:$L$11,$D42)*F42 -> 1.5309241
B43: =$B$17 -> Commercial Services (excl. Data centers) | C43: =Legend!$A$25 -> Water heating | D43: =Legend!$A$42 -> Solar | F43: 1 | G43: =SUMIFS($D$17:$L$17,$D$11:$L$11,$D43)*F43 -> 0.0069707985
B44: =$B$17 -> Commercial Services (excl. Data centers) | C44: =Legend!$A$25 -> Water heating | D44: All fuels | G44: =SUM(G36:G43) -> 3.7479369
B45: =$B$17 -> Commercial Services (excl. Data centers) | C45: =Legend!$A$26 -> Space cooling | D45: =Legend!$A$39 -> Natural Gas | F45: 0.00055954038 | G45: =SUMIFS($D$17:$L$17,$D$11:$L$11,$D45)*F45 -> 0.005088548
...

Sheet Key Inputs
A1: Key input assumptions and elaborations
A3: Building stock
B4: Source | C4: Unit | D4: =Legend!$B$5 -> 2018
A5: Total stock | B5: JRC-IDEES | C5: Mm2 | D5: 87.053207
A6: Average size | B6: CSO | C6: m2/dwelling | D6: ='CSO data'!O36 -> 670
A8: Breakdown of floor areas by non-residential sub-sector
A9: Source: BPIE (2011), Europe's building under the microscope
C10: Fraction of m2 | D10: Stock
A11: Source: | C11: BPIE
C12: % | D12: Mm2
A13: Offices (all) | C13: 0.23 | D13: =C13*$D$5 -> 20.022238
B14: Public offices | C14: 0.4 | D14: =D13*C14 -> 8.008895
B15: Private offices | C15: =1-C14 -> 0.6 | D15: =D13*C15 -> 12.013343
A16: Wholesale & trade | C16: 0.28 | D16: =C16*$D$5 -> 24.374898
A17: Hotel & restaurent | C17: 0.11 | D17: =C17*$D$5 -> 9.5758527
A18: Health | C18: 0.07 | D18: =C18*$D$5 -> 6.0937245
A19: Education | C19: 0.17 | D19: =C19*$D$5 -> 14.799045
A20: Other | C20: =1-SUM(C16:C19,C13) -> 0.14 | D20: =C20*$D$5 -> 12.187449
A21: Public Services | C21: =D21/SUM($D$21:$D$22) -> 0.332 | D21: =(D14+D18+D19) -> 28.901665
A22: Commercial Services | C22: =D22/SUM($D$21:$D$22) -> 0.668 | D22: =(D15+D16+D17+D20) -> 58.151542
A24: Allocation by system type
A25: 1) Thermal energy services
A26: Sub-sector | B26: Energy service | C26: Fuel | D26: Short name | E26: Long name | F26: Final energy consumption | G26: Efficiency | H26: Technical Life | I26: Number of functioning hours | J26: Useful energy | K26: Stock | L26: Ambient heat consumption
A27: Sources: | G27: JRC-IDEES | H27: Own assumption | I27: Own assumption
F28: PJ | G28: % | H28: Years | I28: hours | J28: PJ | K28: GW | L28: PJ
A29: =Legend!$A$21 -> Commercial Services | B29: =Legend!$A$24 -> Space heating | C29: =Legend!A36 -> Solids | D29: =Legend!B36 -> COA | E29: =Legend!C36 -> SRVCOA | F29: =EB_SRV!G25 -> 0.023484416 | G29: 0.33 | H29: 20 | I29: 1000 | J29: =IF(F29=0,0,F29*G29) -> 0.0077498573 | K29: =J29/(I29/8760*31.536) -> 0.0021527381
A30: =Legend!$A$21 -> Commercial Services | B30: =Legend!$A$24 -> Space heating | C30: =Legend!A37 -> LPG | D30: =Legend!B37 -> LPG | E30: =Legend!C37 -> SRVLPG | F30: =EB_SRV!G26 -> 0 | G30: 0.33 | H30: 20 | I30: 1000 | J30: =IF(F30=0,0,F30*G30) -> 0 | K30: =J30/(I30/8760*31.536) -> 0
A31: =Legend!$A$21 -> Commercial Services | B31: =Legend!$A$24 -> Space heating | C31: =Legend!A38 -> Oil | D31: =Legend!B38 -> OIL | E31: =Legend!$C$38 -> SRVOIL | F31: =EB_SRV!G27 -> 2.1882137 | G31: 0.65835584 | H31: 20 | I31: 1000 | J31: =IF(F31=0,0,F31*G31) -> 1.4406233 | K31: =J31/(I31/8760*31.536) -> 0.40017313
A32: =Legend!$A$21 -> Commercial Services | B32: =Legend!$A$24 -> Space heating | C32: =Legend!A39 -> Natural Gas | D32: =Legend!B39 -> GAS | E32: =Legend!$C$39&", "&Legend!$C$41 -> SRVGAS, SRVBGS | F32: =EB_SRV!G28+EB_SRV!G30 -> 5.3014888 | G32: 0.77299617 | H32: 20 | I32: 1000 | J32: =IF(F32=0,0,F32*G32) -> 4.0980305 | K32: =J32/(I32/8760*31.536) -> 1.1383418
A33: =Legend!$A$21 -> Commercial Services | B33: =Legend!$A$24 -> Space heating | C33: =Legend!A40 -> Biomass | D33: =Legend!B40 -> BIO | E33: =Legend!C40 -> SRVBIO | F33: =EB_SRV!G29 -> 0.29850706 | G33: 0.63490443 | H33: 20 | I33: 1000 | J33: =IF(F33=0,0,F33*G33) -> 0.18952346 | K33: =J33/(I33/8760*31.536) -> 0.052645404
A34: =Legend!$A$21 -> Commercial Services | B34: =Legend!$A$24 -> Space heating | C34: =Legend!A42 -> Solar | D34: =Legend!B42 -> SOL | E34: =Legend!C42 -> SRVSOL | F34: =EB_SRV!G31 -> 0 | G34: =IF(F34=0,0.33,G44) -> 0.33 | H34: 15 | I34: 1000 | J34: =IF(F34=0,0,F34*G34) -> 0 | K34: =J34/(I34/8760*31.536) -> 0
A35: =Legend!$A$21 -> Commercial Services | B35: =Legend!$A$24 -> Space heating | C35: Electricity (heat pumps) | D35: =Legend!B43&"-HP" -> ELC-HP | E35: =Legend!C43&","&Legend!C44 -> SRVELC,SRVAHT | F35: =EB_SRV!G32 -> 0.62428626 | G35: 2.1 | H35: 10 | I35: 1000 | J35: =IF(F35=0,0,F35*G35) -> 1.3110012 | K35: =J35/(I35/8760*31.536) -> 0.36416699 | L35: =EB_SRV!G34 -> 0.65533684
A36: =Legend!$A$21 -> Commercial Services | B36: =Legend!$A$24 -> Space heating | C36: Electricity (heaters) | D36: =Legend!B43 -> ELC | E36: =Legend!C43 -> SRVELC | F36: =EB_SRV!G33 -> 2.6985137 | G36: 0.81595511 | H36: 10 | I36: 1000 | J36: =IF(F36=0,0,F36*G36) -> 2.201866 | K36: =J36/(I36/8760*31.536) -> 0.61162945
A37: =Legend!$A$21 -> Commercial Services | B37: =Legend!$A$24 -> Space heating | C37: All fuels | F37: =SUM(F29:F36) -> 11.134494 | J37: =SUM(J29:J36) -> 9.2487943 | K37: =SUM(K29:K36) -> 2.5691095
A38: =Legend!$A$21 -> Commercial Services | B38: =Legend!$A$25 -> Water heating | C38: =Legend!A36 -> Solids | D38: =Legend!B36 -> COA | E38: =Legend!C36 -> SRVCOA | F38: =EB_SRV!G36 -> 0 | G38: 0.33 | H38: 20 | I38: 200 | J38: =IF(F38=0,0,F38*G38) -> 0 | K38: =J38/(I38/8760*31.536) -> 0
A39: =Legend!$A$21 -> Commercial Services | B39: =Legend!$A$25 -> Water heating | C39: =Legend!A37 -> LPG | D39: =Legend!B37 -> LPG | E39: =Legend!C37 -> SRVLPG | F39: =EB_SRV!G37 -> 0 | G39: 0.33 | H39: 20 | I39: 200 | J39: =IF(F39=0,0,F39*G39) -> 0 | K39: =J39/(I39/8760*31.536) -> 0
A40: =Legend!$A$21 -> Commercial Services | B40: =Legend!$A$25 -> Water heating | C40: =Legend!A38 -> Oil | D40: =Legend!B38 -> OIL | E40: =Legend!$C$38 -> SRVOIL | F40: =EB_SRV!G38 -> 0.64813396 | G40: 0.59834964 | H40: 20 | I40: 200 | J40: =IF(F40=0,0,F40*G40) -> 0.38781072 | K40: =J40/(I40/8760*31.536) -> 0.538626
A41: =Legend!$A$21 -> Commercial Services | B41: =Legend!$A$25 -> Water heating | C41: =Legend!A39 -> Natural Gas | D41: =Legend!B39 -> GAS | E41: =Legend!$C$39&", "&Legend!$C$41 -> SRVGAS, SRVBGS | F41: =EB_SRV!G39+EB_SRV!G41 -> 1.561908 | G41: 0.63024758 | H41: 20 | I41: 200 | J41: =IF(F41=0,0,F41*G41) -> 0.98438875 | K41: =J41/(I41/8760*31.536) -> 1.3672066
A42: =Legend!$A$21 -> Commercial Services | B42: =Legend!$A$25 -> Water heating | C42: =Legend!A40 -> Biomass | D42: =Legend!B40 -> BIO | E42: =Legend!C40 -> SRVBIO | F42: =EB_SRV!G40 -> 0 | G42: 0.33 | H42: 20 | I42: 200 | J42: =IF(F42=0,0,F42*G42) -> 0 | K42: =J42/(I42/8760*31.536) -> 0
A43: =Legend!$A$21 -> Commercial Services | B43: =Legend!$A$25 -> Water heating | C43: =Legend!A43 -> Electricity | D43: =Legend!B43 -> ELC | E43: =Legend!C43 -> SRVELC | F43: =EB_SRV!G42 -> 1.5309241 | G43: 0.77915339 | H43: 10 | I43: 200 | J43: =IF(F43=0,0,F43*G43) -> 1.1928247 | K43: =J43/(I43/8760*31.536) -> 1.656701
...

Sheet Commodities
B1: Commodities definition
B2: ~FI_Comm
B3: Csets | C3: Region | D3: CommName | E3: CommDesc | F3: Unit | G3: LimType | H3: CTSLvl | I3: PeakTS | J3: Ctype
B4: *Commodity set | C4: Regions | D4: Commodity name | E4: Description
B5: DEM | C5: =_xlfn.TEXTJOIN(",",TRUE,IF(LEFT(Regions!$C$3,1)<>"*",Regions!$C$3,""),IF(LEFT(Regions!$D$3,1)<>"*",Regions!$D$3,"")) -> IE,National | D5: =CONCATENATE(Legend!$C$4,"-",Legend!C21) -> SRV-CS | E5: =CONCATENATE(Legend!$B$4," - ",Legend!A21) -> Services - Commercial Services | F5: Mm2
B6: DEM | C6: =_xlfn.TEXTJOIN(",",TRUE,IF(LEFT(Regions!$C$3,1)<>"*",Regions!$C$3,""),IF(LEFT(Regions!$D$3,1)<>"*",Regions!$D$3,"")) -> IE,National | D6: =CONCATENATE(Legend!$C$4,"-",Legend!C22) -> SRV-PU | E6: =CONCATENATE(Legend!$B$4," - ",Legend!A22) -> Services - Public Services | F6: Mm2
B7: NRG | C7: =_xlfn.TEXTJOIN(",",TRUE,IF(LEFT(Regions!$C$3,1)<>"*",Regions!$C$3,""),IF(LEFT(Regions!$D$3,1)<>"*",Regions!$D$3,"")) -> IE,National | D7: =CONCATENATE(Legend!$C$4,Legend!$C24,"-",Legend!$C$21) -> SRVSH-CS | E7: =CONCATENATE(Legend!$C$4,"-",Legend!$A$21,": ",Legend!A24) -> SRV-Commercial Services: Space heating | F7: PJ | H7: ANNUAL
B8: NRG | C8: =_xlfn.TEXTJOIN(",",TRUE,IF(LEFT(Regions!$C$3,1)<>"*",Regions!$C$3,""),IF(LEFT(Regions!$D$3,1)<>"*",Regions!$D$3,"")) -> IE,National | D8: =CONCATENATE(Legend!$C$4,Legend!$C25,"-",Legend!$C$21) -> SRVWH-CS | E8: =CONCATENATE(Legend!$C$4,"-",Legend!$A$21,": ",Legend!A25) -> SRV-Commercial Services: Water heating | F8: PJ | H8: ANNUAL
B9: NRG | C9: =_xlfn.TEXTJOIN(",",TRUE,IF(LEFT(Regions!$C$3,1)<>"*",Regions!$C$3,""),IF(LEFT(Regions!$D$3,1)<>"*",Regions!$D$3,"")) -> IE,National | D9: =CONCATENATE(Legend!$C$4,Legend!$C26,"-",Legend!$C$21) -> SRVSC-CS | E9: =CONCATENATE(Legend!$C$4,"-",Legend!$A$21,": ",Legend!A26) -> SRV-Commercial Services: Space cooling | F9: PJ | H9: ANNUAL
B10: NRG | C10: =_xlfn.TEXTJOIN(",",TRUE,IF(LEFT(Regions!$C$3,1)<>"*",Regions!$C$3,""),IF(LEFT(Regions!$D$3,1)<>"*",Regions!$D$3,"")) -> IE,National | D10: =CONCATENATE(Legend!$C$4,Legend!$C28,"-",Legend!$C$21) -> SRVCK-CS | E10: =CONCATENATE(Legend!$C$4,"-",Legend!$A$21,": ",Legend!A28) -> SRV-Commercial Services: Cooking | F10: PJ | H10: ANNUAL
B11: NRG | C11: =_xlfn.TEXTJOIN(",",TRUE,IF(LEFT(Regions!$C$3,1)<>"*",Regions!$C$3,""),IF(LEFT(Regions!$D$3,1)<>"*",Regions!$D$3,"")) -> IE,National | D11: =CONCATENATE(Legend!$C$4,Legend!$C29,"-",Legend!$C$21) -> SRVLIG-CS | E11: =CONCATENATE(Legend!$C$4,"-",Legend!$A$21,": ",Legend!A29) -> SRV-Commercial Services: Building lighting | F11: Munits | H11: ANNUAL
B12: NRG | C12: =_xlfn.TEXTJOIN(",",TRUE,IF(LEFT(Regions!$C$3,1)<>"*",Regions!$C$3,""),IF(LEFT(Regions!$D$3,1)<>"*",Regions!$D$3,"")) -> IE,National | D12: =CONCATENATE(Legend!$C$4,Legend!$C30,"-",Legend!$C$21) -> SRVREF-CS | E12: =CONCATENATE(Legend!$C$4,"-",Legend!$A$21,": ",Legend!A30) -> SRV-Commercial Services: Refrigeration | F12: kunits | H12: ANNUAL
B13: NRG | C13: =_xlfn.TEXTJOIN(",",TRUE,IF(LEFT(Regions!$C$3,1)<>"*",Regions!$C$3,""),IF(LEFT(Regions!$D$3,1)<>"*",Regions!$D$3,"")) -> IE,National | D13: =CONCATENATE(Legend!$C$4,Legend!$C31,"-",Legend!$C$21) -> SRVOEL-CS | E13: =CONCATENATE(Legend!$C$4,"-",Legend!$A$21,": ",Legend!A31) -> SRV-Commercial Services: Other appliances | F13: PJ | H13: ANNUAL
B14: NRG | C14: =_xlfn.TEXTJOIN(",",TRUE,IF(LEFT(Regions!$C$3,1)<>"*",Regions!$C$3,""),IF(LEFT(Regions!$D$3,1)<>"*",Regions!$D$3,"")) -> IE,National | D14: =CONCATENATE(Legend!$C$4,Legend!$C24,"-",Legend!$C$22) -> SRVSH-PU | E14: =CONCATENATE(Legend!$C$4,"-",Legend!$A$22,": ",Legend!A24) -> SRV-Public Services: Space heating | F14: PJ | H14: ANNUAL
B15: NRG | C15: =_xlfn.TEXTJOIN(",",TRUE,IF(LEFT(Regions!$C$3,1)<>"*",Regions!$C$3,""),IF(LEFT(Regions!$D$3,1)<>"*",Regions!$D$3,"")) -> IE,National | D15: =CONCATENATE(Legend!$C$4,Legend!$C25,"-",Legend!$C$22) -> SRVWH-PU | E15: =CONCATENATE(Legend!$C$4,"-",Legend!$A$22,": ",Legend!A25) -> SRV-Public Services: Water heating | F15: PJ | H15: ANNUAL
B16: NRG | C16: =_xlfn.TEXTJOIN(",",TRUE,IF(LEFT(Regions!$C$3,1)<>"*",Regions!$C$3,""),IF(LEFT(Regions!$D$3,1)<>"*",Regions!$D$3,"")) -> IE,National | D16: =CONCATENATE(Legend!$C$4,Legend!$C26,"-",Legend!$C$22) -> SRVSC-PU | E16: =CONCATENATE(Legend!$C$4,"-",Legend!$A$22,": ",Legend!A26) -> SRV-Public Services: Space cooling | F16: PJ | H16: ANNUAL
B17: NRG | C17: =_xlfn.TEXTJOIN(",",TRUE,IF(LEFT(Regions!$C$3,1)<>"*",Regions!$C$3,""),IF(LEFT(Regions!$D$3,1)<>"*",Regions!$D$3,"")) -> IE,National | D17: =CONCATENATE(Legend!$C$4,Legend!$C28,"-",Legend!$C$22) -> SRVCK-PU | E17: =CONCATENATE(Legend!$C$4,"-",Legend!$A$22,": ",Legend!A28) -> SRV-Public Services: Cooking | F17: PJ | H17: ANNUAL
B18: NRG | C18: =_xlfn.TEXTJOIN(",",TRUE,IF(LEFT(Regions!$C$3,1)<>"*",Regions!$C$3,""),IF(LEFT(Regions!$D$3,1)<>"*",Regions!$D$3,"")) -> IE,National | D18: =CONCATENATE(Legend!$C$4,Legend!$C29,"-",Legend!$C$22) -> SRVLIG-PU | E18: =CONCATENATE(Legend!$C$4,"-",Legend!$A$22,": ",Legend!A29) -> SRV-Public Services: Building lighting | F18: Munits | H18: ANNUAL
B19: NRG | C19: =_xlfn.TEXTJOIN(",",TRUE,IF(LEFT(Regions!$C$3,1)<>"*",Regions!$C$3,""),IF(LEFT(Regions!$D$3,1)<>"*",Regions!$D$3,"")) -> IE,National | D19: =CONCATENATE(Legend!$C$4,Legend!$C30,"-",Legend!$C$22) -> SRVREF-PU | E19: =CONCATENATE(Legend!$C$4,"-",Legend!$A$22,": ",Legend!A30) -> SRV-Public Services: Refrigeration | F19: kunits | H19: ANNUAL
B20: NRG | C20: =_xlfn.TEXTJOIN(",",TRUE,IF(LEFT(Regions!$C$3,1)<>"*",Regions!$C$3,""),IF(LEFT(Regions!$D$3,1)<>"*",Regions!$D$3,"")) -> IE,National | D20: =CONCATENATE(Legend!$C$4,Legend!$C31,"-",Legend!$C$22) -> SRVOEL-PU | E20: =CONCATENATE(Legend!$C$4,"-",Legend!$A$22,": ",Legend!A31) -> SRV-Public Services: Other appliances | F20: PJ | H20: ANNUAL
B21: DEM | C21: =_xlfn.TEXTJOIN(",",TRUE,IF(LEFT(Regions!$C$3,1)<>"*",Regions!$C$3,""),IF(LEFT(Regions!$D$3,1)<>"*",Regions!$D$3,"")) -> IE,National | D21: =CONCATENATE(Legend!$C$4,Legend!$C32,"-",Legend!$C$21) -> SRVDCE-CS | E21: =CONCATENATE(Legend!$C$4,"-",Legend!$A$21,": ",Legend!A32) -> SRV-Commercial Services: Data centers | F21: PJ | H21: ANNUAL
B22: DEM | C22: =_xlfn.TEXTJOIN(",",TRUE,IF(LEFT(Regions!$C$3,1)<>"*",Regions!$C$3,""),IF(LEFT(Regions!$D$3,1)<>"*",Regions!$D$3,"")) -> IE,National | D22: =CONCATENATE(Legend!$C$4,Legend!$C33,"-",Legend!$C$22) -> SRVPLIG-PU | E22: =CONCATENATE(Legend!$C$4,"-",Legend!$A$22,": ",Legend!A33) -> SRV-Public Services: Public lighting | F22: =PLIG_Techs!P7 -> Mlamps | H22: ANNUAL
B23: NRG | C23: =_xlfn.TEXTJOIN(",",TRUE,IF(LEFT(Regions!$C$3,1)<>"*",Regions!$C$3,""),IF(LEFT(Regions!$D$3,1)<>"*",Regions!$D$3,"")) -> IE,National | D23: =Legend!C36 -> SRVCOA | E23: =Legend!A36&" (SRV)" -> Solids (SRV) | F23: PJ | G23: FX
B24: NRG | C24: =_xlfn.TEXTJOIN(",",TRUE,IF(LEFT(Regions!$C$3,1)<>"*",Regions!$C$3,""),IF(LEFT(Regions!$D$3,1)<>"*",Regions!$D$3,"")) -> IE,National | D24: =Legend!C37 -> SRVLPG | E24: =Legend!A37&" (SRV)" -> LPG (SRV) | F24: PJ | G24: FX
B25: NRG | C25: =_xlfn.TEXTJOIN(",",TRUE,IF(LEFT(Regions!$C$3,1)<>"*",Regions!$C$3,""),IF(LEFT(Regions!$D$3,1)<>"*",Regions!$D$3,"")) -> IE,National | D25: =Legend!C38 -> SRVOIL | E25: =Legend!A38&" (SRV)" -> Oil (SRV) | F25: PJ | G25: FX
B26: NRG | C26: =_xlfn.TEXTJOIN(",",TRUE,IF(LEFT(Regions!$C$3,1)<>"*",Regions!$C$3,""),IF(LEFT(Regions!$D$3,1)<>"*",Regions!$D$3,"")) -> IE,National | D26: =Legend!C39 -> SRVGAS | E26: =Legend!A39&" (SRV)" -> Natural Gas (SRV) | F26: PJ | G26: FX
B27: NRG | C27: =_xlfn.TEXTJOIN(",",TRUE,IF(LEFT(Regions!$C$3,1)<>"*",Regions!$C$3,""),IF(LEFT(Regions!$D$3,1)<>"*",Regions!$D$3,"")) -> IE,National | D27: =Legend!C40 -> SRVBIO | E27: =Legend!A40&" (SRV)" -> Biomass (SRV) | F27: PJ | G27: FX
B28: NRG | C28: =_xlfn.TEXTJOIN(",",TRUE,IF(LEFT(Regions!$C$3,1)<>"*",Regions!$C$3,""),IF(LEFT(Regions!$D$3,1)<>"*",Regions!$D$3,"")) -> IE,National | D28: =Legend!C41 -> SRVBGS | E28: =Legend!A41&" (SRV)" -> Biogas (SRV) | F28: PJ | G28: FX
B29: NRG | C29: =_xlfn.TEXTJOIN(",",TRUE,IF(LEFT(Regions!$C$3,1)<>"*",Regions!$C$3,""),IF(LEFT(Regions!$D$3,1)<>"*",Regions!$D$3,"")) -> IE,National | D29: =Legend!C42 -> SRVSOL | E29: =Legend!A42&" (SRV)" -> Solar (SRV) | F29: PJ | G29: FX
B30: NRG | C30: =_xlfn.TEXTJOIN(",",TRUE,IF(LEFT(Regions!$C$3,1)<>"*",Regions!$C$3,""),IF(LEFT(Regions!$D$3,1)<>"*",Regions!$D$3,"")) -> IE,National | D30: =Legend!C43 -> SRVELC | E30: =Legend!A43&" (SRV)" -> Electricity (SRV) | F30: PJ | G30: FX | H30: DAYNITE | J30: ELC
B31: NRG | C31: =_xlfn.TEXTJOIN(",",TRUE,IF(LEFT(Regions!$C$3,1)<>"*",Regions!$C$3,""),IF(LEFT(Regions!$D$3,1)<>"*",Regions!$D$3,"")) -> IE,National | D31: =Legend!C44 -> SRVAHT | E31: =Legend!A44&" (SRV)" -> Ambient Heat (SRV) | F31: PJ | G31: FX
B32: NRG | C32: =_xlfn.TEXTJOIN(",",TRUE,IF(LEFT(Regions!$C$3,1)<>"*",Regions!$C$3,""),IF(LEFT(Regions!$D$3,1)<>"*",Regions!$D$3,"")) -> IE,National | D32: =Legend!C45 -> SRVAHT2 | E32: =Legend!A45&" (SRV)" -> Ambient Heat 2 (SRV) | F32: PJ | G32: FX
B33: NRG | C33: =_xlfn.TEXTJOIN(",",TRUE,IF(LEFT(Regions!$C$3,1)<>"*",Regions!$C$3,""),IF(LEFT(Regions!$D$3,1)<>"*",Regions!$D$3,"")) -> IE,National | D33: =Legend!C46 -> SRVHET | E33: =Legend!A46&" (SRV)" -> District heating (SRV) | F33: PJ | G33: FX | H33: DAYNITE
B34: NRG | C34: =_xlfn.TEXTJOIN(",",TRUE,IF(LEFT(Regions!$C$3,1)<>"*",Regions!$C$3,""),IF(LEFT(Regions!$D$3,1)<>"*",Regions!$D$3,"")) -> IE,National | D34: =Legend!C47 -> SRVWIN | E34: =Legend!A47&" (SRV)" -> Wind (SRV) | F34: PJ | G34: FX
B35: NRG | C35: =_xlfn.TEXTJOIN(",",TRUE,IF(LEFT(Regions!$C$3,1)<>"*",Regions!$C$3,""),IF(LEFT(Regions!$D$3,1)<>"*",Regions!$D$3,"")) -> IE,National | D35: =Legend!C48 -> SRVH2G | E35: =Legend!A48&" (SRV)" -> Hydrogen (gaseous) (SRV) | F35: PJ | G35: FX
B36: NRG | C36: =_xlfn.TEXTJOIN(",",TRUE,IF(LEFT(Regions!$C$3,1)<>"*",Regions!$C$3,""),IF(LEFT(Regions!$D$3,1)<>"*",Regions!$D$3,"")) -> IE,National | D36: =Legend!C49 -> SRVH2L | E36: =Legend!A49&" (SRV)" -> Hydrogen (liquid) (SRV) | F36: PJ | G36: FX
B37: NRG | C37: =_xlfn.TEXTJOIN(",",TRUE,IF(LEFT(Regions!$C$3,1)<>"*",Regions!$C$3,""),IF(LEFT(Regions!$D$3,1)<>"*",Regions!$D$3,"")) -> IE,National | D37: =Legend!C50 -> SRVBDL | E37: =Legend!A50&" (SRV)" -> Biodiesel (SRV) | F37: PJ | G37: FX
B38: ENV | C38: =_xlfn.TEXTJOIN(",",TRUE,IF(LEFT(Regions!$C$3,1)<>"*",Regions!$C$3,""),IF(LEFT(Regions!$D$3,1)<>"*",Regions!$D$3,"")) -> IE,National | D38: SRVCO2N | E38: Carbon Dioxide - Combustion (SRV) | F38: kt
B39: ENV | C39: =_xlfn.TEXTJOIN(",",TRUE,IF(LEFT(Regions!$C$3,1)<>"*",Regions!$C$3,""),IF(LEFT(Regions!$D$3,1)<>"*",Regions!$D$3,"")) -> IE,National | D39: SRVCH4N | E39: Methane (SRV) | F39: kt
B40: ENV | C40: =_xlfn.TEXTJOIN(",",TRUE,IF(LEFT(Regions!$C$3,1)<>"*",Regions!$C$3,""),IF(LEFT(Regions!$D$3,1)<>"*",Regions!$D$3,"")) -> IE,National | D40: SRVSO2N | E40: Sulphur Oxides (SRV) | F40: kt
...

Sheet Fuel Techs
B1: Fuel Techs/Distribution Infrastructure
B2: ~FI_T | N2: ~FI_Process
B3: =P3 -> TechName | C3: Comm-IN | D3: Comm-OUT | E3: EFF | F3: Share-I~FX | G3: Share-I~FX~0 | H3: INVCOST | I3: FIXOM | J3: LIFE | K3: AFA | L3: CAP2ACT | N3: Sets | O3: Region | P3: TechName | Q3: TechDesc | R3: Tact | S3: Tcap | T3: Tslvl | U3: PrimaryCG | V3: Vintage
B4: *Technology name | C4: Input commodity | D4: Output commodity | E4: Efficiency | F4: Input shares | G4: I/E rule | N4: *Process Set Membership | O4: Regions | P4: Technology name | Q4: Description | R4: Activity unit | S4: Capacity unit | T4: TimeSlice level of Process Activity | U4: Primary Commodity Group | V4: Vintage Tracking
B5: =P5 -> FT-SRVCOA | C5: COABIT,COALIG,COAHAR | D5: =Legend!C36 -> SRVCOA | E5: 1 | N5: PRE | O5: =_xlfn.TEXTJOIN(",",TRUE,IF(LEFT(Regions!$C$3,1)<>"*",Regions!$C$3,""),IF(LEFT(Regions!$D$3,1)<>"*",Regions!$D$3,"")) -> IE,National | P5: ="FT-"&D5 -> FT-SRVCOA | Q5: ="Fuel Tech - "&Legend!A36 -> Fuel Tech - Solids | R5: PJ | S5: PJa
B6: =P6 -> FT-SRVLPG | C6: OILLPG | D6: =Legend!C37 -> SRVLPG | E6: 1 | N6: PRE | O6: =_xlfn.TEXTJOIN(",",TRUE,IF(LEFT(Regions!$C$3,1)<>"*",Regions!$C$3,""),IF(LEFT(Regions!$D$3,1)<>"*",Regions!$D$3,"")) -> IE,National | P6: ="FT-"&D6 -> FT-SRVLPG | Q6: ="Fuel Tech - "&Legend!A37 -> Fuel Tech - LPG | R6: PJ | S6: PJa
B7: =P7 -> FT-SRVOIL | C7: OILKER | D7: =Legend!C38 -> SRVOIL | E7: 1 | F7: =EB_SRV!R5*Legend!$B$65/EB_SRV!$F$12 -> 0.3662915 | G7: 5 | N7: PRE | O7: =_xlfn.TEXTJOIN(",",TRUE,IF(LEFT(Regions!$C$3,1)<>"*",Regions!$C$3,""),IF(LEFT(Regions!$D$3,1)<>"*",Regions!$D$3,"")) -> IE,National | P7: ="FT-"&D7 -> FT-SRVOIL | Q7: ="Fuel Tech - "&Legend!A38 -> Fuel Tech - Oil | R7: PJ | S7: PJa
C8: OILDST | F8: =EB_SRV!V5*Legend!$B$65/EB_SRV!$F$12 -> 0.62988507 | G8: 5 | N8: PRE | O8: =_xlfn.TEXTJOIN(",",TRUE,IF(LEFT(Regions!$C$3,1)<>"*",Regions!$C$3,""),IF(LEFT(Regions!$D$3,1)<>"*",Regions!$D$3,"")) -> IE,National | P8: ="FT-"&D10 -> FT-SRVGAS | Q8: ="Fuel Tech - "&Legend!A39 -> Fuel Tech - Natural Gas | R8: PJ | S8: PJa
C9: OILHFO | F9: =EB_SRV!T5*Legend!$B$65/EB_SRV!$F$12 -> 0.0038234269 | G9: 5 | N9: PRE | O9: =_xlfn.TEXTJOIN(",",TRUE,IF(LEFT(Regions!$C$3,1)<>"*",Regions!$C$3,""),IF(LEFT(Regions!$D$3,1)<>"*",Regions!$D$3,"")) -> IE,National | P9: ="FT-"&D11 -> FT-SRVBIO | Q9: ="Fuel Tech - "&Legend!A40 -> Fuel Tech - Biomass | R9: PJ | S9: PJa
B10: =P8 -> FT-SRVGAS | C10: GASNAT | D10: =Legend!C39 -> SRVGAS | E10: 1 | H10: 50 | I10: =+H10*0.05 -> 2.5 | J10: 30 | K10: 0.35 | L10: 31.536 | N10: PRE | O10: =_xlfn.TEXTJOIN(",",TRUE,IF(LEFT(Regions!$C$3,1)<>"*",Regions!$C$3,""),IF(LEFT(Regions!$D$3,1)<>"*",Regions!$D$3,"")) -> IE,National | P10: ="FT-"&D12 -> FT-SRVBGS | Q10: ="Fuel Tech - "&Legend!A41 -> Fuel Tech - Biogas | R10: PJ | S10: PJa
B11: =P9 -> FT-SRVBIO | C11: BIOWOO,BIOWPE,BIOWCH | D11: =Legend!C40 -> SRVBIO | E11: 1 | N11: PRE | O11: =_xlfn.TEXTJOIN(",",TRUE,IF(LEFT(Regions!$C$3,1)<>"*",Regions!$C$3,""),IF(LEFT(Regions!$D$3,1)<>"*",Regions!$D$3,"")) -> IE,National | P11: ="FT-"&D13 -> FT-SRVSOL | Q11: ="Fuel Tech - "&Legend!A42 -> Fuel Tech - Solar | R11: PJ | S11: PJa
B12: =P10 -> FT-SRVBGS | C12: BIOGAS1G, BIOGAS2G | D12: =Legend!C41 -> SRVBGS | E12: 1 | N12: PRE | O12: =_xlfn.TEXTJOIN(",",TRUE,IF(LEFT(Regions!$C$3,1)<>"*",Regions!$C$3,""),IF(LEFT(Regions!$D$3,1)<>"*",Regions!$D$3,"")) -> IE,National | P12: ="FT-"&D14 -> FT-SRVELC | Q12: ="Fuel Tech - "&Legend!A43 -> Fuel Tech - Electricity | R12: PJ | S12: PJa | T12: DAYNITE
B13: =P11 -> FT-SRVSOL | C13: RENSOL | D13: =Legend!C42 -> SRVSOL | E13: 1 | N13: PRE | O13: =_xlfn.TEXTJOIN(",",TRUE,IF(LEFT(Regions!$C$3,1)<>"*",Regions!$C$3,""),IF(LEFT(Regions!$D$3,1)<>"*",Regions!$D$3,"")) -> IE,National | P13: ="FT-"&D15 -> FT-SRVAHT | Q13: ="Fuel Tech - "&Legend!A44 -> Fuel Tech - Ambient Heat | R13: PJ | S13: PJa
B14: =P12 -> FT-SRVELC | C14: ELCD | D14: =Legend!C43 -> SRVELC | E14: 1 | H14: 200 | I14: =+H14*0.05 -> 10 | J14: 50 | K14: 0.35 | L14: 31.536 | N14: PRE | O14: =_xlfn.TEXTJOIN(",",TRUE,IF(LEFT(Regions!$C$3,1)<>"*",Regions!$C$3,""),IF(LEFT(Regions!$D$3,1)<>"*",Regions!$D$3,"")) -> IE,National | P14: ="FT-"&D17 -> FT-SRVHET | Q14: ="Fuel Tech - "&Legend!A46 -> Fuel Tech - District heating | R14: PJ | S14: PJa | T14: DAYNITE
B15: =P13 -> FT-SRVAHT | C15: RENAHT | D15: =Legend!C44 -> SRVAHT | E15: 1 | N15: PRE | O15: =_xlfn.TEXTJOIN(",",TRUE,IF(LEFT(Regions!$C$3,1)<>"*",Regions!$C$3,""),IF(LEFT(Regions!$D$3,1)<>"*",Regions!$D$3,"")) -> IE,National | P15: ="FT-"&D18 -> FT-SRVWIN | Q15: ="Fuel Tech - "&Legend!A47 -> Fuel Tech - Wind | R15: PJ | S15: PJa
D16: =Legend!C45 -> SRVAHT2 | N16: PRE | O16: =_xlfn.TEXTJOIN(",",TRUE,IF(LEFT(Regions!$C$3,1)<>"*",Regions!$C$3,""),IF(LEFT(Regions!$D$3,1)<>"*",Regions!$D$3,"")) -> IE,National | P16: ="FT-"&D19 -> FT-SRVH2G | Q16: ="Fuel Tech - "&Legend!A48 -> Fuel Tech - Hydrogen (gaseous) | R16: PJ | S16: PJa
B17: =P14 -> FT-SRVHET | C17: HETD | D17: =Legend!C46 -> SRVHET | E17: 1 | H17: 50 | I17: =+H17*0.05 -> 2.5 | J17: 30 | K17: 0.35 | L17: 31.536 | N17: PRE | O17: =_xlfn.TEXTJOIN(",",TRUE,IF(LEFT(Regions!$C$3,1)<>"*",Regions!$C$3,""),IF(LEFT(Regions!$D$3,1)<>"*",Regions!$D$3,"")) -> IE,National | P17: ="FT-"&D20 -> FT-SRVH2L | Q17: ="Fuel Tech - "&Legend!A49 -> Fuel Tech - Hydrogen (liquid) | R17: PJ | S17: PJa
B18: =P15 -> FT-SRVWIN | C18: RENWIN | D18: =Legend!C47 -> SRVWIN | E18: 1 | N18: PRE | O18: =_xlfn.TEXTJOIN(",",TRUE,IF(LEFT(Regions!$C$3,1)<>"*",Regions!$C$3,""),IF(LEFT(Regions!$D$3,1)<>"*",Regions!$D$3,"")) -> IE,National | P18: ="FT-"&D21 -> FT-SRVBDL | Q18: ="Fuel Tech - "&Legend!A50 -> Fuel Tech - Biodiesel | R18: PJ | S18: PJa
B19: =P16 -> FT-SRVH2G | C19: SUPH2GD | D19: =Legend!C48 -> SRVH2G | E19: 1 | N19: PRE | O19: =_xlfn.TEXTJOIN(",",TRUE,IF(LEFT(Regions!$C$3,1)<>"*",Regions!$C$3,""),IF(LEFT(Regions!$D$3,1)<>"*",Regions!$D$3,"")) -> IE,National | P19: ="FT-"&D22 -> FT-SRVETH | Q19: ="Fuel Tech - "&Legend!A51 -> Fuel Tech - Ethanol | R19: PJ | S19: PJa
B20: =P17 -> FT-SRVH2L | C20: SUPH2LD | D20: =Legend!C49 -> SRVH2L | E20: 1
B21: =P18 -> FT-SRVBDL | C21: BIODST1G,BIODST2G | D21: =Legend!C50 -> SRVBDL | E21: 1
B22: =P19 -> FT-SRVETH | C22: BIOETH1G,BIOETH2G | D22: =Legend!C51 -> SRVETH | E22: 1

Sheet Building stock
B1: Characterization of Building stocks
B2: ~FI_T | L2: ~FI_Process
B3: TechName | C3: *TechDesc | D3: Comm-IN | E3: Comm-OUT | F3: PASTI | G3: Input | H3: AFA~FX | I3: AFA~FX~0 | J3: Life | L3: Sets | M3: Region | N3: TechName | O3: TechDesc | P3: Tact | Q3: Tcap | R3: Tslvl | S3: PrimaryCG | T3: Vintage
B4: *Technology name | C4: Description | D4: Input commodity | E4: Output commodity | F4: Dwelling stocks | G4: Energy intensities | H4: Fixed availability factor | I4: Interpolation rule | J4: Technical life | L4: *Process Set Membership | M4: Regions | N4: Technology name | O4: Description | P4: Activity unit | Q4: Capacity unit | R4: TimeSlice level of Process Activity | S4: Primary Commodity Group | T4: Vintage Tracking
B5: *Units | F5: Mm2 | G5: (see notes) | J5: years | L5: *
B6: ='Building stock'!N6 -> S-BLD_CS | C6: ='Building stock'!O6 -> Services Buildings - Commercial Services | D6: =Commodities!D7 -> SRVSH-CS | E6: =Commodities!D5 -> SRV-CS | F6: ='Key Inputs'!D21 -> 28.901665 | G6: =SUM(TH_Techs!$AJ$7:$AJ$14)/'Building stock'!$F$6 -> 0.32100597 | H6: 1 | I6: 3 | J6: 100 | L6: DMD | M6: =_xlfn.TEXTJOIN(",",TRUE,IF(LEFT(Regions!$C$3,1)<>"*",Regions!$C$3,""),IF(LEFT(Regions!$D$3,1)<>"*",Regions!$D$3,"")) -> IE,National | N6: =CONCATENATE(LEFT(Legend!$C$4),"-BLD_",Legend!C21) -> S-BLD_CS | O6: =CONCATENATE(Legend!$B$4," Buildings - ",Legend!A21) -> Services Buildings - Commercial Services | P6: Mm2 | Q6: Mm2 | R6: ANNUAL
D7: =Commodities!D8 -> SRVWH-CS | G7: =SUM(TH_Techs!$AJ$16:$AJ$22)/'Building stock'!$F$6 -> 0.089259606 | L7: DMD | M7: =_xlfn.TEXTJOIN(",",TRUE,IF(LEFT(Regions!$C$3,1)<>"*",Regions!$C$3,""),IF(LEFT(Regions!$D$3,1)<>"*",Regions!$D$3,"")) -> IE,National | N7: =CONCATENATE(LEFT(Legend!$C$4),"-BLD_",Legend!C22) -> S-BLD_PU | O7: =CONCATENATE(Legend!$B$4," Buildings - ",Legend!A22) -> Services Buildings - Public Services | P7: Mm2 | Q7: Mm2 | R7: ANNUAL
D8: =Commodities!D9 -> SRVSC-CS | G8: =SUM(TH_Techs!$AJ$24:$AJ$25)/'Building stock'!$F$6 -> 0.12810823
D9: =Commodities!D10 -> SRVCK-CS | G9: =SUM(CK_Techs!$AD$7:$AD$10)/'Building stock'!$F$6 -> 0.14156432
D10: =Commodities!D11 -> SRVLIG-CS | G10: =EAP_Techs!AD6/'Building stock'!$F$6 -> 0.65611068
D11: =Commodities!D12 -> SRVREF-CS | G11: =EAP_Techs!AD7/'Building stock'!$F$6 -> 3.4112422
D12: =Commodities!D13 -> SRVOEL-CS | G12: =EAP_Techs!AD8/'Building stock'!$F$6 -> 0.349503
B13: ='Building stock'!N7 -> S-BLD_PU | C13: ='Building stock'!O7 -> Services Buildings - Public Services | D13: =Commodities!D14 -> SRVSH-PU | E13: =Commodities!D6 -> SRV-PU | F13: ='Key Inputs'!D22 -> 58.151542 | G13: =SUM(TH_Techs!$AJ$27:$AJ$34)/'Building stock'!$F$13 -> 0.10255744 | H13: 1 | I13: 3 | J13: 100
D14: =Commodities!D15 -> SRVWH-PU | G14: =SUM(TH_Techs!$AJ$36:$AJ$42)/'Building stock'!$F$13 -> 0.025647153
D15: =Commodities!D16 -> SRVSC-PU | G15: =SUM(TH_Techs!$AJ$44:$AJ$45)/'Building stock'!$F$13 -> 0.018339681
D16: =Commodities!D17 -> SRVCK-PU | G16: =SUM(CK_Techs!$AD$12:$AD$15)/'Building stock'!$F$13 -> 0.029568686
D17: =Commodities!D18 -> SRVLIG-PU | G17: =EAP_Techs!AD9/'Building stock'!$F$13 -> 0.16206915
D18: =Commodities!D19 -> SRVREF-PU | G18: =EAP_Techs!AD10/'Building stock'!$F$13 -> 0.84262783
D19: =Commodities!D20 -> SRVOEL-PU | G19: =EAP_Techs!AD11/'Building stock'!$F$13 -> 0.049837987
B23: BY demands
D24: ~FI_T
B25: Region | C25: CommName | D25: Attribute | E25: 2018
B26: *Region name | C26: Commodity name | E26: Dwelling demand
B27: *Units | E27: Mm2
B28: =_xlfn.TEXTJOIN(",",TRUE,IF(LEFT(Regions!$C$3,1)<>"*",Regions!$C$3,""),IF(LEFT(Regions!$D$3,1)<>"*",Regions!$D$3,"")) -> IE,National | C28: =Commodities!D5 -> SRV-CS | D28: Demand | E28: =F6 -> 28.901665
B29: =_xlfn.TEXTJOIN(",",TRUE,IF(LEFT(Regions!$C$3,1)<>"*",Regions!$C$3,""),IF(LEFT(Regions!$D$3,1)<>"*",Regions!$D$3,"")) -> IE,National | C29: =Commodities!D6 -> SRV-PU | D29: Demand | E29: =F13 -> 58.151542

Sheet TH_Techs
B1: Characterization of thermal energy services
B2: ~FI_T | R2: ~FI_Process
B3: Region | C3: TechName | D3: *TechDesc | E3: Comm-IN | F3: Comm-IN-A | G3: Comm-OUT | H3: Stock | I3: EFF | J3: AFA | K3: Life | L3: Cap2Act | M3: ="Share-I~"&Legend!$C$44 -> Share-I~SRVAHT | N3: ="Share-I~UP~"&Legend!$C$41 -> Share-I~UP~SRVBGS | O3: ="Share-I~LO~"&Legend!$C$41 -> Share-I~LO~SRVBGS | P3: ="Share-I~LO~0~"&Legend!$C$41 -> Share-I~LO~0~SRVBGS | R3: Sets | S3: Region | T3: TechName | U3: TechDesc | V3: Tact | W3: Tcap | X3: Tslvl | Y3: PrimaryCG | Z3: Vintage | AB3: Sub-sector | AC3: Energy service | AD3: Fuel | AE3: Fuel Short name | AF3: Fuel Long name | AG3: Sub-sector short name | AH3: Energy service short name | AI3: Calibration checks
B4: *Region | C4: Technology name | D4: Description | E4: Input commodity | F4: Auxiliary input commodity | G4: Output commodity | H4: Total device stock | I4: Efficiency | J4: Availability factor | K4: Technical life | L4: Capacity to Activity Factor | N4: Maximum blending share | O4: Minimum blending share | P4: Extrapolation rule | R4: *Process Set Membership | S4: Regions | T4: Technology name | U4: Description | V4: Activity unit | W4: Capacity unit | X4: TimeSlice level of Process Activity | Y4: Primary Commodity Group | Z4: Vintage Tracking | AI4: Expected consumption | AJ4: Expected production
B5: *Units | H5: GW | I5: % | J5: % | K5: years | L5: GW to PJ | M5: PJin/PJout | N5: % | O5: % | R5: * | AI5: PJ | AJ5: PJ
B6: =IF($AE6="",R6,T6) -> *Commercial Services Space heating | D6: =IF($AE6="","",U6) | E6: =IF($AE6="","",AF6) | G6: =IF($AE6="","",CONCATENATE(Legend!$C$4,AH6,"-",AG6)) | H6: =IF($AE6="","",SUMIFS('Key Inputs'!$K$29:$K$114,'Key Inputs'!$A$29:$A$114,$AB6,'Key Inputs'!$B$29:$B$114,$AC6,'Key Inputs'!$C$29:$C$114,$AD6)) | I6: =IF($AE6="","",SUMIFS('Key Inputs'!$G$29:$G$114,'Key Inputs'!$A$29:$A$114,$AB6,'Key Inputs'!$B$29:$B$114,$AC6,'Key Inputs'!$C$29:$C$114,$AD6)) | J6: =IF($AE6="","",SUMIFS('Key Inputs'!$I$29:$I$114,'Key Inputs'!$A$29:$A$114,$AB6,'Key Inputs'!$B$29:$B$114,$AC6,'Key Inputs'!$C$29:$C$114,$AD6)/8760) | K6: =IF($AE6="","",SUMIFS('Key Inputs'!$H$29:$H$114,'Key Inputs'!$A$29:$A$114,$AB6,'Key Inputs'!$B$29:$B$114,$AC6,'Key Inputs'!$C$29:$C$114,$AD6)) | L6: =IF($AE6="","",31.536) | R6: =IF($AE6="","*"&AB7&" "&AC7,"PRE") -> *Commercial Services Space heating
B7: =IF($AE7="",Q7,S7) -> IE,National | C7: =IF($AE7="",R7,T7) -> S-SH-CS_COA_X0 | D7: =IF($AE7="","",U7) -> Commercial Services - Space heating: Solids | E7: =IF($AE7="","",AF7) -> SRVCOA | G7: =IF($AE7="","",CONCATENATE(Legend!$C$4,AH7,"-",AG7)) -> SRVSH-CS | H7: =IF($AE7="","",SUMIFS('Key Inputs'!$K$29:$K$114,'Key Inputs'!$A$29:$A$114,$AB7,'Key Inputs'!$B$29:$B$114,$AC7,'Key Inputs'!$C$29:$C$114,$AD7)) -> 0.0021527381 | I7: =IF($AE7="","",SUMIFS('Key Inputs'!$G$29:$G$114,'Key Inputs'!$A$29:$A$114,$AB7,'Key Inputs'!$B$29:$B$114,$AC7,'Key Inputs'!$C$29:$C$114,$AD7)) -> 0.33 | J7: =IF($AE7="","",SUMIFS('Key Inputs'!$I$29:$I$114,'Key Inputs'!$A$29:$A$114,$AB7,'Key Inputs'!$B$29:$B$114,$AC7,'Key Inputs'!$C$29:$C$114,$AD7)/8760) -> 0.11415525 | K7: =IF($AE7="","",SUMIFS('Key Inputs'!$H$29:$H$114,'Key Inputs'!$A$29:$A$114,$AB7,'Key Inputs'!$B$29:$B$114,$AC7,'Key Inputs'!$C$29:$C$114,$AD7)) -> 20 | L7: =IF($AE7="","",31.536) -> 31.536 | R7: =IF($AE7="","*"&AB8&" "&AC8,"PRE") -> PRE | S7: =IF($AE7="","",_xlfn.TEXTJOIN(",",TRUE,IF(LEFT(Regions!$C$3,1)<>"*",Regions!$C$3,""),IF(LEFT(Regions!$D$3,1)<>"*",Regions!$D$3,""))) -> IE,National | T7: =IF($AE7="","",CONCATENATE(LEFT(Legend!$C$4),"-",$AH7,"-",$AG7,"_",$AE7,"_X0")) -> S-SH-CS_COA_X0 | U7: =IF($AE7="","",CONCATENATE(AB7," - ",AC7,": ",AD7)) -> Commercial Services - Space heating: Solids | V7: =IF($AE7="","","PJ") -> PJ | W7: =IF($AE7="","","GW") -> GW | X7: =IF($AE7="","","ANNUAL") -> ANNUAL | AB7: =IF('Key Inputs'!A29="","",'Key Inputs'!A29) -> Commercial Services | AC7: =IF('Key Inputs'!B29="","",'Key Inputs'!B29) -> Space heating | AD7: =IF('Key Inputs'!C29="","",'Key Inputs'!C29) -> Solids | AE7: =IF('Key Inputs'!D29="","",'Key Inputs'!D29) -> COA | AF7: =IF('Key Inputs'!E29="","",'Key Inputs'!E29) -> SRVCOA | AG7: =_xlfn.XLOOKUP(AB7,Legend!$A$21:$A$22,Legend!$C$21:$C$22) -> CS | AH7: =_xlfn.XLOOKUP(AC7,Legend!$A$24:$A$34,Legend!$C$24:$C$34) -> SH | AI7: =IF($AE7="","",AJ7/I7) -> 0.023484416 | AJ7: =IF($AE7="","",H7*J7*L7) -> 0.0077498573
B8: =IF($AE8="",Q8,S8) -> IE,National | C8: =IF($AE8="",R8,T8) -> S-SH-CS_LPG_X0 | D8: =IF($AE8="","",U8) -> Commercial Services - Space heating: LPG | E8: =IF($AE8="","",AF8) -> SRVLPG | G8: =IF($AE8="","",CONCATENATE(Legend!$C$4,AH8,"-",AG8)) -> SRVSH-CS | H8: =IF($AE8="","",SUMIFS('Key Inputs'!$K$29:$K$114,'Key Inputs'!$A$29:$A$114,$AB8,'Key Inputs'!$B$29:$B$114,$AC8,'Key Inputs'!$C$29:$C$114,$AD8)) -> 0 | I8: =IF($AE8="","",SUMIFS('Key Inputs'!$G$29:$G$114,'Key Inputs'!$A$29:$A$114,$AB8,'Key Inputs'!$B$29:$B$114,$AC8,'Key Inputs'!$C$29:$C$114,$AD8)) -> 0.33 | J8: =IF($AE8="","",SUMIFS('Key Inputs'!$I$29:$I$114,'Key Inputs'!$A$29:$A$114,$AB8,'Key Inputs'!$B$29:$B$114,$AC8,'Key Inputs'!$C$29:$C$114,$AD8)/8760) -> 0.11415525 | K8: =IF($AE8="","",SUMIFS('Key Inputs'!$H$29:$H$114,'Key Inputs'!$A$29:$A$114,$AB8,'Key Inputs'!$B$29:$B$114,$AC8,'Key Inputs'!$C$29:$C$114,$AD8)) -> 20 | L8: =IF($AE8="","",31.536) -> 31.536 | R8: =IF($AE8="","*"&AB9&" "&AC9,"PRE") -> PRE | S8: =IF($AE8="","",_xlfn.TEXTJOIN(",",TRUE,IF(LEFT(Regions!$C$3,1)<>"*",Regions!$C$3,""),IF(LEFT(Regions!$D$3,1)<>"*",Regions!$D$3,""))) -> IE,National | T8: =IF($AE8="","",CONCATENATE(LEFT(Legend!$C$4),"-",$AH8,"-",$AG8,"_",$AE8,"_X0")) -> S-SH-CS_LPG_X0 | U8: =IF($AE8="","",CONCATENATE(AB8," - ",AC8,": ",AD8)) -> Commercial Services - Space heating: LPG | V8: =IF($AE8="","","PJ") -> PJ | W8: =IF($AE8="","","GW") -> GW | X8: =IF($AE8="","","ANNUAL") -> ANNUAL | AB8: =IF('Key Inputs'!A30="","",'Key Inputs'!A30) -> Commercial Services | AC8: =IF('Key Inputs'!B30="","",'Key Inputs'!B30) -> Space heating | AD8: =IF('Key Inputs'!C30="","",'Key Inputs'!C30) -> LPG | AE8: =IF('Key Inputs'!D30="","",'Key Inputs'!D30) -> LPG | AF8: =IF('Key Inputs'!E30="","",'Key Inputs'!E30) -> SRVLPG | AG8: =_xlfn.XLOOKUP(AB8,Legend!$A$21:$A$22,Legend!$C$21:$C$22) -> CS | AH8: =_xlfn.XLOOKUP(AC8,Legend!$A$24:$A$34,Legend!$C$24:$C$34) -> SH | AI8: =IF($AE8="","",AJ8/I8) -> 0 | AJ8: =IF($AE8="","",H8*J8*L8) -> 0
B9: =IF($AE9="",Q9,S9) -> IE,National | C9: =IF($AE9="",R9,T9) -> S-SH-CS_OIL_X0 | D9: =IF($AE9="","",U9) -> Commercial Services - Space heating: Oil | E9: =IF($AE9="","",AF9) -> SRVOIL | G9: =IF($AE9="","",CONCATENATE(Legend!$C$4,AH9,"-",AG9)) -> SRVSH-CS | H9: =IF($AE9="","",SUMIFS('Key Inputs'!$K$29:$K$114,'Key Inputs'!$A$29:$A$114,$AB9,'Key Inputs'!$B$29:$B$114,$AC9,'Key Inputs'!$C$29:$C$114,$AD9)) -> 0.40017313 | I9: =IF($AE9="","",SUMIFS('Key Inputs'!$G$29:$G$114,'Key Inputs'!$A$29:$A$114,$AB9,'Key Inputs'!$B$29:$B$114,$AC9,'Key Inputs'!$C$29:$C$114,$AD9)) -> 0.65835584 | J9: =IF($AE9="","",SUMIFS('Key Inputs'!$I$29:$I$114,'Key Inputs'!$A$29:$A$114,$AB9,'Key Inputs'!$B$29:$B$114,$AC9,'Key Inputs'!$C$29:$C$114,$AD9)/8760)*1.02 -> 0.11643836 | K9: =IF($AE9="","",SUMIFS('Key Inputs'!$H$29:$H$114,'Key Inputs'!$A$29:$A$114,$AB9,'Key Inputs'!$B$29:$B$114,$AC9,'Key Inputs'!$C$29:$C$114,$AD9)) -> 20 | L9: =IF($AE9="","",31.536) -> 31.536 | R9: =IF($AE9="","*"&#REF!&" "&#REF!,"PRE") -> PRE | S9: =IF($AE9="","",_xlfn.TEXTJOIN(",",TRUE,IF(LEFT(Regions!$C$3,1)<>"*",Regions!$C$3,""),IF(LEFT(Regions!$D$3,1)<>"*",Regions!$D$3,""))) -> IE,National | T9: =IF($AE9="","",CONCATENATE(LEFT(Legend!$C$4),"-",$AH9,"-",$AG9,"_",$AE9,"_X0")) -> S-SH-CS_OIL_X0 | U9: =IF($AE9="","",CONCATENATE(AB9," - ",AC9,": ",AD9)) -> Commercial Services - Space heating: Oil | V9: =IF($AE9="","","PJ") -> PJ | W9: =IF($AE9="","","GW") -> GW | X9: =IF($AE9="","","ANNUAL") -> ANNUAL | AB9: =IF('Key Inputs'!A31="","",'Key Inputs'!A31) -> Commercial Services | AC9: =IF('Key Inputs'!B31="","",'Key Inputs'!B31) -> Space heating | AD9: =IF('Key Inputs'!C31="","",'Key Inputs'!C31) -> Oil | AE9: =IF('Key Inputs'!D31="","",'Key Inputs'!D31) -> OIL | AF9: =IF('Key Inputs'!E31="","",'Key Inputs'!E31) -> SRVOIL | AG9: =_xlfn.XLOOKUP(AB9,Legend!$A$21:$A$22,Legend!$C$21:$C$22) -> CS | AH9: =_xlfn.XLOOKUP(AC9,Legend!$A$24:$A$34,Legend!$C$24:$C$34) -> SH | AI9: =IF($AE9="","",AJ9/I9) -> 2.231978 | AJ9: =IF($AE9="","",H9*J9*L9) -> 1.4694357
B10: =IF($AE10="",Q10,S10) -> IE,National | C10: =IF($AE10="",R10,T10) -> S-SH-CS_GAS_X0 | D10: =IF($AE10="","",U10) -> Commercial Services - Space heating: Natural Gas | E10: =IF($AE10="","",AF10) -> SRVGAS, SRVBGS | G10: =IF($AE10="","",CONCATENATE(Legend!$C$4,AH10,"-",AG10)) -> SRVSH-CS | H10: =IF($AE10="","",SUMIFS('Key Inputs'!$K$29:$K$114,'Key Inputs'!$A$29:$A$114,$AB10,'Key Inputs'!$B$29:$B$114,$AC10,'Key Inputs'!$C$29:$C$114,$AD10)) -> 1.1383418 | I10: =IF($AE10="","",SUMIFS('Key Inputs'!$G$29:$G$114,'Key Inputs'!$A$29:$A$114,$AB10,'Key Inputs'!$B$29:$B$114,$AC10,'Key Inputs'!$C$29:$C$114,$AD10)) -> 0.77299617 | J10: =IF($AE10="","",SUMIFS('Key Inputs'!$I$29:$I$114,'Key Inputs'!$A$29:$A$114,$AB10,'Key Inputs'!$B$29:$B$114,$AC10,'Key Inputs'!$C$29:$C$114,$AD10)/8760) -> 0.11415525 | K10: =IF($AE10="","",SUMIFS('Key Inputs'!$H$29:$H$114,'Key Inputs'!$A$29:$A$114,$AB10,'Key Inputs'!$B$29:$B$114,$AC10,'Key Inputs'!$C$29:$C$114,$AD10)) -> 20 | L10: =IF($AE10="","",31.536) -> 31.536 | N10: =EB_SRV!$G$30/'Key Inputs'!$F$32 -> 0.0063529148 | O10: =N10 -> 0.0063529148 | P10: 5 | R10: =IF($AE10="","*"&AB11&" "&AC11,"PRE") -> PRE | S10: =IF($AE10="","",_xlfn.TEXTJOIN(",",TRUE,IF(LEFT(Regions!$C$3,1)<>"*",Regions!$C$3,""),IF(LEFT(Regions!$D$3,1)<>"*",Regions!$D$3,""))) -> IE,National | T10: =IF($AE10="","",CONCATENATE(LEFT(Legend!$C$4),"-",$AH10,"-",$AG10,"_",$AE10,"_X0")) -> S-SH-CS_GAS_X0 | U10: =IF($AE10="","",CONCATENATE(AB10," - ",AC10,": ",AD10)) -> Commercial Services - Space heating: Natural Gas | V10: =IF($AE10="","","PJ") -> PJ | W10: =IF($AE10="","","GW") -> GW | X10: =IF($AE10="","","ANNUAL") -> ANNUAL | AB10: =IF('Key Inputs'!A32="","",'Key Inputs'!A32) -> Commercial Services | AC10: =IF('Key Inputs'!B32="","",'Key Inputs'!B32) -> Space heating | AD10: =IF('Key Inputs'!C32="","",'Key Inputs'!C32) -> Natural Gas | AE10: =IF('Key Inputs'!D32="","",'Key Inputs'!D32) -> GAS | AF10: =IF('Key Inputs'!E32="","",'Key Inputs'!E32) -> SRVGAS, SRVBGS | AG10: =_xlfn.XLOOKUP(AB10,Legend!$A$21:$A$22,Legend!$C$21:$C$22) -> CS | AH10: =_xlfn.XLOOKUP(AC10,Legend!$A$24:$A$34,Legend!$C$24:$C$34) -> SH | AI10: =IF($AE10="","",AJ10/I10) -> 5.3014888 | AJ10: =IF($AE10="","",H10*J10*L10) -> 4.0980305
B11: =IF($AE11="",Q11,S11) -> IE,National | C11: =IF($AE11="",R11,T11) -> S-SH-CS_BIO_X0 | D11: =IF($AE11="","",U11) -> Commercial Services - Space heating: Biomass | E11: =IF($AE11="","",AF11) -> SRVBIO | G11: =IF($AE11="","",CONCATENATE(Legend!$C$4,AH11,"-",AG11)) -> SRVSH-CS | H11: =IF($AE11="","",SUMIFS('Key Inputs'!$K$29:$K$114,'Key Inputs'!$A$29:$A$114,$AB11,'Key Inputs'!$B$29:$B$114,$AC11,'Key Inputs'!$C$29:$C$114,$AD11)) -> 0.052645404 | I11: =IF($AE11="","",SUMIFS('Key Inputs'!$G$29:$G$114,'Key Inputs'!$A$29:$A$114,$AB11,'Key Inputs'!$B$29:$B$114,$AC11,'Key Inputs'!$C$29:$C$114,$AD11)) -> 0.63490443 | J11: =IF($AE11="","",SUMIFS('Key Inputs'!$I$29:$I$114,'Key Inputs'!$A$29:$A$114,$AB11,'Key Inputs'!$B$29:$B$114,$AC11,'Key Inputs'!$C$29:$C$114,$AD11)/8760) -> 0.11415525 | K11: =IF($AE11="","",SUMIFS('Key Inputs'!$H$29:$H$114,'Key Inputs'!$A$29:$A$114,$AB11,'Key Inputs'!$B$29:$B$114,$AC11,'Key Inputs'!$C$29:$C$114,$AD11)) -> 20 | L11: =IF($AE11="","",31.536) -> 31.536 | R11: =IF($AE11="","*"&AB12&" "&AC12,"PRE") -> PRE | S11: =IF($AE11="","",_xlfn.TEXTJOIN(",",TRUE,IF(LEFT(Regions!$C$3,1)<>"*",Regions!$C$3,""),IF(LEFT(Regions!$D$3,1)<>"*",Regions!$D$3,""))) -> IE,National | T11: =IF($AE11="","",CONCATENATE(LEFT(Legend!$C$4),"-",$AH11,"-",$AG11,"_",$AE11,"_X0")) -> S-SH-CS_BIO_X0 | U11: =IF($AE11="","",CONCATENATE(AB11," - ",AC11,": ",AD11)) -> Commercial Services - Space heating: Biomass | V11: =IF($AE11="","","PJ") -> PJ | W11: =IF($AE11="","","GW") -> GW | X11: =IF($AE11="","","ANNUAL") -> ANNUAL | AB11: =IF('Key Inputs'!A33="","",'Key Inputs'!A33) -> Commercial Services | AC11: =IF('Key Inputs'!B33="","",'Key Inputs'!B33) -> Space heating | AD11: =IF('Key Inputs'!C33="","",'Key Inputs'!C33) -> Biomass | AE11: =IF('Key Inputs'!D33="","",'Key Inputs'!D33) -> BIO | AF11: =IF('Key Inputs'!E33="","",'Key Inputs'!E33) -> SRVBIO | AG11: =_xlfn.XLOOKUP(AB11,Legend!$A$21:$A$22,Legend!$C$21:$C$22) -> CS | AH11: =_xlfn.XLOOKUP(AC11,Legend!$A$24:$A$34,Legend!$C$24:$C$34) -> SH | AI11: =IF($AE11="","",AJ11/I11) -> 0.29850706 | AJ11: =IF($AE11="","",H11*J11*L11) -> 0.18952346
B12: =IF($AE12="",Q12,S12) -> IE,National | C12: =IF($AE12="",R12,T12) -> S-SH-CS_SOL_X0 | D12: =IF($AE12="","",U12) -> Commercial Services - Space heating: Solar | E12: =IF($AE12="","",AF12) -> SRVSOL | G12: =IF($AE12="","",CONCATENATE(Legend!$C$4,AH12,"-",AG12)) -> SRVSH-CS | H12: =IF($AE12="","",SUMIFS('Key Inputs'!$K$29:$K$114,'Key Inputs'!$A$29:$A$114,$AB12,'Key Inputs'!$B$29:$B$114,$AC12,'Key Inputs'!$C$29:$C$114,$AD12)) -> 0 | I12: =IF($AE12="","",SUMIFS('Key Inputs'!$G$29:$G$114,'Key Inputs'!$A$29:$A$114,$AB12,'Key Inputs'!$B$29:$B$114,$AC12,'Key Inputs'!$C$29:$C$114,$AD12)) -> 0.33 | J12: =IF($AE12="","",SUMIFS('Key Inputs'!$I$29:$I$114,'Key Inputs'!$A$29:$A$114,$AB12,'Key Inputs'!$B$29:$B$114,$AC12,'Key Inputs'!$C$29:$C$114,$AD12)/8760) -> 0.11415525 | K12: =IF($AE12="","",SUMIFS('Key Inputs'!$H$29:$H$114,'Key Inputs'!$A$29:$A$114,$AB12,'Key Inputs'!$B$29:$B$114,$AC12,'Key Inputs'!$C$29:$C$114,$AD12)) -> 15 | L12: =IF($AE12="","",31.536) -> 31.536 | R12: =IF($AE12="","*"&AB13&" "&AC13,"PRE") -> PRE | S12: =IF($AE12="","",_xlfn.TEXTJOIN(",",TRUE,IF(LEFT(Regions!$C$3,1)<>"*",Regions!$C$3,""),IF(LEFT(Regions!$D$3,1)<>"*",Regions!$D$3,""))) -> IE,National | T12: =IF($AE12="","",CONCATENATE(LEFT(Legend!$C$4),"-",$AH12,"-",$AG12,"_",$AE12,"_X0")) -> S-SH-CS_SOL_X0 | U12: =IF($AE12="","",CONCATENATE(AB12," - ",AC12,": ",AD12)) -> Commercial Services - Space heating: Solar | V12: =IF($AE12="","","PJ") -> PJ | W12: =IF($AE12="","","GW") -> GW | X12: =IF($AE12="","","ANNUAL") -> ANNUAL | AB12: =IF('Key Inputs'!A34="","",'Key Inputs'!A34) -> Commercial Services | AC12: =IF('Key Inputs'!B34="","",'Key Inputs'!B34) -> Space heating | AD12: =IF('Key Inputs'!C34="","",'Key Inputs'!C34) -> Solar | AE12: =IF('Key Inputs'!D34="","",'Key Inputs'!D34) -> SOL | AF12: =IF('Key Inputs'!E34="","",'Key Inputs'!E34) -> SRVSOL | AG12: =_xlfn.XLOOKUP(AB12,Legend!$A$21:$A$22,Legend!$C$21:$C$22) -> CS | AH12: =_xlfn.XLOOKUP(AC12,Legend!$A$24:$A$34,Legend!$C$24:$C$34) -> SH | AI12: =IF($AE12="","",AJ12/I12) -> 0 | AJ12: =IF($AE12="","",H12*J12*L12) -> 0
B13: =IF($AE13="",Q13,S13) -> IE,National | C13: =IF($AE13="",R13,T13) -> S-SH-CS_ELC-HP_X0 | D13: =IF($AE13="","",U13) -> Commercial Services - Space heating: Electricity (heat pumps) | E13: =IF($AE13="","",AF13) -> SRVELC,SRVAHT | G13: =IF($AE13="","",CONCATENATE(Legend!$C$4,AH13,"-",AG13)) -> SRVSH-CS | H13: =IF($AE13="","",SUMIFS('Key Inputs'!$K$29:$K$114,'Key Inputs'!$A$29:$A$114,$AB13,'Key Inputs'!$B$29:$B$114,$AC13,'Key Inputs'!$C$29:$C$114,$AD13)) -> 0.36416699 | I13: =IF($AE13="","",SUMIFS('Key Inputs'!$G$29:$G$114,'Key Inputs'!$A$29:$A$114,$AB13,'Key Inputs'!$B$29:$B$114,$AC13,'Key Inputs'!$C$29:$C$114,$AD13)) -> 2.1 | J13: =IF($AE13="","",SUMIFS('Key Inputs'!$I$29:$I$114,'Key Inputs'!$A$29:$A$114,$AB13,'Key Inputs'!$B$29:$B$114,$AC13,'Key Inputs'!$C$29:$C$114,$AD13)/8760) -> 0.11415525 | K13: =IF($AE13="","",SUMIFS('Key Inputs'!$H$29:$H$114,'Key Inputs'!$A$29:$A$114,$AB13,'Key Inputs'!$B$29:$B$114,$AC13,'Key Inputs'!$C$29:$C$114,$AD13)) -> 10 | L13: =IF($AE13="","",31.536) -> 31.536 | M13: ='Key Inputs'!L35/'Key Inputs'!J35 -> 0.49987511 | R13: =IF($AE13="","*"&AB14&" "&AC14,"PRE") -> PRE | S13: =IF($AE13="","",_xlfn.TEXTJOIN(",",TRUE,IF(LEFT(Regions!$C$3,1)<>"*",Regions!$C$3,""),IF(LEFT(Regions!$D$3,1)<>"*",Regions!$D$3,""))) -> IE,National | T13: =IF($AE13="","",CONCATENATE(LEFT(Legend!$C$4),"-",$AH13,"-",$AG13,"_",$AE13,"_X0")) -> S-SH-CS_ELC-HP_X0 | U13: =IF($AE13="","",CONCATENATE(AB13," - ",AC13,": ",AD13)) -> Commercial Services - Space heating: Electricity (heat pumps) | V13: =IF($AE13="","","PJ") -> PJ | W13: =IF($AE13="","","GW") -> GW | X13: =IF($AE13="","","ANNUAL") -> ANNUAL | AB13: =IF('Key Inputs'!A35="","",'Key Inputs'!A35) -> Commercial Services | AC13: =IF('Key Inputs'!B35="","",'Key Inputs'!B35) -> Space heating | AD13: =IF('Key Inputs'!C35="","",'Key Inputs'!C35) -> Electricity (heat pumps) | AE13: =IF('Key Inputs'!D35="","",'Key Inputs'!D35) -> ELC-HP | AF13: =IF('Key Inputs'!E35="","",'Key Inputs'!E35) -> SRVELC,SRVAHT | AG13: =_xlfn.XLOOKUP(AB13,Legend!$A$21:$A$22,Legend!$C$21:$C$22) -> CS | AH13: =_xlfn.XLOOKUP(AC13,Legend!$A$24:$A$34,Legend!$C$24:$C$34) -> SH | AI13: =IF($AE13="","",AJ13/I13) -> 0.62428626 | AJ13: =IF($AE13="","",H13*J13*L13) -> 1.3110012
B14: =IF($AE14="",Q14,S14) -> IE,National | C14: =IF($AE14="",R14,T14) -> S-SH-CS_ELC_X0 | D14: =IF($AE14="","",U14) -> Commercial Services - Space heating: Electricity (heaters) | E14: =IF($AE14="","",AF14) -> SRVELC | G14: =IF($AE14="","",CONCATENATE(Legend!$C$4,AH14,"-",AG14)) -> SRVSH-CS | H14: =IF($AE14="","",SUMIFS('Key Inputs'!$K$29:$K$114,'Key Inputs'!$A$29:$A$114,$AB14,'Key Inputs'!$B$29:$B$114,$AC14,'Key Inputs'!$C$29:$C$114,$AD14)) -> 0.61162945 | I14: =IF($AE14="","",SUMIFS('Key Inputs'!$G$29:$G$114,'Key Inputs'!$A$29:$A$114,$AB14,'Key Inputs'!$B$29:$B$114,$AC14,'Key Inputs'!$C$29:$C$114,$AD14)) -> 0.81595511 | J14: =IF($AE14="","",SUMIFS('Key Inputs'!$I$29:$I$114,'Key Inputs'!$A$29:$A$114,$AB14,'Key Inputs'!$B$29:$B$114,$AC14,'Key Inputs'!$C$29:$C$114,$AD14)/8760) -> 0.11415525 | K14: =IF($AE14="","",SUMIFS('Key Inputs'!$H$29:$H$114,'Key Inputs'!$A$29:$A$114,$AB14,'Key Inputs'!$B$29:$B$114,$AC14,'Key Inputs'!$C$29:$C$114,$AD14)) -> 10 | L14: =IF($AE14="","",31.536) -> 31.536 | R14: =IF($AE14="","*"&AB15&" "&AC15,"PRE") -> PRE | S14: =IF($AE14="","",_xlfn.TEXTJOIN(",",TRUE,IF(LEFT(Regions!$C$3,1)<>"*",Regions!$C$3,""),IF(LEFT(Regions!$D$3,1)<>"*",Regions!$D$3,""))) -> IE,National | T14: =IF($AE14="","",CONCATENATE(LEFT(Legend!$C$4),"-",$AH14,"-",$AG14,"_",$AE14,"_X0")) -> S-SH-CS_ELC_X0 | U14: =IF($AE14="","",CONCATENATE(AB14," - ",AC14,": ",AD14)) -> Commercial Services - Space heating: Electricity (heaters) | V14: =IF($AE14="","","PJ") -> PJ | W14: =IF($AE14="","","GW") -> GW | X14: =IF($AE14="","","ANNUAL") -> ANNUAL | AB14: =IF('Key Inputs'!A36="","",'Key Inputs'!A36) -> Commercial Services | AC14: =IF('Key Inputs'!B36="","",'Key Inputs'!B36) -> Space heating | AD14: =IF('Key Inputs'!C36="","",'Key Inputs'!C36) -> Electricity (heaters) | AE14: =IF('Key Inputs'!D36="","",'Key Inputs'!D36) -> ELC | AF14: =IF('Key Inputs'!E36="","",'Key Inputs'!E36) -> SRVELC | AG14: =_xlfn.XLOOKUP(AB14,Legend!$A$21:$A$22,Legend!$C$21:$C$22) -> CS | AH14: =_xlfn.XLOOKUP(AC14,Legend!$A$24:$A$34,Legend!$C$24:$C$34) -> SH | AI14: =IF($AE14="","",AJ14/I14) -> 2.6985137 | AJ14: =IF($AE14="","",H14*J14*L14) -> 2.201866
B15: =IF($AE15="",R15,T15) -> *Commercial Services Water heating | R15: =IF($AE15="","*"&AB16&" "&AC16,"PRE") -> *Commercial Services Water heating
