Workbook
Name FID_1: [1]AGR_Fuels!$A$2

Sheet Cover
A16: TIMES-Ireland Model
A19: Document type: | B19: New Technologies - Transformation
A20: Sector(s): | B20: Residential sector (RSD)
A21: Purpose: | B21: Assigns new technology data (AF and EFF), relative to base year data.
A23: Original developer(s): | B23: Jason Mc Guire ( MaREI, jason.mcguire@ucc.ie)
B24: Alessandro Chiodi ( E4SMA, alessandro.chiodi@e4sma.com)
B25: Olexandr Balyk ( MaREI, olexandr.balyk@ucc.ie)
A26: Current maintainer(s): | B26: Jason Mc Guire ( MaREI, jason.mcguire@ucc.ie)
B27: Olexandr Balyk ( MaREI, olexandr.balyk@ucc.ie)
A29: Part of TIM version: | B29: 1
A30: Model repository: | B30: https://github.com/MaREI-EPMG/TIMES-Ireland-model
A31: Licence: | B31: CC BY-NC-SA 4.0 (unless specified otherwise)
B32: https://creativecommons.org/licenses/by-nc-sa/4.0/

Sheet LOG
A3: Date | B3: Name | C3: Sheet Name | D3: Cells | E3: Comments
A4: 44237 | B4: Ale | C4: AF,EFF | E4: Corrected issues and enabled
A5: 44232 | B5: Olex | C5: AF | D5: =ADDRESS(ROW(AF!A3),COLUMN(AF!A3),4,1)&","&ADDRESS(ROW(AF!J3),COLUMN(AF!J3),4,1)&","&ADDRESS(ROW(AF!J17),COLUMN(AF!J17),4,1) -> A3,J3,J17 | E5: Disabled these tables, because commodity group is not specified

Sheet Regions
C3: {=INDEX(C5:C7,$A$4)} -> IE | D3: {=INDEX(D5:D7,$A$4)} -> National | E3: {=INDEX(E5:E7,$A$4)} -> IE-CW | F3: {=INDEX(F5:F7,$A$4)} -> IE-D | G3: {=INDEX(G5:G7,$A$4)} -> IE-KE | H3: {=INDEX(H5:H7,$A$4)} -> IE-KK | I3: {=INDEX(I5:I7,$A$4)} -> IE-LS | J3: {=INDEX(J5:J7,$A$4)} -> IE-LD | ... AD3: {=INDEX(AD5:AD7,$A$4)} -> IE-MN
A4: 1
A5: Development | C5: IE | D5: National | E5: =Regions!A11 -> IE-CW | F5: =Regions!A16 -> IE-D | G5: =Regions!A19 -> IE-KE | H5: =Regions!A20 -> IE-KK | I5: =Regions!A21 -> IE-LS | J5: =Regions!A24 -> IE-LD | K5: =Regions!A25 -> IE-LH | L5: =Regions!A27 -> IE-MH | M5: =Regions!A29 -> IE-OY | N5: =Regions!A34 -> IE-WH | O5: =Regions!A35 -> IE-WX | P5: =Regions!A36 -> IE-WW | Q5: =Regions!A13 -> IE-CE | R5: =Regions!A14 -> IE-CO | S5: =Regions!A18 -> IE-KY | T5: =Regions!A23 -> IE-LK | U5: =Regions!A32 -> IE-TA | V5: =Regions!A33 -> IE-WD | W5: =Regions!A17 -> IE-G | X5: =Regions!A22 -> IE-LM | Y5: =Regions!A26 -> IE-MO | Z5: =Regions!A30 -> IE-RN | AA5: =Regions!A31 -> IE-SO | AB5: =Regions!A12 -> IE-CN | AC5: =Regions!A15 -> IE-DL | AD5: =Regions!A28 -> IE-MN
A6: Single-region | C6: =C5 -> IE | D6: ="*"&D5 -> *National | E6: ="*"&E5 -> *IE-CW | F6: ="*"&F5 -> *IE-D | G6: ="*"&G5 -> *IE-KE | H6: ="*"&H5 -> *IE-KK | I6: ="*"&I5 -> *IE-LS | J6: ="*"&J5 -> *IE-LD | K6: ="*"&K5 -> *IE-LH | ... AD6: ="*"&AD5 -> *IE-MN
A7: Multi-region | C7: ="*"&C5 -> *IE | D7: =D5 -> National | E7: =E5 -> IE-CW | F7: =F5 -> IE-D | G7: =G5 -> IE-KE | H7: =H5 -> IE-KK | I7: =I5 -> IE-LS | J7: =J5 -> IE-LD | K7: =K5 -> IE-LH | ... AD7: =AD5 -> IE-MN
A10: Code | B10: County name
A11: IE-CW | B11: Carlow
A12: IE-CN | B12: Cavan
A13: IE-CE | B13: Clare
A14: IE-CO | B14: Cork
A15: IE-DL | B15: Donegal
A16: IE-D | B16: Dublin
A17: IE-G | B17: Galway
A18: IE-KY | B18: Kerry
A19: IE-KE | B19: Kildare
A20: IE-KK | B20: Kilkenny
A21: IE-LS | B21: Laois
... A36: IE-WW | B36: Wicklow
A37: Source: https://en.wikipedia.org/wiki/ISO_3166-2:IE

Sheet TechSelection
B3: ~TFM_AVA
B4: PSET_SET | C4: PSET_PN | D4: PSET_PD | E4: PSET_CO | F4: PSET_CI | G4: Allregions | H4: =Regions!C3 -> IE | I4: =Regions!D3 -> National
C5: * | G5: 0 | H5: 1 | I5: 1

Sheet FillTable
B1: Fill Table to capture Base-Year Availability | L1: Fill Table to capture Base-Year Availability | V1: Update Table to capture Base-Year Efficiency
B3: ~TFM_Fill-R: w=BY-RSD-SH_AF; Hcol=Region | L3: ~TFM_Fill-R: w=BY-RSD-RF; Hcol=Region | V3: ~TFM_Fill-R: w=BY-RSD-EFF; Hcol=Region
B4: Scenario | C4: LimType | D4: Attribute | E4: Year | F4: AllRegions | G4: Pset_CI | H4: Pset_PN | I4: Pset_CO | J4: Cset_CN | L4: Scenario | M4: LimType | N4: Attribute | O4: Year | P4: AllRegions | Q4: Pset_CI | R4: Pset_PN | S4: Pset_CO | T4: Cset_CN | V4: Scenario | W4: LimType | X4: Attribute | Y4: Year | Z4: AllRegions | AA4: Pset_CI | AB4: Pset_PN | AC4: Pset_CO | AD4: Cset_CN
B5: BASE | D5: AFA | E5: 2018 | F5: 1 | H5: R-S* | L5: BASE | N5: AFA | O5: 2018 | P5: 1 | R5: R-RSDRF* | V5: BASE | X5: EFF | Y5: 2018 | Z5: 1 | AB5: R-SH*
V6: BASE | X6: EFF | Y6: 2018 | Z6: 1 | AB6: R-WH*
B8: ~TFM_Fill-R: w=BY-RSD-WH_AF; Hcol=Region | L8: ~TFM_Fill-R: w=BY-RSD-CK; Hcol=Region
B9: Scenario | C9: LimType | D9: Attribute | E9: Year | F9: AllRegions | G9: Pset_CI | H9: Pset_PN | I9: Pset_CO | J9: Cset_CN | L9: Scenario | M9: LimType | N9: Attribute | O9: Year | P9: AllRegions | Q9: Pset_CI | R9: Pset_PN | S9: Pset_CO | T9: Cset_CN
B10: BASE | D10: AFA | E10: 2018 | F10: 1 | H10: R-WH* | L10: BASE | N10: AFA | O10: 2018 | P10: 1 | R10: R-RSDCK*
B13: **~TFM_Fill-R: w=BY-RSD-SC_AF; Hcol=Region | L13: ~TFM_Fill-R: w=BY-RSD-CW; Hcol=Region
B14: Scenario | C14: LimType | D14: Attribute | E14: Year | F14: AllRegions | G14: Pset_CI | H14: Pset_PN | I14: Pset_CO | J14: Cset_CN | L14: Scenario | M14: LimType | N14: Attribute | O14: Year | P14: AllRegions | Q14: Pset_CI | R14: Pset_PN | S14: Pset_CO | T14: Cset_CN
B15: BASE | D15: AFA | E15: 2018 | F15: 1 | H15: R-?C* | L15: BASE | N15: AFA | O15: 2018 | P15: 1 | R15: R-RSDCW*
B18: ~TFM_Fill-R: w=BY-RSD-LT; Hcol=Region | L18: ~TFM_Fill-R: w=BY-RSD-CD; Hcol=Region
B19: Scenario | C19: LimType | D19: Attribute | E19: Year | F19: AllRegions | G19: Pset_CI | H19: Pset_PN | I19: Pset_CO | J19: Cset_CN | L19: Scenario | M19: LimType | N19: Attribute | O19: Year | P19: AllRegions | Q19: Pset_CI | R19: Pset_PN | S19: Pset_CO | T19: Cset_CN
B20: BASE | D20: AFA | E20: 2018 | F20: 1 | H20: R-LT* | L20: BASE | N20: AFA | O20: 2018 | P20: 1 | R20: R-RSDCD*
B23: ~TFM_Fill-R: w=BY-RSD-PF; Hcol=Region | L23: ~TFM_Fill-R: w=BY-RSD-DW; Hcol=Region
B24: Scenario | C24: LimType | D24: Attribute | E24: Year | F24: AllRegions | G24: Pset_CI | H24: Pset_PN | I24: Pset_CO | J24: Cset_CN | L24: Scenario | M24: LimType | N24: Attribute | O24: Year | P24: AllRegions | Q24: Pset_CI | R24: Pset_PN | S24: Pset_CO | T24: Cset_CN
B25: BASE | D25: AFA | E25: 2018 | F25: 1 | H25: R-PF* | L25: BASE | N25: AFA | O25: 2018 | P25: 1 | R25: R-RSDDW*
L28: ~TFM_Fill-R: w=BY-RSD-OE; Hcol=Region
L29: Scenario | M29: LimType | N29: Attribute | O29: Year | P29: AllRegions | Q29: Pset_CI | R29: Pset_PN | S29: Pset_CO | T29: Cset_CN
L30: BASE | N30: AFA | O30: 2018 | P30: 1 | R30: R-RSDOE*
L33: **~TFM_Fill-R: w=BY-RSD-OA; Hcol=Region
L34: Scenario | M34: LimType | N34: Attribute | O34: Year | P34: AllRegions | Q34: Pset_CI | R34: Pset_PN | S34: Pset_CO | T34: Cset_CN
L35: BASE | N35: AFA | O35: 2018 | P35: 1 | R35: R-RSDOA*

Sheet AF
A1: AFA for RSD techs
A3: ~TFM_INS | J3: ~TFM_INS
A4: Attribute | B4: PSet_PN | C4: Cset_CN | D4: AllRegions | F4: Type | G4: Fuel | H4: Reference Tech | J4: Attribute | K4: PSet_PN | L4: AllRegions
A5: *Apartment Space Heat | J5: *Appliances
A6: * | B6: ="R-SH*"&F6&"_"&G6&"*" -> R-SH*Apt_COA* | D6: =AVERAGEIFS('BY-RSD-SH_AF'!$L$2:$L$100,'BY-RSD-SH_AF'!$C$2:$C$100,B6,'BY-RSD-SH_AF'!$A$2:$A$100,"BASE") -> 0.12 | F6: Apt | G6: COA | H6: ="R-S*_"&F6&"_"&G6&"*" -> R-S*_Apt_COA* | J6: AFA | K6: =FillTable!R5 -> R-RSDRF* | L6: =AVERAGEIFS('BY-RSD-RF'!$L$2:$L$100,'BY-RSD-RF'!$C$2:$C$100,AF!K6,'BY-RSD-RF'!$A$2:$A$100,"BASE") -> 0.11719939
A7: * | B7: ="R-SH*"&F7&"_"&G7&"*" -> R-SH*Apt_BDL* | D7: =AVERAGEIFS('BY-RSD-SH_AF'!$L$2:$L$100,'BY-RSD-SH_AF'!$C$2:$C$100,B7,'BY-RSD-SH_AF'!$A$2:$A$100,"BASE") -> 0.12 | F7: Apt | G7: BDL | H7: ="R-S*_"&F7&"_"&G7&"*" -> R-S*_Apt_BDL* | J7: AFA | K7: =FillTable!R10&"ELC*" -> R-RSDCK*ELC* | L7: =AVERAGEIFS('BY-RSD-CK'!$L$2:$L$100,'BY-RSD-CK'!$C$2:$C$100,AF!K7,'BY-RSD-CK'!$A$2:$A$100,"BASE") -> 0.012186512
A8: * | B8: ="R-SH*"&F8&"_"&G8&"*" -> R-SH*Apt_ETH* | D8: =AVERAGEIFS('BY-RSD-SH_AF'!$L$2:$L$100,'BY-RSD-SH_AF'!$C$2:$C$100,B8,'BY-RSD-SH_AF'!$A$2:$A$100,"BASE") -> 0.12 | F8: Apt | G8: ETH | H8: ="R-S*_"&F8&"_"&G8&"*" -> R-S*_Apt_ETH* | J8: AFA | K8: =FillTable!R10&"GAS*" -> R-RSDCK*GAS* | L8: =AVERAGEIFS('BY-RSD-CK'!$L$2:$L$100,'BY-RSD-CK'!$C$2:$C$100,AF!K8,'BY-RSD-CK'!$A$2:$A$100,"BASE") -> 0.010445598
A9: NCAP_AFA | B9: ="R-SH*"&F9&"_"&G9&"*" -> R-SH*Apt_LPG* | D9: =AVERAGEIFS('BY-RSD-SH_AF'!$L$2:$L$100,'BY-RSD-SH_AF'!$C$2:$C$100,B9,'BY-RSD-SH_AF'!$A$2:$A$100,"BASE") -> 0.12 | F9: Apt | G9: LPG | H9: ="R-S*_"&F9&"_"&G9&"*" -> R-S*_Apt_LPG* | J9: AFA | K9: =FillTable!R10&"LPG*" -> R-RSDCK*LPG* | L9: =AVERAGEIFS('BY-RSD-CK'!$L$2:$L$100,'BY-RSD-CK'!$C$2:$C$100,AF!K9,'BY-RSD-CK'!$A$2:$A$100,"BASE") -> 0.010445583
A10: NCAP_AFA | B10: ="R-*_"&F10&"*"&"HPN*" -> R-*_Apt*HPN* | D10: =AVERAGEIFS('BY-RSD-SH_AF'!$L$2:$L$100,'BY-RSD-SH_AF'!$C$2:$C$100,H10,'BY-RSD-SH_AF'!$A$2:$A$100,"BASE") -> 0.1813027 | F10: Apt | G10: ELC | H10: ="R-SH*"&F10&"_"&G10&"*X1" -> R-SH*Apt_ELC*X1 | J10: AFA | K10: =FillTable!R15 -> R-RSDCW* | L10: =AVERAGEIFS('BY-RSD-CW'!$L$2:$L$100,'BY-RSD-CW'!$C$2:$C$100,AF!K10,'BY-RSD-RF'!$A$2:$A$100,"BASE") -> 0.0067195932
A11: NCAP_AFA | B11: ="R-S*_"&F11&"_"&G11&"_N1"&",-R-SC*" -> R-S*_Apt_ELC_N1,-R-SC* | D11: =AVERAGEIFS('BY-RSD-SH_AF'!$L$2:$L$100,'BY-RSD-SH_AF'!$C$2:$C$100,H11,'BY-RSD-SH_AF'!$A$2:$A$100,"BASE") -> 0.013931119 | F11: Apt | G11: ELC | H11: ="R-SH*"&F10&"_"&G10&"*X0" -> R-SH*Apt_ELC*X0 | J11: AFA | K11: =FillTable!R20 -> R-RSDCD* | L11: =AVERAGEIFS('BY-RSD-CD'!$L$2:$L$100,'BY-RSD-CD'!$C$2:$C$100,AF!K11,'BY-RSD-CD'!$A$2:$A$100,"BASE") -> 0.011863014
A12: NCAP_AFA | B12: ="R-SH*"&F12&"_"&G12&"*" -> R-SH*Apt_KER* | D12: =AVERAGEIFS('BY-RSD-SH_AF'!$L$2:$L$100,'BY-RSD-SH_AF'!$C$2:$C$100,B12,'BY-RSD-SH_AF'!$A$2:$A$100,"BASE") -> 0.066604255 | F12: Apt | G12: KER | H12: ="R-S*_"&F12&"_"&G12&"*" -> R-S*_Apt_KER* | J12: AFA | K12: =FillTable!R25 -> R-RSDDW* | L12: =AVERAGEIFS('BY-RSD-DW'!$L$2:$L$100,'BY-RSD-DW'!$C$2:$C$100,AF!K12,'BY-RSD-DW'!$A$2:$A$100,"BASE") -> 0.010896638
A13: NCAP_AFA | B13: ="R-SH*"&F13&"_"&G13&"*" -> R-SH*Apt_GAS* | D13: =AVERAGEIFS('BY-RSD-SH_AF'!$L$2:$L$100,'BY-RSD-SH_AF'!$C$2:$C$100,B13,'BY-RSD-SH_AF'!$A$2:$A$100,"BASE") -> 0.025618486 | F13: Apt | G13: GAS | H13: ="R-S*_"&F12&"_"&G13&"*" -> R-S*_Apt_GAS* | J13: AFA | K13: =FillTable!R30 -> R-RSDOE* | L13: =AVERAGEIFS('BY-RSD-OE'!$L$2:$L$100,'BY-RSD-OE'!$C$2:$C$100,AF!K13,'BY-RSD-OE'!$A$2:$A$100,"BASE") -> 0.93569571
A14: * | B14: ="R-SH*"&F14&"_"&G14&"*" -> R-SH*Apt_PEA* | D14: =AVERAGEIFS('BY-RSD-SH_AF'!$L$2:$L$100,'BY-RSD-SH_AF'!$C$2:$C$100,B14,'BY-RSD-SH_AF'!$A$2:$A$100,"BASE") -> 0.16174375 | F14: Apt | G14: PEA | H14: ="R-S*_"&F14&"_"&G14&"*" -> R-S*_Apt_PEA* | J14: * | K14: =FillTable!R35 -> R-RSDOA* | L14: =AVERAGEIFS('BY-RSD-RF'!$L$2:$L$100,'BY-RSD-RF'!$C$2:$C$100,AF!K14,'BY-RSD-RF'!$A$2:$A$100,"BASE") -> #DIV/0!
A15: * | B15: ="R-SH*"&F15&"_"&G15&"*" -> R-SH*Apt_SMF* | D15: =AVERAGEIFS('BY-RSD-SH_AF'!$L$2:$L$100,'BY-RSD-SH_AF'!$C$2:$C$100,B15,'BY-RSD-SH_AF'!$A$2:$A$100,"BASE") -> 0.12 | F15: Apt | G15: SMF | H15: ="R-S*_"&F15&"_"&G15&"*" -> R-S*_Apt_SMF*
A16: NCAP_AFA | B16: ="R-SH*"&F16&"_"&G16&"*" -> R-SH*Apt_WOO* | D16: =AVERAGEIFS('BY-RSD-SH_AF'!$L$2:$L$100,'BY-RSD-SH_AF'!$C$2:$C$100,B16,'BY-RSD-SH_AF'!$A$2:$A$100,"BASE") -> 0.12 | F16: Apt | G16: WOO | H16: ="R-S*_"&F16&"_"&G16&"*" -> R-S*_Apt_WOO*
A17: * | B17: ="R-SH*"&F17&"_"&G17&"*" -> R-SH*Apt_HET* | D17: =AVERAGEIFS('BY-RSD-SH_AF'!$L$2:$L$100,'BY-RSD-SH_AF'!$C$2:$C$100,B17,'BY-RSD-SH_AF'!$A$2:$A$100,"BASE") -> 0.12 | F17: Apt | G17: HET | H17: ="R-S*_"&F17&"_"&G17&"*" -> R-S*_Apt_HET* | J17: ~TFM_INS
A18: *Attached Space Heat | J18: Attribute | K18: PSet_PN | L18: AllRegions
A19: * | B19: ="R-SH*"&F19&"_"&G19&"*" -> R-SH*Att_COA* | D19: =AVERAGEIFS('BY-RSD-SH_AF'!$L$2:$L$100,'BY-RSD-SH_AF'!$C$2:$C$100,H19,'BY-RSD-SH_AF'!$A$2:$A$100,"BASE") -> 0.30984485 | F19: Att | G19: COA | H19: ="R-S*_"&F19&"_"&G19&"*" -> R-S*_Att_COA* | J19: *Appliances
A20: * | B20: ="R-SH*"&F20&"_"&G20&"*" -> R-SH*Att_BDL* | D20: =AVERAGEIFS('BY-RSD-SH_AF'!$L$2:$L$100,'BY-RSD-SH_AF'!$C$2:$C$100,H20,'BY-RSD-SH_AF'!$A$2:$A$100,"BASE") -> 0.12 | F20: Att | G20: BDL | H20: ="R-S*_"&F20&"_"&G20&"*" -> R-S*_Att_BDL* | J20: AFA | K20: R-LT_Apt* | L20: =AVERAGEIFS('BY-RSD-LT'!$L$2:$L$100,'BY-RSD-LT'!$C$2:$C$100,AF!K20,'BY-RSD-LT'!$A$2:$A$100,"BASE") -> 0.21098595
A21: * | B21: ="R-SH*"&F21&"_"&G21&"*" -> R-SH*Att_ETH* | D21: =AVERAGEIFS('BY-RSD-SH_AF'!$L$2:$L$100,'BY-RSD-SH_AF'!$C$2:$C$100,H21,'BY-RSD-SH_AF'!$A$2:$A$100,"BASE") -> 0.12 | F21: Att | G21: ETH | H21: ="R-S*_"&F21&"_"&G21&"*" -> R-S*_Att_ETH* | J21: AFA | K21: R-LT_Att* | L21: =AVERAGEIFS('BY-RSD-LT'!$L$2:$L$100,'BY-RSD-LT'!$C$2:$C$100,AF!K21,'BY-RSD-LT'!$A$2:$A$100,"BASE") -> 0.29847129
A22: NCAP_AFA | B22: ="R-SH*"&F22&"_"&G22&"*" -> R-SH*Att_LPG* | D22: =AVERAGEIFS('BY-RSD-SH_AF'!$L$2:$L$100,'BY-RSD-SH_AF'!$C$2:$C$100,H22,'BY-RSD-SH_AF'!$A$2:$A$100,"BASE") -> 0.048109166 | F22: Att | G22: LPG | H22: ="R-S*_"&F22&"_"&G22&"*" -> R-S*_Att_LPG* | J22: AFA | K22: R-LT_Det* | L22: =AVERAGEIFS('BY-RSD-LT'!$L$2:$L$100,'BY-RSD-LT'!$C$2:$C$100,AF!K22,'BY-RSD-LT'!$A$2:$A$100,"BASE") -> 0.49065562
A23: NCAP_AFA | B23: ="R-*_"&F23&"*"&"HPN*" -> R-*_Att*HPN* | D23: =AVERAGEIFS('BY-RSD-SH_AF'!$L$2:$L$100,'BY-RSD-SH_AF'!$C$2:$C$100,H23,'BY-RSD-SH_AF'!$A$2:$A$100,"BASE") -> 0.11404304 | F23: Att | G23: ELC | H23: ="R-SH*"&F23&"_"&G23&"*X1" -> R-SH*Att_ELC*X1 | J23: AFA | K23: R-PF_Apt* | L23: =AVERAGEIFS('BY-RSD-PF'!$L$2:$L$100,'BY-RSD-PF'!$C$2:$C$100,AF!K23,'BY-RSD-PF'!$A$2:$A$100,"BASE") -> 0.12716586
A24: NCAP_AFA | B24: ="R-S*_"&F24&"_"&G24&"_N1"&",-R-SC*" -> R-S*_Att_ELC_N1,-R-SC* | D24: =AVERAGEIFS('BY-RSD-SH_AF'!$L$2:$L$100,'BY-RSD-SH_AF'!$C$2:$C$100,H24,'BY-RSD-SH_AF'!$A$2:$A$100,"BASE") -> 0.035156391 | F24: Att | G24: ELC | H24: ="R-SH*"&F23&"_"&G23&"*X0" -> R-SH*Att_ELC*X0 | J24: AFA | K24: R-PF_Att* | L24: =AVERAGEIFS('BY-RSD-PF'!$L$2:$L$100,'BY-RSD-PF'!$C$2:$C$100,AF!K24,'BY-RSD-PF'!$A$2:$A$100,"BASE") -> 0.24175609
A25: NCAP_AFA | B25: ="R-SH*"&F25&"_"&G25&"*" -> R-SH*Att_KER* | D25: =AVERAGEIFS('BY-RSD-SH_AF'!$L$2:$L$100,'BY-RSD-SH_AF'!$C$2:$C$100,H25,'BY-RSD-SH_AF'!$A$2:$A$100,"BASE") -> 0.047079298 | F25: Att | G25: KER | H25: ="R-S*_"&F25&"_"&G25&"*" -> R-S*_Att_KER* | J25: AFA | K25: R-PF_Det* | L25: =AVERAGEIFS('BY-RSD-PF'!$L$2:$L$100,'BY-RSD-PF'!$C$2:$C$100,AF!K25,'BY-RSD-PF'!$A$2:$A$100,"BASE") -> 0.29872123
A26: NCAP_AFA | B26: R-SH_Att_HVO* | D26: =D25 -> 0.047079298
A27: NCAP_AFA | B27: ="R-SH*"&F27&"_"&G27&"*" -> R-SH*Att_GAS* | D27: =AVERAGEIFS('BY-RSD-SH_AF'!$L$2:$L$100,'BY-RSD-SH_AF'!$C$2:$C$100,H27,'BY-RSD-SH_AF'!$A$2:$A$100,"BASE") -> 0.035964558 | F27: Att | G27: GAS | H27: ="R-S*_"&F25&"_"&G27&"*" -> R-S*_Att_GAS*
A28: * | B28: ="R-SH*"&F28&"_"&G28&"*" -> R-SH*Att_PEA* | D28: =AVERAGEIFS('BY-RSD-SH_AF'!$L$2:$L$100,'BY-RSD-SH_AF'!$C$2:$C$100,H28,'BY-RSD-SH_AF'!$A$2:$A$100,"BASE") -> 0.072779079 | F28: Att | G28: PEA | H28: ="R-S*_"&F28&"_"&G28&"*" -> R-S*_Att_PEA*
A29: * | B29: ="R-SH*"&F29&"_"&G29&"*" -> R-SH*Att_SMF* | D29: =AVERAGEIFS('BY-RSD-SH_AF'!$L$2:$L$100,'BY-RSD-SH_AF'!$C$2:$C$100,H29,'BY-RSD-SH_AF'!$A$2:$A$100,"BASE") -> 0.072438724 | F29: Att | G29: SMF | H29: ="R-S*_"&F29&"_"&G29&"*" -> R-S*_Att_SMF*
A30: NCAP_AFA | B30: ="R-SH*"&F30&"_"&G30&"*" -> R-SH*Att_WOO* | D30: =AVERAGEIFS('BY-RSD-SH_AF'!$L$2:$L$100,'BY-RSD-SH_AF'!$C$2:$C$100,H30,'BY-RSD-SH_AF'!$A$2:$A$100,"BASE") -> 0.12 | F30: Att | G30: WOO | H30: ="R-S*_"&F30&"_"&G30&"*" -> R-S*_Att_WOO*
A31: NCAP_AFA | B31: R-SH_Att_FPL* | D31: =D30 -> 0.12
A32: * | B32: ="R-SH*"&F32&"_"&G32&"*" -> R-SH*Att_HET* | D32: =AVERAGEIFS('BY-RSD-SH_AF'!$L$2:$L$100,'BY-RSD-SH_AF'!$C$2:$C$100,H32,'BY-RSD-SH_AF'!$A$2:$A$100,"BASE") -> 0.12 | F32: Att | G32: HET | H32: ="R-S*_"&F32&"_"&G32&"*" -> R-S*_Att_HET*
A33: *Detached Space Heat
A34: * | B34: ="R-SH*"&F34&"_"&G34&"*" -> R-SH*Det_COA* | D34: =AVERAGEIFS('BY-RSD-SH_AF'!$L$2:$L$100,'BY-RSD-SH_AF'!$C$2:$C$100,H34,'BY-RSD-SH_AF'!$A$2:$A$100,"BASE") -> 0.46414376 | F34: Det | G34: COA | H34: ="R-S*_"&F34&"_"&G34&"*" -> R-S*_Det_COA*
A35: * | B35: ="R-SH*"&F35&"_"&G35&"*" -> R-SH*Det_BDL* | D35: =AVERAGEIFS('BY-RSD-SH_AF'!$L$2:$L$100,'BY-RSD-SH_AF'!$C$2:$C$100,H35,'BY-RSD-SH_AF'!$A$2:$A$100,"BASE") -> 0.069794672 | F35: Det | G35: BDL | H35: ="R-S*_"&F35&"_"&G35&"*" -> R-S*_Det_BDL*
A36: * | B36: ="R-SH*"&F36&"_"&G36&"*" -> R-SH*Det_ETH* | D36: =AVERAGEIFS('BY-RSD-SH_AF'!$L$2:$L$100,'BY-RSD-SH_AF'!$C$2:$C$100,H36,'BY-RSD-SH_AF'!$A$2:$A$100,"BASE") -> 0.069794672 | F36: Det | G36: ETH | H36: ="R-S*_"&F36&"_"&G36&"*" -> R-S*_Det_ETH*
A37: NCAP_AFA | B37: ="R-SH*"&F37&"_"&G37&"*" -> R-SH*Det_LPG* | D37: =AVERAGEIFS('BY-RSD-SH_AF'!$L$2:$L$100,'BY-RSD-SH_AF'!$C$2:$C$100,H37,'BY-RSD-SH_AF'!$A$2:$A$100,"BASE") -> 0.069794672 | F37: Det | G37: LPG | H37: ="R-S*_"&F37&"_"&G37&"*" -> R-S*_Det_LPG*
A38: NCAP_AFA | B38: ="R-*_"&F38&"*"&"HPN*" -> R-*_Det*HPN* | D38: =AVERAGEIFS('BY-RSD-SH_AF'!$L$2:$L$100,'BY-RSD-SH_AF'!$C$2:$C$100,H38,'BY-RSD-SH_AF'!$A$2:$A$100,"BASE") -> 0.13831907 | F38: Det | G38: ELC | H38: ="R-SH*"&F38&"_"&G38&"*X1" -> R-SH*Det_ELC*X1
A39: NCAP_AFA | B39: ="R-S*_"&F39&"_"&G39&"_N1"&",-R-SC*" -> R-S*_Det_ELC_N1,-R-SC* | D39: =AVERAGEIFS('BY-RSD-SH_AF'!$L$2:$L$100,'BY-RSD-SH_AF'!$C$2:$C$100,H39,'BY-RSD-SH_AF'!$A$2:$A$100,"BASE") -> 0.043843218 | F39: Det | G39: ELC | H39: ="R-SH*"&F38&"_"&G38&"*X0" -> R-SH*Det_ELC*X0
A40: NCAP_AFA | B40: ="R-SH*"&F40&"_"&G40&"*" -> R-SH*Det_KER* | D40: =AVERAGEIFS('BY-RSD-SH_AF'!$L$2:$L$100,'BY-RSD-SH_AF'!$C$2:$C$100,H40,'BY-RSD-SH_AF'!$A$2:$A$100,"BASE") -> 0.053753547 | F40: Det | G40: KER | H40: ="R-S*_"&F40&"_"&G40&"*" -> R-S*_Det_KER*
A41: NCAP_AFA | B41: R-SH_Det_HVO* | D41: =D40 -> 0.053753547
...

Sheet EFF
A1: EFF for RSD techs
E3: ~TFM_UPD
A4: Type | B4: Fuel | C4: Reference Tech | E4: Attribute | F4: PSet_PN | G4: AllRegions
E5: *Apartment Heat
A6: Apt | B6: COA | C6: ="R-SH_"&A6&"_"&B6&"*" -> R-SH_Apt_COA* | E6: CEFF | F6: ="R-S*"&A6&"_"&B6&"*" -> R-S*Apt_COA* | G6: =IFERROR("*"&AVERAGEIFS('BY-RSD-EFF'!$L$2:$L$100,'BY-RSD-EFF'!$C$2:$C$100,EFF!C6,'BY-RSD-EFF'!$A$2:$A$100,"BASE"),"") -> *0.590188034188034
A7: Apt | B7: BDL | C7: ="R-SH_"&A7&"_"&B7&"*" -> R-SH_Apt_BDL* | E7: CEFF | F7: ="R-S*_"&A7&"_"&B7&"*" -> R-S*_Apt_BDL* | G7: *0.8
A8: Apt | B8: ETH | C8: ="R-SH_"&A8&"_"&B8&"*" -> R-SH_Apt_ETH* | E8: CEFF | F8: ="R-S*_"&A8&"_"&B8&"*" -> R-S*_Apt_ETH* | G8: *0.8
A9: Apt | B9: LPG | C9: ="R-SH_"&A9&"_"&B9&"*" -> R-SH_Apt_LPG* | E9: CEFF | F9: ="R-S*_"&A9&"_"&B9&"*" -> R-S*_Apt_LPG* | G9: =IFERROR("*"&AVERAGEIFS('BY-RSD-EFF'!$L$2:$L$100,'BY-RSD-EFF'!$C$2:$C$100,EFF!C9,'BY-RSD-EFF'!$A$2:$A$100,"BASE"),"") -> *0.806779026217228
A10: Apt | B10: ELC | C10: ="R-SH_"&A10&"_"&B10&"*X1" -> R-SH_Apt_ELC*X1 | E10: CEFF | F10: ="R-*_"&A10&"*"&"HPN*"&",-*GAS*" -> R-*_Apt*HPN*,-*GAS* | G10: =IFERROR("*"&AVERAGEIFS('BY-RSD-EFF'!$L$2:$L$100,'BY-RSD-EFF'!$C$2:$C$100,EFF!C10,'BY-RSD-EFF'!$A$2:$A$100,"BASE"),"") -> *3.07019607843137
A11: Apt | B11: KER | C11: ="R-SH_"&A11&"_"&B11&"*" -> R-SH_Apt_KER* | E11: CEFF | F11: ="R-S*_"&A11&"_"&B11&"*" -> R-S*_Apt_KER* | G11: =IFERROR("*"&AVERAGEIFS('BY-RSD-EFF'!$L$2:$L$100,'BY-RSD-EFF'!$C$2:$C$100,EFF!C11,'BY-RSD-EFF'!$A$2:$A$100,"BASE"),"") -> *0.810162162162162
A12: Apt | B12: GAS | C12: ="R-SH_"&A12&"_"&B12&"*" -> R-SH_Apt_GAS* | E12: CEFF | F12: ="R-S*_"&A12&"_"&B12&"*" -> R-S*_Apt_GAS* | G12: =IFERROR("*"&AVERAGEIFS('BY-RSD-EFF'!$L$2:$L$100,'BY-RSD-EFF'!$C$2:$C$100,EFF!C12,'BY-RSD-EFF'!$A$2:$A$100,"BASE"),"") -> *0.810268817204301
A13: Apt | B13: PEA | C13: ="R-SH_"&A13&"_"&B13&"*" -> R-SH_Apt_PEA* | E13: CEFF | F13: ="R-S*_"&A13&"_"&B13&"*" -> R-S*_Apt_PEA* | G13: =IFERROR("*"&AVERAGEIFS('BY-RSD-EFF'!$L$2:$L$100,'BY-RSD-EFF'!$C$2:$C$100,EFF!C13,'BY-RSD-EFF'!$A$2:$A$100,"BASE"),"") -> *0.525
A14: Apt | B14: SMF | C14: ="R-SH_"&A14&"_"&B14&"*" -> R-SH_Apt_SMF* | E14: CEFF | F14: ="R-S*_"&A14&"_"&B14&"*" -> R-S*_Apt_SMF* | G14: =IFERROR("*"&AVERAGEIFS('BY-RSD-EFF'!$L$2:$L$100,'BY-RSD-EFF'!$C$2:$C$100,EFF!C14,'BY-RSD-EFF'!$A$2:$A$100,"BASE"),"") -> *0.581777777777778
A15: Apt | B15: WOO | C15: ="R-SH_"&A15&"_"&B15&"*" -> R-SH_Apt_WOO* | E15: CEFF | F15: ="R-S*_"&A15&"_"&B15&"*" -> R-S*_Apt_WOO* | G15: =IFERROR("*"&AVERAGEIFS('BY-RSD-EFF'!$L$2:$L$100,'BY-RSD-EFF'!$C$2:$C$100,EFF!C15,'BY-RSD-EFF'!$A$2:$A$100,"BASE"),"") -> *0.688045112781955
A16: Apt | B16: HET | C16: ="R-SH_"&A16&"_"&B16&"*" -> R-SH_Apt_HET* | E16: CEFF | F16: ="R-S*_"&A16&"_*"&B16&"*" -> R-S*_Apt_*HET* | G16: *1
A17: Apt | B17: ELC | C17: ="R-SH_"&A17&"_"&B17&"*X0" -> R-SH_Apt_ELC*X0 | E17: CEFF | F17: ="R-S*_"&A17&"_"&B17&"_N1"&",-R-SC*" -> R-S*_Apt_ELC_N1,-R-SC* | G17: =IFERROR("*"&AVERAGEIFS('BY-RSD-EFF'!$L$2:$L$100,'BY-RSD-EFF'!$C$2:$C$100,EFF!C17,'BY-RSD-EFF'!$A$2:$A$100,"BASE"),"") -> *1
E18: *Attached Space Heat
A19: Att | B19: COA | C19: ="R-SH_"&A19&"_"&B19&"*" -> R-SH_Att_COA* | E19: CEFF | F19: ="R-S*_"&A19&"_"&B19&"*" -> R-S*_Att_COA* | G19: =IFERROR("*"&AVERAGEIFS('BY-RSD-EFF'!$L$2:$L$100,'BY-RSD-EFF'!$C$2:$C$100,EFF!C19,'BY-RSD-EFF'!$A$2:$A$100,"BASE"),"") -> *0.557980879057327
A20: Att | B20: BDL | C20: ="R-SH_"&A20&"_"&B20&"*" -> R-SH_Att_BDL* | E20: CEFF | F20: ="R-S*_"&A20&"_"&B20&"*" -> R-S*_Att_BDL* | G20: *0.8
A21: Att | B21: ETH | C21: ="R-SH_"&A21&"_"&B21&"*" -> R-SH_Att_ETH* | E21: CEFF | F21: ="R-S*_"&A21&"_"&B21&"*" -> R-S*_Att_ETH* | G21: *0.8
A22: Att | B22: LPG | C22: ="R-SH_"&A22&"_"&B22&"*" -> R-SH_Att_LPG* | E22: CEFF | F22: ="R-S*_"&A22&"_"&B22&"*" -> R-S*_Att_LPG* | G22: =IFERROR("*"&AVERAGEIFS('BY-RSD-EFF'!$L$2:$L$100,'BY-RSD-EFF'!$C$2:$C$100,EFF!C22,'BY-RSD-EFF'!$A$2:$A$100,"BASE"),"") -> *0.807075774336283
A23: Att | B23: ELC | C23: ="R-SH_"&A23&"_"&B23&"*X1" -> R-SH_Att_ELC*X1 | E23: CEFF | F23: ="R-*_"&A23&"*"&"HPN*"&",-*GAS*" -> R-*_Att*HPN*,-*GAS* | G23: =IFERROR("*"&AVERAGEIFS('BY-RSD-EFF'!$L$2:$L$100,'BY-RSD-EFF'!$C$2:$C$100,EFF!C23,'BY-RSD-EFF'!$A$2:$A$100,"BASE"),"") -> *3.11576271186441
A24: Att | B24: KER | C24: ="R-SH_"&A24&"_"&B24&"*" -> R-SH_Att_KER* | E24: CEFF | F24: ="R-S*_"&A24&"_"&B24&"*" -> R-S*_Att_KER* | G24: =IFERROR("*"&AVERAGEIFS('BY-RSD-EFF'!$L$2:$L$100,'BY-RSD-EFF'!$C$2:$C$100,EFF!C24,'BY-RSD-EFF'!$A$2:$A$100,"BASE"),"") -> *0.819415584415584
A25: Att | B25: GAS | C25: ="R-SH_"&A25&"_"&B25&"*" -> R-SH_Att_GAS* | E25: CEFF | F25: ="R-S*_"&A25&"_"&B25&"*" -> R-S*_Att_GAS* | G25: =IFERROR("*"&AVERAGEIFS('BY-RSD-EFF'!$L$2:$L$100,'BY-RSD-EFF'!$C$2:$C$100,EFF!C25,'BY-RSD-EFF'!$A$2:$A$100,"BASE"),"") -> *0.817294117647059
A26: Att | B26: PEA | C26: ="R-SH_"&A26&"_"&B26&"*" -> R-SH_Att_PEA* | E26: CEFF | F26: ="R-S*_"&A26&"_"&B26&"*" -> R-S*_Att_PEA* | G26: =IFERROR("*"&AVERAGEIFS('BY-RSD-EFF'!$L$2:$L$100,'BY-RSD-EFF'!$C$2:$C$100,EFF!C26,'BY-RSD-EFF'!$A$2:$A$100,"BASE"),"") -> *0.550929487179487
A27: Att | B27: SMF | C27: ="R-SH_"&A27&"_"&B27&"*" -> R-SH_Att_SMF* | E27: CEFF | F27: ="R-S*_"&A27&"_"&B27&"*" -> R-S*_Att_SMF* | G27: =IFERROR("*"&AVERAGEIFS('BY-RSD-EFF'!$L$2:$L$100,'BY-RSD-EFF'!$C$2:$C$100,EFF!C27,'BY-RSD-EFF'!$A$2:$A$100,"BASE"),"") -> *0.571137724550898
A28: Att | B28: WOO | C28: ="R-SH_"&A28&"_"&B28&"*" -> R-SH_Att_WOO* | E28: CEFF | F28: ="R-S*_"&A28&"_"&B28&"*" -> R-S*_Att_WOO* | G28: =IFERROR("*"&AVERAGEIFS('BY-RSD-EFF'!$L$2:$L$100,'BY-RSD-EFF'!$C$2:$C$100,EFF!C28,'BY-RSD-EFF'!$A$2:$A$100,"BASE"),"") -> *0.704006568144499
A29: Att | B29: HET | C29: ="R-SH_"&A29&"_"&B29&"*" -> R-SH_Att_HET* | E29: CEFF | F29: ="R-S*_"&A29&"_*"&B29&"*" -> R-S*_Att_*HET* | G29: *1
A30: Att | B30: ELC | C30: ="R-SH_"&A30&"_"&B30&"*X0" -> R-SH_Att_ELC*X0 | E30: CEFF | F30: ="R-S*_"&A30&"_"&B30&"_N1"&",-R-SC*" -> R-S*_Att_ELC_N1,-R-SC* | G30: =IFERROR("*"&AVERAGEIFS('BY-RSD-EFF'!$L$2:$L$100,'BY-RSD-EFF'!$C$2:$C$100,EFF!C30,'BY-RSD-EFF'!$A$2:$A$100,"BASE"),"") -> *1
E31: *Detached Space Heat
A32: Det | B32: COA | C32: ="R-SH_"&A32&"_"&B32&"*" -> R-SH_Det_COA* | E32: CEFF | F32: ="R-S*_"&A32&"_"&B32&"*" -> R-S*_Det_COA* | G32: =IFERROR("*"&AVERAGEIFS('BY-RSD-EFF'!$L$2:$L$100,'BY-RSD-EFF'!$C$2:$C$100,EFF!C32,'BY-RSD-EFF'!$A$2:$A$100,"BASE"),"") -> *0.619863294600137
A33: Det | B33: BDL | C33: ="R-SH_"&A33&"_"&B33&"*" -> R-SH_Det_BDL* | E33: CEFF | F33: ="R-S*_"&A33&"_"&B33&"*" -> R-S*_Det_BDL* | G33: *0.8
A34: Det | B34: ETH | C34: ="R-SH_"&A34&"_"&B34&"*" -> R-SH_Det_ETH* | E34: CEFF | F34: ="R-S*_"&A34&"_"&B34&"*" -> R-S*_Det_ETH* | G34: *0.8
A35: Det | B35: LPG | C35: ="R-SH_"&A35&"_"&B35&"*" -> R-SH_Det_LPG* | E35: CEFF | F35: ="R-S*_"&A35&"_"&B35&"*" -> R-S*_Det_LPG* | G35: =IFERROR("*"&AVERAGEIFS('BY-RSD-EFF'!$L$2:$L$100,'BY-RSD-EFF'!$C$2:$C$100,EFF!C35,'BY-RSD-EFF'!$A$2:$A$100,"BASE"),"") -> *0.826617747626993
A36: Det | B36: ELC | C36: ="R-SH_"&A36&"_"&B36&"*X1" -> R-SH_Det_ELC*X1 | E36: CEFF | F36: ="R-*_"&A36&"*"&"HPN*"&",-*GAS*" -> R-*_Det*HPN*,-*GAS* | G36: =IFERROR("*"&AVERAGEIFS('BY-RSD-EFF'!$L$2:$L$100,'BY-RSD-EFF'!$C$2:$C$100,EFF!C36,'BY-RSD-EFF'!$A$2:$A$100,"BASE"),"") -> *3.08978378378378
A37: Det | B37: KER | C37: ="R-SH_"&A37&"_"&B37&"*" -> R-SH_Det_KER* | E37: CEFF | F37: ="R-S*_"&A37&"_"&B37&"*" -> R-S*_Det_KER* | G37: =IFERROR("*"&AVERAGEIFS('BY-RSD-EFF'!$L$2:$L$100,'BY-RSD-EFF'!$C$2:$C$100,EFF!C37,'BY-RSD-EFF'!$A$2:$A$100,"BASE"),"") -> *0.822803738317757
A38: Det | B38: GAS | C38: ="R-SH_"&A38&"_"&B38&"*" -> R-SH_Det_GAS* | E38: CEFF | F38: ="R-S*_"&A38&"_"&B38&"*" -> R-S*_Det_GAS* | G38: =IFERROR("*"&AVERAGEIFS('BY-RSD-EFF'!$L$2:$L$100,'BY-RSD-EFF'!$C$2:$C$100,EFF!C38,'BY-RSD-EFF'!$A$2:$A$100,"BASE"),"") -> *0.827287581699346
A39: Det | B39: PEA | C39: ="R-SH_"&A39&"_"&B39&"*" -> R-SH_Det_PEA* | E39: CEFF | F39: ="R-S*_"&A39&"_"&B39&"*" -> R-S*_Det_PEA* | G39: =IFERROR("*"&AVERAGEIFS('BY-RSD-EFF'!$L$2:$L$100,'BY-RSD-EFF'!$C$2:$C$100,EFF!C39,'BY-RSD-EFF'!$A$2:$A$100,"BASE"),"") -> *0.545789473684211
A40: Det | B40: SMF | C40: ="R-SH_"&A40&"_"&B40&"*" -> R-SH_Det_SMF* | E40: CEFF | F40: ="R-S*_"&A40&"_"&B40&"*" -> R-S*_Det_SMF* | G40: =IFERROR("*"&AVERAGEIFS('BY-RSD-EFF'!$L$2:$L$100,'BY-RSD-EFF'!$C$2:$C$100,EFF!C40,'BY-RSD-EFF'!$A$2:$A$100,"BASE"),"") -> *0.614742268041237
A41: Det | B41: WOO | C41: ="R-SH_"&A41&"_"&B41&"*" -> R-SH_Det_WOO* | E41: CEFF | F41: ="R-S*_"&A41&"_"&B41&"*" -> R-S*_Det_WOO* | G41: =IFERROR("*"&AVERAGEIFS('BY-RSD-EFF'!$L$2:$L$100,'BY-RSD-EFF'!$C$2:$C$100,EFF!C41,'BY-RSD-EFF'!$A$2:$A$100,"BASE"),"") -> *0.729286096921694
...

Sheet BY-RSD-WH_AF
A1: scenario | B1: attribute | C1: process | D1: commodity | E1: lim_type | F1: time_slice | G1: year | H1: commodity_group | I1: currency | J1: stage | K1: sow | L1: IE | M1: National
A2: BASE | B2: AFA | C2: R-WH_Apt_BDL_X0 | D2: - | E2: UP | F2: - | G2: 2018 | H2: - | I2: - | J2: - | K2: - | L2: 0.12 | M2: 0.12
A3: BASE | B3: AFA | C3: R-WH_Apt_COA_X0 | D3: - | E3: UP | F3: - | G3: 2018 | H3: - | I3: - | J3: - | K3: - | L3: 0.12 | M3: 0.12
A4: BASE | B4: AFA | C4: R-WH_Apt_ELC_X0 | D4: - | E4: UP | F4: - | G4: 2018 | H4: - | I4: - | J4: - | K4: - | L4: 0.053377456 | M4: 0.053377456
A5: BASE | B5: AFA | C5: R-WH_Apt_ELC_X1 | D5: - | E5: UP | F5: - | G5: 2018 | H5: - | I5: - | J5: - | K5: - | L5: 0.49058779 | M5: 0.49058779
A6: BASE | B6: AFA | C6: R-WH_Apt_ETH_X0 | D6: - | E6: UP | F6: - | G6: 2018 | H6: - | I6: - | J6: - | K6: - | L6: 0.12 | M6: 0.12
A7: BASE | B7: AFA | C7: R-WH_Apt_GAS_X0 | D7: - | E7: UP | F7: - | G7: 2018 | H7: - | I7: - | J7: - | K7: - | L7: 0.060645497 | M7: 0.060645497
A8: BASE | B8: AFA | C8: R-WH_Apt_HET_X0 | D8: - | E8: UP | F8: - | G8: 2018 | H8: - | I8: - | J8: - | K8: - | L8: 0.12 | M8: 0.12
A9: BASE | B9: AFA | C9: R-WH_Apt_KER_X0 | D9: - | E9: UP | F9: - | G9: 2018 | H9: - | I9: - | J9: - | K9: - | L9: 0.12 | M9: 0.12
A10: BASE | B10: AFA | C10: R-WH_Apt_LPG_X0 | D10: - | E10: UP | F10: - | G10: 2018 | H10: - | I10: - | J10: - | K10: - | L10: 0.12 | M10: 0.12
A11: BASE | B11: AFA | C11: R-WH_Apt_PEA_X0 | D11: - | E11: UP | F11: - | G11: 2018 | H11: - | I11: - | J11: - | K11: - | L11: 0.12 | M11: 0.12
A12: BASE | B12: AFA | C12: R-WH_Apt_SMF_X0 | D12: - | E12: UP | F12: - | G12: 2018 | H12: - | I12: - | J12: - | K12: - | L12: 0.12 | M12: 0.12
A13: BASE | B13: AFA | C13: R-WH_Apt_SOL_X0 | D13: - | E13: UP | F13: - | G13: 2018 | H13: - | I13: - | J13: - | K13: - | L13: 0.13976566 | M13: 0.13976566
... A40: BASE | B40: AFA | C40: R-WH_Det_WOO_X0 | D40: - | E40: UP | F40: - | G40: 2018 | H40: - | I40: - | J40: - | K40: - | L40: 0.12 | M40: 0.12

Sheet BY-RSD-SH_AF
A1: scenario | B1: attribute | C1: process | D1: commodity | E1: lim_type | F1: time_slice | G1: year | H1: commodity_group | I1: currency | J1: stage | K1: sow | L1: IE | M1: National
A2: BASE | B2: AFA | C2: R-SH_Apt_BDL_X0 | D2: - | E2: UP | F2: - | G2: 2018 | H2: - | I2: - | J2: - | K2: - | L2: 0.12 | M2: 0.12
A3: BASE | B3: AFA | C3: R-SH_Apt_COA_X0 | D3: - | E3: UP | F3: - | G3: 2018 | H3: - | I3: - | J3: - | K3: - | L3: 0.12 | M3: 0.12
A4: BASE | B4: AFA | C4: R-SH_Apt_ELC_X0 | D4: - | E4: UP | F4: - | G4: 2018 | H4: - | I4: - | J4: - | K4: - | L4: 0.013931119 | M4: 0.013931119
A5: BASE | B5: AFA | C5: R-SH_Apt_ELC_X1 | D5: - | E5: UP | F5: - | G5: 2018 | H5: - | I5: - | J5: - | K5: - | L5: 0.1813027 | M5: 0.1813027
A6: BASE | B6: AFA | C6: R-SH_Apt_ETH_X0 | D6: - | E6: UP | F6: - | G6: 2018 | H6: - | I6: - | J6: - | K6: - | L6: 0.12 | M6: 0.12
A7: BASE | B7: AFA | C7: R-SH_Apt_GAS_X0 | D7: - | E7: UP | F7: - | G7: 2018 | H7: - | I7: - | J7: - | K7: - | L7: 0.025618486 | M7: 0.025618486
A8: BASE | B8: AFA | C8: R-SH_Apt_HET_X0 | D8: - | E8: UP | F8: - | G8: 2018 | H8: - | I8: - | J8: - | K8: - | L8: 0.12 | M8: 0.12
A9: BASE | B9: AFA | C9: R-SH_Apt_KER_X0 | D9: - | E9: UP | F9: - | G9: 2018 | H9: - | I9: - | J9: - | K9: - | L9: 0.066604255 | M9: 0.066604255
A10: BASE | B10: AFA | C10: R-SH_Apt_LPG_X0 | D10: - | E10: UP | F10: - | G10: 2018 | H10: - | I10: - | J10: - | K10: - | L10: 0.12 | M10: 0.12
A11: BASE | B11: AFA | C11: R-SH_Apt_PEA_X0 | D11: - | E11: UP | F11: - | G11: 2018 | H11: - | I11: - | J11: - | K11: - | L11: 0.16174375 | M11: 0.16174375
A12: BASE | B12: AFA | C12: R-SH_Apt_SMF_X0 | D12: - | E12: UP | F12: - | G12: 2018 | H12: - | I12: - | J12: - | K12: - | L12: 0.12 | M12: 0.12
A13: BASE | B13: AFA | C13: R-SH_Apt_WOO_X0 | D13: - | E13: UP | F13: - | G13: 2018 | H13: - | I13: - | J13: - | K13: - | L13: 0.12 | M13: 0.12
... A37: BASE | B37: AFA | C37: R-SH_Det_WOO_X0 | D37: - | E37: UP | F37: - | G37: 2018 | H37: - | I37: - | J37: - | K37: - | L37: 0.094687204 | M37: 0.094687204

Sheet BY-RSD-EFF
A1: scenario | B1: attribute | C1: process | D1: commodity | E1: lim_type | F1: time_slice | G1: year | H1: commodity_group | I1: currency | J1: stage | K1: sow | L1: IE | M1: National
A2: BASE | B2: EFF | C2: R-SH_Apt_BDL_X0 | D2: - | E2: - | F2: ANNUAL | G2: 2018 | H2: - | I2: - | J2: - | K2: - | L2: 0.9 | M2: 0.9
A3: BASE | B3: EFF | C3: R-SH_Apt_COA_X0 | D3: - | E3: - | F3: ANNUAL | G3: 2018 | H3: - | I3: - | J3: - | K3: - | L3: 0.59018803 | M3: 0.59018803
A4: BASE | B4: EFF | C4: R-SH_Apt_ELC_X0 | D4: - | E4: - | F4: ANNUAL | G4: 2018 | H4: - | I4: - | J4: - | K4: - | L4: 1 | M4: 1
A5: BASE | B5: EFF | C5: R-SH_Apt_ELC_X1 | D5: - | E5: - | F5: ANNUAL | G5: 2018 | H5: - | I5: - | J5: - | K5: - | L5: 3.0701961 | M5: 3.0701961
A6: BASE | B6: EFF | C6: R-SH_Apt_ETH_X0 | D6: - | E6: - | F6: ANNUAL | G6: 2018 | H6: - | I6: - | J6: - | K6: - | L6: 0.9 | M6: 0.9
A7: BASE | B7: EFF | C7: R-SH_Apt_GAS_X0 | D7: - | E7: - | F7: ANNUAL | G7: 2018 | H7: - | I7: - | J7: - | K7: - | L7: 0.81026882 | M7: 0.81026882
A8: BASE | B8: EFF | C8: R-SH_Apt_HET_X0 | D8: - | E8: - | F8: ANNUAL | G8: 2018 | H8: - | I8: - | J8: - | K8: - | L8: 0.39838442 | M8: 0.39838442
A9: BASE | B9: EFF | C9: R-SH_Apt_KER_X0 | D9: - | E9: - | F9: ANNUAL | G9: 2018 | H9: - | I9: - | J9: - | K9: - | L9: 0.81016216 | M9: 0.81016216
A10: BASE | B10: EFF | C10: R-SH_Apt_LPG_X0 | D10: - | E10: - | F10: ANNUAL | G10: 2018 | H10: - | I10: - | J10: - | K10: - | L10: 0.80677903 | M10: 0.80677903
A11: BASE | B11: EFF | C11: R-SH_Apt_PEA_X0 | D11: - | E11: - | F11: ANNUAL | G11: 2018 | H11: - | I11: - | J11: - | K11: - | L11: 0.525 | M11: 0.525
A12: BASE | B12: EFF | C12: R-SH_Apt_SMF_X0 | D12: - | E12: - | F12: ANNUAL | G12: 2018 | H12: - | I12: - | J12: - | K12: - | L12: 0.58177778 | M12: 0.58177778
A13: BASE | B13: EFF | C13: R-SH_Apt_WOO_X0 | D13: - | E13: - | F13: ANNUAL | G13: 2018 | H13: - | I13: - | J13: - | K13: - | L13: 0.68804511 | M13: 0.68804511
... A76: BASE | B76: EFF | C76: R-WH_Det_WOO_X0 | D76: - | E76: - | F76: ANNUAL | G76: 2018 | H76: - | I76: - | J76: - | K76: - | L76: 0.7292861 | M76: 0.7292861

Sheet BY-RSD-DW
A1: scenario | B1: attribute | C1: process | D1: commodity | E1: lim_type | F1: time_slice | G1: year | H1: commodity_group | I1: currency | J1: stage | K1: sow | L1: IE | M1: National
A2: BASE | B2: AFA | C2: R-RSDDW_X0 | D2: - | E2: UP | F2: - | G2: 2018 | H2: - | I2: - | J2: - | K2: - | L2: 0.010896638 | M2: 0.010896638

Sheet BY-RSD-PF
A1: scenario | B1: attribute | C1: process | D1: commodity | E1: lim_type | F1: time_slice | G1: year | H1: commodity_group | I1: currency | J1: stage | K1: sow | L1: IE | M1: National
A2: BASE | B2: AFA | C2: R-PF_Apt_X0 | D2: - | E2: UP | F2: - | G2: 2018 | H2: - | I2: - | J2: - | K2: - | L2: 0.12716586 | M2: 0.12716586
A3: BASE | B3: AFA | C3: R-PF_Att_X0 | D3: - | E3: UP | F3: - | G3: 2018 | H3: - | I3: - | J3: - | K3: - | L3: 0.24175609 | M3: 0.24175609
A4: BASE | B4: AFA | C4: R-PF_Det_X0 | D4: - | E4: UP | F4: - | G4: 2018 | H4: - | I4: - | J4: - | K4: - | L4: 0.29872123 | M4: 0.29872123

Sheet BY-RSD-CD
A1: scenario | B1: attribute | C1: process | D1: commodity | E1: lim_type | F1: time_slice | G1: year | H1: commodity_group | I1: currency | J1: stage | K1: sow | L1: IE | M1: National
A2: BASE | B2: AFA | C2: R-RSDCD_X0 | D2: - | E2: UP | F2: - | G2: 2018 | H2: - | I2: - | J2: - | K2: - | L2: 0.011863014 | M2: 0.011863014

Sheet BY-RSD-LT
A1: scenario | B1: attribute | C1: process | D1: commodity | E1: lim_type | F1: time_slice | G1: year | H1: commodity_group | I1: currency | J1: stage | K1: sow | L1: IE | M1: National
A2: BASE | B2: AFA | C2: R-LT_Apt_X0 | D2: - | E2: UP | F2: - | G2: 2018 | H2: - | I2: - | J2: - | K2: - | L2: 0.21098595 | M2: 0.21098595
A3: BASE | B3: AFA | C3: R-LT_Att_X0 | D3: - | E3: UP | F3: - | G3: 2018 | H3: - | I3: - | J3: - | K3: - | L3: 0.29847129 | M3: 0.29847129
A4: BASE | B4: AFA | C4: R-LT_Det_X0 | D4: - | E4: UP | F4: - | G4: 2018 | H4: - | I4: - | J4: - | K4: - | L4: 0.49065562 | M4: 0.49065562

Sheet BY-RSD-CW
A1: scenario | B1: attribute | C1: process | D1: commodity | E1: lim_type | F1: time_slice | G1: year | H1: commodity_group | I1: currency | J1: stage | K1: sow | L1: IE | M1: National
A2: BASE | B2: AFA | C2: R-RSDCW_X0 | D2: - | E2: UP | F2: - | G2: 2018 | H2: - | I2: - | J2: - | K2: - | L2: 0.0067195932 | M2: 0.0067195932

Sheet BY-RSD-CK
A1: scenario | B1: attribute | C1: process | D1: commodity | E1: lim_type | F1: time_slice | G1: year | H1: commodity_group | I1: currency | J1: stage | K1: sow | L1: IE | M1: National
A2: BASE | B2: AFA | C2: R-RSDCK_ELC_X0 | D2: - | E2: UP | F2: - | G2: 2018 | H2: - | I2: - | J2: - | K2: - | L2: 0.012186512 | M2: 0.012186512
A3: BASE | B3: AFA | C3: R-RSDCK_GAS_X0 | D3: - | E3: UP | F3: - | G3: 2018 | H3: - | I3: - | J3: - | K3: - | L3: 0.010445598 | M3: 0.010445598
A4: BASE | B4: AFA | C4: R-RSDCK_LPG_X0 | D4: - | E4: UP | F4: - | G4: 2018 | H4: - | I4: - | J4: - | K4: - | L4: 0.010445583 | M4: 0.010445583

Sheet BY-RSD-RF
A1: scenario | B1: attribute | C1: process | D1: commodity | E1: lim_type | F1: time_slice | G1: year | H1: commodity_group | I1: currency | J1: stage | K1: sow | L1: IE | M1: National
A2: BASE | B2: AFA | C2: R-RSDRF_X0 | D2: - | E2: UP | F2: - | G2: 2018 | H2: - | I2: - | J2: - | K2: - | L2: 0.11719939 | M2: 0.11719939

Sheet BY-RSD-OE
A1: scenario | B1: attribute | C1: process | D1: commodity | E1: lim_type | F1: time_slice | G1: year | H1: commodity_group | I1: currency | J1: stage | K1: sow | L1: IE | M1: National
A2: BASE | B2: AFA | C2: R-RSDOE_X0 | D2: - | E2: UP | F2: - | G2: 2018 | H2: - | I2: - | J2: - | K2: - | L2: 0.93569571 | M2: 0.93569571
