Workbook

Sheet Cover
A16: TIMES-Ireland Model
A19: Document type: | B19: New Technologies
A20: Sector(s): | B20: Transport sector (TRA)
A21: Purpose: | B21: Techno-economic data for new vehicles
A23: Original developer(s): | B23: Vahid Aryanpur (UCC, vahid.aryanpur@ucc.ie)
A26: Current maintainer(s): | B26: Vahid Aryanpur (UCC, vahid.aryanpur@ucc.ie)
A29: Part of TIM version: | B29: 1
A30: Model repository: | B30: https://github.com/MaREI-EPMG/TIMES-Ireland-model
A31: Licence: | B31: CC BY-NC-SA 4.0 (unless specified otherwise)
B32: https://creativecommons.org/licenses/by-nc-sa/4.0/

Sheet Commodities
A1: Commodities
A4: Csets | B4: CommName | C4: CommDesc | D4: Unit | E4: LimType | F4: CTSLvl | G4: PeakTS | H4: Ctype
A5: *Commodity Set Membership | B5: Commodity Name | C5: Commodity Description | D5: Unit | E5: Balance equation | F5: Timeslice Level | G5: Peak Monitoring | H5: Electricity Indicator
A6: NRG | B6: TRAWLK | C6: Walking (TRA) | D6: PJ
B7: TRACYC | C7: Cycling (TRA) | D7: PJ
B8: TRAGSL | C8: Gasoline (TRA) | D8: PJ
B9: TRADST | C9: Diesel (TRA) | D9: PJ
B10: TRAETH | C10: BioEthanol (TRA) | D10: PJ
B11: TRABDL | C11: BioDiesel (TRA) | D11: PJ
B12: TRABJK | C12: Bio Jet Kerosene (TRA)_SAF | D12: PJ
B13: TRACNG | C13: CNG (TRA) | D13: PJ
B14: TRAPtLKER | C14: Power to Liquid, pure synthetic kerosene (TRA) | D14: PJ
B15: TRABNG | C15: BioCNG (TRA) | D15: PJ
B16: TRAELC | C16: Electricity (TRA) | D16: PJ | F16: DAYNITE | H16: ELC
B17: TRALNG | C17: LNG (TRA) | D17: PJ
B18: TRAH2 | C18: Hydrogen (TRA) | D18: PJ
B19: TRAKER | C19: Kerosene (TRA) | D19: PJ
A20: DEM | B20: TRAPS | C20: Transport Demand: Short-range passenger travels | D20: Bpkm
B21: TRAPM | C21: Transport Demand: Medium-range passenger travels | D21: Bpkm
B22: TRAPL | C22: Transport Demand: Long-range passenger travels | D22: Bpkm
B23: TRAF | C23: Transport Demand: Goods vehicle for freight | D23: Btkm
B24: TTURS | C24: Transport Demand: Turism fuel | D24: PJ
B25: TNAV | C25: Transport Demand: Navigation fuel | D25: PJ
B26: TOTH | C26: Transport Demand: Unspecified fuel | D26: PJ
B27: TAVIDOM | C27: Transport Demand: Aviation domestic | D27: PJ
B28: TAVIINT | C28: Transport Demand: Aviation international | D28: PJ
A29: ENV | B29: TRACO2N | C29: Carbon Dioxide - Combustion (TRA) | D29: kt
B30: TRACH4N | C30: Methane (TRA) | D30: kt
B31: TRASO2N | C31: Sulphur Oxides (TRA) | D31: kt
B32: TRANOXN | C32: Nitrogen Oxide (TRA) | D32: kt
B33: TRAPM10 | C33: Particulate Matter <10 µm (TRA) | D33: kt
B34: TRAPM25 | C34: Particulate Matter <2.5 µm (TRA) | D34: kt
B35: AVIKER | C35: Kerosene for Aviation
B36: AVIBJK | C36: Biojet kerosene or SAF for Aviation
B37: AVIELC | C37: Electricity for Aviation
B38: AVIH2 | C38: Hydrogen for Aviation
B39: AVIPtL | C39: Syntethic fuel for Aviation
B47: Vehicle type (New technologies)
B48: End-use technologies | C48: Description
B49: Passenger
...

Sheet TRA
B3: ~FI_Process
B4: Sets | C4: Region | D4: TechName | E4: TechDesc | F4: Tact | G4: Tcap | H4: Tslvl | I4: PrimaryCG | J4: Vintage
B5: *Process Set Membership | C5: Region Name | D5: Technology Name | E5: Technology Description | F5: Activity Unit | G5: Capacity Unit | H5: TimeSlice level of Process Activity | I5: Primary Commodity Group | J5: Vintage Tracking
B6: *Two-wheelers
B7: DMD | D7: =Commodities!B51 -> T-MOT-ICE_GSL01 | E7: =Commodities!C51 -> TRA Motorcycles: Gasoline ICEs - New | F7: Bpkm | G7: 000_Units
B8: DMD | D8: =Commodities!B52 -> T-MOT-EV_ELC01 | E8: =Commodities!C52 -> TRA Motorcycles: Electric - New | F8: Bpkm | G8: 000_Units
B9: *Private cars
B10: DMD | D10: =Commodities!B54 -> T-CAR-ICE_GSL21 | E10: =Commodities!C54 -> TRA Cars: Gasoline ICEs - New | F10: Bpkm | G10: 000_Units
B11: DMD | D11: =Commodities!B55 -> T-CAR-ICE_DST21 | E11: =Commodities!C55 -> TRA Cars: Diesel ICEs - New | F11: Bpkm | G11: 000_Units
B12: DMD | D12: =Commodities!B56 -> T-CAR-ICE_DF21 | E12: =Commodities!C56 -> TRA Cars: Dual fuel ICEs (CNG/BCNG & Gasoline) - New | F12: Bpkm | G12: 000_Units
B13: DMD | D13: =Commodities!B57 -> T-CAR-ICE_NGB21 | E13: =Commodities!C57 -> TRA Cars: BioCNG and CNG ICEs - New | F13: Bpkm | G13: 000_Units
B14: DMD | D14: =Commodities!B58 -> T-CAR-ICE_E8521 | E14: =Commodities!C58 -> TRA Cars: Flex fuel ICEs - New | F14: Bpkm | G14: 000_Units
B15: DMD | D15: =Commodities!B59 -> T-CAR-ICE_B10021 | E15: =Commodities!C59 -> TRA Cars: Biodiesel ICEs - New | F15: Bpkm | G15: 000_Units
B16: DMD | D16: =Commodities!B60 -> T-CAR-HEV_GSL21 | E16: =Commodities!C60 -> TRA Cars: Gasoline HEVs - New | F16: Bpkm | G16: 000_Units
B17: DMD | D17: =Commodities!B61 -> T-CAR-HEV_DST21 | E17: =Commodities!C61 -> TRA Cars: Diesel HEVs - New | F17: Bpkm | G17: 000_Units
B18: DMD | D18: =Commodities!B62 -> T-CAR-PHEV10_GSL21 | E18: =Commodities!C62 -> TRA Cars: Gasoline PHEV, 10-mile all-electric range - New | F18: Bpkm | G18: 000_Units
B19: DMD | D19: =Commodities!B63 -> T-CAR-PHEV20_GSL21 | E19: =Commodities!C63 -> TRA Cars: Gasoline PHEV, 20-mile all-electric range - New | F19: Bpkm | G19: 000_Units
B20: DMD | D20: =Commodities!B64 -> T-CAR-PHEV40_GSL21 | E20: =Commodities!C64 -> TRA Cars: Gasoline PHEV, 40-mile all-electric range - New | F20: Bpkm | G20: 000_Units
B21: DMD | D21: =Commodities!B65 -> T-CAR-PHEV10_DST21 | E21: =Commodities!C65 -> TRA Cars: Diesel PHEV, 10-mile all-electric range - New | F21: Bpkm | G21: 000_Units
... B28: DMD | D28: =Commodities!B72 -> T-CAR-FCV_HYD21 | E28: =Commodities!C72 -> TRA Cars: Fuel cell vehicles - New | F28: Bpkm | G28: 000_Units
B29: *Taxis
B30: DMD | D30: =Commodities!B74 -> T-TAX-ICE_GSL31 | E30: =Commodities!C74 -> TRA Taxis: Gasoline ICEs - New | F30: Bpkm | G30: 000_Units
B31: DMD | D31: =Commodities!B75 -> T-TAX-ICE_DST31 | E31: =Commodities!C75 -> TRA Taxis: Diesel ICEs - New | F31: Bpkm | G31: 000_Units
B32: DMD | D32: =Commodities!B76 -> T-TAX-ICE_DF31 | E32: =Commodities!C76 -> TRA Taxis: Dual fuel ICEs (CNG/BCNG & Gasoline) - New | F32: Bpkm | G32: 000_Units
B33: DMD | D33: =Commodities!B77 -> T-TAX-ICE_NGB31 | E33: =Commodities!C77 -> TRA Taxis: BioCNG and CNG ICEs - New | F33: Bpkm | G33: 000_Units
B34: DMD | D34: =Commodities!B78 -> T-TAX-ICE_E8531 | E34: =Commodities!C78 -> TRA Taxis: Flex fuel ICEs - New | F34: Bpkm | G34: 000_Units
B35: DMD | D35: =Commodities!B79 -> T-TAX-ICE_B10031 | E35: =Commodities!C79 -> TRA Taxis: Biodiesel ICEs - New | F35: Bpkm | G35: 000_Units
B36: DMD | D36: =Commodities!B80 -> T-TAX-HEV_GSL31 | E36: =Commodities!C80 -> TRA Taxis: Gasoline HEVs - New | F36: Bpkm | G36: 000_Units
B37: DMD | D37: =Commodities!B81 -> T-TAX-HEV_DST31 | E37: =Commodities!C81 -> TRA Taxis: Diesel HEV - New | F37: Bpkm | G37: 000_Units
B38: DMD | D38: =Commodities!B82 -> T-TAX-PHEV10_GSL31 | E38: =Commodities!C82 -> TRA Taxis: Gasoline PHEV, 10-mile all-electric range - New | F38: Bpkm | G38: 000_Units
B39: DMD | D39: =Commodities!B83 -> T-TAX-PHEV20_GSL31 | E39: =Commodities!C83 -> TRA Taxis: Gasoline PHEV, 20-mile all-electric range - New | F39: Bpkm | G39: 000_Units
B40: DMD | D40: =Commodities!B84 -> T-TAX-PHEV40_GSL31 | E40: =Commodities!C84 -> TRA Taxis: Gasoline PHEV, 40-mile all-electric range - New | F40: Bpkm | G40: 000_Units
B41: DMD | D41: =Commodities!B85 -> T-TAX-PHEV10_DST31 | E41: =Commodities!C85 -> TRA Taxis: Diesel PHEV, 10-mile all-electric range - New | F41: Bpkm | G41: 000_Units
... B48: DMD | D48: =Commodities!B92 -> T-TAX-FCV_HYD31 | E48: =Commodities!C92 -> TRA Taxis: Fuel cell vehicles - New | F48: Bpkm | G48: 000_Units
B49: *Buses
B50: DMD | D50: =Commodities!B94 -> T-BUS-ICE_DST41 | E50: =Commodities!C94 -> TRA BUS: Diesel ICEs - New | F50: Bpkm | G50: 000_Units
B51: DMD | D51: =Commodities!B95 -> T-BUS-ICE_B10041 | E51: =Commodities!C95 -> TRA BUS: Biodiesel ICEs - New | F51: Bpkm | G51: 000_Units
B52: DMD | D52: =Commodities!B96 -> T-BUS-ICE_NGB41 | E52: =Commodities!C96 -> TRA BUS: BioCNG and CNG ICEs - New | F52: Bpkm | G52: 000_Units
B53: DMD | D53: =Commodities!B97 -> T-BUS-BEV_ELC41 | E53: =Commodities!C97 -> TRA BUS: BEV - New | F53: Bpkm | G53: 000_Units
B54: DMD | D54: =Commodities!B98 -> T-BUS-FCV_HYD41 | E54: =Commodities!C98 -> TRA BUS: Fuel Cell Vehicles - New | F54: Bpkm | G54: 000_Units
...

Sheet Purchase price
A1: New Private Cars (Number) by Car Make and Engine Capacity cc in 2018
B2: All capacities | C2: Up to 900 cc | D2: 901-1000 cc | E2: 1001-1300 cc | F2: 1301-1400 cc | G2: 1401-1500 cc | H2: 1501-1600 cc | I2: 1601-2000 cc | J2: 2001-2400 cc | K2: >2400 cc
A3: All makes | B3: 121157 | C3: 2439 | D3: 20545 | E3: 13872 | F3: 7002 | G3: 20335 | H3: 20414 | I3: 30556 | J3: 3420 | K3: 2574
A4: All other makes | B4: 49 | C4: 13 | D4: 0 | E4: 6 | F4: 10 | G4: 1 | H4: 0 | I4: 8 | J4: 0 | K4: 11 | L4: =B4/$B$3 -> 0.00040443392
A5: Alfa Romeo | B5: 86 | C5: 1 | D5: 0 | E5: 2 | F5: 16 | G5: 0 | H5: 11 | I5: 22 | J5: 29 | K5: 5 | L5: =B5/$B$3 -> 0.00070982279
A6: Audi | B6: 4806 | C6: 0 | D6: 483 | E6: 0 | F6: 197 | G6: 114 | H6: 810 | I6: 2776 | J6: 0 | K6: 426 | L6: =B6/$B$3 -> 0.039667539
A7: BMW | B7: 4128 | C7: 76 | D7: 0 | E7: 0 | F7: 0 | G7: 556 | H7: 0 | I7: 3210 | J7: 0 | K7: 286 | L7: =B7/$B$3 -> 0.034071494
A8: Chevrolet | B8: 0 | C8: 0 | D8: 0 | E8: 0 | F8: 0 | G8: 0 | H8: 0 | I8: 0 | J8: 0 | K8: 0 | L8: =B8/$B$3 -> 0
A9: Chrysler Jeep | B9: 0 | C9: 0 | D9: 0 | E9: 0 | F9: 0 | G9: 0 | H9: 0 | I9: 0 | J9: 0 | K9: 0 | L9: =B9/$B$3 -> 0
A10: Chrysler | B10: 0 | C10: 0 | D10: 0 | E10: 0 | F10: 0 | G10: 0 | H10: 0 | I10: 0 | J10: 0 | K10: 0 | L10: =B10/$B$3 -> 0
A11: Citroen | B11: 1186 | C11: 1 | D11: 20 | E11: 401 | F11: 0 | G11: 0 | H11: 742 | I11: 22 | J11: 0 | K11: 0 | L11: =B11/$B$3 -> 0.0097889515
A12: Dacia | B12: 3411 | C12: 274 | D12: 683 | E12: 1 | F12: 0 | G12: 2451 | H12: 2 | I12: 0 | J12: 0 | K12: 0 | L12: =B12/$B$3 -> 0.028153553
A13: Fiat | B13: 698 | C13: 3 | D13: 1 | E13: 489 | F13: 56 | G13: 0 | H13: 147 | I13: 0 | J13: 2 | K13: 0 | L13: =B13/$B$3 -> 0.0057611199
A14: Ford | B14: 10746 | C14: 0 | D14: 1293 | E14: 2645 | F14: 0 | G14: 5833 | H14: 1 | I14: 928 | J14: 44 | K14: 2 | L14: =B14/$B$3 -> 0.088694834
A15: Honda | B15: 1260 | C15: 2 | D15: 328 | E15: 0 | F15: 237 | G15: 232 | H15: 456 | I15: 5 | J15: 0 | K15: 0 | L15: =B15/$B$3 -> 0.010399729
... A44: Volvo | B44: 1690 | C44: 0 | D44: 0 | E44: 0 | F44: 0 | G44: 58 | H44: 0 | I44: 1631 | J44: 1 | K44: 0 | L44: =B44/$B$3 -> 0.013948843
A45: Source: CSO, Table: TEA29
A50: Purchase price in 2018 (Euro/vehicle)
B51: All capacities | C51: Up to 900 cc | D51: 901-1000 cc | E51: 1001-1300 cc | F51: 1301-1400 cc | G51: 1401-1500 cc | H51: 1501-1600 cc | I51: 1601-2000 cc | J51: 2001-2400 cc | K51: >2400 cc
A52: Ford | C52: 16650 | D52: 19600 | E52: 19600 | F52: 20835 | G52: 20835 | H52: 20835 | I52: 27990 | J52: 53175 | K52: 61500
A53: Hyundai | C53: 11995 | D53: 12995 | E53: 13995 | F53: 17495 | G53: 18995 | H53: 20495 | I53: 25495 | J53: 35995 | K53: 43995
A54: Kia | C54: 11685 | D54: 12810 | E54: 15550 | F54: 18190 | G54: 19035 | H54: 20280 | I54: 26025 | J54: 38625 | K54: 41670
A55: Nissan | C55: 15895 | D55: 15895 | E55: 16395 | F55: 18545 | G55: 19195 | H55: 19995 | I55: 27520 | J55: 30520 | K55: 37720
A56: Renault | C56: 12990 | D56: 13590 | E56: 16390 | F56: 18090 | G56: 19990 | H56: 22390 | I56: 28490 | J56: 31990 | K56: 37990
A57: Skoda | C57: 11095 | D57: 12155 | E57: 15600 | F57: 18285 | G57: 27485 | H57: 27250 | I57: 33065 | J57: 39725 | K57: 42025
A58: Toyota | C58: 13360 | D58: 14580 | E58: 23500 | F58: 23500 | G58: 26000 | H58: 26790 | I58: 31630 | J58: 36500 | K58: 40395
A59: Volkswagen | C59: 13770 | D59: 13770 | E59: 17928 | F59: 21445 | G59: 28265 | H59: 24662 | I59: 31420 | J59: 38700 | K59: 73975
A60: Source: SIMI (Society of the Irish Motor Industry), https://www.simi.ie/en/motorstats/recommended-price-guide
A63: New Private Cars (Number) by Car Make and Engine Capacity cc in 2018
B64: All capacities | C64: Up to 900 cc | D64: 901-1000 cc | E64: 1001-1300 cc | F64: 1301-1400 cc | G64: 1401-1500 cc | H64: 1501-1600 cc | I64: 1601-2000 cc | J64: 2001-2400 cc | K64: >2400 cc
A65: Ford | B65: =B14 -> 10746 | C65: =C14 -> 0 | D65: =D14 -> 1293 | E65: =E14 -> 2645 | F65: =F14 -> 0 | G65: =G14 -> 5833 | H65: =H14 -> 1 | I65: =I14 -> 928 | ... K65: =K14 -> 2
A66: Hyundai | B66: =B16 -> 10950 | C66: =C16 -> 92 | D66: =D16 -> 3571 | E66: =E16 -> 1027 | F66: =F16 -> 806 | G66: =G16 -> 0 | H66: =H16 -> 1171 | I66: =I16 -> 3853 | ... K66: =K16 -> 1
A67: Kia | B67: =B20 -> 7005 | C67: =C20 -> 0 | D67: =D20 -> 613 | E67: =E20 -> 506 | F67: =F20 -> 1090 | G67: =G20 -> 0 | H67: =H20 -> 947 | I67: =I20 -> 3245 | ... K67: =K20 -> 2
A68: Nissan | B68: =B28 -> 9277 | C68: =C28 -> 985 | D68: =D28 -> 1885 | E68: =E28 -> 3043 | F68: =F28 -> 0 | G68: =G28 -> 2224 | H68: =H28 -> 1102 | I68: =I28 -> 17 | ... K68: =K28 -> 0
A69: Renault | B69: =B32 -> 7075 | C69: =C32 -> 794 | D69: =D32 -> 2 | E69: =E32 -> 1441 | F69: =F32 -> 0 | G69: =G32 -> 4248 | H69: =H32 -> 450 | I69: =I32 -> 95 | ... K69: =K32 -> 0
A70: Skoda | B70: =B35 -> 8668 | C70: =C35 -> 0 | D70: =D35 -> 3027 | E70: =E35 -> 238 | F70: =F35 -> 266 | G70: =G35 -> 266 | H70: =H35 -> 2962 | I70: =I35 -> 1909 | ... K70: =K35 -> 0
A71: Toyota | B71: =B41 -> 11484 | C71: =C41 -> 0 | D71: =D41 -> 1636 | E71: =E41 -> 794 | F71: =F41 -> 2107 | G71: =G41 -> 1448 | H71: =H41 -> 229 | I71: =I41 -> 4391 | ... K71: =K41 -> 866
A72: Volkswagen | B72: =B43 -> 13496 | C72: =C43 -> 75 | D72: =D43 -> 4558 | E72: =E43 -> 168 | F72: =F43 -> 356 | G72: =G43 -> 407 | H72: =H43 -> 3563 | I72: =I43 -> 4309 | ... K72: =K43 -> 60
A73: Total | B73: =SUM(B65:B72) -> 78701 | C73: =SUM(C65:C72) -> 1946 | D73: =SUM(D65:D72) -> 16585 | E73: =SUM(E65:E72) -> 9862 | F73: =SUM(F65:F72) -> 4625 | G73: =SUM(G65:G72) -> 14426 | H73: =SUM(H65:H72) -> 10425 | I73: =SUM(I65:I72) -> 18747 | ... K73: =SUM(K65:K72) -> 931
A77: New Private Cars (share) by Car Make and Engine Capacity cc in 2018
...
