Workbook

Sheet Cover
A16: TIMES-Ireland Model
A19: Document type: | B19: Scenario
A20: Sector(s): | B20: Transport sector (TRA)
A21: Purpose: | B21: Share of transport modes in passenger demand in BAU scenario
A23: Original developer(s): | B23: Vahid Aryanpur (UCC, vahid.aryanpur@ucc.ie)
A26: Current maintainer(s): | B26: Vahid Aryanpur (UCC, vahid.aryanpur@ucc.ie)
B27: Olexandr Balyk ( MaREI, olexandr.balyk@ucc.ie)
A29: Part of TIM version: | B29: 1
A30: Model repository: | B30: https://github.com/MaREI-EPMG/TIMES-Ireland-model
A31: Licence: | B31: CC BY-NC-SA 4.0 (unless specified otherwise)
B32: https://creativecommons.org/licenses/by-nc-sa/4.0/

Sheet Regions
C3: {=INDEX(C5:C7,$A$4)} -> IE | D3: {=INDEX(D5:D7,$A$4)} -> National | E3: {=INDEX(E5:E7,$A$4)} -> IE-CW | F3: {=INDEX(F5:F7,$A$4)} -> IE-D | G3: {=INDEX(G5:G7,$A$4)} -> IE-KE | H3: {=INDEX(H5:H7,$A$4)} -> IE-KK | I3: {=INDEX(I5:I7,$A$4)} -> IE-LS | J3: {=INDEX(J5:J7,$A$4)} -> IE-LD | ... AD3: {=INDEX(AD5:AD7,$A$4)} -> IE-MN
A4: 1
A5: Development | C5: IE | D5: National | E5: =Regions!A11 -> IE-CW | F5: =Regions!A16 -> IE-D | G5: =Regions!A19 -> IE-KE | H5: =Regions!A20 -> IE-KK | I5: =Regions!A21 -> IE-LS | J5: =Regions!A24 -> IE-LD | K5: =Regions!A25 -> IE-LH | L5: =Regions!A27 -> IE-MH | M5: =Regions!A29 -> IE-OY | N5: =Regions!A34 -> IE-WH | O5: =Regions!A35 -> IE-WX | P5: =Regions!A36 -> IE-WW | Q5: =Regions!A13 -> IE-CE | R5: =Regions!A14 -> IE-CO | S5: =Regions!A18 -> IE-KY | T5: =Regions!A23 -> IE-LK | U5: =Regions!A32 -> IE-TA | V5: =Regions!A33 -> IE-WD | W5: =Regions!A17 -> IE-G | X5: =Regions!A22 -> IE-LM | Y5: =Regions!A26 -> IE-MO | Z5: =Regions!A30 -> IE-RN | AA5: =Regions!A31 -> IE-SO | AB5: =Regions!A12 -> IE-CN | AC5: =Regions!A15 -> IE-DL | AD5: =Regions!A28 -> IE-MN
A6: Single-region | C6: =C5 -> IE | D6: ="*"&D5 -> *National | E6: ="*"&E5 -> *IE-CW | F6: ="*"&F5 -> *IE-D | G6: ="*"&G5 -> *IE-KE | H6: ="*"&H5 -> *IE-KK | I6: ="*"&I5 -> *IE-LS | J6: ="*"&J5 -> *IE-LD | K6: ="*"&K5 -> *IE-LH | ... AD6: ="*"&AD5 -> *IE-MN
A7: Multi-region | C7: ="*"&C5 -> *IE | D7: =D5 -> National | E7: =E5 -> IE-CW | F7: =F5 -> IE-D | G7: =G5 -> IE-KE | H7: =H5 -> IE-KK | I7: =I5 -> IE-LS | J7: =J5 -> IE-LD | K7: =K5 -> IE-LH | ... AD7: =AD5 -> IE-MN
A10: Code | B10: County name
A11: IE-CW | B11: Carlow
A12: IE-CN | B12: Cavan
A13: IE-CE | B13: Clare
A14: IE-CO | B14: Cork
A15: IE-DL | B15: Donegal
A16: IE-D | B16: Dublin
A17: IE-G | B17: Galway
A18: IE-KY | B18: Kerry
A19: IE-KE | B19: Kildare
A20: IE-KK | B20: Kilkenny
A21: IE-LS | B21: Laois
... A36: IE-WW | B36: Wicklow
A37: Source: https://en.wikipedia.org/wiki/ISO_3166-2:IE

Sheet UC_ModalShares
C3: User constraints for modal share in passenger transport
B6: UC - Each Region/Period
C7: ~UC_Sets: R_E:AllRegions
C8: ~UC_Sets: T_E:
K9: ~UC_T:UC_COMPRD
C10: UC_N | D10: Pset_Set | E10: Pset_PN | F10: Pset_CI | G10: Pset_CO | H10: Cset_CN | I10: Attribute | J10: Year | K10: LimType | L10: UC_FLO | M10: UC_Desc | N10: =Regions!C$3 -> IE | O10: =Regions!E$3 -> IE-CW | P10: =Regions!F$3 -> IE-D | Q10: =Regions!G$3 -> IE-KE | R10: =Regions!H$3 -> IE-KK | S10: =Regions!I$3 -> IE-LS | T10: =Regions!J$3 -> IE-LD | U10: =Regions!K$3 -> IE-LH | V10: =Regions!L$3 -> IE-MH | ... AN10: =Regions!AD$3 -> IE-MN | AO10: UC_RHSRTS
C11: UC_walking_S | E11: =C68 -> T-WLK_WLK | H11: =E109 -> TRAPS | J11: 2018 | K11: LO | L11: -1 | M11: =D116 -> Walk | N11: =ROUNDUP(C130,3) -> 0.324 | O11: =ROUNDUP(D130,3) -> 0.296 | P11: =ROUNDUP(E130,3) -> 0.35 | Q11: =ROUNDUP(F130,3) -> 0.314 | R11: =ROUNDUP(G130,3) -> 0.301 | S11: =ROUNDUP(H130,3) -> 0.326 | T11: =ROUNDUP(I130,3) -> 0.313 | U11: =ROUNDUP(J130,3) -> 0.345 | ... AN11: =ROUNDUP(AC130,3) -> 0.293 | AO11: 0
J12: 0 | K12: LO | AO12: 5
C13: UC_cycling_S | E13: =C69 -> T-CYC_CYC | H13: =H11 -> TRAPS | J13: 2018 | K13: LO | L13: -1 | M13: =D117 -> Bike | N13: =ROUNDUP(C131,3) -> 0.054 | O13: =ROUNDUP(D131,3) -> 0.05 | P13: =ROUNDUP(E131,3) -> 0.059 | Q13: =ROUNDUP(F131,3) -> 0.053 | R13: =ROUNDUP(G131,3) -> 0.051 | S13: =ROUNDUP(H131,3) -> 0.055 | T13: =ROUNDUP(I131,3) -> 0.053 | U13: =ROUNDUP(J131,3) -> 0.058 | ... AN13: =ROUNDUP(AC131,3) -> 0.049 | AO13: 0
J14: 0 | K14: LO | AO14: 5
C15: UC_motorcycle_S | E15: =LEFT(C71,5)&"*" -> T-MOT* | H15: =H13 -> TRAPS | J15: 2018 | K15: LO | L15: -1 | M15: =D118 -> 2-wheelers | N15: =ROUNDUP(C132,4) -> 0.0013 | O15: =ROUNDUP(D132,4) -> 0.0009 | P15: =ROUNDUP(E132,4) -> 0.0015 | Q15: =ROUNDUP(F132,4) -> 0.0014 | R15: =ROUNDUP(G132,4) -> 0.001 | S15: =ROUNDUP(H132,4) -> 0.0007 | T15: =ROUNDUP(I132,4) -> 0.0013 | U15: =ROUNDUP(J132,4) -> 0.0009 | ... AG15: =ROUNDUP(V132,4) -> 0.0008 | AH15: =ROUNDUP(W132,3) -> 0.002 | AI15: =ROUNDUP(X132,4) -> 0.0008 | AJ15: =ROUNDUP(Y132,4) -> 0.0008 | AK15: =ROUNDUP(Z132,4) -> 0.0009 | AL15: =ROUNDUP(AA132,4) -> 0.0008 | AM15: =ROUNDUP(AB132,4) -> 0.0008 | AN15: =ROUNDUP(AC132,4) -> 0.0008 | AO15: 0
J16: 0 | K16: LO | AO16: 5
C17: UC_LDVs_S | E17: =LEFT(C73,5)&"*" -> T-CAR* | H17: =H15 -> TRAPS | J17: 2018 | K17: LO | L17: -1 | M17: =D119 -> LDV | N17: =ROUNDUP(C133,3) -> 0.515 | O17: =ROUNDUP(D133,3) -> 0.577 | P17: =ROUNDUP(E133,3) -> 0.416 | Q17: =ROUNDUP(F133,3) -> 0.539 | R17: =ROUNDUP(G133,3) -> 0.528 | S17: =ROUNDUP(H133,3) -> 0.545 | T17: =ROUNDUP(I133,3) -> 0.548 | U17: =ROUNDUP(J133,3) -> 0.507 | ... AN17: =ROUNDUP(AC133,3) -> 0.493 | AO17: 0
J18: 0 | K18: LO | AO18: 5
C19: UC_Taxis_S | E19: =LEFT(C83,5)&"*" -> T-TAX* | H19: =H17 -> TRAPS | J19: 2018 | K19: LO | L19: -1 | M19: =D120 -> Taxis | N19: =ROUNDUP(C134,3) -> 0.017 | O19: =ROUNDUP(D134,3) -> 0.008 | P19: =ROUNDUP(E134,3) -> 0.033 | Q19: =ROUNDUP(F134,3) -> 0.015 | R19: =ROUNDUP(G134,3) -> 0.008 | S19: =ROUNDUP(H134,3) -> 0.01 | T19: =ROUNDUP(I134,3) -> 0.009 | U19: =ROUNDUP(J134,3) -> 0.02 | ... AN19: =ROUNDUP(AC134,3) -> 0.005 | AO19: 0
J20: 0 | K20: LO | AO20: 5
C21: UC_BUS_S | E21: =LEFT(C87,5)&"*" -> T-BUS* | H21: =H19 -> TRAPS | J21: 2018 | K21: LO | L21: -1 | M21: =D121 -> BUS | N21: =ROUNDUP(C135,3) -> 0.083 | O21: =ROUNDUP(D135,3) -> 0.071 | P21: =ROUNDUP(E135,3) -> 0.114 | Q21: =ROUNDUP(F135,3) -> 0.081 | R21: =ROUNDUP(G135,3) -> 0.113 | S21: =ROUNDUP(H135,3) -> 0.065 | T21: =ROUNDUP(I135,3) -> 0.078 | U21: =ROUNDUP(J135,3) -> 0.073 | ... AN21: =ROUNDUP(AC135,3) -> 0.161 | AO21: 0
J22: 0 | K22: LO | AO22: 5
C23: UC_Light_rail_LUAS_S | E23: =LEFT(C89,5)&"*" -> T-LPT* | H23: =H21 -> TRAPS | J23: 2018 | K23: LO | L23: -1 | M23: =D122 -> Light rail (LUAS) | N23: =ROUNDUP(C136,3) -> 0.008 | O23: =ROUNDUP(D136,3) -> 0 | P23: =ROUNDUP(E136,3) -> 0.03 | Q23: =ROUNDUP(F136,3) -> 0 | R23: =ROUNDUP(G136,3) -> 0 | S23: =ROUNDUP(H136,3) -> 0 | T23: =ROUNDUP(I136,3) -> 0 | U23: =ROUNDUP(J136,3) -> 0 | ... AN23: =ROUNDUP(AC136,3) -> 0 | AO23: 0
J24: 0 | K24: LO | AO24: 5
M26: check | N26: =SUM(N11:N24) -> 1.0023 | O26: =SUM(O11:O24) -> 1.0029 | P26: =SUM(P11:P24) -> 1.0035 | Q26: =SUM(Q11:Q24) -> 1.0034 | R26: =SUM(R11:R24) -> 1.002 | S26: =SUM(S11:S24) -> 1.0017 | T26: =SUM(T11:T24) -> 1.0023 | U26: =SUM(U11:U24) -> 1.0039 | ... AN26: =SUM(AN11:AN24) -> 1.0018
K31: ~UC_T:UC_COMPRD
C32: UC_N | D32: Pset_Set | E32: Pset_PN | F32: Pset_CI | G32: Pset_CO | H32: Cset_CN | I32: Attribute | J32: Year | K32: LimType | L32: UC_FLO | M32: UC_Desc | N32: =Regions!C$3 -> IE | O32: =Regions!E$3 -> IE-CW | P32: =Regions!F$3 -> IE-D | Q32: =Regions!G$3 -> IE-KE | R32: =Regions!H$3 -> IE-KK | S32: =Regions!I$3 -> IE-LS | T32: =Regions!J$3 -> IE-LD | U32: =Regions!K$3 -> IE-LH | V32: =Regions!L$3 -> IE-MH | ... AN32: =Regions!AD$3 -> IE-MN | AO32: UC_RHSRTS
C33: UC_motorcycle_M | E33: =E15 -> T-MOT* | H33: =E110 -> TRAPM | J33: 2018 | K33: LO | L33: -1 | M33: =M15 -> 2-wheelers | N33: =ROUNDUP(C146,4) -> 0.0033 | O33: =ROUNDUP(D146,4) -> 0.0022 | P33: =ROUNDUP(E146,4) -> 0.0042 | Q33: =ROUNDUP(F146,4) -> 0.0037 | R33: =ROUNDUP(G146,4) -> 0.0026 | S33: =ROUNDUP(H146,4) -> 0.0017 | T33: =ROUNDUP(I146,4) -> 0.0033 | U33: =ROUNDUP(J146,4) -> 0.0025 | ... AG33: =ROUNDUP(V146,4) -> 0.0022 | AH33: =ROUNDUP(W146,3) -> 0.005 | AI33: =ROUNDUP(X146,4) -> 0.002 | AJ33: =ROUNDUP(Y146,4) -> 0.0018 | AK33: =ROUNDUP(Z146,4) -> 0.0022 | AL33: =ROUNDUP(AA146,4) -> 0.002 | AM33: =ROUNDUP(AB146,4) -> 0.0022 | AN33: =ROUNDUP(AC146,4) -> 0.002 | AO33: 0
J34: 0 | K34: LO | AO34: 5
C35: UC_LDVs_M | E35: =E17 -> T-CAR* | H35: =H33 -> TRAPM | J35: 2018 | K35: LO | L35: -1 | M35: =M17 -> LDV | N35: =ROUNDUP(C147,3) -> 0.835 | O35: =ROUNDUP(D147,3) -> 0.882 | P35: =ROUNDUP(E147,3) -> 0.725 | Q35: =ROUNDUP(F147,3) -> 0.851 | R35: =ROUNDUP(G147,3) -> 0.814 | S35: =ROUNDUP(H147,3) -> 0.881 | T35: =ROUNDUP(I147,3) -> 0.863 | U35: =ROUNDUP(J147,3) -> 0.85 | ... AN35: =ROUNDUP(AC147,3) -> 0.749 | AO35: 0
J36: 0 | K36: LO | AO36: 5
C37: UC_Taxis_M | E37: =E19 -> T-TAX* | H37: =H35 -> TRAPM | J37: 2018 | K37: LO | L37: -1 | M37: =M19 -> Taxis | N37: =ROUNDUP(C148,3) -> 0.022 | O37: =ROUNDUP(D148,3) -> 0.01 | P37: =ROUNDUP(E148,3) -> 0.047 | Q37: =ROUNDUP(F148,3) -> 0.019 | R37: =ROUNDUP(G148,3) -> 0.01 | S37: =ROUNDUP(H148,3) -> 0.014 | T37: =ROUNDUP(I148,3) -> 0.012 | U37: =ROUNDUP(J148,3) -> 0.027 | ... AN37: =ROUNDUP(AC148,3) -> 0.006 | AO37: 0
J38: 0 | K38: LO | AO38: 5
C39: UC_BUS_M | E39: =E21 -> T-BUS* | H39: =H37 -> TRAPM | J39: 2018 | K39: LO | L39: -1 | M39: =M21 -> BUS | N39: =ROUNDUP(C149,3) -> 0.135 | O39: =ROUNDUP(D149,3) -> 0.108 | P39: =ROUNDUP(E149,3) -> 0.199 | Q39: =ROUNDUP(F149,3) -> 0.128 | R39: =ROUNDUP(G149,3) -> 0.174 | S39: =ROUNDUP(H149,3) -> 0.106 | T39: =ROUNDUP(I149,3) -> 0.123 | U39: =ROUNDUP(J149,3) -> 0.122 | ... AN39: =ROUNDUP(AC149,3) -> 0.245 | AO39: 0
J40: 0 | K40: LO | AO40: 5
C41: UC_Light_rail_LUAS_M | E41: =E23 -> T-LPT* | H41: =H39 -> TRAPM | J41: 2018 | K41: LO | L41: -1 | M41: =M23 -> Light rail (LUAS) | N41: =ROUNDUP(C150,3) -> 0.007 | O41: =ROUNDUP(D150,3) -> 0 | P41: =ROUNDUP(E150,3) -> 0.027 | Q41: =ROUNDUP(F150,3) -> 0 | R41: =ROUNDUP(G150,3) -> 0 | S41: =ROUNDUP(H150,3) -> 0 | T41: =ROUNDUP(I150,3) -> 0 | U41: =ROUNDUP(J150,3) -> 0 | ... AN41: =ROUNDUP(AC150,3) -> 0 | AO41: 0
J42: 0 | K42: LO | AO42: 5
M44: check | N44: =SUM(N33:N42) -> 1.0023 | O44: =SUM(O33:O42) -> 1.0022 | P44: =SUM(P33:P42) -> 1.0022 | Q44: =SUM(Q33:Q42) -> 1.0017 | R44: =SUM(R33:R42) -> 1.0006 | S44: =SUM(S33:S42) -> 1.0027 | T44: =SUM(T33:T42) -> 1.0013 | U44: =SUM(U33:U42) -> 1.0015 | ... AN44: =SUM(AN33:AN42) -> 1.002
K49: ~UC_T:UC_COMPRD
C50: UC_N | D50: Pset_Set | E50: Pset_PN | F50: Pset_CI | G50: Pset_CO | H50: Cset_CN | I50: Attribute | J50: Year | K50: LimType | L50: UC_FLO | M50: UC_Desc | N50: =Regions!C$3 -> IE | O50: =Regions!E$3 -> IE-CW | P50: =Regions!F$3 -> IE-D | Q50: =Regions!G$3 -> IE-KE | R50: =Regions!H$3 -> IE-KK | S50: =Regions!I$3 -> IE-LS | T50: =Regions!J$3 -> IE-LD | U50: =Regions!K$3 -> IE-LH | V50: =Regions!L$3 -> IE-MH | ... AN50: =Regions!AD$3 -> IE-MN | AO50: UC_RHSRTS
C51: UC_LDVs_L | E51: =E35 -> T-CAR* | H51: =E111 -> TRAPL | J51: 2018 | K51: LO | L51: -1 | M51: =M35 -> LDV | N51: =ROUNDUP(C161,3) -> 0.742 | O51: =ROUNDUP(D161,3) -> 0.791 | P51: =ROUNDUP(E161,3) -> 0.639 | Q51: =ROUNDUP(F161,3) -> 0.756 | R51: =ROUNDUP(G161,3) -> 0.714 | S51: =ROUNDUP(H161,3) -> 0.782 | T51: =ROUNDUP(I161,3) -> 0.767 | U51: =ROUNDUP(J161,3) -> 0.749 | ... AN51: =ROUNDUP(AC161,3) -> 0.643 | AO51: 0
J52: 0 | K52: LO | AO52: 5
C53: UC_Taxis_L | E53: =E37 -> T-TAX* | H53: =H51 -> TRAPL | J53: 2018 | K53: LO | L53: -1 | M53: =M37 -> Taxis | N53: =ROUNDUP(C162,3) -> 0.013 | O53: =ROUNDUP(D162,3) -> 0.006 | P53: =ROUNDUP(E162,3) -> 0.026 | Q53: =ROUNDUP(F162,3) -> 0.011 | R53: =ROUNDUP(G162,3) -> 0.006 | S53: =ROUNDUP(H162,3) -> 0.008 | T53: =ROUNDUP(I162,3) -> 0.007 | U53: =ROUNDUP(J162,3) -> 0.015 | ... AN53: =ROUNDUP(AC162,3) -> 0.003 | AO53: 0
J54: 0 | K54: LO | AO54: 5
...
