Workbook

Sheet Cover
A16: TIMES-Ireland Model
A19: Document type: | B19: Scenario
A20: Sector(s): | B20: Residential sector (RSD)
A21: Purpose: | B21: Sets the maximum share of retrofits per selected years
A23: Original developer(s): | B23: Jason Mc Guire ( MaREI, jason.mcguire@ucc.ie)
B24: Alessandro Chiodi ( E4SMA, alessandro.chiodi@e4sma.com)
A26: Current maintainer(s): | B26: Jason Mc Guire ( MaREI, jason.mcguire@ucc.ie)
B27: Olexandr Balyk ( MaREI, olexandr.balyk@ucc.ie)
A29: Part of TIM version: | B29: 1
A30: Model repository: | B30: https://github.com/MaREI-EPMG/TIMES-Ireland-model
A31: Licence: | B31: CC BY-NC-SA 4.0 (unless specified otherwise)
B32: https://creativecommons.org/licenses/by-nc-sa/4.0/

Sheet Regions
C3: {=INDEX(C5:C7,$A$4)} -> IE | D3: {=INDEX(D5:D7,$A$4)} -> National | E3: {=INDEX(E5:E7,$A$4)} -> IE-CW | F3: {=INDEX(F5:F7,$A$4)} -> IE-D | G3: {=INDEX(G5:G7,$A$4)} -> IE-KE | H3: {=INDEX(H5:H7,$A$4)} -> IE-KK | I3: {=INDEX(I5:I7,$A$4)} -> IE-LS | J3: {=INDEX(J5:J7,$A$4)} -> IE-LD | ... AD3: {=INDEX(AD5:AD7,$A$4)} -> IE-MN
A4: 1
A5: Development | C5: IE | D5: National | E5: =Regions!A11 -> IE-CW | F5: =Regions!A16 -> IE-D | G5: =Regions!A19 -> IE-KE | H5: =Regions!A20 -> IE-KK | I5: =Regions!A21 -> IE-LS | J5: =Regions!A24 -> IE-LD | K5: =Regions!A25 -> IE-LH | L5: =Regions!A27 -> IE-MH | M5: =Regions!A29 -> IE-OY | N5: =Regions!A34 -> IE-WH | O5: =Regions!A35 -> IE-WX | P5: =Regions!A36 -> IE-WW | Q5: =Regions!A13 -> IE-CE | R5: =Regions!A14 -> IE-CO | S5: =Regions!A18 -> IE-KY | T5: =Regions!A23 -> IE-LK | U5: =Regions!A32 -> IE-TA | V5: =Regions!A33 -> IE-WD | W5: =Regions!A17 -> IE-G | X5: =Regions!A22 -> IE-LM | Y5: =Regions!A26 -> IE-MO | Z5: =Regions!A30 -> IE-RN | AA5: =Regions!A31 -> IE-SO | AB5: =Regions!A12 -> IE-CN | AC5: =Regions!A15 -> IE-DL | AD5: =Regions!A28 -> IE-MN
A6: Single-region | C6: =C5 -> IE | D6: ="*"&D5 -> *National | E6: ="*"&E5 -> *IE-CW | F6: ="*"&F5 -> *IE-D | G6: ="*"&G5 -> *IE-KE | H6: ="*"&H5 -> *IE-KK | I6: ="*"&I5 -> *IE-LS | J6: ="*"&J5 -> *IE-LD | K6: ="*"&K5 -> *IE-LH | ... AD6: ="*"&AD5 -> *IE-MN
A7: Multi-region | C7: ="*"&C5 -> *IE | D7: =D5 -> National | E7: =E5 -> IE-CW | F7: =F5 -> IE-D | G7: =G5 -> IE-KE | H7: =H5 -> IE-KK | I7: =I5 -> IE-LS | J7: =J5 -> IE-LD | K7: =K5 -> IE-LH | ... AD7: =AD5 -> IE-MN
A10: Code | B10: County name
A11: IE-CW | B11: Carlow
A12: IE-CN | B12: Cavan
A13: IE-CE | B13: Clare
A14: IE-CO | B14: Cork
A15: IE-DL | B15: Donegal
A16: IE-D | B16: Dublin
A17: IE-G | B17: Galway
A18: IE-KY | B18: Kerry
A19: IE-KE | B19: Kildare
A20: IE-KK | B20: Kilkenny
A21: IE-LS | B21: Laois
... A36: IE-WW | B36: Wicklow
A37: Source: https://en.wikipedia.org/wiki/ISO_3166-2:IE

Sheet UC unit boilers
A1: Maximum retrofit
A2: Note: This UC controls the maximum amount of retrofitted dwellings
A4: =_xlfn.TEXTJOIN(" ",TRUE,"~UC_Sets: R_E:",_xlfn.TEXTJOIN(",",TRUE,IF(LEFT(Regions!$C$3,1)<>"*",Regions!$C$3,""),IF(LEFT(Regions!$D$3,1)<>"*",Regions!$D$3,""))) -> ~UC_Sets: R_E: IE,National
A5: ~UC_Sets: T_E:
D6: ~UC_T: UC_RHSRT
A7: UC_N | B7: UC_Desc | C7: PSet_PN | D7: LimType | E7: UC_CAP | F7: 2018 | G7: 2030 | H7: 2070 | I7: UC_RHSRT~0 | K7: Dwelling type
A8: ="UC_RSD_RTFT_"&RIGHT(C8,5) -> UC_RSD_RTFT_Apt_G | B8: ="Maximum number of deep retrofits from Apartment_" &RIGHT(C8,1) -> Maximum number of deep retrofits from Apartment_G | C8: R-RTFT-Apt_G | D8: UP | E8: 1 | F8: =($E$54*F$29)/1000 -> 3.0422344 | G8: =(E54*G$28)/1000 -> 11.408379 | H8: =(H54*H$27)/1000 -> 12.041696 | I8: 5 | K8: Apt
A9: ="UC_RSD_RTFT_"&RIGHT(C9,5) -> UC_RSD_RTFT_Apt_F | B9: ="Maximum number of deep retrofits from Apartment_" &RIGHT(C9,1) -> Maximum number of deep retrofits from Apartment_F | C9: R-RTFT-Apt_F | D9: UP | E9: 1 | F9: =($E$53*F$29)/1000 -> 2.4662346 | G9: =(E53*G$28)/1000 -> 9.2483799 | H9: =(H53*H$27)/1000 -> 9.7617883 | I9: 5 | K9: Apt
A10: ="UC_RSD_RTFT_"&RIGHT(C10,5) -> UC_RSD_RTFT_Apt_E | B10: ="Maximum number of deep retrofits from Apartment_" &RIGHT(C10,1) -> Maximum number of deep retrofits from Apartment_E | C10: R-RTFT-Apt_E | D10: UP | E10: 1 | F10: =($E$52*F$29)/1000 -> 5.1535753 | G10: =(E52*G$28)/1000 -> 19.325907 | H10: =(H52*H$27)/1000 -> 20.398753 | I10: 5 | K10: Apt
A11: ="UC_RSD_RTFT_"&RIGHT(C11,5) -> UC_RSD_RTFT_Apt_D | B11: ="Maximum number of deep retrofits from Apartment_" &RIGHT(C11,1) -> Maximum number of deep retrofits from Apartment_D | C11: R-RTFT-Apt_D | D11: UP | E11: 1 | F11: =($E$51*F$29)/1000 -> 8.7478683 | G11: =(E51*G$28)/1000 -> 32.804506 | H11: =(H51*H$27)/1000 -> 34.625594 | I11: 5 | K11: Apt
A12: ="UC_RSD_RTFT_"&RIGHT(C12,5) -> UC_RSD_RTFT_Apt_C | B12: ="Maximum number of deep retrofits from Apartment_" &RIGHT(C12,1) -> Maximum number of deep retrofits from Apartment_C | C12: R-RTFT-Apt_C | D12: UP | E12: 1 | F12: =($E$50*F$29)/1000 -> 11.780961 | G12: =(E50*G$28)/1000 -> 44.178603 | H12: =(H50*H$27)/1000 -> 46.631104 | I12: 5 | K12: Apt
A13: ="UC_RSD_RTFT_"&RIGHT(C13,6) -> UC_RSD_RTFT_Apt_B3 | B13: ="Maximum number of deep retrofits from Apartment_" &RIGHT(C13,2) -> Maximum number of deep retrofits from Apartment_B3 | C13: R-RTFT-Apt_B3 | D13: UP | E13: 1 | F13: =($E$49*F$29)/1000 -> 3.9848961 | G13: =(E49*G$28)/1000 -> 14.94336 | H13: =(H49*H$27)/1000 -> 15.772916 | I13: 5 | K13: Apt
A14: ="UC_RSD_RTFT_"&RIGHT(C14,5) -> UC_RSD_RTFT_Att_G | B14: ="Maximum number of deep retrofits from Attached_" &RIGHT(C14,1) -> Maximum number of deep retrofits from Attached_G | C14: R-RTFT-Att_G | D14: UP | E14: 1 | F14: =($C$54*F$29)/1000 -> 10.541335 | G14: =(C54*G$28)/1000 -> 39.530006 | H14: =(F54*H$27)/1000 -> 41.724448 | I14: 5 | K14: Att
A15: ="UC_RSD_RTFT_"&RIGHT(C15,5) -> UC_RSD_RTFT_Att_F | B15: ="Maximum number of deep retrofits from Attached_" &RIGHT(C15,1) -> Maximum number of deep retrofits from Attached_F | C15: R-RTFT-Att_F | D15: UP | E15: 1 | F15: =($C$53*F$29)/1000 -> 10.024761 | G15: =(C53*G$28)/1000 -> 37.592855 | H15: =(F53*H$27)/1000 -> 39.679759 | I15: 5 | K15: Att
A16: ="UC_RSD_RTFT_"&RIGHT(C16,5) -> UC_RSD_RTFT_Att_E | B16: ="Maximum number of deep retrofits from Attached_" &RIGHT(C16,1) -> Maximum number of deep retrofits from Attached_E | C16: R-RTFT-Att_E | D16: UP | E16: 1 | F16: =($C$52*F$29)/1000 -> 20.283779 | G16: =(C52*G$28)/1000 -> 76.064172 | H16: =(F52*H$27)/1000 -> 80.286748 | I16: 5 | K16: Att
A17: ="UC_RSD_RTFT_"&RIGHT(C17,5) -> UC_RSD_RTFT_Att_D | B17: ="Maximum number of deep retrofits from Attached_" &RIGHT(C17,1) -> Maximum number of deep retrofits from Attached_D | C17: R-RTFT-Att_D | D17: UP | E17: 1 | F17: =($C$51*F$29)/1000 -> 37.525404 | G17: =(C51*G$28)/1000 -> 140.72027 | H17: =(F51*H$27)/1000 -> 148.53212 | I17: 5 | K17: Att
A18: ="UC_RSD_RTFT_"&RIGHT(C18,5) -> UC_RSD_RTFT_Att_C | B18: ="Maximum number of deep retrofits from Attached_" &RIGHT(C18,1) -> Maximum number of deep retrofits from Attached_C | C18: R-RTFT-Att_C | D18: UP | E18: 1 | F18: =($C$50*F$29)/1000 -> 56.430305 | G18: =(C50*G$28)/1000 -> 211.61365 | H18: =(F50*H$27)/1000 -> 223.36102 | I18: 5 | K18: Att
A19: ="UC_RSD_RTFT_"&RIGHT(C19,6) -> UC_RSD_RTFT_Att_B3 | B19: ="Maximum number of deep retrofits from Attached_" &RIGHT(C19,2) -> Maximum number of deep retrofits from Attached_B3 | C19: R-RTFT-Att_B3 | D19: UP | E19: 1 | F19: =($C$49*F$29)/1000 -> 9.9537699 | G19: =(C49*G$28)/1000 -> 37.326637 | H19: =(F49*H$27)/1000 -> 39.398763 | I19: 5 | K19: Att
A20: ="UC_RSD_RTFT_"&RIGHT(C20,5) -> UC_RSD_RTFT_Det_G | B20: ="Maximum number of deep retrofits from Detached_" &RIGHT(C20,1) -> Maximum number of deep retrofits from Detached_G | C20: R-RTFT-Det_G | D20: UP | E20: 1 | F20: =($D$54*F$29)/1000 -> 15.687107 | G20: =(D54*G$28)/1000 -> 58.82665 | H20: =(G54*H$27)/1000 -> 62.092314 | I20: 5 | K20: Det
A21: ="UC_RSD_RTFT_"&RIGHT(C21,5) -> UC_RSD_RTFT_Det_F | B21: ="Maximum number of deep retrofits from Detached_" &RIGHT(C21,1) -> Maximum number of deep retrofits from Detached_F | C21: R-RTFT-Det_F | D21: UP | E21: 1 | F21: =($D$53*F$29)/1000 -> 8.6482012 | G21: =(D53*G$28)/1000 -> 32.430754 | H21: =(G53*H$27)/1000 -> 34.231094 | I21: 5 | K21: Det
A22: ="UC_RSD_RTFT_"&RIGHT(C22,5) -> UC_RSD_RTFT_Det_E | B22: ="Maximum number of deep retrofits from Detached_" &RIGHT(C22,1) -> Maximum number of deep retrofits from Detached_E | C22: R-RTFT-Det_E | D22: UP | E22: 1 | F22: =($D$52*F$29)/1000 -> 16.27934 | G22: =(D52*G$28)/1000 -> 61.047523 | H22: =(G52*H$27)/1000 -> 64.436475 | I22: 5 | K22: Det
A23: ="UC_RSD_RTFT_"&RIGHT(C23,5) -> UC_RSD_RTFT_Det_D | B23: ="Maximum number of deep retrofits from Detached_" &RIGHT(C23,1) -> Maximum number of deep retrofits from Detached_D | C23: R-RTFT-Det_D | D23: UP | E23: 1 | F23: =($D$51*F$29)/1000 -> 33.333558 | G23: =(D51*G$28)/1000 -> 125.00084 | H23: =(G51*H$27)/1000 -> 131.94006 | I23: 5 | K23: Det
A24: ="UC_RSD_RTFT_"&RIGHT(C24,5) -> UC_RSD_RTFT_Det_C | B24: ="Maximum number of deep retrofits from Detached_" &RIGHT(C24,1) -> Maximum number of deep retrofits from Detached_C | C24: R-RTFT-Det_C | D24: UP | E24: 1 | F24: =($D$50*F$29)/1000 -> 50.263787 | G24: =(D50*G$28)/1000 -> 188.4892 | H24: =(G50*H$27)/1000 -> 198.95286 | I24: 5 | K24: Det
A25: ="UC_RSD_RTFT_"&RIGHT(C25,6) -> UC_RSD_RTFT_Det_B3 | B25: ="Maximum number of deep retrofits from Detached_" &RIGHT(C25,2) -> Maximum number of deep retrofits from Detached_B3 | C25: R-RTFT-Det_B3 | D25: UP | E25: 1 | F25: =($D$49*F$29)/1000 -> 10.693242 | G25: =(D49*G$28)/1000 -> 40.099658 | H25: =(G49*H$27)/1000 -> 42.325723 | I25: 5 | K25: Det
C27: Max % retrofit by 2070: | H27: 0.95
C28: Max % retrofit by 2030: | G28: 0.75
C29: Max % retrofit by 2018: | F29: 0.2
F30: =SUM(F8:F25) -> 314.84036 | G30: =SUM(G8:G25) -> 1180.6513 | H30: =SUM(H8:H25) -> 1246.1932
D32: UC_T: UC_RHSRT
A33: UC_N | B33: UC_Desc | C33: PSet_PN | D33: LimType | E33: UC_CAP | F33: 2018 | G33: 2030 | H33: 2070 | I33: UC_RHSRT~0
A34: ="UC_RSD_RTFT_Apt" -> UC_RSD_RTFT_Apt | B34: ="Minimum number of deep retrofits from Apartments" -> Minimum number of deep retrofits from Apartments | C34: R-RTFT-Apt_G,R-RTFT-Apt_F,R-RTFT-Apt_E,R-RTFT-Apt_D,R-RTFT-Apt_C,R-RTFT-Apt_B3 | D34: LO | E34: 1 | F34: =(SUM($E$49:$E$54)*F$40)/1000 -> 0 | G34: =(SUM($E$49:$E$54)*G$39)/1000 -> 17.587885 | H34: =(SUM($H$49:$H$54)*H$38)/1000 -> 36.639961 | I34: 1
A35: ="UC_RSD_RTFT_Att" -> UC_RSD_RTFT_Att | B35: ="Minimum number of deep retrofits from Attached" -> Minimum number of deep retrofits from Attached | C35: R-RTFT-Att_G,R-RTFT-Att_F,R-RTFT-Att_E,R-RTFT-Att_D,R-RTFT-Att_C,R-RTFT-Att_B3 | D35: LO | E35: 1 | F35: =(SUM($C$49:$C$54)*F$40)/1000 -> 0 | G35: =(SUM($C$49:$C$54)*G$39)/1000 -> 72.379678 | H35: =(SUM($F$49:$F$54)*H$38)/1000 -> 150.78496 | I35: 1
A36: ="UC_RSD_RTFT_Det" -> UC_RSD_RTFT_Det | B36: ="Minimum number of deep retrofits from Detached" -> Minimum number of deep retrofits from Detached | C36: R-RTFT-Det_G,R-RTFT-Det_F,R-RTFT-Det_E,R-RTFT-Det_D,R-RTFT-Det_C,R-RTFT-Det_B3 | D36: LO | E36: 1 | F36: =(SUM($D$49:$D$54)*F$40)/1000 -> 0 | G36: =(SUM($D$49:$D$54)*G$39)/1000 -> 67.452617 | H36: =(SUM($G$49:$G$54)*H$38)/1000 -> 140.52066 | I36: 1
C38: Min % retrofit by 2070: | H38: 0.25
C39: Min % retrofit by 2030: | G39: 0.1
C40: Min % retrofit by 2018: | F40: 0
F41: =SUM(F34:F37) -> 0 | G41: =SUM(G34:G36) -> 157.42018 | H41: =SUM(H34:H37) -> 327.94559
B43: Final Dwelling Stock Table | K43: 2070 compared to 2018
C44: 2018 | F44: 2070 | K44: 0.8333
B45: BER Rating | C45: Attached | D45: Detached | E45: Apartment | F45: Attached | G45: Detached | H45: Apartment
...
