Workbook

Sheet Cover
A16: TIMES-Ireland Model
A19: Document type: | B19: Scenario
A20: Sector(s): | B20: All sectors
A21: Purpose: | B21: Impose historical bounds on emissions, car sales, fuel consumption, etc.
A23: Original developer(s): | B23: Olexandr Balyk (UCC, olexandr.balyk@ucc.ie)
B24: Vahid Aryanpur (UCC, vahid.aryanpur@ucc.ie)
B25: Hannah Daly (UCC, h.daly@ucc.ie)
A26: Current maintainer(s): | B26: Bakytzhan Suleimenov (UCC, bsuleimenov@ucc.ie)
B27: Vahid Aryanpur (UCC, vahid.aryanpur@ucc.ie)
A29: Part of TIM version: | B29: 1
A30: Model repository: | B30: https://github.com/MaREI-EPMG/TIMES-Ireland-model
A31: Licence: | B31: CC BY-NC-SA 4.0 (unless specified otherwise)
B32: https://creativecommons.org/licenses/by-nc-sa/4.0/

Sheet Regions
C3: {=INDEX(C5:C7,$A$4)} -> IE | D3: {=INDEX(D5:D7,$A$4)} -> National | E3: {=INDEX(E5:E7,$A$4)} -> IE-CW | F3: {=INDEX(F5:F7,$A$4)} -> IE-D | G3: {=INDEX(G5:G7,$A$4)} -> IE-KE | H3: {=INDEX(H5:H7,$A$4)} -> IE-KK | I3: {=INDEX(I5:I7,$A$4)} -> IE-LS | J3: {=INDEX(J5:J7,$A$4)} -> IE-LD | ... AD3: {=INDEX(AD5:AD7,$A$4)} -> IE-MN
A4: 1
A5: Development | C5: IE | D5: National | E5: =A11 -> IE-CW | F5: =A16 -> IE-D | G5: =A19 -> IE-KE | H5: =A20 -> IE-KK | I5: =A21 -> IE-LS | J5: =A24 -> IE-LD | K5: =A25 -> IE-LH | L5: =A27 -> IE-MH | M5: =A29 -> IE-OY | N5: =A34 -> IE-WH | O5: =A35 -> IE-WX | P5: =A36 -> IE-WW | Q5: =A13 -> IE-CE | R5: =A14 -> IE-CO | S5: =A18 -> IE-KY | T5: =A23 -> IE-LK | U5: =A32 -> IE-TA | V5: =A33 -> IE-WD | W5: =A17 -> IE-G | X5: =A22 -> IE-LM | Y5: =A26 -> IE-MO | Z5: =A30 -> IE-RN | AA5: =A31 -> IE-SO | AB5: =A12 -> IE-CN | AC5: =A15 -> IE-DL | AD5: =A28 -> IE-MN
A6: Single-region | C6: =C5 -> IE | D6: ="*"&D5 -> *National | E6: ="*"&E5 -> *IE-CW | F6: ="*"&F5 -> *IE-D | G6: ="*"&G5 -> *IE-KE | H6: ="*"&H5 -> *IE-KK | I6: ="*"&I5 -> *IE-LS | J6: ="*"&J5 -> *IE-LD | K6: ="*"&K5 -> *IE-LH | ... AD6: ="*"&AD5 -> *IE-MN
A7: Multi-region | C7: ="*"&C5 -> *IE | D7: =D5 -> National | E7: =E5 -> IE-CW | F7: =F5 -> IE-D | G7: =G5 -> IE-KE | H7: =H5 -> IE-KK | I7: =I5 -> IE-LS | J7: =J5 -> IE-LD | K7: =K5 -> IE-LH | ... AD7: =AD5 -> IE-MN
A10: Code | B10: County name
A11: IE-CW | B11: Carlow
A12: IE-CN | B12: Cavan
A13: IE-CE | B13: Clare
A14: IE-CO | B14: Cork
A15: IE-DL | B15: Donegal
A16: IE-D | B16: Dublin
A17: IE-G | B17: Galway
A18: IE-KY | B18: Kerry
A19: IE-KE | B19: Kildare
A20: IE-KK | B20: Kilkenny
A21: IE-LS | B21: Laois
... A36: IE-WW | B36: Wicklow
A37: Source: https://en.wikipedia.org/wiki/ISO_3166-2:IE

Sheet SUP
A1: UC - Each Region/All Periods
B2: ="~UC_Sets: R_E: " & _xlfn.TEXTJOIN(",",TRUE,Regions!C3,Regions!D3) -> ~UC_Sets: R_E: IE,National
B3: ~UC_Sets: T_S:
H4: =IF(RIGHT(B2,1)<>" ","~UC_T","") -> ~UC_T
B5: UC_N | C5: Cset_CN | D5: Pset_Set | E5: Pset_PN | F5: Year | G5: LimType | H5: Other_indexes | I5: UC_IRE | J5: UC_RHSRTS | K5: UC_Desc
B6: *Units | J6: *Pja
B7: UC_Historic_ELC-Import | C7: ELCC | D7: IRE | E7: IMPELC* | F7: 2018 | G7: FX | H7: imp | I7: 1 | J7: =Conversions!$B$2*'EB2018'!$AO$3 -> 5.8385184 | K7: Historic electricity import
F8: 2019 | G8: FX | J8: =Conversions!$B$2*'EB2019'!$AO$3 -> 7.8478966
F9: 2020 | G9: FX | J9: =Conversions!$B$2*'EB2020'!$AO$3 -> 6.3411437
F10: 2021 | G10: FX | J10: =Conversions!$B$2*'EB2021'!$AO$3 -> 8.8241635
F11: 2022 | G11: FX | J11: =Conversions!$B$2*'EB2022'!$AO$3 -> 5.6948893
F12: 0 | G12: FX | J12: 1
B13: UC_Historic_ELC-Export | C13: ELCC | D13: IRE | E13: EXPELC* | F13: 2018 | G13: FX | H13: exp | I13: 1 | J13: =Conversions!$B$2*'EB2018'!$AO$4 -> 5.9383641 | K13: Historic electricity export
F14: 2019 | G14: FX | J14: =Conversions!$B$2*'EB2019'!$AO$4 -> 5.5271334
F15: 2020 | G15: FX | J15: =Conversions!$B$2*'EB2020'!$AO$4 -> 6.8879158
F16: 2021 | G16: FX | J16: =Conversions!$B$2*'EB2021'!$AO$4 -> 3.1077995
F17: 2022 | G17: FX | J17: =Conversions!$B$2*'EB2022'!$AO$4 -> 4.7878933
F18: 0 | G18: FX | J18: 1
H21: deact~UC_T
B22: UC_N | C22: Cset_CN | D22: Pset_Set | E22: Pset_PN | F22: Year | G22: LimType | H22: Other_indexes | I22: UC_COMPRD | J22: UC_RHSRTS | K22: UC_Desc
B23: UC_Historic_BIOGAS-Production | C23: BIOGAS*G | F23: 2018 | G23: UP | I23: 1 | J23: =Conversions!$B$2*'EB2018'!$AH$2 -> 0.70393223 | K23: Historic production of biogas
F24: 2019 | G24: UP | J24: =Conversions!$B$2*'EB2019'!$AH$2 -> 0.78962633
F25: 2020 | G25: UP | J25: =Conversions!$B$2*'EB2020'!$AH$2 -> 0.87833841
F26: 2021 | G26: UP | J26: =Conversions!$B$2*'EB2021'!$AH$2 -> 0.94933194
F27: 2022 | G27: UP | J27: =Conversions!$B$2*'EB2022'!$AH$2 -> 1.1527997
F28: 0 | G28: UP | J28: 1

Sheet PWR
K1: Calibration margin | L1: 0.05
B2: deact~TFM_INS-TS | P2: ~TFM_INS-TS
B3: LimType | C3: PSET_PN | D3: Attribute | E3: Region | F3: 2018 | G3: 2019 | H3: 2020 | I3: 2021 | J3: 2022 | K3: 0 | P3: LimType | Q3: PSET_PN | R3: Attribute | S3: Region | T3: 2018 | U3: 2019 | V3: 2020 | W3: 2021 | X3: 2022 | Y3: 0
C4: FT-PWRBGS | D4: ACT_BND | E4: =_xlfn.TEXTJOIN(",",TRUE,Regions!$C$3:$D$3) -> IE,National | F4: =ROUNDUP(Conversions!$B$2*SUM('EB2018'!$AG$10,'EB2018'!$AG$11,'EB2018'!$AH$10,'EB2018'!$AH$11),1) -> 1.7 | G4: =ROUNDUP(Conversions!$B$2*SUM('EB2019'!$AG$10,'EB2019'!$AG$11,'EB2019'!$AH$10,'EB2019'!$AH$11),1) -> 1.7 | H4: =ROUNDUP(Conversions!$B$2*SUM('EB2020'!$AG$10,'EB2020'!$AG$11,'EB2020'!$AH$10,'EB2020'!$AH$11),1) -> 1.6 | I4: =ROUNDUP(Conversions!$B$2*SUM('EB2021'!$AG$10,'EB2021'!$AG$11,'EB2021'!$AH$10,'EB2021'!$AH$11),1) -> 1.7 | J4: =ROUNDUP(Conversions!$B$2*SUM('EB2022'!$AG$10,'EB2022'!$AG$11,'EB2022'!$AH$10,'EB2022'!$AH$11),1) -> 1.6 | K4: 1 | P4: UP | Q4: FT-PWRBGS | R4: ACT_BND | S4: =_xlfn.TEXTJOIN(",",TRUE,Regions!$C$3:$D$3) -> IE,National | T4: =+F4*(1+$L$1) -> 1.785 | U4: =+G4*(1+$L$1) -> 1.785 | V4: =+H4*(1+$L$1) -> 1.68 | W4: =+I4*(1+$L$1) -> 1.785 | X4: =+J4*(1+$L$1) -> 1.68 | Y4: 1
B5: LO | C5: FT-PWRBIO | D5: ACT_BND | E5: =_xlfn.TEXTJOIN(",",TRUE,Regions!$C$3:$D$3) -> IE,National | F5: =ROUNDUP(Conversions!$B$2*SUM('EB2018'!$AE$10,'EB2018'!$AE$11),1) -> 3.2 | G5: =ROUNDUP(Conversions!$B$2*SUM('EB2019'!$AE$10,'EB2019'!$AE$11),1) -> 3.3 | H5: =ROUNDUP(Conversions!$B$2*SUM('EB2020'!$AE$10,'EB2020'!$AE$11),1) -> 4.2 | I5: =ROUNDUP(Conversions!$B$2*SUM('EB2021'!$AE$10,'EB2021'!$AE$11),1) -> 4.3 | J5: =ROUNDUP(Conversions!$B$2*SUM('EB2022'!$AE$10,'EB2022'!$AE$11),1) -> 4.6 | K5: 1 | P5: UP | Q5: FT-PWRBIO | R5: ACT_BND | S5: =_xlfn.TEXTJOIN(",",TRUE,Regions!$C$3:$D$3) -> IE,National | T5: =+F5*(1+$L$1) -> 3.36 | U5: =+G5*(1+$L$1) -> 3.465 | V5: =+H5*(1+$L$1) -> 4.41 | W5: =+I5*(1+$L$1) -> 4.515 | X5: =+J5*(1+$L$1) -> 4.83 | Y5: 1
C6: FT-PWRCOA | D6: ACT_BND | E6: =_xlfn.TEXTJOIN(",",TRUE,Regions!$C$3:$D$3) -> IE,National | F6: =ROUNDUP(Conversions!$B$2*SUM('EB2018'!$C$10,'EB2018'!$C$11),1) -> 20.5 | G6: =ROUNDUP(Conversions!$B$2*SUM('EB2019'!$C$10,'EB2019'!$C$11),1) -> 6.2 | H6: =ROUNDUP(Conversions!$B$2*SUM('EB2020'!$C$10,'EB2020'!$C$11),1) -> 8.2 | I6: =ROUNDUP(Conversions!$B$2*SUM('EB2021'!$C$10,'EB2021'!$C$11),1) -> 28.2 | J6: =ROUNDUP(Conversions!$B$2*SUM('EB2022'!$C$10,'EB2022'!$C$11),1) -> 23.7 | K6: 5 | P6: UP | Q6: FT-PWRCOA | R6: ACT_BND | S6: =_xlfn.TEXTJOIN(",",TRUE,Regions!$C$3:$D$3) -> IE,National | T6: =+F6*(1+$L$1) -> 21.525 | U6: =+G6*(1+$L$1) -> 6.51 | V6: =+H6*(1+$L$1) -> 8.61 | W6: =+I6*(1+$L$1) -> 29.61 | X6: =+J6*(1+$L$1) -> 24.885 | Y6: 5
C7: FT-PWRDIS | D7: ACT_BND | E7: =_xlfn.TEXTJOIN(",",TRUE,Regions!$C$3:$D$3) -> IE,National | F7: =ROUNDUP(Conversions!$B$2*SUM('EB2018'!$U$10,'EB2018'!$U$11),1) -> 0.4 | G7: =ROUNDUP(Conversions!$B$2*SUM('EB2019'!$U$10,'EB2019'!$U$11),1) -> 0.6 | H7: =ROUNDUP(Conversions!$B$2*SUM('EB2020'!$U$10,'EB2020'!$U$11),1) -> 0.5 | I7: =ROUNDUP(Conversions!$B$2*SUM('EB2021'!$U$10,'EB2021'!$U$11),1) -> 1.3 | J7: =ROUNDUP(Conversions!$B$2*SUM('EB2022'!$U$10,'EB2022'!$U$11),1) -> 1.2 | K7: 1 | P7: UP | Q7: FT-PWRDIS | R7: ACT_BND | S7: =_xlfn.TEXTJOIN(",",TRUE,Regions!$C$3:$D$3) -> IE,National | T7: =+F7*(1+$L$1) -> 0.42 | U7: =+G7*(1+$L$1) -> 0.63 | V7: =+H7*(1+$L$1) -> 0.525 | W7: =+I7*(1+$L$1) -> 1.365 | X7: =+J7*(1+$L$1) -> 1.26 | Y7: 1
C8: FT-PWRGAS | D8: ACT_BND | E8: =_xlfn.TEXTJOIN(",",TRUE,Regions!$C$3:$D$3) -> IE,National | F8: =ROUNDUP(Conversions!$B$2*SUM('EB2018'!$AA$10,'EB2018'!$AA$11),1) -> 103.1 | G8: =ROUNDUP(Conversions!$B$2*SUM('EB2019'!$AA$10,'EB2019'!$AA$11),1) -> 105.6 | H8: =ROUNDUP(Conversions!$B$2*SUM('EB2020'!$AA$10,'EB2020'!$AA$11),1) -> 107.5 | I8: =ROUNDUP(Conversions!$B$2*SUM('EB2021'!$AA$10,'EB2021'!$AA$11),1) -> 98.1 | J8: =ROUNDUP(Conversions!$B$2*SUM('EB2022'!$AA$10,'EB2022'!$AA$11),1) -> 108.7 | K8: 1 | P8: UP | Q8: FT-PWRGAS | R8: ACT_BND | S8: =_xlfn.TEXTJOIN(",",TRUE,Regions!$C$3:$D$3) -> IE,National | T8: =+F8*(1+$L$1) -> 108.255 | U8: =+G8*(1+$L$1) -> 110.88 | V8: =+H8*(1+$L$1) -> 112.875 | W8: =+I8*(1+$L$1) -> 103.005 | X8: =+J8*(1+$L$1) -> 114.135 | Y8: 1
B9: FX | C9: FT-PWRHFO | D9: ACT_BND | E9: =_xlfn.TEXTJOIN(",",TRUE,Regions!$C$3:$D$3) -> IE,National | F9: =ROUNDUP(Conversions!$B$2*SUM('EB2018'!$S$10,'EB2018'!$S$11),1) -> 1.1 | G9: =ROUNDUP(Conversions!$B$2*SUM('EB2019'!$S$10,'EB2019'!$S$11),1) -> 2.8 | H9: =ROUNDUP(Conversions!$B$2*SUM('EB2020'!$S$10,'EB2020'!$S$11),1) -> 4 | I9: =ROUNDUP(Conversions!$B$2*SUM('EB2021'!$S$10,'EB2021'!$S$11),1) -> 13.8 | J9: =ROUNDUP(Conversions!$B$2*SUM('EB2022'!$S$10,'EB2022'!$S$11),1) -> 9.5 | K9: 1 | P9: UP | Q9: FT-PWRHFO | R9: ACT_BND | S9: =_xlfn.TEXTJOIN(",",TRUE,Regions!$C$3:$D$3) -> IE,National | T9: =+F9*(1+$L$1) -> 1.155 | U9: =+G9*(1+$L$1) -> 2.94 | V9: =+H9*(1+$L$1) -> 4.2 | W9: =+I9*(1+$L$1) -> 14.49 | X9: =+J9*(1+$L$1) -> 9.975 | Y9: 1
C10: FT-PWRHYD | D10: ACT_BND | E10: =_xlfn.TEXTJOIN(",",TRUE,Regions!$C$3:$D$3) -> IE,National | F10: =ROUNDUP(Conversions!$B$2*SUM(-'EB2018'!$AC$22),1) -> 2.5 | G10: =ROUNDUP(Conversions!$B$2*SUM(-'EB2019'!$AC$22),1) -> 3.2 | H10: =ROUNDUP(Conversions!$B$2*SUM(-'EB2020'!$AC$22),1) -> 3.4 | I10: =ROUNDUP(Conversions!$B$2*SUM(-'EB2021'!$AC$22),1) -> 2.7 | J10: =ROUNDUP(Conversions!$B$2*SUM(-'EB2022'!$AC$22),1) -> 2.6 | K10: 1 | P10: * | Q10: FT-PWRHYD | R10: ACT_BND | S10: =_xlfn.TEXTJOIN(",",TRUE,Regions!$C$3:$D$3) -> IE,National | T10: =+F10*(1+$L$1) -> 2.625 | U10: =+G10*(1+$L$1) -> 3.36 | V10: =+H10*(1+$L$1) -> 3.57 | W10: =+I10*(1+$L$1) -> 2.835 | X10: =+J10*(1+$L$1) -> 2.73 | Y10: 1
B11: LO | C11: FT-PWRMSW | D11: ACT_BND | E11: =_xlfn.TEXTJOIN(",",TRUE,Regions!$C$3:$D$3) -> IE,National | F11: =ROUNDUP(Conversions!$B$2*SUM('EB2018'!$AF$10,'EB2018'!$AF$11,'EB2018'!$AN$10,'EB2018'!$AN$11),1) -> 8 | G11: =ROUNDUP(Conversions!$B$2*SUM('EB2019'!$AF$10,'EB2019'!$AF$11,'EB2019'!$AN$10,'EB2019'!$AN$11),1) -> 7.8 | H11: =ROUNDUP(Conversions!$B$2*SUM('EB2020'!$AF$10,'EB2020'!$AF$11,'EB2020'!$AN$10,'EB2020'!$AN$11),1) -> 8.2 | I11: =ROUNDUP(Conversions!$B$2*SUM('EB2021'!$AF$10,'EB2021'!$AF$11,'EB2021'!$AN$10,'EB2021'!$AN$11),1) -> 7.8 | J11: =ROUNDUP(Conversions!$B$2*SUM('EB2022'!$AF$10,'EB2022'!$AF$11,'EB2022'!$AN$10,'EB2022'!$AN$11),1) -> 7.9 | K11: 1 | P11: UP | Q11: FT-PWRMSW | R11: ACT_BND | S11: =_xlfn.TEXTJOIN(",",TRUE,Regions!$C$3:$D$3) -> IE,National | T11: =+F11*(1+$L$1) -> 8.4 | U11: =+G11*(1+$L$1) -> 8.19 | V11: =+H11*(1+$L$1) -> 8.61 | W11: =+I11*(1+$L$1) -> 8.19 | X11: =+J11*(1+$L$1) -> 8.295 | Y11: 1
C12: FT-PWRPEA | D12: ACT_BND | E12: =_xlfn.TEXTJOIN(",",TRUE,Regions!$C$3:$D$3) -> IE,National | F12: =ROUNDUP(Conversions!$B$2*SUM('EB2018'!$H$10,'EB2018'!$H$11),1) -> 19.9 | G12: =ROUNDUP(Conversions!$B$2*SUM('EB2019'!$H$10,'EB2019'!$H$11),1) -> 18.2 | H12: =ROUNDUP(Conversions!$B$2*SUM('EB2020'!$H$10,'EB2020'!$H$11),1) -> 9 | I12: =ROUNDUP(Conversions!$B$2*SUM('EB2021'!$H$10,'EB2021'!$H$11),1) -> 3 | J12: =ROUNDUP(Conversions!$B$2*SUM('EB2022'!$H$10,'EB2022'!$H$11),1) -> 2.3 | K12: 1 | P12: UP | Q12: FT-PWRPEA | R12: ACT_BND | S12: =_xlfn.TEXTJOIN(",",TRUE,Regions!$C$3:$D$3) -> IE,National | T12: =+F12*(1+$L$1) -> 20.895 | U12: =+G12*(1+$L$1) -> 19.11 | V12: =+H12*(1+$L$1) -> 9.45 | W12: =+I12*(1+$L$1) -> 3.15 | X12: =+J12*(1+$L$1) -> 2.415 | Y12: 1
C13: FT-PWRSOL | D13: ACT_BND | E13: =_xlfn.TEXTJOIN(",",TRUE,Regions!$C$3:$D$3) -> IE,National | F13: =ROUNDUP(Conversions!$B$2*SUM(-'EB2018'!$AK$22),1) -> 0.1 | G13: =ROUNDUP(Conversions!$B$2*SUM(-'EB2019'!$AK$22),1) -> 0.2 | H13: =ROUNDUP(Conversions!$B$2*SUM(-'EB2020'!$AK$22),1) -> 0.2 | I13: =ROUNDUP(Conversions!$B$2*SUM(-'EB2021'!$AK$22),1) -> 0.3 | J13: =ROUNDUP(Conversions!$B$2*SUM(-'EB2022'!$AK$22),1) -> 0.6 | K13: 1 | P13: * | Q13: FT-PWRSOL | R13: ACT_BND | S13: =_xlfn.TEXTJOIN(",",TRUE,Regions!$C$3:$D$3) -> IE,National | T13: =+F13*(1+$L$1) -> 0.105 | U13: =+G13*(1+$L$1) -> 0.21 | V13: =+H13*(1+$L$1) -> 0.21 | W13: =+I13*(1+$L$1) -> 0.315 | X13: =+J13*(1+$L$1) -> 0.63 | Y13: 1
C14: FT-PWRWIN | D14: ACT_BND | E14: =_xlfn.TEXTJOIN(",",TRUE,Regions!$C$3:$D$3) -> IE,National | F14: =ROUNDUP(Conversions!$B$2*SUM(-'EB2018'!$AD$22),1) -> 31.2 | G14: =ROUNDUP(Conversions!$B$2*SUM(-'EB2019'!$AD$22),1) -> 36.1 | H14: =ROUNDUP(Conversions!$B$2*SUM(-'EB2020'!$AD$22),1) -> 41.6 | I14: =ROUNDUP(Conversions!$B$2*SUM(-'EB2021'!$AD$22),1) -> 35.3 | J14: =ROUNDUP(Conversions!$B$2*SUM(-'EB2022'!$AD$22),1) -> 40.4 | K14: 1 | P14: * | Q14: FT-PWRWIN | R14: ACT_BND | S14: =_xlfn.TEXTJOIN(",",TRUE,Regions!$C$3:$D$3) -> IE,National | T14: =+F14*(1+$L$1) -> 32.76 | U14: =+G14*(1+$L$1) -> 37.905 | V14: =+H14*(1+$L$1) -> 43.68 | W14: =+I14*(1+$L$1) -> 37.065 | X14: =+J14*(1+$L$1) -> 42.42 | Y14: 1
P15: LO | Q15: FT-PWRBGS | R15: ACT_BND | S15: =_xlfn.TEXTJOIN(",",TRUE,Regions!$C$3:$D$3) -> IE,National | T15: =+F4*(1-$L$1) -> 1.615 | U15: =+G4*(1-$L$1) -> 1.615 | V15: =+H4*(1-$L$1) -> 1.52 | W15: =+I4*(1-$L$1) -> 1.615 | X15: =+J4*(1-$L$1) -> 1.52 | Y15: 1
P16: LO | Q16: FT-PWRBIO | R16: ACT_BND | S16: =_xlfn.TEXTJOIN(",",TRUE,Regions!$C$3:$D$3) -> IE,National | T16: =+F5*(1-$L$1) -> 3.04 | U16: =+G5*(1-$L$1) -> 3.135 | V16: =+H5*(1-$L$1) -> 3.99 | W16: =+I5*(1-$L$1) -> 4.085 | X16: =+J5*(1-$L$1) -> 4.37 | Y16: 1
P17: LO | Q17: FT-PWRCOA | R17: ACT_BND | S17: =_xlfn.TEXTJOIN(",",TRUE,Regions!$C$3:$D$3) -> IE,National | T17: =+F6*(1-$L$1) -> 19.475 | U17: =+G6*(1-$L$1) -> 5.89 | V17: =+H6*(1-$L$1) -> 7.79 | W17: =+I6*(1-$L$1) -> 26.79 | X17: =+J6*(1-$L$1) -> 22.515 | Y17: 1
C18: FT-PWRBGS | D18: ACT_BND | E18: IE,National | F18: 1.7 | G18: 1.7 | H18: 1.6 | I18: 1.7 | J18: 1.6 | K18: 1 | P18: LO | Q18: FT-PWRDIS | R18: ACT_BND | S18: =_xlfn.TEXTJOIN(",",TRUE,Regions!$C$3:$D$3) -> IE,National | T18: =+F7*(1-$L$1) -> 0.38 | U18: =+G7*(1-$L$1) -> 0.57 | V18: =+H7*(1-$L$1) -> 0.475 | W18: =+I7*(1-$L$1) -> 1.235 | X18: =+J7*(1-$L$1) -> 1.14 | Y18: 1
C19: FT-PWRBIO | D19: ACT_BND | E19: IE,National | F19: 3.2 | G19: 3.3 | H19: 4.2 | I19: 4.3 | J19: 4.6 | K19: 1 | P19: LO | Q19: FT-PWRGAS | R19: ACT_BND | S19: =_xlfn.TEXTJOIN(",",TRUE,Regions!$C$3:$D$3) -> IE,National | T19: =+F8*(1-$L$1) -> 97.945 | U19: =+G8*(1-$L$1) -> 100.32 | V19: =+H8*(1-$L$1) -> 102.125 | W19: =+I8*(1-$L$1) -> 93.195 | X19: =+J8*(1-$L$1) -> 103.265 | Y19: 1
C20: FT-PWRCOA | D20: ACT_BND | E20: IE,National | F20: 20.5 | G20: 6.2 | H20: 8.2 | I20: 28.2 | J20: 23.7 | K20: 5 | P20: LO | Q20: FT-PWRHFO | R20: ACT_BND | S20: =_xlfn.TEXTJOIN(",",TRUE,Regions!$C$3:$D$3) -> IE,National | T20: =+F9*(1-$L$1) -> 1.045 | U20: =+G9*(1-$L$1) -> 2.66 | V20: =+H9*(1-$L$1) -> 3.8 | W20: =+I9*(1-$L$1) -> 13.11 | X20: =+J9*(1-$L$1) -> 9.025 | Y20: 1
B21: * | C21: FT-PWRDIS | D21: ACT_BND | E21: IE,National | F21: 0.4 | G21: 0.6 | H21: 0.5 | I21: 1.3 | J21: 1.2 | K21: 1 | P21: * | Q21: FT-PWRHYD | R21: ACT_BND | S21: =_xlfn.TEXTJOIN(",",TRUE,Regions!$C$3:$D$3) -> IE,National | T21: =+F10*(1-$L$1) -> 2.375 | U21: =+G10*(1-$L$1) -> 3.04 | V21: =+H10*(1-$L$1) -> 3.23 | W21: =+I10*(1-$L$1) -> 2.565 | X21: =+J10*(1-$L$1) -> 2.47 | Y21: 1
C22: FT-PWRGAS | D22: ACT_BND | E22: IE,National | F22: 103.1 | G22: 105.6 | H22: 107.5 | I22: 98.1 | J22: 108.7 | K22: 1 | P22: LO | Q22: FT-PWRMSW | R22: ACT_BND | S22: =_xlfn.TEXTJOIN(",",TRUE,Regions!$C$3:$D$3) -> IE,National | T22: =+F11*(1-$L$1) -> 7.6 | U22: =+G11*(1-$L$1) -> 7.41 | V22: =+H11*(1-$L$1) -> 7.79 | W22: =+I11*(1-$L$1) -> 7.41 | X22: =+J11*(1-$L$1) -> 7.505 | Y22: 1
B23: * | C23: FT-PWRHFO | D23: ACT_BND | E23: IE,National | F23: 1.1 | G23: 2.8 | H23: 4 | I23: 13.8 | J23: 9.5 | K23: 1 | P23: LO | Q23: FT-PWRPEA | R23: ACT_BND | S23: =_xlfn.TEXTJOIN(",",TRUE,Regions!$C$3:$D$3) -> IE,National | T23: =+F12*(1-$L$1) -> 18.905 | U23: =+G12*(1-$L$1) -> 17.29 | V23: =+H12*(1-$L$1) -> 8.55 | W23: =+I12*(1-$L$1) -> 2.85 | X23: =+J12*(1-$L$1) -> 2.185 | Y23: 1
C24: FT-PWRHYD | D24: ACT_BND | E24: IE,National | F24: 2.5 | G24: 3.2 | H24: 3.4 | I24: 2.7 | J24: 2.6 | K24: 1 | P24: * | Q24: FT-PWRSOL | R24: ACT_BND | S24: =_xlfn.TEXTJOIN(",",TRUE,Regions!$C$3:$D$3) -> IE,National | T24: =+F13*(1-$L$1) -> 0.095 | U24: =+G13*(1-$L$1) -> 0.19 | V24: =+H13*(1-$L$1) -> 0.19 | W24: =+I13*(1-$L$1) -> 0.285 | X24: =+J13*(1-$L$1) -> 0.57 | Y24: 1
C25: FT-PWRMSW | D25: ACT_BND | E25: IE,National | F25: 8 | G25: 7.8 | H25: 8.2 | I25: 7.8 | J25: 7.9 | K25: 1 | P25: * | Q25: FT-PWRWIN | R25: ACT_BND | S25: =_xlfn.TEXTJOIN(",",TRUE,Regions!$C$3:$D$3) -> IE,National | T25: =+F14*(1-$L$1) -> 29.64 | U25: =+G14*(1-$L$1) -> 34.295 | V25: =+H14*(1-$L$1) -> 39.52 | W25: =+I14*(1-$L$1) -> 33.535 | X25: =+J14*(1-$L$1) -> 38.38 | Y25: 1
C26: FT-PWRPEA | D26: ACT_BND | E26: IE,National | F26: 19.9 | G26: 18.2 | H26: 9 | I26: 3 | J26: 2.3 | K26: 1
C27: FT-PWRSOL | D27: ACT_BND | E27: IE,National | F27: 0.1 | G27: 0.2 | H27: 0.3 | I27: 0.4 | J27: 0.6 | K27: 1
C28: FT-PWRWIN | D28: ACT_BND | E28: IE,National | F28: 31.2 | G28: 36.1 | H28: 41.6 | I28: 35.2 | J28: 40.4 | K28: 1

Sheet PWR-CAPs
B3: ="~UC_Sets: R_E: " & _xlfn.TEXTJOIN(",",TRUE,Regions!$C$3:$D$3) -> ~UC_Sets: R_E: IE,National
B4: ~UC_Sets: T_S:
E5: ~UC_T
B6: UC_N | C6: Pset_PN | D6: Year | E6: LimType | F6: UC_CAP | G6: UC_RHSRTS | H6: UC_Desc
B7: *Units | G7: *GW
B8: *UC_PWR_WON_Historic | C8: P*WIN*ON* | D8: 2019 | E8: UP | F8: 1 | G8: =+L9/1000*1.02 -> 4.195056 | H8: Historic Capacity of Wind Onshore | K8: 2018 | L8: 3667
B9: * | C9: =$C$8 -> P*WIN*ON* | D9: 2020 | E9: FX | F9: 1 | G9: =+L10/1000 -> 4.3229 | K9: 2019 | L9: 4112.8
B10: * | C10: =$C$8 -> P*WIN*ON* | D10: 2021 | E10: =+E9 -> FX | F10: 1 | G10: =+L11/1000 -> 4.3322 | K10: 2020 | L10: 4322.9
B11: * | C11: =$C$8 -> P*WIN*ON* | D11: 2022 | E11: =+E10 -> FX | F11: 1 | G11: =+L12/1000 -> 4.5273 | K11: 2021 | L11: 4332.2
B12: * | C12: =$C$8 -> P*WIN*ON* | D12: 2023 | E12: =+E11 -> FX | F12: 1 | G12: 4.777 | K12: 2022 | L12: 4527.3
B13: * | C13: =$C$8 -> P*WIN*ON* | D13: 0 | E13: =+E12 -> FX | G13: 1
B14: UC_PWR_PV_Historic | C14: P*SOL*PV* | D14: 2019 | E14: FX | F14: 1 | G14: 0.02 | H14: Historic Capacity of PV
C15: =$C$14 -> P*SOL*PV* | D15: 2020 | E15: =$E$14 -> FX | F15: 1 | G15: 0.053
C16: =$C$14 -> P*SOL*PV* | D16: 2021 | E16: =$E$14 -> FX | F16: 1 | G16: 0.261
C17: =$C$14 -> P*SOL*PV* | D17: 2022 | E17: =$E$14 -> FX | F17: 1 | G17: 0.384
C18: =$C$14 -> P*SOL*PV* | D18: 2023 | E18: =$E$14 -> FX | F18: 1 | G18: 0.716
C19: =$C$14 -> P*SOL*PV* | D19: 2024 | E19: =$E$14 -> FX | F19: 1 | G19: =G18+0.239 -> 0.955
C20: =$C$14 -> P*SOL*PV* | D20: 0 | E20: =$E$14 -> FX | G20: 1

Sheet AGR
B2: ~TFM_INS-TS
B3: LimType | C3: PSET_PN | D3: Attribute | E3: Region | F3: 2018 | G3: 2019 | H3: 2020 | I3: 2021 | J3: 2022 | K3: 0
B4: FX | C4: FT-AGRELC | D4: ACT_BND | E4: =_xlfn.TEXTJOIN(",",TRUE,Regions!$C$3:$D$3) -> IE,National | F4: =ROUNDUP(Conversions!$B$2*SUM('EB2018'!$AO$70,'EB2018'!$AO$71),1) -> 2.1 | G4: =ROUNDUP(Conversions!$B$2*SUM('EB2019'!$AO$70,'EB2019'!$AO$71),1) -> 2 | H4: =ROUNDUP(Conversions!$B$2*SUM('EB2020'!$AO$70,'EB2020'!$AO$71),1) -> 2.1 | I4: =ROUNDUP(Conversions!$B$2*SUM('EB2021'!$AO$70,'EB2021'!$AO$71),1) -> 2 | J4: =ROUNDUP(Conversions!$B$2*SUM('EB2022'!$AO$70,'EB2022'!$AO$71),1) -> 1.9 | K4: 1
B5: FX | C5: FT-AGRDST | D5: ACT_BND | E5: =_xlfn.TEXTJOIN(",",TRUE,Regions!$C$3:$D$3) -> IE,National | F5: =ROUNDUP(Conversions!$B$2*SUM('EB2018'!$U$70,'EB2018'!$U$71),1) -> 8.5 | G5: =ROUNDUP(Conversions!$B$2*SUM('EB2019'!$U$70,'EB2019'!$U$71),1) -> 8.7 | H5: =ROUNDUP(Conversions!$B$2*SUM('EB2020'!$U$70,'EB2020'!$U$71),1) -> 8.5 | I5: =ROUNDUP(Conversions!$B$2*SUM('EB2021'!$U$70,'EB2021'!$U$71),1) -> 8.5 | J5: =ROUNDUP(Conversions!$B$2*SUM('EB2022'!$U$70,'EB2022'!$U$71),1) -> 12.1 | K5: 1

Sheet IND
M1: Calibration margin | N1: 0.2
B2: deact~TFM_INS-TS | P2: ~TFM_INS-TS
B3: LimType | C3: PSET_PN | D3: Attribute | E3: Region | F3: 2018 | G3: 2019 | H3: 2020 | I3: 2021 | J3: 2022 | K3: 0 | P3: LimType | Q3: PSET_PN | R3: Attribute | S3: Region | T3: *2018 | U3: 2019 | V3: 2020 | W3: 2021 | X3: 2022 | Y3: 0
B4: * | C4: FT-INDCOK | D4: ACT_BND | E4: =_xlfn.TEXTJOIN(",",TRUE,Regions!$C$3:$D$3) -> IE,National | F4: =ROUNDUP(Conversions!$B$2*SUM('EB2018'!$V$30),1) -> 6 | G4: =ROUNDUP(Conversions!$B$2*SUM('EB2019'!$V$30),1) -> 5.8 | H4: =ROUNDUP(Conversions!$B$2*SUM('EB2020'!$V$30),1) -> 5.3 | I4: =ROUNDUP(Conversions!$B$2*SUM('EB2021'!$V$30),1) -> 6.1 | J4: =ROUNDUP(Conversions!$B$2*SUM('EB2022'!$V$30),1) -> 5 | K4: 1 | P4: UP | Q4: FT-INDCOK | R4: ACT_BND | S4: =_xlfn.TEXTJOIN(",",TRUE,Regions!$C$3:$D$3) -> IE,National | T4: =+F4*(1+$N$1) -> 7.2 | U4: =+G4*(1+$N$1) -> 6.96 | V4: =+H4*(1+$N$1) -> 6.36 | W4: =+I4*(1+$N$1) -> 7.32 | X4: =+J4*(1+$N$1) -> 6 | Y4: 1
C5: FT-INDBIO | D5: ACT_BND | E5: =_xlfn.TEXTJOIN(",",TRUE,Regions!$C$3:$D$3) -> IE,National | F5: =ROUNDUP(Conversions!$B$2*SUM('EB2018'!$AE$30),1) -> 6.5 | G5: =ROUNDUP(Conversions!$B$2*SUM('EB2019'!$AE$30),1) -> 6.2 | H5: =ROUNDUP(Conversions!$B$2*SUM('EB2020'!$AE$30),1) -> 5.8 | I5: =ROUNDUP(Conversions!$B$2*SUM('EB2021'!$AE$30),1) -> 5.3 | J5: =ROUNDUP(Conversions!$B$2*SUM('EB2022'!$AE$30),1) -> 5.5 | K5: 1 | P5: UP | Q5: FT-INDBIO | R5: ACT_BND | S5: =_xlfn.TEXTJOIN(",",TRUE,Regions!$C$3:$D$3) -> IE,National | T5: =+F5*(1+$N$1) -> 7.8 | U5: =+G5*(1+$N$1) -> 7.44 | V5: =+H5*(1+$N$1) -> 6.96 | W5: =+I5*(1+$N$1) -> 6.36 | X5: =+J5*(1+$N$1) -> 6.6 | Y5: 1
C6: FT-INDCOA | D6: ACT_BND | E6: =_xlfn.TEXTJOIN(",",TRUE,Regions!$C$3:$D$3) -> IE,National | F6: =ROUNDUP(Conversions!$B$2*SUM('EB2018'!$C$30),1) -> 4.5 | G6: =ROUNDUP(Conversions!$B$2*SUM('EB2019'!$C$30),1) -> 3.4 | H6: =ROUNDUP(Conversions!$B$2*SUM('EB2020'!$C$30),1) -> 3.2 | I6: =ROUNDUP(Conversions!$B$2*SUM('EB2021'!$C$30),1) -> 3.8 | J6: =ROUNDUP(Conversions!$B$2*SUM('EB2022'!$C$30),1) -> 3 | K6: 1 | P6: UP | Q6: FT-INDCOA | R6: ACT_BND | S6: =_xlfn.TEXTJOIN(",",TRUE,Regions!$C$3:$D$3) -> IE,National | T6: =+F6*(1+$N$1) -> 5.4 | U6: =+G6*(1+$N$1) -> 4.08 | V6: =+H6*(1+$N$1) -> 3.84 | W6: =+I6*(1+$N$1) -> 4.56 | X6: =+J6*(1+$N$1) -> 3.6 | Y6: 5
C7: FT-INDPEA,FT-INDWOO | D7: ACT_BND | E7: =_xlfn.TEXTJOIN(",",TRUE,Regions!$C$3:$D$3) -> IE,National | F7: =ROUNDUP(Conversions!$B$2*SUM('EB2018'!$H$30),1) -> 0.1 | G7: =ROUNDUP(Conversions!$B$2*SUM('EB2019'!$H$30),1) -> 0 | H7: =ROUNDUP(Conversions!$B$2*SUM('EB2020'!$H$30),1) -> 0 | I7: =ROUNDUP(Conversions!$B$2*SUM('EB2021'!$H$30),1) -> 0 | J7: =ROUNDUP(Conversions!$B$2*SUM('EB2022'!$H$30),1) -> 0 | K7: 1 | P7: UP | Q7: FT-INDPEA,FT-INDWOO | R7: ACT_BND | S7: =_xlfn.TEXTJOIN(",",TRUE,Regions!$C$3:$D$3) -> IE,National | T7: =+F7*(1+$N$1) -> 0.12 | U7: =+G7*(1+$N$1) -> 0 | V7: =+H7*(1+$N$1) -> 0 | W7: =+I7*(1+$N$1) -> 0 | X7: =+J7*(1+$N$1) -> 0 | Y7: 1
C8: FT-INDELC | D8: ACT_BND | E8: =_xlfn.TEXTJOIN(",",TRUE,Regions!$C$3:$D$3) -> IE,National | F8: =ROUNDUP(Conversions!$B$2*SUM('EB2018'!$AO$30),1) -> 23.4 | G8: =ROUNDUP(Conversions!$B$2*SUM('EB2019'!$AO$30),1)+1.5 -> 25.6 | H8: =ROUNDUP(Conversions!$B$2*SUM('EB2020'!$AO$30),1) -> 24.9 | I8: =ROUNDUP(Conversions!$B$2*SUM('EB2021'!$AO$30),1) -> 24.7 | J8: =ROUNDUP(Conversions!$B$2*SUM('EB2022'!$AO$30),1) -> 24.8 | K8: 1 | P8: UP | Q8: FT-INDELC | R8: ACT_BND | S8: =_xlfn.TEXTJOIN(",",TRUE,Regions!$C$3:$D$3) -> IE,National | T8: =+F8*(1+$N$1) -> 28.08 | U8: =+G8*(1+$N$1) -> 30.72 | V8: =+H8*(1+$N$1) -> 29.88 | W8: =+I8*(1+$N$1) -> 29.64 | X8: =+J8*(1+$N$1) -> 29.76 | Y8: 1
B9: * | C9: FT-INDNWS | D9: ACT_BND | E9: =_xlfn.TEXTJOIN(",",TRUE,Regions!$C$3:$D$3) -> IE,National | F9: =ROUNDUP(Conversions!$B$2*SUM('EB2018'!$AN$30),1) -> 2.3 | G9: =ROUNDUP(Conversions!$B$2*SUM('EB2019'!$AN$30),1) -> 2.4 | H9: =ROUNDUP(Conversions!$B$2*SUM('EB2020'!$AN$30),1) -> 2.3 | I9: =ROUNDUP(Conversions!$B$2*SUM('EB2021'!$AN$30),1) -> 2.3 | J9: =ROUNDUP(Conversions!$B$2*SUM('EB2022'!$AN$30),1) -> 2.5 | K9: 1 | P9: UP | Q9: FT-INDNWS | R9: ACT_BND | S9: =_xlfn.TEXTJOIN(",",TRUE,Regions!$C$3:$D$3) -> IE,National | T9: =+F9*(1+3*$N$1) -> 3.68 | U9: =+G9*(1+3*$N$1) -> 3.84 | V9: =+H9*(1+3*$N$1) -> 3.68 | W9: =+I9*(1+3*$N$1) -> 3.68 | X9: =+J9*(1+3*$N$1) -> 4 | Y9: 1
C10: FT-INDGAS | D10: ACT_BND | E10: =_xlfn.TEXTJOIN(",",TRUE,Regions!$C$3:$D$3) -> IE,National | F10: =ROUNDUP(Conversions!$B$2*SUM('EB2018'!$AA$30),1) -> 41.5 | G10: =ROUNDUP(Conversions!$B$2*SUM('EB2019'!$AA$30),1) -> 43.1 | H10: =ROUNDUP(Conversions!$B$2*SUM('EB2020'!$AA$30),1) -> 43.9 | I10: =ROUNDUP(Conversions!$B$2*SUM('EB2021'!$AA$30),1) -> 41.4 | J10: =ROUNDUP(Conversions!$B$2*SUM('EB2022'!$AA$30),1) -> 38.1 | K10: 1 | P10: UP | Q10: FT-INDGAS | R10: ACT_BND | S10: =_xlfn.TEXTJOIN(",",TRUE,Regions!$C$3:$D$3) -> IE,National | T10: =+F10*(1+$N$1) -> 49.8 | U10: =+G10*(1+$N$1) -> 51.72 | V10: =+H10*(1+$N$1) -> 52.68 | W10: =+I10*(1+$N$1) -> 49.68 | X10: =+J10*(1+$N$1) -> 45.72 | Y10: 1
B11: * | C11: FT-INDCOK | D11: ACT_BND | E11: =_xlfn.TEXTJOIN(",",TRUE,Regions!$C$3:$D$3) -> IE,National | F11: =ROUNDUP(Conversions!$B$2*SUM('EB2018'!$AP$30),1) -> 0 | G11: =ROUNDUP(Conversions!$B$2*SUM('EB2019'!$AP$30),1) -> 0 | H11: =ROUNDUP(Conversions!$B$2*SUM('EB2020'!$AP$30),1) -> 0 | I11: =ROUNDUP(Conversions!$B$2*SUM('EB2021'!$AP$30),1) -> 0 | J11: =ROUNDUP(Conversions!$B$2*SUM('EB2022'!$AP$30),1) -> 0 | K11: 1 | P11: * | Q11: * | R11: * | S11: *
C12: FT-INDBGS | D12: ACT_BND | E12: =_xlfn.TEXTJOIN(",",TRUE,Regions!$C$3:$D$3) -> IE,National | F12: =ROUNDUP(Conversions!$B$2*SUM('EB2018'!$AH$30),1) -> 0.2 | G12: =ROUNDUP(Conversions!$B$2*SUM('EB2019'!$AH$30),1) -> 0.2 | H12: =ROUNDUP(Conversions!$B$2*SUM('EB2020'!$AH$30),1) -> 0.3 | I12: =ROUNDUP(Conversions!$B$2*SUM('EB2021'!$AH$30),1) -> 0.3 | J12: =ROUNDUP(Conversions!$B$2*SUM('EB2022'!$AH$30),1) -> 0.3 | K12: 1 | P12: UP | Q12: FT-INDBGS | R12: ACT_BND | S12: =_xlfn.TEXTJOIN(",",TRUE,Regions!$C$3:$D$3) -> IE,National | T12: =+F12*(1+$N$1) -> 0.24 | U12: =+G12*(1+$N$1) -> 0.24 | V12: =+H12*(1+$N$1) -> 0.36 | W12: =+I12*(1+$N$1) -> 0.36 | X12: =+J12*(1+$N$1) -> 0.36 | Y12: 1
C13: FT-INDOIL | D13: ACT_BND | E13: =_xlfn.TEXTJOIN(",",TRUE,Regions!$C$3:$D$3) -> IE,National | F13: =ROUNDUP(Conversions!$B$2*SUM('EB2018'!$Q$30,'EB2018'!$U$30,'EB2018'!$S$30,'EB2018'!$T$30),1) -> 8.2 | G13: =ROUNDUP(Conversions!$B$2*SUM('EB2019'!$Q$30,'EB2019'!$U$30,'EB2019'!$S$30,'EB2019'!$T$30),1) -> 8.1 | H13: =ROUNDUP(Conversions!$B$2*SUM('EB2020'!$Q$30,'EB2020'!$U$30,'EB2020'!$S$30,'EB2020'!$T$30),1) -> 8.6 | I13: =ROUNDUP(Conversions!$B$2*SUM('EB2021'!$Q$30,'EB2021'!$U$30,'EB2021'!$S$30,'EB2021'!$T$30),1) -> 8.2 | J13: =ROUNDUP(Conversions!$B$2*SUM('EB2022'!$Q$30,'EB2021'!$U$30,'EB2021'!$S$30,'EB2021'!$T$30),1) -> 8.2 | K13: 1 | P13: UP | Q13: FT-INDOIL | R13: ACT_BND | S13: =_xlfn.TEXTJOIN(",",TRUE,Regions!$C$3:$D$3) -> IE,National | T13: =+F13*(1+$N$1) -> 9.84 | U13: =+G13*(1+$N$1) -> 9.72 | V13: =+H13*(1+$N$1) -> 10.32 | W13: =+I13*(1+$N$1) -> 9.84 | X13: =+J13*(1+$N$1) -> 9.84 | Y13: 5
C14: FT-INDRWS | D14: ACT_BND | E14: =_xlfn.TEXTJOIN(",",TRUE,Regions!$C$3:$D$3) -> IE,National | F14: =ROUNDUP(Conversions!$B$2*SUM('EB2018'!$AF$30),1) -> 1.8 | G14: =ROUNDUP(Conversions!$B$2*SUM('EB2019'!$AF$30),1) -> 1.7 | H14: =ROUNDUP(Conversions!$B$2*SUM('EB2020'!$AF$30),1) -> 1.9 | I14: =ROUNDUP(Conversions!$B$2*SUM('EB2021'!$AF$30),1) -> 2 | J14: =ROUNDUP(Conversions!$B$2*SUM('EB2022'!$AF$30),1) -> 2.3 | K14: 1 | P14: UP | Q14: FT-INDRWS | R14: ACT_BND | S14: =_xlfn.TEXTJOIN(",",TRUE,Regions!$C$3:$D$3) -> IE,National | T14: =+F14*(1+$N$1) -> 2.16 | U14: =+G14*(1+$N$1) -> 2.04 | V14: =+H14*(1+$N$1) -> 2.28 | W14: =+I14*(1+$N$1) -> 2.4 | X14: =+J14*(1+$N$1) -> 2.76 | Y14: 1
P15: LO | Q15: FT-INDCOK | R15: ACT_BND | S15: =_xlfn.TEXTJOIN(",",TRUE,Regions!$C$3:$D$3) -> IE,National | T15: =+F4*(1-$N$1) -> 4.8 | U15: =+G4*(1-$N$1) -> 4.64 | V15: =+H4*(1-$N$1) -> 4.24 | W15: =+I4*(1-$N$1) -> 4.88 | X15: =+J4*(1-$N$1) -> 4 | Y15: 1
F16: =SUM(F4:F15) -> 94.5 | G16: =SUM(G4:G15) -> 96.5 | H16: =SUM(H4:H15) -> 96.2 | I16: =SUM(I4:I15) -> 94.1 | J16: =SUM(J4:J15) -> 89.7 | P16: LO | Q16: FT-INDBIO | R16: ACT_BND | S16: =_xlfn.TEXTJOIN(",",TRUE,Regions!$C$3:$D$3) -> IE,National | T16: =+F5*(1-$N$1)*0.95 -> 4.94 | U16: =+G5*(1-$N$1) -> 4.96 | V16: =+H5*(1-$N$1) -> 4.64 | W16: =+I5*(1-$N$1) -> 4.24 | X16: =+J5*(1-$N$1) -> 4.4 | Y16: 1
P17: LO | Q17: FT-INDCOA | R17: ACT_BND | S17: =_xlfn.TEXTJOIN(",",TRUE,Regions!$C$3:$D$3) -> IE,National | T17: =+F6*(1-$N$1) -> 3.6 | U17: =+G6*(1-$N$1) -> 2.72 | V17: =+H6*(1-$N$1) -> 2.56 | W17: =+I6*(1-$N$1) -> 3.04 | X17: =+J6*(1-$N$1) -> 2.4 | Y17: 1
C18: FT-INDCOA | P18: * | Q18: FT-INDPEA,FT-INDWOO | R18: ACT_BND | S18: =_xlfn.TEXTJOIN(",",TRUE,Regions!$C$3:$D$3) -> IE,National | T18: =+F7*(1-$N$1)*0.95 -> 0.076 | U18: =+G7*(1-$N$1) -> 0 | V18: =+H7*(1-$N$1) -> 0 | W18: =+I7*(1-$N$1) -> 0 | X18: =+J7*(1-$N$1) -> 0 | Y18: 1
C19: FT-INDPEA | P19: LO | Q19: FT-INDELC | R19: ACT_BND | S19: =_xlfn.TEXTJOIN(",",TRUE,Regions!$C$3:$D$3) -> IE,National | T19: =+F8*(1-$N$1) -> 18.72 | U19: =+G8*(1-$N$1) -> 20.48 | V19: =+H8*(1-$N$1) -> 19.92 | W19: =+I8*(1-$N$1) -> 19.76 | X19: =+J8*(1-$N$1) -> 19.84 | Y19: 1
C20: FT-INDOIL | P20: LO | Q20: FT-INDNWS | R20: ACT_BND | S20: =_xlfn.TEXTJOIN(",",TRUE,Regions!$C$3:$D$3) -> IE,National | T20: =+F9*(1-3*$N$1) -> 0.92 | U20: =+G9*(1-3*$N$1) -> 0.96 | V20: =+H9*(1-3*$N$1) -> 0.92 | W20: =+I9*(1-3*$N$1) -> 0.92 | X20: =+J9*(1-3*$N$1) -> 1 | Y20: 5
C21: FT-INDCOK | P21: LO | Q21: FT-INDGAS | R21: ACT_BND | S21: =_xlfn.TEXTJOIN(",",TRUE,Regions!$C$3:$D$3) -> IE,National | T21: =+F10*(1-$N$1) -> 33.2 | U21: =+G10*(1-$N$1) -> 34.48 | V21: =+H10*(1-$N$1) -> 35.12 | W21: =+I10*(1-$N$1) -> 33.12 | X21: =+J10*(1-$N$1) -> 30.48 | Y21: 1
C22: FT-INDGAS | P22: * | Q22: * | R22: * | S22: *
C23: FT-INDELC | P23: * | Q23: FT-INDBGS | R23: ACT_BND | S23: =_xlfn.TEXTJOIN(",",TRUE,Regions!$C$3:$D$3) -> IE,National | T23: =+F12*(1-$N$1)*0.9 -> 0.144 | U23: =+G12*(1-$N$1) -> 0.16 | V23: =+H12*(1-$N$1) -> 0.24 | W23: =+I12*(1-$N$1) -> 0.24 | X23: =+J12*(1-$N$1) -> 0.24 | Y23: 1
C24: FT-INDBGS | P24: LO | Q24: FT-INDOIL | R24: ACT_BND | S24: =_xlfn.TEXTJOIN(",",TRUE,Regions!$C$3:$D$3) -> IE,National | T24: =+F13*(1-$N$1) -> 6.56 | U24: =+G13*(1-$N$1) -> 6.48 | V24: =+H13*(1-$N$1) -> 6.88 | W24: =+I13*(1-$N$1) -> 6.56 | X24: =+J13*(1-$N$1) -> 6.56 | Y24: 1
C25: FT-INDBIO | P25: LO | Q25: FT-INDRWS | R25: ACT_BND | S25: =_xlfn.TEXTJOIN(",",TRUE,Regions!$C$3:$D$3) -> IE,National | T25: =+F14*(1-3*$N$1) -> 0.72 | U25: =+G14*(1-3*$N$1) -> 0.68 | V25: =+H14*(1-3*$N$1) -> 0.76 | W25: =+I14*(1-3*$N$1) -> 0.8 | X25: =+J14*(1-3*$N$1) -> 0.92 | Y25: 5
C26: FT-INDRWS
C27: FT-INDNWS
C28: FT-INDH2G
C29: FT-INDH2L
C30: FT-INDWOO

Sheet RSD
M1: Calibration margin | N1: 0.02
B2: deact~TFM_INS-TS | P2: ~TFM_INS-TS
B3: LimType | C3: PSET_PN | D3: Attribute | E3: Region | F3: 2018 | G3: 2019 | H3: 2020 | I3: 2021 | J3: 2022 | K3: 0 | P3: LimType | Q3: PSET_PN | R3: Attribute | S3: Region | T3: 2018 | U3: 2019 | V3: 2020 | W3: 2021 | X3: 2022 | Y3: 0
B4: * | C4: FT-RSDBDL | D4: ACT_BND | E4: =_xlfn.TEXTJOIN(",",TRUE,Regions!$C$3:$D$3) -> IE,National | F4: =ROUNDUP(Conversions!$B$2*SUM('EB2018'!$AI$56),1) -> 0 | G4: =ROUNDUP(Conversions!$B$2*SUM('EB2019'!$AI$56),1) -> 0 | H4: =ROUNDUP(Conversions!$B$2*SUM('EB2020'!$AI$56),1) -> 0 | I4: =ROUNDUP(Conversions!$B$2*SUM('EB2021'!$AI$56),1) -> 0 | J4: =ROUNDUP(Conversions!$B$2*SUM('EB2022'!$AI$56),1) -> 0 | K4: 1 | P4: UP | Q4: FT-RSDBDL | R4: ACT_BND | S4: =_xlfn.TEXTJOIN(",",TRUE,Regions!$C$3:$D$3) -> IE,National | T4: =+F4*(1+$N$1) -> 0 | U4: =+G4*(1+$N$1) -> 0 | V4: =+H4*(1+$N$1) -> 0 | W4: =+I4*(1+$N$1) -> 0 | X4: =+J4*(1+$N$1) -> 0 | Y4: 1
C5: FT-RSDWOO | D5: ACT_BND | E5: =_xlfn.TEXTJOIN(",",TRUE,Regions!$C$3:$D$3) -> IE,National | F5: =ROUNDUP(Conversions!$B$2*SUM('EB2018'!$AE$56),1) -> 1.3 | G5: =ROUNDUP(Conversions!$B$2*SUM('EB2019'!$AE$56),1) -> 1.1 | H5: =ROUNDUP(Conversions!$B$2*SUM('EB2020'!$AE$56),1) -> 1.1 | I5: =ROUNDUP(Conversions!$B$2*SUM('EB2021'!$AE$56),1) -> 1.2 | J5: =ROUNDUP(Conversions!$B$2*SUM('EB2022'!$AE$56),1) -> 1 | K5: 1 | P5: UP | Q5: FT-RSDWOO | R5: ACT_BND | S5: =_xlfn.TEXTJOIN(",",TRUE,Regions!$C$3:$D$3) -> IE,National | T5: =+F5*(1+$N$1) -> 1.326 | U5: =+G5*(1+$N$1) -> 1.122 | V5: =+H5*(1+$N$1) -> 1.122 | W5: =+I5*(1+$N$1) -> 1.224 | X5: =+J5*(1+$N$1) -> 1.02 | Y5: 1
C6: FT-RSDCOA | D6: ACT_BND | E6: =_xlfn.TEXTJOIN(",",TRUE,Regions!$C$3:$D$3) -> IE,National | F6: =ROUNDUP(Conversions!$B$2*SUM('EB2018'!$C$56),1) -> 9.1 | G6: =ROUNDUP(Conversions!$B$2*SUM('EB2019'!$C$56),1) -> 7.8 | H6: =ROUNDUP(Conversions!$B$2*SUM('EB2020'!$C$56),1) -> 8.2 | I6: =ROUNDUP(Conversions!$B$2*SUM('EB2021'!$C$56),1) -> 7.8 | J6: =ROUNDUP(Conversions!$B$2*SUM('EB2022'!$C$56),1) -> 5.2 | K6: 1 | P6: UP | Q6: FT-RSDCOA | R6: ACT_BND | S6: =_xlfn.TEXTJOIN(",",TRUE,Regions!$C$3:$D$3) -> IE,National | T6: =+F6*(1+$N$1) -> 9.282 | U6: =+G6*(1+$N$1) -> 7.956 | V6: =+H6*(1+$N$1) -> 8.364 | W6: =+I6*(1+$N$1) -> 7.956 | X6: =+J6*(1+$N$1) -> 5.304 | Y6: 5
C7: FT-RSDPEA | D7: ACT_BND | E7: =_xlfn.TEXTJOIN(",",TRUE,Regions!$C$3:$D$3) -> IE,National | F7: =ROUNDUP(Conversions!$B$2*SUM('EB2018'!$H$56),1) -> 8.3 | G7: =ROUNDUP(Conversions!$B$2*SUM('EB2019'!$H$56),1) -> 7.7 | H7: =ROUNDUP(Conversions!$B$2*SUM('EB2020'!$H$56),1) -> 8 | I7: =ROUNDUP(Conversions!$B$2*SUM('EB2021'!$H$56),1) -> 7.6 | J7: =ROUNDUP(Conversions!$B$2*SUM('EB2022'!$H$56),1) -> 6.6 | K7: 1 | P7: UP | Q7: FT-RSDPEA | R7: ACT_BND | S7: =_xlfn.TEXTJOIN(",",TRUE,Regions!$C$3:$D$3) -> IE,National | T7: =+F7*(1+$N$1) -> 8.466 | U7: =+G7*(1+$N$1) -> 7.854 | V7: =+H7*(1+$N$1) -> 8.16 | W7: =+I7*(1+$N$1) -> 7.752 | X7: =+J7*(1+$N$1) -> 6.732 | Y7: 5
C8: FT-RSDELC | D8: ACT_BND | E8: =_xlfn.TEXTJOIN(",",TRUE,Regions!$C$3:$D$3) -> IE,National | F8: =ROUNDUP(Conversions!$B$2*SUM('EB2018'!$AO$56),1) -> 29.5 | G8: =ROUNDUP(Conversions!$B$2*SUM('EB2019'!$AO$56),1)+1.5 -> 30.8 | H8: =ROUNDUP(Conversions!$B$2*SUM('EB2020'!$AO$56),1) -> 31.4 | I8: =ROUNDUP(Conversions!$B$2*SUM('EB2021'!$AO$56),1) -> 31.8 | J8: =ROUNDUP(Conversions!$B$2*SUM('EB2022'!$AO$56),1) -> 30 | K8: 1 | P8: UP | Q8: FT-RSDELC | R8: ACT_BND | S8: =_xlfn.TEXTJOIN(",",TRUE,Regions!$C$3:$D$3) -> IE,National | T8: =+F8*(1+$N$1) -> 30.09 | U8: =+G8*(1+$N$1) -> 31.416 | V8: =+H8*(1+$N$1) -> 32.028 | W8: =+I8*(1+$N$1) -> 32.436 | X8: =+J8*(1+$N$1) -> 30.6 | Y8: 1
B9: * | C9: FT-RSDETH | D9: ACT_BND | E9: =_xlfn.TEXTJOIN(",",TRUE,Regions!$C$3:$D$3) -> IE,National | F9: =ROUNDUP(Conversions!$B$2*SUM('EB2018'!$AJ$56),1) -> 0 | G9: =ROUNDUP(Conversions!$B$2*SUM('EB2019'!$AJ$56),1) -> 0 | H9: =ROUNDUP(Conversions!$B$2*SUM('EB2020'!$AJ$56),1) -> 0 | I9: =ROUNDUP(Conversions!$B$2*SUM('EB2021'!$AJ$56),1) -> 0 | J9: =ROUNDUP(Conversions!$B$2*SUM('EB2022'!$AJ$56),1) -> 0 | K9: 1 | P9: UP | Q9: FT-RSDETH | R9: ACT_BND | S9: =_xlfn.TEXTJOIN(",",TRUE,Regions!$C$3:$D$3) -> IE,National | T9: =+F9*(1+$N$1) -> 0 | U9: =+G9*(1+$N$1) -> 0 | V9: =+H9*(1+$N$1) -> 0 | W9: =+I9*(1+$N$1) -> 0 | X9: =+J9*(1+$N$1) -> 0 | Y9: 1
C10: FT-RSDGAS | D10: ACT_BND | E10: =_xlfn.TEXTJOIN(",",TRUE,Regions!$C$3:$D$3) -> IE,National | F10: =ROUNDUP(Conversions!$B$2*SUM('EB2018'!$AA$56),1) -> 25.3 | G10: =ROUNDUP(Conversions!$B$2*SUM('EB2019'!$AA$56),1) -> 24.8 | H10: =ROUNDUP(Conversions!$B$2*SUM('EB2020'!$AA$56),1) -> 24.7 | I10: =ROUNDUP(Conversions!$B$2*SUM('EB2021'!$AA$56),1) -> 25 | J10: =ROUNDUP(Conversions!$B$2*SUM('EB2022'!$AA$56),1) -> 22.7 | K10: 1 | P10: UP | Q10: FT-RSDGAS | R10: ACT_BND | S10: =_xlfn.TEXTJOIN(",",TRUE,Regions!$C$3:$D$3) -> IE,National | T10: =+F10*(1+$N$1) -> 25.806 | U10: =+G10*(1+$N$1) -> 25.296 | V10: =+H10*(1+$N$1) -> 25.194 | W10: =+I10*(1+$N$1) -> 25.5 | X10: =+J10*(1+$N$1) -> 23.154 | Y10: 1
B11: * | C11: FT-RSDHET | D11: ACT_BND | E11: =_xlfn.TEXTJOIN(",",TRUE,Regions!$C$3:$D$3) -> IE,National | F11: =ROUNDUP(Conversions!$B$2*SUM('EB2018'!$AP$56),1) -> 0 | G11: =ROUNDUP(Conversions!$B$2*SUM('EB2019'!$AP$56),1) -> 0 | H11: =ROUNDUP(Conversions!$B$2*SUM('EB2020'!$AP$56),1) -> 0 | I11: =ROUNDUP(Conversions!$B$2*SUM('EB2021'!$AP$56),1) -> 0 | J11: =ROUNDUP(Conversions!$B$2*SUM('EB2022'!$AP$56),1) -> 0 | K11: 1 | P11: UP | Q11: FT-RSDHET | R11: ACT_BND | S11: =_xlfn.TEXTJOIN(",",TRUE,Regions!$C$3:$D$3) -> IE,National | T11: =+F11*(1+$N$1) -> 0 | U11: =+G11*(1+$N$1) -> 0 | V11: =+H11*(1+$N$1) -> 0 | W11: =+I11*(1+$N$1) -> 0 | X11: =+J11*(1+$N$1) -> 0 | Y11: 1
C12: FT-RSDLPG | D12: ACT_BND | E12: =_xlfn.TEXTJOIN(",",TRUE,Regions!$C$3:$D$3) -> IE,National | F12: =ROUNDUP(Conversions!$B$2*SUM('EB2018'!$T$56),1) -> 2.3 | G12: =ROUNDUP(Conversions!$B$2*SUM('EB2019'!$T$56),1) -> 2.1 | H12: =ROUNDUP(Conversions!$B$2*SUM('EB2020'!$T$56),1) -> 2.4 | I12: =ROUNDUP(Conversions!$B$2*SUM('EB2021'!$T$56),1) -> 2.1 | J12: =ROUNDUP(Conversions!$B$2*SUM('EB2022'!$T$56),1) -> 1.9 | K12: 1 | P12: UP | Q12: FT-RSDLPG | R12: ACT_BND | S12: =_xlfn.TEXTJOIN(",",TRUE,Regions!$C$3:$D$3) -> IE,National | T12: =+F12*(1+$N$1) -> 2.346 | U12: =+G12*(1+$N$1) -> 2.142 | V12: =+H12*(1+$N$1) -> 2.448 | W12: =+I12*(1+$N$1) -> 2.142 | X12: =+J12*(1+$N$1) -> 1.938 | Y12: 1
C13: FT-RSDKER | D13: ACT_BND | E13: =_xlfn.TEXTJOIN(",",TRUE,Regions!$C$3:$D$3) -> IE,National | F13: =ROUNDUP(Conversions!$B$2*SUM('EB2018'!$Q$56,'EB2018'!$U$56,'EB2018'!$V$56),1) -> 50.5 | G13: =ROUNDUP(Conversions!$B$2*SUM('EB2019'!$Q$56,'EB2019'!$U$56,'EB2019'!$V$56),1) -> 49.9 | H13: =ROUNDUP(Conversions!$B$2*SUM('EB2020'!$Q$56,'EB2020'!$U$56,'EB2020'!$V$56),1) -> 57.2 | I13: =ROUNDUP(Conversions!$B$2*SUM('EB2021'!$Q$56,'EB2021'!$U$56,'EB2021'!$V$56),1) -> 52.3 | J13: =ROUNDUP(Conversions!$B$2*SUM('EB2022'!$Q$56,'EB2021'!$U$56,'EB2021'!$V$56),1) -> 46.1 | K13: 1 | P13: UP | Q13: FT-RSDKER | R13: ACT_BND | S13: =_xlfn.TEXTJOIN(",",TRUE,Regions!$C$3:$D$3) -> IE,National | T13: =+F13*(1+$N$1) -> 51.51 | U13: =+G13*(1+$N$1) -> 50.898 | V13: =+H13*(1+$N$1) -> 58.344 | W13: =+I13*(1+$N$1) -> 53.346 | X13: =+J13*(1+$N$1) -> 47.022 | Y13: 5
C14: FT-RSDSOL | D14: ACT_BND | E14: =_xlfn.TEXTJOIN(",",TRUE,Regions!$C$3:$D$3) -> IE,National | F14: =ROUNDUP(Conversions!$B$2*SUM('EB2018'!$AL$56),1) -> 0.6 | G14: =ROUNDUP(Conversions!$B$2*SUM('EB2019'!$AL$56),1) -> 0.6 | H14: =ROUNDUP(Conversions!$B$2*SUM('EB2020'!$AL$56),1) -> 0.6 | I14: =ROUNDUP(Conversions!$B$2*SUM('EB2021'!$AL$56),1) -> 0.6 | J14: =ROUNDUP(Conversions!$B$2*SUM('EB2022'!$AL$56),1) -> 0.6 | K14: 1 | P14: UP | Q14: FT-RSDBGS | R14: ACT_BND | S14: =_xlfn.TEXTJOIN(",",TRUE,Regions!$C$3:$D$3) -> IE,National | T14: 0 | U14: 0 | V14: 0 | W14: 0 | X14: 0 | Y14: 1
P15: * | Q15: FT-RSDBDL | R15: ACT_BND | S15: =_xlfn.TEXTJOIN(",",TRUE,Regions!$C$3:$D$3) -> IE,National | T15: =+F4*(1-$N$1) -> 0 | U15: =+G4*(1-$N$1) -> 0 | V15: =+H4*(1-$N$1) -> 0 | W15: =+I4*(1-$N$1) -> 0 | X15: =+J4*(1-$N$1) -> 0 | Y15: 1
P16: LO | Q16: FT-RSDWOO | R16: ACT_BND | S16: =_xlfn.TEXTJOIN(",",TRUE,Regions!$C$3:$D$3) -> IE,National | T16: =+F5*(1-$N$1)*0.95 -> 1.2103 | U16: =+G5*(1-$N$1) -> 1.078 | V16: =+H5*(1-$N$1) -> 1.078 | W16: =+I5*(1-$N$1) -> 1.176 | X16: =+J5*(1-$N$1) -> 0.98 | Y16: 1
P17: LO | Q17: FT-RSDCOA | R17: ACT_BND | S17: =_xlfn.TEXTJOIN(",",TRUE,Regions!$C$3:$D$3) -> IE,National | T17: =+F6*(1-$N$1) -> 8.918 | U17: =+G6*(1-$N$1) -> 7.644 | V17: =+H6*(1-$N$1) -> 8.036 | W17: =+I6*(1-$N$1) -> 7.644 | X17: =+J6*(1-$N$1) -> 5.096 | Y17: 1
P18: LO | Q18: FT-RSDPEA | R18: ACT_BND | S18: =_xlfn.TEXTJOIN(",",TRUE,Regions!$C$3:$D$3) -> IE,National | T18: =+F7*(1-$N$1)*0.95 -> 7.7273 | U18: =+G7*(1-$N$1) -> 7.546 | V18: =+H7*(1-$N$1) -> 7.84 | W18: =+I7*(1-$N$1) -> 7.448 | X18: =+J7*(1-$N$1) -> 6.468 | Y18: 1
P19: LO | Q19: FT-RSDELC | R19: ACT_BND | S19: =_xlfn.TEXTJOIN(",",TRUE,Regions!$C$3:$D$3) -> IE,National | T19: =+F8*(1-$N$1) -> 28.91 | U19: =+G8*(1-$N$1) -> 30.184 | V19: =+H8*(1-$N$1) -> 30.772 | W19: =+I8*(1-$N$1) -> 31.164 | X19: =+J8*(1-$N$1) -> 29.4 | Y19: 1
P20: * | Q20: FT-RSDETH | R20: ACT_BND | S20: =_xlfn.TEXTJOIN(",",TRUE,Regions!$C$3:$D$3) -> IE,National | T20: =+F9*(1-$N$1) -> 0 | U20: =+G9*(1-$N$1) -> 0 | V20: =+H9*(1-$N$1) -> 0 | W20: =+I9*(1-$N$1) -> 0 | X20: =+J9*(1-$N$1) -> 0 | Y20: 1
P21: LO | Q21: FT-RSDGAS | R21: ACT_BND | S21: =_xlfn.TEXTJOIN(",",TRUE,Regions!$C$3:$D$3) -> IE,National | T21: =+F10*(1-$N$1) -> 24.794 | U21: =+G10*(1-$N$1) -> 24.304 | V21: =+H10*(1-$N$1) -> 24.206 | W21: =+I10*(1-$N$1) -> 24.5 | X21: =+J10*(1-$N$1) -> 22.246 | Y21: 1
P22: * | Q22: FT-RSDHET | R22: ACT_BND | S22: =_xlfn.TEXTJOIN(",",TRUE,Regions!$C$3:$D$3) -> IE,National | T22: =+F11*(1-$N$1) -> 0 | U22: =+G11*(1-$N$1) -> 0 | V22: =+H11*(1-$N$1) -> 0 | W22: =+I11*(1-$N$1) -> 0 | X22: =+J11*(1-$N$1) -> 0 | Y22: 1
P23: LO | Q23: FT-RSDLPG | R23: ACT_BND | S23: =_xlfn.TEXTJOIN(",",TRUE,Regions!$C$3:$D$3) -> IE,National | T23: =+F12*(1-$N$1)*0.8 -> 1.8032 | U23: =+G12*(1-$N$1)*0.8 -> 1.6464 | V23: =+H12*(1-$N$1)*0.8 -> 1.8816 | W23: =+I12*(1-$N$1)*0.8 -> 1.6464 | X23: =+J12*(1-$N$1)*0.8 -> 1.4896 | Y23: 1
P24: LO | Q24: FT-RSDKER | R24: ACT_BND | S24: =_xlfn.TEXTJOIN(",",TRUE,Regions!$C$3:$D$3) -> IE,National | T24: =+F13*(1-$N$1) -> 49.49 | U24: =+G13*(1-$N$1) -> 48.902 | V24: =+H13*(1-$N$1) -> 56.056 | W24: =+I13*(1-$N$1) -> 51.254 | X24: =+J13*(1-$N$1) -> 45.178 | Y24: 1
P25: * | Q25: FT-RSDSOL | R25: ACT_BND | S25: =_xlfn.TEXTJOIN(",",TRUE,Regions!$C$3:$D$3) -> IE,National | T25: =+F14*(1-$N$1) -> 0.588 | U25: =+G14*(1-$N$1) -> 0.588 | V25: =+H14*(1-$N$1) -> 0.588 | W25: =+I14*(1-$N$1) -> 0.588 | X25: =+J14*(1-$N$1) -> 0.588 | Y25: 1

Sheet SRV
M1: Calibration margin | N1: 0.03
B2: deact~TFM_INS-TS | P2: ~TFM_INS-TS
B3: LimType | C3: PSET_PN | D3: Attribute | E3: Region | F3: 2018 | G3: 2019 | H3: 2020 | I3: 2021 | J3: 2022 | K3: 0 | P3: LimType | Q3: PSET_PN | R3: Attribute | S3: Region | T3: 2018 | U3: 2019 | V3: 2020 | W3: 2021 | X3: 2022 | Y3: 0
C4: FT-SRVAHT | D4: ACT_BND | E4: =_xlfn.TEXTJOIN(",",TRUE,Regions!$C$3:$D$3) -> IE,National | F4: =ROUNDUP(Conversions!$B$2*SUM('EB2018'!$AM$57),1) -> 0.7 | G4: =ROUNDUP(Conversions!$B$2*SUM('EB2019'!$AM$57),1) -> 0.7 | H4: =ROUNDUP(Conversions!$B$2*SUM('EB2020'!$AM$57),1) -> 0.9 | I4: =ROUNDUP(Conversions!$B$2*SUM('EB2021'!$AM$57),1) -> 1 | J4: =0.31+ROUNDUP(Conversions!$B$2*SUM('EB2022'!$AM$57),1) -> 1.31 | K4: 1 | P4: UP | Q4: FT-SRVAHT | R4: ACT_BND | S4: =_xlfn.TEXTJOIN(",",TRUE,Regions!$C$3:$D$3) -> IE,National | T4: =+F4*(2+$N$1) -> 1.421 | U4: =+G4*(2+$N$1) -> 1.421 | V4: =+H4*(2+$N$1) -> 1.827 | W4: =+I4*(2+$N$1) -> 2.03 | X4: =+J4*(2+$N$1) -> 2.6593 | Y4: 1
C5: FT-SRVBDL | D5: ACT_BND | E5: =_xlfn.TEXTJOIN(",",TRUE,Regions!$C$3:$D$3) -> IE,National | F5: =ROUNDUP(Conversions!$B$2*SUM('EB2018'!$AI$57),1) -> 0 | G5: =ROUNDUP(Conversions!$B$2*SUM('EB2019'!$AI$57),1) -> 0 | H5: =ROUNDUP(Conversions!$B$2*SUM('EB2020'!$AI$57),1) -> 0 | I5: =ROUNDUP(Conversions!$B$2*SUM('EB2021'!$AI$57),1) -> 0 | J5: =ROUNDUP(Conversions!$B$2*SUM('EB2022'!$AI$57),1) -> 0 | K5: 1 | P5: UP | Q5: FT-SRVBDL | R5: ACT_BND | S5: =_xlfn.TEXTJOIN(",",TRUE,Regions!$C$3:$D$3) -> IE,National | T5: =+F5*(1+$N$1) -> 0 | U5: =+G5*(1+$N$1) -> 0 | V5: =+H5*(1+$N$1) -> 0 | W5: =+I5*(1+$N$1) -> 0 | X5: =+J5*(1+$N$1) -> 0 | Y5: 1
C6: FT-SRVBGS | D6: ACT_BND | E6: =_xlfn.TEXTJOIN(",",TRUE,Regions!$C$3:$D$3) -> IE,National | F6: =ROUNDUP(Conversions!$B$2*SUM('EB2018'!$AH$57),1) -> 0.3 | G6: =ROUNDUP(Conversions!$B$2*SUM('EB2019'!$AH$57),1) -> 0.3 | H6: =ROUNDUP(Conversions!$B$2*SUM('EB2020'!$AH$57),1) -> 0.3 | I6: =ROUNDUP(Conversions!$B$2*SUM('EB2021'!$AH$57),1) -> 0.3 | J6: =ROUNDUP(Conversions!$B$2*SUM('EB2022'!$AH$57),1) -> 0.3 | K6: 1 | P6: UP | Q6: FT-SRVBGS | R6: ACT_BND | S6: =_xlfn.TEXTJOIN(",",TRUE,Regions!$C$3:$D$3) -> IE,National | T6: =+F6*(1+$N$1) -> 0.309 | U6: =+G6*(1+$N$1) -> 0.309 | V6: =+H6*(1+$N$1) -> 0.309 | W6: =+I6*(1+$N$1) -> 0.309 | X6: =+J6*(1+$N$1) -> 0.309 | Y6: 1
C7: FT-SRVBIO | D7: ACT_BND | E7: =_xlfn.TEXTJOIN(",",TRUE,Regions!$C$3:$D$3) -> IE,National | F7: =ROUNDUP(Conversions!$B$2*SUM('EB2018'!$AE$57),1) -> 0.8 | G7: =ROUNDUP(Conversions!$B$2*SUM('EB2019'!$AE$57),1) -> 0.6 | H7: =ROUNDUP(Conversions!$B$2*SUM('EB2020'!$AE$57),1) -> 0.7 | I7: =ROUNDUP(Conversions!$B$2*SUM('EB2021'!$AE$57),1) -> 0.8 | J7: =ROUNDUP(Conversions!$B$2*SUM('EB2022'!$AE$57),1) -> 0.9 | K7: 1 | P7: UP | Q7: FT-SRVBIO | R7: ACT_BND | S7: =_xlfn.TEXTJOIN(",",TRUE,Regions!$C$3:$D$3) -> IE,National | T7: =+F7*(1+$N$1)*1.03 -> 0.84872 | U7: =+G7*(1+$N$1) -> 0.618 | V7: =+H7*(1+$N$1) -> 0.721 | W7: =+I7*(1+$N$1) -> 0.824 | X7: =+J7*(1+$N$1) -> 0.927 | Y7: 1
C8: FT-SRVCOA | D8: ACT_BND | E8: =_xlfn.TEXTJOIN(",",TRUE,Regions!$C$3:$D$3) -> IE,National | F8: =ROUNDUP(Conversions!$B$2*SUM('EB2018'!$C$57),1) -> 0.1 | G8: =ROUNDUP(Conversions!$B$2*SUM('EB2019'!$C$57),1) -> 0.1 | H8: =ROUNDUP(Conversions!$B$2*SUM('EB2020'!$C$57),1) -> 0.1 | I8: =ROUNDUP(Conversions!$B$2*SUM('EB2021'!$C$57),1) -> 0.1 | J8: =ROUNDUP(Conversions!$B$2*SUM('EB2022'!$C$57),1) -> 0.1 | K8: 1 | P8: UP | Q8: FT-SRVCOA | R8: ACT_BND | S8: =_xlfn.TEXTJOIN(",",TRUE,Regions!$C$3:$D$3) -> IE,National | T8: =+F8*(1+$N$1) -> 0.103 | U8: =+G8*(1+$N$1) -> 0.103 | V8: =+H8*(1+$N$1) -> 0.103 | W8: =+I8*(1+$N$1) -> 0.103 | X8: =+J8*(1+$N$1) -> 0.103 | Y8: 5
C9: FT-SRVELC | D9: ACT_BND | E9: =_xlfn.TEXTJOIN(",",TRUE,Regions!$C$3:$D$3) -> IE,National | F9: =ROUNDUP(Conversions!$B$2*SUM('EB2018'!$AO$57),1) -> 45.4 | G9: =ROUNDUP(Conversions!$B$2*SUM('EB2019'!$AO$57),1) -> 46.9 | H9: =ROUNDUP(Conversions!$B$2*SUM('EB2020'!$AO$57),1) -> 44.6 | I9: =ROUNDUP(Conversions!$B$2*SUM('EB2021'!$AO$57),1) -> 49.1 | J9: =ROUNDUP(Conversions!$B$2*SUM('EB2022'!$AO$57),1) -> 53.7 | K9: 1 | P9: UP | Q9: FT-SRVELC | R9: ACT_BND | S9: =_xlfn.TEXTJOIN(",",TRUE,Regions!$C$3:$D$3) -> IE,National | T9: =+F9*(1+$N$1) -> 46.762 | U9: =+G9*(1+$N$1) -> 48.307 | V9: =+H9*(1+$N$1) -> 45.938 | W9: =+I9*(1+$N$1) -> 50.573 | X9: =+J9*(1+$N$1) -> 55.311 | Y9: 1
C10: FT-SRVETH | D10: ACT_BND | E10: =_xlfn.TEXTJOIN(",",TRUE,Regions!$C$3:$D$3) -> IE,National | F10: =ROUNDUP(Conversions!$B$2*SUM('EB2018'!$AJ$57),1) -> 0 | G10: =ROUNDUP(Conversions!$B$2*SUM('EB2019'!$AJ$57),1) -> 0 | H10: =ROUNDUP(Conversions!$B$2*SUM('EB2020'!$AJ$57),1) -> 0 | I10: =ROUNDUP(Conversions!$B$2*SUM('EB2021'!$AJ$57),1) -> 0 | J10: =ROUNDUP(Conversions!$B$2*SUM('EB2022'!$AJ$57),1) -> 0 | K10: 1 | P10: UP | Q10: FT-SRVETH | R10: ACT_BND | S10: =_xlfn.TEXTJOIN(",",TRUE,Regions!$C$3:$D$3) -> IE,National | T10: =+F10*(1+$N$1) -> 0 | U10: =+G10*(1+$N$1) -> 0 | V10: =+H10*(1+$N$1) -> 0 | W10: =+I10*(1+$N$1) -> 0 | X10: =+J10*(1+$N$1) -> 0 | Y10: 1
C11: FT-SRVGAS | D11: ACT_BND | E11: =_xlfn.TEXTJOIN(",",TRUE,Regions!$C$3:$D$3) -> IE,National | F11: =ROUNDUP(Conversions!$B$2*SUM('EB2018'!$AA$57),1) -> 14.5 | G11: =ROUNDUP(Conversions!$B$2*SUM('EB2019'!$AA$57),1) -> 14.2 | H11: =ROUNDUP(Conversions!$B$2*SUM('EB2020'!$AA$57),1) -> 12.9 | I11: =ROUNDUP(Conversions!$B$2*SUM('EB2021'!$AA$57),1) -> 14.7 | J11: =ROUNDUP(Conversions!$B$2*SUM('EB2022'!$AA$57),1) -> 14.4 | K11: 1 | P11: UP | Q11: FT-SRVGAS | R11: ACT_BND | S11: =_xlfn.TEXTJOIN(",",TRUE,Regions!$C$3:$D$3) -> IE,National | T11: =+F11*(1+$N$1) -> 14.935 | U11: =+G11*(1+$N$1) -> 14.626 | V11: =+H11*(1+$N$1) -> 13.287 | W11: =+I11*(1+$N$1) -> 15.141 | X11: =+J11*(1+$N$1) -> 14.832 | Y11: 1
C12: FT-SRVHET | D12: ACT_BND | E12: =_xlfn.TEXTJOIN(",",TRUE,Regions!$C$3:$D$3) -> IE,National | F12: =ROUNDUP(Conversions!$B$2*SUM('EB2018'!$AP$57),1) -> 0 | G12: =ROUNDUP(Conversions!$B$2*SUM('EB2019'!$AP$57),1) -> 0 | H12: =ROUNDUP(Conversions!$B$2*SUM('EB2020'!$AP$57),1) -> 0 | I12: =ROUNDUP(Conversions!$B$2*SUM('EB2021'!$AP$57),1) -> 0 | J12: =ROUNDUP(Conversions!$B$2*SUM('EB2022'!$AP$57),1) -> 0 | K12: 1 | P12: UP | Q12: FT-SRVHET | R12: ACT_BND | S12: =_xlfn.TEXTJOIN(",",TRUE,Regions!$C$3:$D$3) -> IE,National | T12: =+F12*(1+$N$1) -> 0 | U12: =+G12*(1+$N$1) -> 0 | V12: =+H12*(1+$N$1) -> 0 | W12: =+I12*(1+$N$1) -> 0 | X12: =+J12*(1+$N$1) -> 0 | Y12: 1
C13: FT-SRVLPG | D13: ACT_BND | E13: =_xlfn.TEXTJOIN(",",TRUE,Regions!$C$3:$D$3) -> IE,National | F13: =ROUNDUP(Conversions!$B$2*SUM('EB2018'!$T$57),1) -> 2.8 | G13: =ROUNDUP(Conversions!$B$2*SUM('EB2019'!$T$57),1) -> 3 | H13: =ROUNDUP(Conversions!$B$2*SUM('EB2020'!$T$57),1) -> 2.3 | I13: =ROUNDUP(Conversions!$B$2*SUM('EB2021'!$T$57),1) -> 2.6 | J13: =ROUNDUP(Conversions!$B$2*SUM('EB2022'!$T$57),1) -> 2.7 | K13: 1 | P13: UP | Q13: FT-SRVLPG | R13: ACT_BND | S13: =_xlfn.TEXTJOIN(",",TRUE,Regions!$C$3:$D$3) -> IE,National | T13: =+F13*(1+$N$1) -> 2.884 | U13: =+G13*(1+$N$1) -> 3.09 | V13: =+H13*(1+$N$1) -> 2.369 | W13: =+I13*(1+$N$1) -> 2.678 | X13: =+J13*(1+$N$1) -> 2.781 | Y13: 5
C14: FT-SRVOIL | D14: ACT_BND | E14: =_xlfn.TEXTJOIN(",",TRUE,Regions!$C$3:$D$3) -> IE,National | F14: =ROUNDUP(Conversions!$B$2*SUM('EB2018'!$Q$57,'EB2018'!$S$57,'EB2018'!$U$57),1) -> 7.1 | G14: =ROUNDUP(Conversions!$B$2*SUM('EB2019'!$Q$57,'EB2019'!$S$57,'EB2019'!$U$57),1) -> 6.4 | H14: =ROUNDUP(Conversions!$B$2*SUM('EB2020'!$Q$57,'EB2020'!$S$57,'EB2020'!$U$57),1) -> 5.8 | I14: =ROUNDUP(Conversions!$B$2*SUM('EB2021'!$Q$57,'EB2021'!$S$57,'EB2021'!$U$57),1) -> 5.6 | J14: =ROUNDUP(Conversions!$B$2*SUM('EB2022'!$Q$57,'EB2021'!$S$57,'EB2021'!$U$57),1) -> 5.3 | K14: 1 | P14: UP | Q14: FT-SRVOIL | R14: ACT_BND | S14: =_xlfn.TEXTJOIN(",",TRUE,Regions!$C$3:$D$3) -> IE,National | T14: =+F14*(1+$N$1) -> 7.313 | U14: =+G14*(1+$N$1) -> 6.592 | V14: =+H14*(1+$N$1) -> 5.974 | W14: =+I14*(1+$N$1) -> 5.768 | X14: =+J14*(1+$N$1) -> 5.459 | Y14: 5
C15: FT-SRVSOL | D15: ACT_BND | E15: =_xlfn.TEXTJOIN(",",TRUE,Regions!$C$3:$D$3) -> IE,National | F15: =ROUNDUP(Conversions!$B$2*SUM('EB2018'!$AL$57),1) -> 0.1 | G15: =ROUNDUP(Conversions!$B$2*SUM('EB2019'!$AL$57),1) -> 0.1 | H15: =ROUNDUP(Conversions!$B$2*SUM('EB2020'!$AL$57),1) -> 0.1 | I15: =ROUNDUP(Conversions!$B$2*SUM('EB2021'!$AL$57),1) -> 0.1 | J15: =ROUNDUP(Conversions!$B$2*SUM('EB2022'!$AL$57),1) -> 0.1 | K15: 1 | P15: UP | Q15: FT-SRVSOL | R15: ACT_BND | S15: =_xlfn.TEXTJOIN(",",TRUE,Regions!$C$3:$D$3) -> IE,National | T15: =+F15*(5+$N$1) -> 0.503 | U15: =+G15*(5+$N$1) -> 0.503 | V15: =+H15*(5+$N$1) -> 0.503 | W15: =+I15*(5+$N$1) -> 0.503 | X15: =+J15*(5+$N$1) -> 0.503 | Y15: 1
P16: * | Q16: FT-SRVAHT | R16: ACT_BND | S16: =_xlfn.TEXTJOIN(",",TRUE,Regions!$C$3:$D$3) -> IE,National | T16: =+F4*(1-$N$1) -> 0.679 | U16: =+G4*(1-$N$1) -> 0.679 | V16: =+H4*(1-$N$1) -> 0.873 | W16: =+I4*(1-$N$1) -> 0.97 | X16: =+J4*(1-$N$1) -> 1.2707 | Y16: 1
P17: * | Q17: FT-SRVBDL | R17: ACT_BND | S17: =_xlfn.TEXTJOIN(",",TRUE,Regions!$C$3:$D$3) -> IE,National | T17: =+F5*(1-$N$1) -> 0 | U17: =+G5*(1-$N$1) -> 0 | V17: =+H5*(1-$N$1) -> 0 | W17: =+I5*(1-$N$1) -> 0 | X17: =+J5*(1-$N$1) -> 0 | Y17: 1
P18: * | Q18: FT-SRVBGS | R18: ACT_BND | S18: =_xlfn.TEXTJOIN(",",TRUE,Regions!$C$3:$D$3) -> IE,National | T18: =+F6*(1-$N$1) -> 0.291 | U18: =+G6*(1-$N$1) -> 0.291 | V18: =+H6*(1-$N$1) -> 0.291 | W18: =+I6*(1-$N$1) -> 0.291 | X18: =+J6*(1-$N$1) -> 0.291 | Y18: 1
P19: LO | Q19: FT-SRVBIO | R19: ACT_BND | S19: =_xlfn.TEXTJOIN(",",TRUE,Regions!$C$3:$D$3) -> IE,National | T19: =+F7*(1-$N$1)*0.93 -> 0.72168 | U19: =+G7*(1-$N$1) -> 0.582 | V19: =+H7*(1-$N$1) -> 0.679 | W19: =+I7*(1-$N$1) -> 0.776 | X19: =+J7*(1-$N$1) -> 0.873 | Y19: 1
P20: * | Q20: FT-SRVCOA | R20: ACT_BND | S20: =_xlfn.TEXTJOIN(",",TRUE,Regions!$C$3:$D$3) -> IE,National | T20: =+F8*(1-$N$1) -> 0.097 | U20: =+G8*(1-$N$1) -> 0.097 | V20: =+H8*(1-$N$1) -> 0.097 | W20: =+I8*(1-$N$1) -> 0.097 | X20: =+J8*(1-$N$1) -> 0.097 | Y20: 1
P21: LO | Q21: FT-SRVELC | R21: ACT_BND | S21: =_xlfn.TEXTJOIN(",",TRUE,Regions!$C$3:$D$3) -> IE,National | T21: =+F9*(1-$N$1) -> 44.038 | U21: =+G9*(1-$N$1) -> 45.493 | V21: =+H9*(1-$N$1) -> 43.262 | W21: =+I9*(1-$N$1) -> 47.627 | X21: =+J9*(1-$N$1) -> 52.089 | Y21: 1
P22: * | Q22: FT-SRVETH | R22: ACT_BND | S22: =_xlfn.TEXTJOIN(",",TRUE,Regions!$C$3:$D$3) -> IE,National | T22: =+F10*(1-$N$1) -> 0 | U22: =+G10*(1-$N$1) -> 0 | V22: =+H10*(1-$N$1) -> 0 | W22: =+I10*(1-$N$1) -> 0 | X22: =+J10*(1-$N$1) -> 0 | Y22: 1
P23: LO | Q23: FT-SRVGAS | R23: ACT_BND | S23: =_xlfn.TEXTJOIN(",",TRUE,Regions!$C$3:$D$3) -> IE,National | T23: =+F11*(1-$N$1)*0.97 -> 13.64305 | U23: =+G11*(1-$N$1) -> 13.774 | V23: =+H11*(1-$N$1) -> 12.513 | W23: =+I11*(1-$N$1) -> 14.259 | X23: =+J11*(1-$N$1) -> 13.968 | Y23: 1
P24: * | Q24: FT-SRVHET | R24: ACT_BND | S24: =_xlfn.TEXTJOIN(",",TRUE,Regions!$C$3:$D$3) -> IE,National | T24: =+F12*(1-$N$1) -> 0 | U24: =+G12*(1-$N$1) -> 0 | V24: =+H12*(1-$N$1) -> 0 | W24: =+I12*(1-$N$1) -> 0 | X24: =+J12*(1-$N$1) -> 0 | Y24: 1
P25: LO | Q25: FT-SRVLPG | R25: ACT_BND | S25: =_xlfn.TEXTJOIN(",",TRUE,Regions!$C$3:$D$3) -> IE,National | T25: =+F13*(1-$N$1) -> 2.716 | U25: =+G13*(1-$N$1) -> 2.91 | V25: =+H13*(1-$N$1) -> 2.231 | W25: =+I13*(1-$N$1) -> 2.522 | X25: =+J13*(1-$N$1) -> 2.619 | Y25: 1
P26: LO | Q26: FT-SRVOIL | R26: ACT_BND | S26: =_xlfn.TEXTJOIN(",",TRUE,Regions!$C$3:$D$3) -> IE,National | T26: =+F14*(1-$N$1) -> 6.887 | U26: =+G14*(1-$N$1) -> 6.208 | V26: =+H14*(1-$N$1) -> 5.626 | W26: =+I14*(1-$N$1) -> 5.432 | X26: =+J14*(1-$N$1) -> 5.141 | Y26: 1
P27: * | Q27: FT-SRVSOL | R27: ACT_BND | S27: =_xlfn.TEXTJOIN(",",TRUE,Regions!$C$3:$D$3) -> IE,National | T27: =+F15*(1-$N$1) -> 0.097 | U27: =+G15*(1-$N$1) -> 0.097 | V27: =+H15*(1-$N$1) -> 0.097 | W27: =+I15*(1-$N$1) -> 0.097 | X27: =+J15*(1-$N$1) -> 0.097 | Y27: 1

Sheet TRA
G4: =IF(RIGHT(B2,1)<>" ","UC_T","") -> UC_T
B5: UC_N | C5: Cset_CN | D5: Cset_Set | E5: Pset_PN | F5: Year | G5: LimType | H5: UC_COMPRD | I5: UC_RHSTS | J5: UC_Desc
B6: *Units | I6: *kt
B7: ="UC_Historic_"&C7&"-cons_Multi" -> UC_Historic_TRABDL-cons_Multi | C7: TRABDL | F7: 2018 | G7: UP | H7: 1 | I7: =F49 -> 5.9 | J7: Historic biodiesel consumption in TRA - Multi
F8: 2019 | G8: UP | I8: =G49 -> 6.8
F9: 2020 | G9: UP | I9: =H49 -> 6.5
F10: 2021 | G10: UP | I10: =I49 -> 6.7
F11: 2022 | G11: UP | I11: =J49 -> 8.4
F12: 0 | I12: =VLOOKUP("Value", 'CO2-config'!$B$4:$D$14,MATCH($F12,'CO2-config'!$B$6:$D$6,),FALSE) -> 1
B13: ="UC_Historic_"&C13&"-cons_Multi" -> UC_Historic_TRADST-cons_Multi | C13: TRADST | F13: 2018 | G13: UP | H13: 1 | I13: =F50 -> 141.9 | J13: Historic diesel consumption in TRA - Multi
F14: 2019 | G14: UP | I14: =G50 -> 133.22
F15: 2020 | G15: UP | I15: =H50 -> 113.3
F16: 2021 | G16: UP | I16: =I50 -> 120.9
F17: 2022 | G17: UP | I17: =J50 -> 126.3
F18: 0 | I18: =VLOOKUP("Value", 'CO2-config'!$B$4:$D$14,MATCH($F18,'CO2-config'!$B$6:$D$6,),FALSE) -> 1
B19: ="UC_Historic_"&C19&"-cons_Multi" -> UC_Historic_TRAELC-cons_Multi | C19: TRAELC | F19: 2018 | G19: UP | H19: 1 | I19: =F51 -> 0.383 | J19: Historic electricity consumption in TRA - Multi
F20: 2019 | G20: UP | I20: =G51 -> 0.52
F21: 2020 | G21: UP | I21: =H51 -> 0.65
F22: 2021 | G22: UP | I22: =I51 -> 0.72
F23: 2022 | G23: UP | I23: =J51 -> 0.8
F24: 0 | I24: =VLOOKUP("Value", 'CO2-config'!$B$4:$D$14,MATCH($F24,'CO2-config'!$B$6:$D$6,),FALSE) -> 1
B25: ="UC_Historic_"&C25&"-cons_Multi" -> UC_Historic_TRAETH-cons_Multi | C25: TRAETH | F25: 2018 | G25: UP | H25: 1 | I25: =F52 -> 1.2 | J25: Historic ethanol consumption in TRA - Multi
F26: 2019 | G26: UP | I26: =G52 -> 1.1
F27: 2020 | G27: UP | I27: =H52 -> 0.9
F28: 2021 | G28: UP | I28: =I52 -> 0.9
F29: 2022 | G29: UP | I29: =J52 -> 1
F30: 0 | I30: =VLOOKUP("Value", 'CO2-config'!$B$4:$D$14,MATCH($F30,'CO2-config'!$B$6:$D$6,),FALSE) -> 1
B31: ="UC_Historic_"&C31&"-cons_Multi" -> UC_Historic_TRAGSL-cons_Multi | C31: TRAGSL | F31: 2018 | G31: UP | H31: 1 | I31: =F53 -> 34.4 | J31: Historic gasoline consumption in TRA - Multi
F32: 2019 | G32: UP | I32: =G53 -> 32.7
F33: 2020 | G33: UP | I33: =H53 -> 27.87
F34: 2021 | G34: UP | I34: =I53 -> 25.7
F35: 2022 | G35: UP | I35: =J53 -> 29.3
F36: 0 | I36: =VLOOKUP("Value", 'CO2-config'!$B$4:$D$14,MATCH($F36,'CO2-config'!$B$6:$D$6,),FALSE) -> 1
B37: ="UC_Historic_"&C37&"-cons_Multi" -> UC_Historic_TRAKER-cons_Multi | C37: TRAKER | F37: 2018 | G37: UP | H37: 1 | I37: =F54 -> 46.202 | J37: Historic jet kerosene consumption in TRA - Multi
F38: 2019 | G38: UP | I38: =G54 -> 46.8
F39: 2020 | G39: UP | I39: =H54 -> 16.7
F40: 2021 | G40: UP | I40: =I54 -> 18.7
F41: 2022 | G41: UP | I41: =J54 -> 42.7
F42: 0 | I42: =VLOOKUP("Value", 'CO2-config'!$B$4:$D$14,MATCH($F42,'CO2-config'!$B$6:$D$6,),FALSE) -> 1
N46: Calibration margin | O46: 0.035
...

Sheet TRA-CAPs
C1: NCAP for new vehicles according to actual sales in 2019
C3: Trans - Insert
D4: ~TFM_INS
D5: TimeSlice | E5: LimType | F5: Attribute | G5: Year | H5: =Regions!C$3 -> IE | I5: =Regions!E$3 -> IE-CW | J5: =Regions!F$3 -> IE-D | K5: =Regions!G$3 -> IE-KE | L5: =Regions!H$3 -> IE-KK | M5: =Regions!I$3 -> IE-LS | N5: =Regions!J$3 -> IE-LD | O5: =Regions!K$3 -> IE-LH | P5: =Regions!L$3 -> IE-MH | ... AH5: =Regions!AD$3 -> IE-MN | AI5: Pset_PN | AJ5: Pset_PD
A6: =AI6 -> T-CAR*, T-LGT*, T-HGT* | E6: FX | F6: NCAP_BND | G6: 2019 | H6: 0 | I6: =H6 -> 0 | J6: =I6 -> 0 | K6: =J6 -> 0 | L6: =K6 -> 0 | M6: =L6 -> 0 | N6: =M6 -> 0 | O6: =N6 -> 0 | P6: =O6 -> 0 | ... AH6: =AG6 -> 0 | AI6: =AI47 -> T-CAR*, T-LGT*, T-HGT* | AJ6: *New
A7: =AI7 -> T-CAR-ICE_DST21 | B7: Diesel | E7: FX | F7: NCAP_BND | G7: 2019 | H7: =SUMIFS('New vehicle sales'!$G$186:$G$215,'New vehicle sales'!$C$186:$C$215,'TRA-CAPs'!G7,'New vehicle sales'!$E$186:$E$215,B7)/1000 -> 53.201 | I7: =$H7*'New vehicle sales'!D$44 -> 0.63606157 | J7: =$H7*'New vehicle sales'!E$44 -> 15.053103 | K7: =$H7*'New vehicle sales'!F$44 -> 2.4858822 | L7: =$H7*'New vehicle sales'!G$44 -> 1.10865 | M7: =$H7*'New vehicle sales'!H$44 -> 0.94626057 | N7: =$H7*'New vehicle sales'!I$44 -> 0.45664555 | O7: =$H7*'New vehicle sales'!J$44 -> 1.4399311 | P7: =$H7*'New vehicle sales'!K$44 -> 2.1790907 | ... AH7: =$H7*'New vehicle sales'!AC$44 -> 0.68582301 | AI7: =AI48 -> T-CAR-ICE_DST21 | AJ7: *New
A8: =AI8 -> T-CAR-ICE_GSL21 | B8: Petrol | E8: FX | F8: NCAP_BND | G8: 2019 | H8: =SUMIFS('New vehicle sales'!$G$186:$G$215,'New vehicle sales'!$C$186:$C$215,'TRA-CAPs'!G8,'New vehicle sales'!$E$186:$E$215,B8)/1000 -> 45.761 | I8: =$H8*'New vehicle sales'!D$44 -> 0.54711027 | J8: =$H8*'New vehicle sales'!E$44 -> 12.947972 | K8: =$H8*'New vehicle sales'!F$44 -> 2.138239 | L8: =$H8*'New vehicle sales'!G$44 -> 0.95360863 | M8: =$H8*'New vehicle sales'!H$44 -> 0.81392887 | N8: =$H8*'New vehicle sales'!I$44 -> 0.39278504 | O8: =$H8*'New vehicle sales'!J$44 -> 1.2385611 | P8: =$H8*'New vehicle sales'!K$44 -> 1.8743514 | ... AH8: =$H8*'New vehicle sales'!AC$44 -> 0.58991272 | AI8: =AI49 -> T-CAR-ICE_GSL21 | AJ8: *New
A9: =AI9 -> T-CAR-HEV_GSL21 | B9: Hybrid | E9: FX | F9: NCAP_BND | G9: 2019 | H9: =SUMIFS('New vehicle sales'!$G$186:$G$215,'New vehicle sales'!$C$186:$C$215,'TRA-CAPs'!G9,'New vehicle sales'!$E$186:$E$215,B9)/1000 -> 10.9 | I9: =$H9*'New vehicle sales'!D$44 -> 0.13031844 | J9: =$H9*'New vehicle sales'!E$44 -> 3.0841305 | K9: =$H9*'New vehicle sales'!F$44 -> 0.50931591 | L9: =$H9*'New vehicle sales'!G$44 -> 0.22714394 | M9: =$H9*'New vehicle sales'!H$44 -> 0.19387305 | N9: =$H9*'New vehicle sales'!I$44 -> 0.093559078 | O9: =$H9*'New vehicle sales'!J$44 -> 0.29501794 | P9: =$H9*'New vehicle sales'!K$44 -> 0.44645944 | ... AH9: =$H9*'New vehicle sales'!AC$44 -> 0.14051373 | AI9: =AI50 -> T-CAR-HEV_GSL21 | AJ9: *New
