Workbook

Sheet Cover
A16: TIMES-Ireland Model
A19: Document type: | B19: Scenario
A20: Sector(s): | B20: Power (PWR), Transport (TRA) and Service (SRV) sectors
A21: Purpose: | B21: Specify growth rates
A23: Original developer(s): | B23: Hannah Daly (UCC, h.daly@ucc.ie)
B24: Vahid Aryanpur (UCC, vahid.aryanpur@ucc.ie)
B25: Olexandr Balyk (UCC, olexandr.balyk@ucc.ie)
A26: Current maintainer(s): | B26: Bakytzhan Suleimenov (UCC, bsuleimenov@ucc.ie)
B27: Vahid Aryanpur (UCC, vahid.aryanpur@ucc.ie)
A29: Part of TIM version: | B29: 1
A30: Model repository: | B30: https://github.com/MaREI-EPMG/TIMES-Ireland-model
A31: Licence: | B31: CC BY-NC-SA 4.0 (unless specified otherwise)
B32: https://creativecommons.org/licenses/by-nc-sa/4.0/

Sheet Regions
C3: {=IF(LEFT(INDEX(C5:C7,$A$4),1)<>"*",INDEX(C5:C7,$A$4),"")} -> IE | D3: {=IF(LEFT(INDEX(D5:D7,$A$4),1)<>"*",INDEX(D5:D7,$A$4),"")} -> National | E3: {=IF(LEFT(INDEX(E5:E7,$A$4),1)<>"*",INDEX(E5:E7,$A$4),"")} -> IE-CW | F3: {=IF(LEFT(INDEX(F5:F7,$A$4),1)<>"*",INDEX(F5:F7,$A$4),"")} -> IE-D | G3: {=IF(LEFT(INDEX(G5:G7,$A$4),1)<>"*",INDEX(G5:G7,$A$4),"")} -> IE-KE | H3: {=IF(LEFT(INDEX(H5:H7,$A$4),1)<>"*",INDEX(H5:H7,$A$4),"")} -> IE-KK | I3: {=IF(LEFT(INDEX(I5:I7,$A$4),1)<>"*",INDEX(I5:I7,$A$4),"")} -> IE-LS | J3: {=IF(LEFT(INDEX(J5:J7,$A$4),1)<>"*",INDEX(J5:J7,$A$4),"")} -> IE-LD | ... AD3: {=IF(LEFT(INDEX(AD5:AD7,$A$4),1)<>"*",INDEX(AD5:AD7,$A$4),"")} -> IE-MN
A4: 1
A5: Development | C5: IE | D5: National | E5: =Regions!A11 -> IE-CW | F5: =Regions!A16 -> IE-D | G5: =Regions!A19 -> IE-KE | H5: =Regions!A20 -> IE-KK | I5: =Regions!A21 -> IE-LS | J5: =Regions!A24 -> IE-LD | K5: =Regions!A25 -> IE-LH | L5: =Regions!A27 -> IE-MH | M5: =Regions!A29 -> IE-OY | N5: =Regions!A34 -> IE-WH | O5: =Regions!A35 -> IE-WX | P5: =Regions!A36 -> IE-WW | Q5: =Regions!A13 -> IE-CE | R5: =Regions!A14 -> IE-CO | S5: =Regions!A18 -> IE-KY | T5: =Regions!A23 -> IE-LK | U5: =Regions!A32 -> IE-TA | V5: =Regions!A33 -> IE-WD | W5: =Regions!A17 -> IE-G | X5: =Regions!A22 -> IE-LM | Y5: =Regions!A26 -> IE-MO | Z5: =Regions!A30 -> IE-RN | AA5: =Regions!A31 -> IE-SO | AB5: =Regions!A12 -> IE-CN | AC5: =Regions!A15 -> IE-DL | AD5: =Regions!A28 -> IE-MN
A6: Single-region | C6: =C5 -> IE | D6: =IF(LEFT(D5,1)<>"*","*"&D5,D5) -> *National | E6: =IF(LEFT(E5,1)<>"*","*"&E5,E5) -> *IE-CW | F6: =IF(LEFT(F5,1)<>"*","*"&F5,F5) -> *IE-D | G6: =IF(LEFT(G5,1)<>"*","*"&G5,G5) -> *IE-KE | H6: =IF(LEFT(H5,1)<>"*","*"&H5,H5) -> *IE-KK | I6: =IF(LEFT(I5,1)<>"*","*"&I5,I5) -> *IE-LS | J6: =IF(LEFT(J5,1)<>"*","*"&J5,J5) -> *IE-LD | K6: =IF(LEFT(K5,1)<>"*","*"&K5,K5) -> *IE-LH | ... AD6: =IF(LEFT(AD5,1)<>"*","*"&AD5,AD5) -> *IE-MN
A7: Multi-region | C7: ="*"&C5 -> *IE | D7: =D5 -> National | E7: =E5 -> IE-CW | F7: =F5 -> IE-D | G7: =G5 -> IE-KE | H7: =H5 -> IE-KK | I7: =I5 -> IE-LS | J7: =J5 -> IE-LD | K7: =K5 -> IE-LH | ... AD7: =AD5 -> IE-MN
A10: Code | B10: County name
A11: IE-CW | B11: Carlow
A12: IE-CN | B12: Cavan
A13: IE-CE | B13: Clare
A14: IE-CO | B14: Cork
A15: IE-DL | B15: Donegal
A16: IE-D | B16: Dublin
A17: IE-G | B17: Galway
A18: IE-KY | B18: Kerry
A19: IE-KE | B19: Kildare
A20: IE-KK | B20: Kilkenny
A21: IE-LS | B21: Laois
... A36: IE-WW | B36: Wicklow
A37: Source: https://en.wikipedia.org/wiki/ISO_3166-2:IE

Sheet SUP
B2: ="~UC_Sets: R_E: " & _xlfn.TEXTJOIN(",",TRUE,Regions!C3:D3) -> ~UC_Sets: R_E: IE,National
B3: ~UC_Sets: T_E:
F4: ~UC_T
B5: UC_N | C5: UC_ATTR | D5: Pset_PN | E5: Year | F5: LimType | G5: UC_ACT | H5: UC_ACT~RHS | I5: UC_RHSRTS~2018 | J5: UC_RHSRTS~0 | K5: UC_Desc
B6: =_xlfn.TEXTJOIN("_",TRUE,"UC",A15,"MaxGrowth",B15) -> UC_SUP_MaxGrowth_BIOGAS | C6: ACT, GROWTH | D6: SBIORGAS* | E6: 2022 | F6: LO | G6: 1.2 | H6: 1 | I6: =-D15 -> -0.2 | J6: 5 | K6: =_xlfn.TEXTJOIN(" ",TRUE,A15, "maximum growth rate of",B15) -> SUP maximum growth rate of BIOGAS
B7: =_xlfn.TEXTJOIN("_",TRUE,"UC",A16,"MaxGrowth",B16) -> UC_SUP_MaxGrowth_BIODST | C7: ACT, GROWTH | D7: SBIORDST* | E7: 2022 | F7: LO | G7: 1.2 | H7: 1 | I7: =-D16 -> -1 | J7: 5 | K7: =_xlfn.TEXTJOIN(" ",TRUE,A16, "maximum growth rate of",B16) -> SUP maximum growth rate of BIODST
B8: =_xlfn.TEXTJOIN("_",TRUE,"UC",A17,"MaxGrowth",B17) -> UC_SUP_MaxGrowth_BIOETH | C8: ACT, GROWTH | D8: SBIORETH* | E8: 2022 | F8: LO | G8: 1.2 | H8: 1 | I8: =-D17 -> -1 | J8: 5 | K8: =_xlfn.TEXTJOIN(" ",TRUE,A17, "maximum growth rate of",B17) -> SUP maximum growth rate of BIOETH
C14: Max growth rate | D14: Starting value (PJ)
A15: SUP | B15: BIOGAS | C15: 0.4 | D15: 0.2
A16: SUP | B16: BIODST | C16: 0.4 | D16: 1
A17: SUP | B17: BIOETH | C17: 0.4 | D17: 1
A18: SUP | B18: MSW
B20: ~TFM_INS
B21: TimeSlice | C21: LimType | D21: Attribute | E21: Year | F21: =IF(Regions!C$3<>"",Regions!C$3,"*") -> IE | G21: =IF(Regions!C$3<>"",Regions!D$3,"*") -> National | H21: Cset_CN
D22: COM_TAXNET | E22: 2018 | F22: 2222 | G22: =F22 -> 2222 | H22: BIOGAS1G,BIOGAS2G
B25: ="~UC_Sets: R_E: " & _xlfn.TEXTJOIN(",",TRUE,Regions!C26:D26) -> ~UC_Sets: R_E:
B26: ~UC_Sets: T_E:
G27: ~UC_T
B28: UC_N | C28: UC_ATTR | D28: Pset_PN | E28: Cset_CN | F28: Year | G28: LimType | H28: UC_ACT | I28: UC_ACT~RHS | J28: UC_RHSRTS~2019 | K28: UC_RHSRTS~0 | L28: UC_Desc
B29: =_xlfn.TEXTJOIN("_",TRUE,"UC",A18,"MaxGrowth",B18) -> UC_SUP_MaxGrowth_MSW | C29: ACT, GROWTH | D29: MIN*MSW* | F29: 2019 | G29: LO | H29: 1.007 | I29: 1 | J29: =-D39 -> 0 | K29: 5 | L29: =_xlfn.TEXTJOIN(" ",TRUE,A18, "maximum growth rate of",B18) -> SUP maximum growth rate of MSW
B31: =_xlfn.TEXTJOIN("_",TRUE,"UC",A40,"MaxGrowth",B40) -> UC_MaxGrowth | C31: FLO, GROWTH | D31: SBIORDST* | F31: 2019 | G31: LO | H31: 1.01 | I31: 1 | J31: =-D40 -> 0 | K31: 5 | L31: =_xlfn.TEXTJOIN(" ",TRUE,A40, "maximum growth rate of",B40) -> maximum growth rate of
B32: =_xlfn.TEXTJOIN("_",TRUE,"UC",A41,"MaxGrowth",B41) -> UC_MaxGrowth | C32: FLO, GROWTH | D32: SBIORETH* | F32: 2019 | G32: LO | H32: 1.01 | I32: 1 | J32: =-D41 -> 0 | K32: 5 | L32: =_xlfn.TEXTJOIN(" ",TRUE,A41, "maximum growth rate of",B41) -> maximum growth rate of

Sheet PWR
B2: ="~UC_Sets: R_E: " & _xlfn.TEXTJOIN(",",TRUE,Regions!C3:D3) -> ~UC_Sets: R_E: IE,National
B3: ~UC_Sets: T_E: | N3: ="~UC_Sets: R_E: " & _xlfn.TEXTJOIN(",",TRUE,Regions!O4:P4) -> ~UC_Sets: R_E:
F4: ~UC_T | N4: ~UC_Sets: T_E:
B5: UC_N | C5: UC_ATTR | D5: Pset_PN | E5: Year | F5: LimType | G5: UC_CAP | H5: UC_CAP~RHS | I5: UC_RHSRTS~2018 | J5: UC_RHSRTS~0 | K5: UC_Desc | U5: ~UC_T
B6: =_xlfn.TEXTJOIN("_",TRUE,"UC",A14,"MaxGrowth",B14) -> UC_PWR_MaxGrowth_CCS | C6: CAP, GROWTH | D6: P*CCS* | E6: 2022 | F6: LO | G6: =1+$C14 -> 2 | H6: 1 | I6: =-D14 -> -0.8 | J6: 5 | K6: =_xlfn.TEXTJOIN(" ",TRUE,A14, "maximum growth rate of",B14) -> PWR maximum growth rate of CCS | N6: UC_N | O6: UC_ATTR | P6: Pset_Set | Q6: Pset_CI | R6: Pset_CO | S6: Pset_PN | T6: Year | U6: LimType | V6: UC_ACT | W6: UC_ACT~RHS | X6: UC_RHSRTS | Y6: UC_RHSRTS~0 | Z6: UC_Desc
B7: =_xlfn.TEXTJOIN("_",TRUE,"UC",A15,"MaxGrowth",B15) -> UC_PWR_MaxGrowth_Wave | C7: CAP, GROWTH | D7: P*OCE*WAV* | E7: 2035 | F7: LO | G7: =1+$C15 -> 1.2 | H7: 1 | I7: =-D15 -> -0.4 | J7: 5 | K7: =_xlfn.TEXTJOIN(" ",TRUE,A15, "maximum growth rate of",B15) -> PWR maximum growth rate of Wave | N7: UC_PWRMSW_NODECAY | O7: ACT, GROWTH | R7: PWRMSW | S7: FT* | T7: 2022 | U7: UP | V7: 1 | W7: 1 | X7: 0 | Y7: 5 | Z7: Non-decay constraint for waste incineration
B8: =_xlfn.TEXTJOIN("_",TRUE,"UC",A16,"MaxGrowth",B16) -> UC_PWR_MaxGrowth_Tidal | C8: CAP, GROWTH | D8: P*OCE*TID* | E8: 2035 | F8: LO | G8: =1+$C16 -> 1.2 | H8: 1 | I8: =-D16 -> -0.1 | J8: 5 | K8: =_xlfn.TEXTJOIN(" ",TRUE,A16, "maximum growth rate of",B16) -> PWR maximum growth rate of Tidal
B9: =_xlfn.TEXTJOIN("_",TRUE,"UC",A17,"MaxGrowth",B17) -> UC_PWR_MaxGrowth_H2GT | C9: CAP, GROWTH | D9: P-TH*H2-* | E9: 2022 | F9: LO | G9: =1+$C17 -> 1.75 | H9: 1 | I9: =-D17 -> -0.5 | J9: 5 | K9: =_xlfn.TEXTJOIN(" ",TRUE,A17, "maximum growth rate of",B17) -> PWR maximum growth rate of H2GT
B10: =_xlfn.TEXTJOIN("_",TRUE,"UC",A18,"MaxGrowth",B18) -> UC_PWR_MaxGrowth_PV | C10: CAP, GROWTH | D10: P*SOL*PV* | E10: 2022 | F10: LO | G10: =1+$C18 -> 2 | H10: 1 | I10: =-D18 -> -1 | J10: 5 | K10: =_xlfn.TEXTJOIN(" ",TRUE,A18, "maximum growth rate of",B18) -> PWR maximum growth rate of PV
B11: =_xlfn.TEXTJOIN("_",TRUE,"UC",A19,"MaxGrowth",B19) -> UC_PWR_MaxGrowth_CSP | C11: CAP, GROWTH | D11: P*SOL*CSP* | E11: 2022 | F11: LO | G11: =1+$C19 -> 2 | H11: 1 | I11: =-D19 -> -0.5 | J11: 5 | K11: =_xlfn.TEXTJOIN(" ",TRUE,A19, "maximum growth rate of",B19) -> PWR maximum growth rate of CSP
C13: Max growth rate | D13: Starting value (GW)
A14: PWR | B14: CCS | C14: 1 | D14: 0.8
A15: PWR | B15: Wave | C15: 0.2 | D15: 0.4
A16: PWR | B16: Tidal | C16: 0.2 | D16: 0.1
A17: PWR | B17: H2GT | C17: 0.75 | D17: 0.5
A18: PWR | B18: PV | C18: 1 | D18: 1
A19: PWR | B19: CSP | C19: 1 | D19: 0.5
F22: ~UC_T
B23: UC_N | C23: UC_ATTR | D23: Pset_PN | E23: Year | F23: LimType | G23: UC_NCAP | H23: UC_RHSRTS | I23: UC_RHSRTS~0 | J23: UC_Desc
B24: UC_PWR_MaxNCap_WON | D24: P*WIN*ON* | E24: 2019 | F24: UP | G24: =1+$C35 -> 1 | H24: 0.6 | I24: 3 | J24: PWR maximum new capacity of wind onshore
D25: P*WIN*ON* | E25: 2020 | F25: UP | G25: =1+$C36 -> 1 | H25: 0.5
D26: P*WIN*ON* | E26: 2024 | F26: UP | G26: =1+$C37 -> 1 | H26: 0.708
D27: P*WIN*ON* | E27: 2025 | F27: UP | G27: =1+$C38 -> 1 | H27: =5.11-5.06 -> 0.05
D28: P*WIN*ON* | E28: 2026 | F28: UP | G28: =1+$C39 -> 1 | H28: =5.775-5.11 -> 0.665
D29: P*WIN*ON* | E29: 2027 | F29: UP | G29: =1+$C40 -> 1 | H29: =6.4-5.755 -> 0.645
D30: P*WIN*ON* | E30: 2028 | F30: UP | G30: =1+$C41 -> 1 | H30: =6.7-6.4 -> 0.3
D31: P*WIN*ON* | E31: 2029 | F31: UP | G31: =1+$C38 -> 1 | H31: 2
B32: UC_PWR_MaxNCap_WOF | D32: P*WIN*OF* | E32: 2028 | F32: UP | G32: =1+$C36 -> 1 | H32: 0.7 | I32: 3 | J32: PWR maximum new capacity of wind offshore
D33: P*WIN*OF* | E33: 2029 | F33: UP | G33: =1+$C37 -> 1 | H33: =2.865-0.725 -> 2.14
D34: P*WIN*OF* | E34: 2030 | F34: UP | G34: =1+$C38 -> 1 | H34: =5-2.865 -> 2.135
D35: P*WIN*OF* | E35: 2031 | F35: UP | G35: =1+$C39 -> 1 | H35: =7.135-5 -> 2.135
D36: P*WIN*OF* | E36: 2032 | F36: UP | G36: =1+$C40 -> 1 | H36: =9.27-7.135 -> 2.135
B44: https://cms.eirgrid.ie/sites/default/files/publications/19035-EirGrid-Generation-Capacity-Statement-Combined-2023-V5-Jan-2024.pdf
B63: Installed Capacity (MW) | C63: 2022 | D63: 2023
B64: Wind | C64: 4,536 | D64: 4739
B65: Solar PV (AC) | C65: 201 | D65: 716
B66: Hydro | C66: 237 | D66: 237

Sheet IND
B2: ="~UC_Sets: R_E: " & _xlfn.TEXTJOIN(",",TRUE,Regions!C3:D3) -> ~UC_Sets: R_E: IE,National
B3: ~UC_Sets: T_E:
I4: ~UC_T
B5: UC_N | C5: UC_ATTR | D5: Pset_Set | E5: Pset_CI | F5: Pset_CO | G5: Pset_PN | H5: Year | I5: LimType | J5: UC_ACT | K5: UC_ACT~RHS | L5: UC_RHSRTS | M5: UC_RHSRTS~0 | N5: UC_Desc
B6: =_xlfn.TEXTJOIN("_",TRUE,"UC",B14,"MaxGrowth",C14) -> UC_IND_MaxGrowth_Biogas | C6: ACT, GROWTH | F6: INDBGS | G6: FT* | H6: 2022 | I6: LO | J6: =1+D14 -> 1.15 | K6: 1 | L6: =-E14 -> -2 | M6: 5 | N6: =_xlfn.TEXTJOIN(" ",TRUE,B14, "maximum growth rate of",C14) -> IND maximum growth rate of Biogas
B7: =_xlfn.TEXTJOIN("_",TRUE,"UC",B15,"MaxGrowth",C15) -> UC_IND_MaxGrowth_Biofuels | C7: ACT, GROWTH | F7: INDBIO | G7: FT* | H7: 2022 | I7: LO | J7: =1+D15 -> 1 | K7: 1 | L7: =-E15 -> -0.5 | M7: 5 | N7: =_xlfn.TEXTJOIN(" ",TRUE,B15, "maximum growth rate of",C15) -> IND maximum growth rate of Biofuels
B8: =_xlfn.TEXTJOIN("_",TRUE,"UC",B16,"MaxGrowth",C16) -> UC_IND_MaxGrowth_Biomass | C8: ACT, GROWTH | F8: INDWOO,INDBIO | G8: FT* | H8: 2022 | I8: LO | J8: =1+D16 -> 1.07 | K8: 1 | L8: =-E16 -> 0 | M8: 5 | N8: =_xlfn.TEXTJOIN(" ",TRUE,B16, "maximum growth rate of",C16) -> IND maximum growth rate of Biomass
B9: =_xlfn.TEXTJOIN("_",TRUE,"UC",B17,"MaxGrowth",C17) -> UC_IND_MaxGrowth_Hydrogen | C9: ACT, GROWTH | F9: INDH2G,INDH2L | G9: FT* | H9: 2022 | I9: LO | J9: =1+D17 -> 1.15 | K9: 1 | L9: =-E17 -> -2 | M9: 5 | N9: =_xlfn.TEXTJOIN(" ",TRUE,B17, "maximum growth rate of",C17) -> IND maximum growth rate of Hydrogen
B10: =_xlfn.TEXTJOIN("_",TRUE,"UC",B18,"MaxGrowth",C18) -> UC_IND_MaxGrowth_Electricity | C10: ACT, GROWTH | F10: INDELC | G10: FT* | H10: 2022 | I10: LO | J10: =1+D18 -> 1.07 | K10: 1 | L10: =-E18 -> 0 | M10: 5 | N10: =_xlfn.TEXTJOIN(" ",TRUE,B18, "maximum growth rate of",C18) -> IND maximum growth rate of Electricity
D13: Max growth rate | E13: Starting value (PJ) | F13: NRG_BAL,PJ
B14: IND | C14: Biogas | D14: 0.15 | E14: 2 | F14: 0.2
B15: IND | C15: Biofuels | D15: 0 | E15: 0.5 | F15: 0
B16: IND | C16: Biomass | D16: 0.07 | E16: 0 | F16: 6.1
B17: IND | C17: Hydrogen | D17: 0.15 | E17: 2 | F17: 0
B18: IND | C18: Electricity | D18: 0.07 | E18: 0 | F18: 34.1
K20: Energy Balance 2019
K21: Total (excluding electricity | L21: Bio waste | M21: Non-bio waste | N21: Solid Fuels | O21: Oil | P21: Gas | Q21: Bio fuel | R21: Electricity
J22: Cement | K22: 14.8 | L22: 1.7 | M22: 2.4 | N22: 3.3 | O22: 6 | P22: 1.4 | Q22: 0 | R22: 2.8
J23: Chemicals | K23: 6.7 | L23: 0 | M23: 0 | N23: 0 | O23: 1 | P23: 5.7 | Q23: 0 | R23: 4.5
J24: Food and Drink | K24: 16.5 | L24: 0 | M24: 0 | N24: 0 | O24: 2.8 | P24: 12.7 | Q24: 1 | R24: 4.1
J25: Lime | K25: 0
J26: Metals | K26: 18.1 | L26: 0 | M26: 0 | N26: 0 | O26: 0.3 | P26: 17.9 | Q26: 0 | R26: 2.6
J27: Other Industry | K27: 4.3 | L27: 0 | M27: 0 | N27: 0 | O27: 0.8 | P27: 3.6 | Q27: 0 | R27: 7.3
J28: Other Minerals | K28: 1.8 | L28: 0 | M28: 0 | N28: 0 | O28: 1.2 | P28: 0.6 | Q28: 0 | R28: 1.1
J29: Refining | K29: 6.1 | L29: 0 | M29: 0 | N29: 0 | O29: 3.4 | P29: 2.8 | Q29: 0 | R29: 10.7
J30: Wood Products | K30: 5.6 | L30: 0 | M30: 0 | N30: 0 | O30: 0.1 | P30: 0.4 | Q30: 5.1 | R30: 1
K31: 74.1 | L31: 1.7 | M31: 2.4 | N31: 3.3 | O31: 15.5 | P31: 45.1 | Q31: 6.1 | R31: 34.1

Sheet RSD
B2: ="~UC_Sets: R_E: " & _xlfn.TEXTJOIN(",",TRUE,Regions!C3:D3) -> ~UC_Sets: R_E: IE,National
B3: ~UC_Sets: T_E:
I4: ~UC_T
B5: UC_N | C5: UC_ATTR | D5: Pset_Set | E5: Pset_CI | F5: Pset_CO | G5: Pset_PN | H5: Year | I5: LimType | J5: UC_ACT | K5: UC_ACT~RHS | L5: UC_RHSRTS | M5: UC_RHSRTS~0 | N5: UC_Desc
B6: =_xlfn.TEXTJOIN("_",TRUE,"UC",A21,"MaxGrowth",B21) -> UC_RSD_MaxGrowth_AmbientHeat | C6: ACT, GROWTH | F6: RSDAHT,RSDAHT2 | G6: FT* | H6: 2022 | I6: LO | J6: =1+C21 -> 1.15 | K6: 1 | L6: =-D21 -> -3 | M6: 5 | N6: =_xlfn.TEXTJOIN(" ",TRUE,A22, "maximum growth rate of",B21) -> RSD maximum growth rate of AmbientHeat
B7: =_xlfn.TEXTJOIN("_",TRUE,"UC",A22,"MaxGrowth",B22) -> UC_RSD_MaxGrowth_Biodiesel | C7: ACT, GROWTH | F7: RSDBDL | G7: FT* | H7: 2022 | I7: LO | J7: =1+C22 -> 1.03 | K7: 1 | L7: =-D22 -> -0.5 | M7: 5 | N7: =_xlfn.TEXTJOIN(" ",TRUE,A23, "maximum growth rate of",B23) -> RSD maximum growth rate of Biomass
B8: =_xlfn.TEXTJOIN("_",TRUE,"UC",A23,"MaxGrowth",B23) -> UC_RSD_MaxGrowth_Biomass | C8: ACT, GROWTH | F8: RSDWOO | G8: FT* | H8: 2022 | I8: LO | J8: =1+C23 -> 1.01 | K8: 1 | L8: =-D23 -> -0.5 | M8: 5 | N8: =_xlfn.TEXTJOIN(" ",TRUE,A23, "maximum growth rate of",B23) -> RSD maximum growth rate of Biomass
B9: =_xlfn.TEXTJOIN("_",TRUE,"UC",A24,"MaxGrowth",B24) -> UC_RSD_MaxGrowth_Coal | C9: ACT, GROWTH | F9: RSDCOA | G9: FT* | H9: 2022 | I9: LO | J9: =1+C24 -> 0.99 | K9: 1 | L9: =-D24 -> 0 | M9: 5 | N9: =_xlfn.TEXTJOIN(" ",TRUE,A24, "maximum growth rate of",B24) -> RSD maximum growth rate of Coal
B10: =_xlfn.TEXTJOIN("_",TRUE,"UC",A25,"MaxGrowth",B25) -> UC_RSD_MaxGrowth_Peat | C10: ACT, GROWTH | F10: RSDPEA | G10: FT* | H10: 2022 | I10: LO | J10: =1+C25 -> 0.99 | K10: 1 | L10: =-D25 -> 0 | M10: 5 | N10: =_xlfn.TEXTJOIN(" ",TRUE,A25, "maximum growth rate of",B25) -> RSD maximum growth rate of Peat
B11: =_xlfn.TEXTJOIN("_",TRUE,"UC",A26,"MaxGrowth",B26) -> UC_RSD_MaxGrowth_Electricity | C11: ACT, GROWTH | F11: RSDELC | G11: FT* | H11: 2022 | I11: LO | J11: =1+C26 -> 1.07 | K11: 1 | L11: =-D26 -> -32 | M11: 5 | N11: =_xlfn.TEXTJOIN(" ",TRUE,A26, "maximum growth rate of",B26) -> RSD maximum growth rate of Electricity
B12: =_xlfn.TEXTJOIN("_",TRUE,"UC",A27,"MaxGrowth",B27) -> UC_RSD_MaxGrowth_Ethanol | C12: ACT, GROWTH | F12: RSDETH | G12: FT* | H12: 2022 | I12: LO | J12: =1+C27 -> 1.02 | K12: 1 | L12: =-D27 -> -0.5 | M12: 5 | N12: =_xlfn.TEXTJOIN(" ",TRUE,A27, "maximum growth rate of",B27) -> RSD maximum growth rate of Ethanol
B13: =_xlfn.TEXTJOIN("_",TRUE,"UC",A28,"MaxGrowth",B28) -> UC_RSD_MaxGrowth_Gas | C13: ACT, GROWTH | F13: RSDGAS | G13: FT* | H13: 2022 | I13: LO | J13: =1+C28 -> 1.02 | K13: 1 | L13: =-D28 -> -0.5 | M13: 5 | N13: =_xlfn.TEXTJOIN(" ",TRUE,A28, "maximum growth rate of",B28) -> RSD maximum growth rate of Gas
B14: =_xlfn.TEXTJOIN("_",TRUE,"UC",A29,"MaxGrowth",B29) -> UC_RSD_MaxGrowth_DistrictHeat | C14: ACT, GROWTH | F14: RSDHET | G14: FT* | H14: 2022 | I14: LO | J14: =1+C29 -> 1.15 | K14: 1 | L14: =-D29 -> -1 | M14: 5 | N14: =_xlfn.TEXTJOIN(" ",TRUE,A29, "maximum growth rate of",B29) -> RSD maximum growth rate of DistrictHeat
B15: =_xlfn.TEXTJOIN("_",TRUE,"UC",A30,"MaxGrowth",B30) -> UC_RSD_MaxGrowth_LPG | C15: ACT, GROWTH | F15: RSDLPG | G15: FT* | H15: 2022 | I15: LO | J15: =1+C30 -> 1.01 | K15: 1 | L15: =-D30 -> -0.5 | M15: 5 | N15: =_xlfn.TEXTJOIN(" ",TRUE,A30, "maximum growth rate of",B30) -> RSD maximum growth rate of LPG
B16: =_xlfn.TEXTJOIN("_",TRUE,"UC",A31,"MaxGrowth",B31) -> UC_RSD_MaxGrowth_Kerosene | C16: ACT, GROWTH | F16: RSDKER | G16: FT* | H16: 2022 | I16: LO | J16: =1+C31 -> 1.01 | K16: 1 | L16: =-D31 -> -0.5 | M16: 5 | N16: =_xlfn.TEXTJOIN(" ",TRUE,A31, "maximum growth rate of",B31) -> RSD maximum growth rate of Kerosene
B17: =_xlfn.TEXTJOIN("_",TRUE,"UC",A32,"MaxGrowth",B32) -> UC_RSD_MaxGrowth_Solar | C17: ACT, GROWTH | F17: RSDSOL | G17: FT* | H17: 2022 | I17: LO | J17: =1+C32 -> 1.2 | K17: 1 | L17: =-D32 -> -0.5 | M17: 5 | N17: =_xlfn.TEXTJOIN(" ",TRUE,A32, "maximum growth rate of",B32) -> RSD maximum growth rate of Solar
C20: Max growth rate | D20: Starting value (PJ)
A21: RSD | B21: AmbientHeat | C21: 0.15 | D21: 3
A22: RSD | B22: Biodiesel | C22: 0.03 | D22: 0.5
A23: RSD | B23: Biomass | C23: 0.01 | D23: 0.5
A24: RSD | B24: Coal | C24: -0.01 | D24: 0
A25: RSD | B25: Peat | C25: -0.01 | D25: 0
A26: RSD | B26: Electricity | C26: 0.07 | D26: 32
A27: RSD | B27: Ethanol | C27: 0.02 | D27: 0.5
A28: RSD | B28: Gas | C28: 0.02 | D28: 0.5
A29: RSD | B29: DistrictHeat | C29: 0.15 | D29: 1
A30: RSD | B30: LPG | C30: 0.01 | D30: 0.5
A31: RSD | B31: Kerosene | C31: 0.01 | D31: 0.5
A32: RSD | B32: Solar | C32: 0.2 | D32: 0.5
B35: TFM_INS
B36: TimeSlice | C36: LimType | D36: Attribute | E36: Year | F36: =IF(Regions!C$3<>"",Regions!C$3,"*") -> IE | G36: =IF(Regions!C$3<>"",Regions!D$3,"*") -> National | H36: Cset_CN
D37: COM_TAXNET | E37: 2018 | F37: 2222 | G37: =F37 -> 2222 | H37: =_xlfn.TEXTJOIN(",",TRUE,F6:F17) -> RSDAHT,RSDAHT2,RSDBDL,RSDWOO,RSDCOA,RSDPEA,RSDELC,RSDETH,RSDGAS,RSDHET,RSDLPG,RSDKER,RSDSOL

Sheet SRV
B2: ="~UC_Sets: R_E: " & _xlfn.TEXTJOIN(",",TRUE,Regions!C3:D3) -> ~UC_Sets: R_E: IE,National
B3: ~UC_Sets: T_E:
I4: ~UC_T
B5: UC_N | C5: UC_ATTR | D5: Pset_Set | E5: Pset_CI | F5: Pset_CO | G5: Pset_PN | H5: Year | I5: LimType | J5: UC_ACT | K5: UC_ACT~RHS | L5: UC_RHSRTS | M5: UC_RHSRTS~0 | N5: UC_Desc
B6: =_xlfn.TEXTJOIN("_",TRUE,"UC",A14,"MaxGrowth",B14) -> UC_SRV_MaxGrowth_Biomass | C6: ACT, GROWTH | F6: SRVBIO | G6: FT* | H6: 2022 | I6: LO | J6: =1+C14 -> 1.05 | K6: 1 | L6: =-D14 -> -0.3 | M6: 5 | N6: =_xlfn.TEXTJOIN(" ",TRUE,A14, "maximum growth rate of",B14) -> SRV maximum growth rate of Biomass
B7: =_xlfn.TEXTJOIN("_",TRUE,"UC",A15,"MaxGrowth",B15) -> UC_SRV_MaxGrowth_Biogas | C7: ACT, GROWTH | F7: SRVBGS | G7: FT* | H7: 2022 | I7: LO | J7: =1+C15 -> 1.05 | K7: 1 | L7: =-D15 -> -0.3 | M7: 5 | N7: =_xlfn.TEXTJOIN(" ",TRUE,A15, "maximum growth rate of",B15) -> SRV maximum growth rate of Biogas
B8: =_xlfn.TEXTJOIN("_",TRUE,"UC",A16,"MaxGrowth",B16) -> UC_SRV_MaxGrowth_AmbientHeat | C8: ACT, GROWTH | F8: SRVAHT,SRVAHT2 | G8: FT* | H8: 2022 | I8: LO | J8: =1+C16 -> 1.2 | K8: 1 | L8: =-D16 -> -0.8 | M8: 5 | N8: =_xlfn.TEXTJOIN(" ",TRUE,A16, "maximum growth rate of",B16) -> SRV maximum growth rate of AmbientHeat
B9: =_xlfn.TEXTJOIN("_",TRUE,"UC",A17,"MaxGrowth",B17) -> UC_SRV_MaxGrowth_DistrictHeat | C9: ACT, GROWTH | F9: SRVHET | G9: FT* | H9: 2022 | I9: LO | J9: =1+C17 -> 1.1 | K9: 1 | L9: =-D17 -> -1 | M9: 5 | N9: =_xlfn.TEXTJOIN(" ",TRUE,A17, "maximum growth rate of",B17) -> SRV maximum growth rate of DistrictHeat
B10: =_xlfn.TEXTJOIN("_",TRUE,"UC",A18,"MaxGrowth",B18) -> UC_SRV_MaxGrowth_Gas | C10: ACT, GROWTH | F10: SRVGAS | G10: FT* | H10: 2022 | I10: LO | J10: =1+C18 -> 1.08 | K10: 1 | L10: =-D18 -> -0.5 | M10: 5 | N10: =_xlfn.TEXTJOIN(" ",TRUE,A18, "maximum growth rate of",B18) -> SRV maximum growth rate of Gas
C13: Max growth rate | D13: Starting value (PJ)
A14: SRV | B14: Biomass | C14: 0.05 | D14: 0.3
A15: SRV | B15: Biogas | C15: 0.05 | D15: 0.3
A16: SRV | B16: AmbientHeat | C16: 0.2 | D16: 0.8
A17: SRV | B17: DistrictHeat | C17: 0.1 | D17: 1
A18: SRV | B18: Gas | C18: 0.08 | D18: 0.5
B23: TimeSlice | C23: LimType | D23: Attribute | E23: Year | F23: =IF(Regions!C$3<>"",Regions!C$3,"*") -> IE | G23: =IF(Regions!C$3<>"",Regions!D$3,"*") -> National | H23: Cset_CN
D24: COM_TAXNET | E24: 2018 | F24: 2222 | G24: =F24 -> 2222 | H24: =_xlfn.TEXTJOIN(",",TRUE,F6:F10) -> SRVBIO,SRVBGS,SRVAHT,SRVAHT2,SRVHET,SRVGAS

Sheet RSD-Retrofits
B2: ="~UC_Sets: R_E: " & _xlfn.TEXTJOIN(",",TRUE,Regions!C3:D3) -> ~UC_Sets: R_E: IE,National
B3: ~UC_Sets: T_E:
I4: ~UC_T
B5: UC_N | C5: UC_ATTR | D5: Pset_Set | E5: Pset_CI | F5: Pset_CO | G5: Pset_PN | H5: Year | I5: LimType | J5: UC_NCAP | K5: UC_NCAP~RHS | L5: UC_RHSRTS | M5: UC_RHSRTS~0 | N5: UC_Desc
B6: =_xlfn.TEXTJOIN("_",TRUE,"UC",A10,"MaxGrowth",B10) -> UC_RSD_MaxGrowth_Retrofits | C6: NCAP, GROWTH | G6: R-RTFT* | H6: 2019 | I6: LO | J6: =1+C10 -> 1.5 | K6: 1 | L6: =-D10 -> -20 | M6: 5 | N6: =_xlfn.TEXTJOIN(" ",TRUE,A10, "maximum growth rate of",LOWER(B10)) -> RSD maximum growth rate of retrofits
B7: UC_RSD_MaxNCap_Retrofits | G7: R-RTFT* | H7: 2019 | I7: UP | J7: 1 | L7: 60 | M7: 5 | N7: RSD maximum new retrofits
C9: Max growth rate | D9: Starting value (kUnits)
A10: RSD | B10: Retrofits | C10: 0.5 | D10: 20

Sheet TRA
B2: ="~UC_Sets: R_E: " & _xlfn.TEXTJOIN(",",TRUE,Regions!C3,Regions!E3:AD3) -> ~UC_Sets: R_E: IE,IE-CW,IE-D,IE-KE,IE-KK,IE-LS,IE-LD,IE-LH,IE-MH,IE-OY,IE-WH,IE-WX,IE-WW,IE-CE,IE-CO,IE-KY,IE-LK,IE-TA,IE-WD,IE-G,IE-LM,IE-MO,IE-RN,IE-SO,IE-CN,IE-DL,IE-MN
B3: ~UC_Sets: T_E:
I4: ~UC_T
B5: UC_N | C5: UC_ATTR | D5: Pset_Set | E5: Pset_CI | F5: Pset_CO | G5: Pset_PN | H5: Year | I5: LimType | J5: UC_CAP | K5: UC_CAP~RHS | L5: UC_RHSRTS~2018 | M5: UC_RHSRTS~0 | N5: UC_Desc
B6: =IF(H29="*","*",_xlfn.TEXTJOIN("",TRUE,"UC-",I29,"_MaxGrowth",J29)) -> UC-CAR_MaxGrowthBEV | C6: CAP, GROWTH | D6: DMD | G6: T-CAR-BEV* | H6: 2018 | I6: LO | J6: =1+$K29 -> 2 | K6: 1 | L6: =-$B$59*L29/1000 -> -24.2242 | M6: 5 | N6: =_xlfn.TEXTJOIN(" ", TRUE,I29&"s","maximum growth rate of",J29&"s") -> CARs maximum growth rate of BEVs
B7: =IF(H30="*","*",_xlfn.TEXTJOIN("",TRUE,"UC-",I30,"_MaxGrowth",J30)) -> UC-CAR_MaxGrowthPHEV | C7: CAP, GROWTH | D7: DMD | G7: T-CAR-PHEV* | H7: 2018 | I7: LO | J7: =1+$K30 -> 1.8 | K7: 1 | L7: =-$B$59*L30/1000 -> -24.2242 | M7: 5 | N7: =_xlfn.TEXTJOIN(" ", TRUE,I30&"s","maximum growth rate of",J30&"s") -> CARs maximum growth rate of PHEVs
B8: =IF(H31="*","*",_xlfn.TEXTJOIN("",TRUE,"UC-",I31,"_MaxGrowth",J31)) -> UC-CAR_MaxGrowthNG-ICE | C8: CAP, GROWTH | D8: DMD | G8: T-CAR-ICE_NG* | H8: 2018 | I8: LO | J8: =1+$K31 -> 1.5 | K8: 1 | L8: =-$B$59*L31/1000 -> -24.2242 | M8: 5 | N8: =_xlfn.TEXTJOIN(" ", TRUE,I31&"s","maximum growth rate of",J31&"s") -> CARs maximum growth rate of NG-ICEs
B9: =IF(H32="*","*",_xlfn.TEXTJOIN("",TRUE,"UC-",I32,"_MaxGrowth",J32)) -> UC-CAR_MaxGrowthB100-ICE | C9: CAP, GROWTH | D9: DMD | G9: T-CAR-ICE_B100* | H9: 2018 | I9: LO | J9: =1+$K32 -> 1.2 | K9: 1 | L9: =-$B$59*L32/1000 -> -24.2242 | M9: 5 | N9: =_xlfn.TEXTJOIN(" ", TRUE,I32&"s","maximum growth rate of",J32&"s") -> CARs maximum growth rate of B100-ICEs
B10: =IF(H33="*","*",_xlfn.TEXTJOIN("",TRUE,"UC-",I33,"_MaxGrowth",J33)) -> UC-CAR_MaxGrowthE85-ICE | C10: CAP, GROWTH | D10: DMD | G10: T-CAR-ICE_E85* | H10: 2018 | I10: LO | J10: =1+$K33 -> 1.2 | K10: 1 | L10: =-$B$59*L33/1000 -> -24.2242 | M10: 5 | N10: =_xlfn.TEXTJOIN(" ", TRUE,I33&"s","maximum growth rate of",J33&"s") -> CARs maximum growth rate of E85-ICEs
B11: =IF(H32="*","*",_xlfn.TEXTJOIN("",TRUE,"UC-",I34,"_MaxGrowth",J34)) -> UC-CAR_MaxGrowthFCV | C11: CAP, GROWTH | D11: DMD | G11: T-CAR-FCV* | H11: 2018 | I11: LO | J11: =1+$K34 -> 1.5 | K11: 1 | L11: =-$B$59*L34/1000 -> -24.2242 | M11: 5 | N11: =_xlfn.TEXTJOIN(" ", TRUE,I34&"s","maximum growth rate of",J34&"s") -> CARs maximum growth rate of FCVs
B12: =IF(H33="*","*",_xlfn.TEXTJOIN("",TRUE,"UC-",I35,"_MaxGrowth",J35)) -> UC-LGT_MaxGrowthBEV | C12: CAP, GROWTH | D12: DMD | G12: T-LGT-BEV* | H12: 2018 | I12: LO | J12: =1+$K35 -> 1.8 | K12: 1 | L12: =-$B$58*L35/1000 -> -3.3078 | M12: 5 | N12: =_xlfn.TEXTJOIN(" ", TRUE,I35&"s","maximum growth rate of",J35&"s") -> LGTs maximum growth rate of BEVs
B13: =IF(H34="*","*",_xlfn.TEXTJOIN("",TRUE,"UC-",I36,"_MaxGrowth",J36)) -> UC-LGT_MaxGrowthPHEV | C13: CAP, GROWTH | D13: DMD | G13: T-LGT-PHEV* | H13: 2018 | I13: LO | J13: =1+$K36 -> 1.8 | K13: 1 | L13: =-$B$58*L36/1000 -> -3.3078 | M13: 5 | N13: =_xlfn.TEXTJOIN(" ", TRUE,I36&"s","maximum growth rate of",J36&"s") -> LGTs maximum growth rate of PHEVs
B14: =IF(H35="*","*",_xlfn.TEXTJOIN("",TRUE,"UC-",I37,"_MaxGrowth",J37)) -> UC-LGT_MaxGrowthNG-ICE | C14: CAP, GROWTH | D14: DMD | G14: T-LGT-ICE_NG* | H14: 2018 | I14: LO | J14: =1+$K37 -> 1.3 | K14: 1 | L14: =-$B$58*L37/1000 -> -3.3078 | M14: 5 | N14: =_xlfn.TEXTJOIN(" ", TRUE,I37&"s","maximum growth rate of",J37&"s") -> LGTs maximum growth rate of NG-ICEs
B15: =IF(H36="*","*",_xlfn.TEXTJOIN("",TRUE,"UC-",I38,"_MaxGrowth",J38)) -> UC-LGT_MaxGrowthFCV | C15: CAP, GROWTH | D15: DMD | G15: T-LGT-FCV* | H15: 2018 | I15: LO | J15: =1+$K38 -> 1.3 | K15: 1 | L15: =-$B$58*L38/1000 -> -3.3078 | M15: 5 | N15: =_xlfn.TEXTJOIN(" ", TRUE,I38&"s","maximum growth rate of",J38&"s") -> LGTs maximum growth rate of FCVs
B16: =IF(H37="*","*",_xlfn.TEXTJOIN("",TRUE,"UC-",I39,"_MaxGrowth",J39)) -> UC-MGT_MaxGrowthBEV | C16: CAP, GROWTH | D16: DMD | G16: T-MGT-BEV* | H16: 2018 | I16: LO | J16: =1+$K39 -> 2 | K16: 1 | L16: =-$B$57*L39/1000 -> -0.1325 | M16: 5 | N16: =_xlfn.TEXTJOIN(" ", TRUE,I39&"s","maximum growth rate of",J39&"s") -> MGTs maximum growth rate of BEVs
B17: =IF(H38="*","*",_xlfn.TEXTJOIN("",TRUE,"UC-",I40,"_MaxGrowth",J40)) -> UC-MGT_MaxGrowthNG-ICE | C17: CAP, GROWTH | D17: DMD | G17: T-MGT-ICE_NG* | H17: 2018 | I17: LO | J17: =1+$K40 -> 1.5 | K17: 1 | L17: =-$B$57*L40/1000 -> -0.106 | M17: 5 | N17: =_xlfn.TEXTJOIN(" ", TRUE,I40&"s","maximum growth rate of",J40&"s") -> MGTs maximum growth rate of NG-ICEs
B18: =IF(H39="*","*",_xlfn.TEXTJOIN("",TRUE,"UC-",I41,"_MaxGrowth",J41)) -> UC-MGT_MaxGrowthLNG-ICE | C18: CAP, GROWTH | D18: DMD | G18: T-MGT-ICE_LNG* | H18: 2018 | I18: LO | J18: =1+$K41 -> 1.5 | K18: 1 | L18: =-$B$57*L41/1000 -> -0.106 | M18: 5 | N18: =_xlfn.TEXTJOIN(" ", TRUE,I41&"s","maximum growth rate of",J41&"s") -> MGTs maximum growth rate of LNG-ICEs
B19: =IF(H40="*","*",_xlfn.TEXTJOIN("",TRUE,"UC-",I42,"_MaxGrowth",J42)) -> UC-MGT_MaxGrowthHEV | C19: CAP, GROWTH | D19: DMD | G19: T-MGT-HEV* | H19: 2018 | I19: LO | J19: =1+$K42 -> 1.5 | K19: 1 | L19: =-$B$57*L42/1000 -> -0.106 | M19: 5 | N19: =_xlfn.TEXTJOIN(" ", TRUE,I42&"s","maximum growth rate of",J42&"s") -> MGTs maximum growth rate of HEVs
B20: =IF(H41="*","*",_xlfn.TEXTJOIN("",TRUE,"UC-",I43,"_MaxGrowth",J43)) -> UC-MGT_MaxGrowthFCV | C20: CAP, GROWTH | D20: DMD | G20: T-MGT-FCV* | H20: 2018 | I20: LO | J20: =1+$K43 -> 1.5 | K20: 1 | L20: =-$B$57*L43/1000 -> -0.106 | M20: 5 | N20: =_xlfn.TEXTJOIN(" ", TRUE,I43&"s","maximum growth rate of",J43&"s") -> MGTs maximum growth rate of FCVs
B21: =IF(H42="*","*",_xlfn.TEXTJOIN("",TRUE,"UC-",I44,"_MaxGrowth",J44)) -> UC-HGT_MaxGrowthBEV | C21: CAP, GROWTH | D21: DMD | G21: T-HGT-BEV* | H21: 2018 | I21: LO | J21: =1+$K44 -> 2 | K21: 1 | L21: =-$B$56*L44/1000 -> -0.3795 | M21: 5 | N21: =_xlfn.TEXTJOIN(" ", TRUE,I44&"s","maximum growth rate of",J44&"s") -> HGTs maximum growth rate of BEVs
B22: =IF(H43="*","*",_xlfn.TEXTJOIN("",TRUE,"UC-",I45,"_MaxGrowth",J45)) -> UC-HGT_MaxGrowthNG-ICE | C22: CAP, GROWTH | D22: DMD | G22: T-HGT-ICE_NG* | H22: 2018 | I22: LO | J22: =1+$K45 -> 1.5 | K22: 1 | L22: =-$B$56*L45/1000 -> -0.3036 | M22: 5 | N22: =_xlfn.TEXTJOIN(" ", TRUE,I45&"s","maximum growth rate of",J45&"s") -> HGTs maximum growth rate of NG-ICEs
B23: =IF(H44="*","*",_xlfn.TEXTJOIN("",TRUE,"UC-",I46,"_MaxGrowth",J46)) -> UC-HGT_MaxGrowthLNG-ICE | C23: CAP, GROWTH | D23: DMD | G23: T-HGT-ICE_LNG* | H23: 2018 | I23: LO | J23: =1+$K46 -> 1.5 | K23: 1 | L23: =-$B$56*L46/1000 -> -0.3036 | M23: 5 | N23: =_xlfn.TEXTJOIN(" ", TRUE,I46&"s","maximum growth rate of",J46&"s") -> HGTs maximum growth rate of LNG-ICEs
B24: =IF(H45="*","*",_xlfn.TEXTJOIN("",TRUE,"UC-",I47,"_MaxGrowth",J47)) -> UC-HGT_MaxGrowthHEV | C24: CAP, GROWTH | D24: DMD | G24: T-HGT-HEV* | H24: 2018 | I24: LO | J24: =1+$K47 -> 1.5 | K24: 1 | L24: =-$B$56*L47/1000 -> -0.3036 | M24: 5 | N24: =_xlfn.TEXTJOIN(" ", TRUE,I47&"s","maximum growth rate of",J47&"s") -> HGTs maximum growth rate of HEVs
B25: =IF(H46="*","*",_xlfn.TEXTJOIN("",TRUE,"UC-",I48,"_MaxGrowth",J48)) -> UC-HGT_MaxGrowthFCV | C25: CAP, GROWTH | D25: DMD | G25: T-HGT-FCV* | H25: 2018 | I25: LO | J25: =1+$K48 -> 1.5 | K25: 1 | L25: =-$B$56*L48/1000 -> -0.3036 | M25: 5 | N25: =_xlfn.TEXTJOIN(" ", TRUE,I48&"s","maximum growth rate of",J48&"s") -> HGTs maximum growth rate of FCVs
H28: On/Off | I28: Mode | J28: Type | K28: Max growth rate | L28: Seed Value
I29: CAR | J29: BEV | K29: 1 | L29: 0.2
A30: New registered vehicles and total number of vehicles in 2019 | I30: CAR | J30: PHEV | K30: 0.8 | L30: 0.2
C31: Total | D31: New | E31: Proportion | I31: CAR | J31: NG-ICE | K31: 0.5 | L31: 0.2
A32: Freight | B32: 0 - 2 tonnes | C32: 228046 | D32: 9959 | E32: =D32/C32 -> 0.043671014 | I32: CAR | J32: B100-ICE | K32: 0.2 | L32: 0.2
B33: 2 - 5 tonnes | C33: 100649 | D33: 6580 | E33: =D33/C33 -> 0.065375712 | I33: CAR | J33: E85-ICE | K33: 0.2 | L33: 0.2
B34: 5 - 7.5 tonnes | C34: 4546 | D34: 201 | E34: =D34/C34 -> 0.044214694 | I34: CAR | J34: FCV | K34: 0.5 | L34: 0.2
B35: 7.5 - 10 tonnes | C35: 6661 | D35: 329 | E35: =D35/C35 -> 0.049391983 | I35: LGT | J35: BEV | K35: 0.8 | L35: 0.2
B36: 10 - 12.5 tonnes | C36: 8424 | D36: 485 | E36: =D36/C36 -> 0.057573599 | I36: LGT | J36: PHEV | K36: 0.8 | L36: 0.2
B37: Over 12.5 tonnes | C37: 14373 | D37: 1033 | E37: =D37/C37 -> 0.071870869 | I37: LGT | J37: NG-ICE | K37: 0.3 | L37: 0.2
B38: Private cars | C38: 2168099 | D38: 121121 | E38: =D38/C38 -> 0.055865069 | I38: LGT | J38: FCV | K38: 0.3 | L38: 0.2
B39: Motor cycles | C39: 41471 | D39: 2566 | E39: =D39/C39 -> 0.061874563 | I39: MGT | J39: BEV | K39: 1 | L39: 0.25
B40: Small PSVs | C40: 21457 | D40: 1224 | E40: =D40/C40 -> 0.057044321 | I40: MGT | J40: NG-ICE | K40: 0.5 | L40: 0.2
B41: Large PSVs | C41: 11206 | D41: 551 | E41: =D41/C41 -> 0.049170087 | I41: MGT | J41: LNG-ICE | K41: 0.5 | L41: 0.2
A42: CSO, Table THA17 | I42: MGT | J42: HEV | K42: 0.5 | L42: 0.2
I43: MGT | J43: FCV | K43: 0.5 | L43: 0.2
...
