Workbook

Sheet data
D2: 2019 | E2: 2020 | F2: 2021 | G2: 2022 | H2: 2023 | I2: 2024 | J2: 2025 | K2: 2026 | L2: 2027 | M2: 2028 | N2: 2029 | O2: 2030 | P2: 2031 | Q2: 2032 | R2: 2033 | S2: 2034 | T2: 2035 | U2: 2036 | V2: 2037 | W2: 2038 | X2: 2039 | Y2: 2040 | Z2: 2041 | AA2: 2042 | AB2: 2043 | AC2: 2044 | AD2: 2045 | AE2: 2046 | AF2: 2047 | AG2: 2048 | AH2: 2049 | AI2: 2050
A3: RSD-SHALLOW | B3: Shallow Retrofit | C3: R-RTFT-Apt_B3, R-RTFT-Apt_C, R-RTFT-Apt_D, R-RTFT-Att_B3, R-RTFT-Att_C, R-RTFT-Att_D, R-RTFT-Det_B3, R-RTFT-Det_C, R-RTFT-Det_D | D3: {=SUMPRODUCT(SUMIF(caps_data!$B:$B,TRIM(MID(SUBSTITUTE($C3,", ",REPT(" ",100)),(ROW(INDIRECT("1:50"))-1)*100+1,100)),caps_data!C:C))} -> 7.4972968 | E3: {=SUMPRODUCT(SUMIF(caps_data!$B:$B,TRIM(MID(SUBSTITUTE($C3,", ",REPT(" ",100)),(ROW(INDIRECT("1:50"))-1)*100+1,100)),caps_data!D:D))} -> 6.4511985 | F3: {=SUMPRODUCT(SUMIF(caps_data!$B:$B,TRIM(MID(SUBSTITUTE($C3,", ",REPT(" ",100)),(ROW(INDIRECT("1:50"))-1)*100+1,100)),caps_data!E:E))} -> 0 | G3: {=SUMPRODUCT(SUMIF(caps_data!$B:$B,TRIM(MID(SUBSTITUTE($C3,", ",REPT(" ",100)),(ROW(INDIRECT("1:50"))-1)*100+1,100)),caps_data!F:F))} -> 0 | H3: {=SUMPRODUCT(SUMIF(caps_data!$B:$B,TRIM(MID(SUBSTITUTE($C3,", ",REPT(" ",100)),(ROW(INDIRECT("1:50"))-1)*100+1,100)),caps_data!G:G))} -> 0 | I3: {=SUMPRODUCT(SUMIF(caps_data!$B:$B,TRIM(MID(SUBSTITUTE($C3,", ",REPT(" ",100)),(ROW(INDIRECT("1:50"))-1)*100+1,100)),caps_data!H:H))} -> 0 | J3: {=SUMPRODUCT(SUMIF(caps_data!$B:$B,TRIM(MID(SUBSTITUTE($C3,", ",REPT(" ",100)),(ROW(INDIRECT("1:50"))-1)*100+1,100)),caps_data!I:I))} -> 0 | K3: {=SUMPRODUCT(SUMIF(caps_data!$B:$B,TRIM(MID(SUBSTITUTE($C3,", ",REPT(" ",100)),(ROW(INDIRECT("1:50"))-1)*100+1,100)),caps_data!J:J))} -> 0 | L3: {=SUMPRODUCT(SUMIF(caps_data!$B:$B,TRIM(MID(SUBSTITUTE($C3,", ",REPT(" ",100)),(ROW(INDIRECT("1:50"))-1)*100+1,100)),caps_data!K:K))} -> 0 | M3: {=SUMPRODUCT(SUMIF(caps_data!$B:$B,TRIM(MID(SUBSTITUTE($C3,", ",REPT(" ",100)),(ROW(INDIRECT("1:50"))-1)*100+1,100)),caps_data!L:L))} -> 0 | N3: {=SUMPRODUCT(SUMIF(caps_data!$B:$B,TRIM(MID(SUBSTITUTE($C3,", ",REPT(" ",100)),(ROW(INDIRECT("1:50"))-1)*100+1,100)),caps_data!M:M))} -> 0 | O3: {=SUMPRODUCT(SUMIF(caps_data!$B:$B,TRIM(MID(SUBSTITUTE($C3,", ",REPT(" ",100)),(ROW(INDIRECT("1:50"))-1)*100+1,100)),caps_data!N:N))} -> 0 | P3: {=SUMPRODUCT(SUMIF(caps_data!$B:$B,TRIM(MID(SUBSTITUTE($C3,", ",REPT(" ",100)),(ROW(INDIRECT("1:50"))-1)*100+1,100)),caps_data!O:O))} -> 0 | Q3: {=SUMPRODUCT(SUMIF(caps_data!$B:$B,TRIM(MID(SUBSTITUTE($C3,", ",REPT(" ",100)),(ROW(INDIRECT("1:50"))-1)*100+1,100)),caps_data!P:P))} -> 0.44463605 | R3: {=SUMPRODUCT(SUMIF(caps_data!$B:$B,TRIM(MID(SUBSTITUTE($C3,", ",REPT(" ",100)),(ROW(INDIRECT("1:50"))-1)*100+1,100)),caps_data!Q:Q))} -> 0.46046897 | S3: {=SUMPRODUCT(SUMIF(caps_data!$B:$B,TRIM(MID(SUBSTITUTE($C3,", ",REPT(" ",100)),(ROW(INDIRECT("1:50"))-1)*100+1,100)),caps_data!R:R))} -> 0.460469 | T3: {=SUMPRODUCT(SUMIF(caps_data!$B:$B,TRIM(MID(SUBSTITUTE($C3,", ",REPT(" ",100)),(ROW(INDIRECT("1:50"))-1)*100+1,100)),caps_data!S:S))} -> 2.4206012 | U3: {=SUMPRODUCT(SUMIF(caps_data!$B:$B,TRIM(MID(SUBSTITUTE($C3,", ",REPT(" ",100)),(ROW(INDIRECT("1:50"))-1)*100+1,100)),caps_data!T:T))} -> 2.4206011 | V3: {=SUMPRODUCT(SUMIF(caps_data!$B:$B,TRIM(MID(SUBSTITUTE($C3,", ",REPT(" ",100)),(ROW(INDIRECT("1:50"))-1)*100+1,100)),caps_data!U:U))} -> 2.4364326 | W3: {=SUMPRODUCT(SUMIF(caps_data!$B:$B,TRIM(MID(SUBSTITUTE($C3,", ",REPT(" ",100)),(ROW(INDIRECT("1:50"))-1)*100+1,100)),caps_data!V:V))} -> 2.436434 | X3: {=SUMPRODUCT(SUMIF(caps_data!$B:$B,TRIM(MID(SUBSTITUTE($C3,", ",REPT(" ",100)),(ROW(INDIRECT("1:50"))-1)*100+1,100)),caps_data!W:W))} -> 2.436434 | Y3: {=SUMPRODUCT(SUMIF(caps_data!$B:$B,TRIM(MID(SUBSTITUTE($C3,", ",REPT(" ",100)),(ROW(INDIRECT("1:50"))-1)*100+1,100)),caps_data!X:X))} -> 2.436434 | Z3: {=SUMPRODUCT(SUMIF(caps_data!$B:$B,TRIM(MID(SUBSTITUTE($C3,", ",REPT(" ",100)),(ROW(INDIRECT("1:50"))-1)*100+1,100)),caps_data!Y:Y))} -> 2.436434 | AA3: {=SUMPRODUCT(SUMIF(caps_data!$B:$B,TRIM(MID(SUBSTITUTE($C3,", ",REPT(" ",100)),(ROW(INDIRECT("1:50"))-1)*100+1,100)),caps_data!Z:Z))} -> 2.436434 | AB3: {=SUMPRODUCT(SUMIF(caps_data!$B:$B,TRIM(MID(SUBSTITUTE($C3,", ",REPT(" ",100)),(ROW(INDIRECT("1:50"))-1)*100+1,100)),caps_data!AA:AA))} -> 2.436434 | AC3: {=SUMPRODUCT(SUMIF(caps_data!$B:$B,TRIM(MID(SUBSTITUTE($C3,", ",REPT(" ",100)),(ROW(INDIRECT("1:50"))-1)*100+1,100)),caps_data!AB:AB))} -> 2.436434 | AD3: {=SUMPRODUCT(SUMIF(caps_data!$B:$B,TRIM(MID(SUBSTITUTE($C3,", ",REPT(" ",100)),(ROW(INDIRECT("1:50"))-1)*100+1,100)),caps_data!AC:AC))} -> 2.436434 | AE3: {=SUMPRODUCT(SUMIF(caps_data!$B:$B,TRIM(MID(SUBSTITUTE($C3,", ",REPT(" ",100)),(ROW(INDIRECT("1:50"))-1)*100+1,100)),caps_data!AD:AD))} -> 2.436434 | AF3: {=SUMPRODUCT(SUMIF(caps_data!$B:$B,TRIM(MID(SUBSTITUTE($C3,", ",REPT(" ",100)),(ROW(INDIRECT("1:50"))-1)*100+1,100)),caps_data!AE:AE))} -> 2.436434 | AG3: {=SUMPRODUCT(SUMIF(caps_data!$B:$B,TRIM(MID(SUBSTITUTE($C3,", ",REPT(" ",100)),(ROW(INDIRECT("1:50"))-1)*100+1,100)),caps_data!AF:AF))} -> 2.436434 | AH3: {=SUMPRODUCT(SUMIF(caps_data!$B:$B,TRIM(MID(SUBSTITUTE($C3,", ",REPT(" ",100)),(ROW(INDIRECT("1:50"))-1)*100+1,100)),caps_data!AG:AG))} -> 2.436434 | AI3: {=SUMPRODUCT(SUMIF(caps_data!$B:$B,TRIM(MID(SUBSTITUTE($C3,", ",REPT(" ",100)),(ROW(INDIRECT("1:50"))-1)*100+1,100)),caps_data!AH:AH))} -> 2.436434
A4: RSD-DEEP | B4: Deep Retrofit | C4: R-RTFT-Apt_E, R-RTFT-Apt_F, R-RTFT-Apt_G, R-RTFT-Att_E, R-RTFT-Att_F, R-RTFT-Att_G, R-RTFT-Det_E, R-RTFT-Det_F, R-RTFT-Det_G | E4: {=SUMPRODUCT(SUMIF(caps_data!$B:$B,TRIM(MID(SUBSTITUTE($C4,", ",REPT(" ",100)),(ROW(INDIRECT("1:50"))-1)*100+1,100)),caps_data!D:D))} -> 3.6584498 | F4: {=SUMPRODUCT(SUMIF(caps_data!$B:$B,TRIM(MID(SUBSTITUTE($C4,", ",REPT(" ",100)),(ROW(INDIRECT("1:50"))-1)*100+1,100)),caps_data!E:E))} -> 25.399042 | G4: {=SUMPRODUCT(SUMIF(caps_data!$B:$B,TRIM(MID(SUBSTITUTE($C4,", ",REPT(" ",100)),(ROW(INDIRECT("1:50"))-1)*100+1,100)),caps_data!F:F))} -> 37.836289 | H4: {=SUMPRODUCT(SUMIF(caps_data!$B:$B,TRIM(MID(SUBSTITUTE($C4,", ",REPT(" ",100)),(ROW(INDIRECT("1:50"))-1)*100+1,100)),caps_data!G:G))} -> 0 | I4: {=SUMPRODUCT(SUMIF(caps_data!$B:$B,TRIM(MID(SUBSTITUTE($C4,", ",REPT(" ",100)),(ROW(INDIRECT("1:50"))-1)*100+1,100)),caps_data!H:H))} -> 0 | J4: {=SUMPRODUCT(SUMIF(caps_data!$B:$B,TRIM(MID(SUBSTITUTE($C4,", ",REPT(" ",100)),(ROW(INDIRECT("1:50"))-1)*100+1,100)),caps_data!I:I))} -> 7.2471677 | K4: {=SUMPRODUCT(SUMIF(caps_data!$B:$B,TRIM(MID(SUBSTITUTE($C4,", ",REPT(" ",100)),(ROW(INDIRECT("1:50"))-1)*100+1,100)),caps_data!J:J))} -> 22.364961 | L4: {=SUMPRODUCT(SUMIF(caps_data!$B:$B,TRIM(MID(SUBSTITUTE($C4,", ",REPT(" ",100)),(ROW(INDIRECT("1:50"))-1)*100+1,100)),caps_data!K:K))} -> 7.3921218 | M4: {=SUMPRODUCT(SUMIF(caps_data!$B:$B,TRIM(MID(SUBSTITUTE($C4,", ",REPT(" ",100)),(ROW(INDIRECT("1:50"))-1)*100+1,100)),caps_data!L:L))} -> 3.1129013 | N4: {=SUMPRODUCT(SUMIF(caps_data!$B:$B,TRIM(MID(SUBSTITUTE($C4,", ",REPT(" ",100)),(ROW(INDIRECT("1:50"))-1)*100+1,100)),caps_data!M:M))} -> 3.1129013 | O4: {=SUMPRODUCT(SUMIF(caps_data!$B:$B,TRIM(MID(SUBSTITUTE($C4,", ",REPT(" ",100)),(ROW(INDIRECT("1:50"))-1)*100+1,100)),caps_data!N:N))} -> 0.69717873 | P4: {=SUMPRODUCT(SUMIF(caps_data!$B:$B,TRIM(MID(SUBSTITUTE($C4,", ",REPT(" ",100)),(ROW(INDIRECT("1:50"))-1)*100+1,100)),caps_data!O:O))} -> 0 | Q4: {=SUMPRODUCT(SUMIF(caps_data!$B:$B,TRIM(MID(SUBSTITUTE($C4,", ",REPT(" ",100)),(ROW(INDIRECT("1:50"))-1)*100+1,100)),caps_data!P:P))} -> 0.031665839 | R4: {=SUMPRODUCT(SUMIF(caps_data!$B:$B,TRIM(MID(SUBSTITUTE($C4,", ",REPT(" ",100)),(ROW(INDIRECT("1:50"))-1)*100+1,100)),caps_data!Q:Q))} -> 0.015832931 | S4: {=SUMPRODUCT(SUMIF(caps_data!$B:$B,TRIM(MID(SUBSTITUTE($C4,", ",REPT(" ",100)),(ROW(INDIRECT("1:50"))-1)*100+1,100)),caps_data!R:R))} -> 0.015832923 | T4: {=SUMPRODUCT(SUMIF(caps_data!$B:$B,TRIM(MID(SUBSTITUTE($C4,", ",REPT(" ",100)),(ROW(INDIRECT("1:50"))-1)*100+1,100)),caps_data!S:S))} -> 0.01583288 | U4: {=SUMPRODUCT(SUMIF(caps_data!$B:$B,TRIM(MID(SUBSTITUTE($C4,", ",REPT(" ",100)),(ROW(INDIRECT("1:50"))-1)*100+1,100)),caps_data!T:T))} -> 0.015832963
A5: RSD-APT-HP | B5: Heat Pumps | C5: R-HC_Apt_ELC_HPN1, R-HC_Apt_ELC_HPN2-AB, R-HC_Apt_ELC_HPN2-C, R-HC_Apt_ELC_HPN2-D, R-HC_Apt_ELC_HPN2-E, R-HC_Apt_ELC_HPN2-F, R-HC_Apt_ELC_HPN2-G, R-SH_Apt_ELC_HPN1, R-SH_Apt_ELC_HPN2-AB, R-SH_Apt_ELC_HPN2-C, R-SH_Apt_ELC_HPN2-D, R-SH_Apt_ELC_HPN2-E, R-SH_Apt_ELC_HPN2-F, R-SH_Apt_ELC_HPN2-G, R-SH_Apt_ELC_HPN3-AB, R-SH_Apt_ELC_HPN3-C, R-SH_Apt_ELC_HPN3-D, R-SH_Apt_ELC_HPN3-E, R-SH_Apt_ELC_HPN3-F, R-SH_Apt_ELC_HPN3-G, R-SW_Apt_ELC_HPN1-AB, R-SW_Apt_ELC_HPN1-C, R-SW_Apt_ELC_HPN1-D, R-SW_Apt_ELC_HPN1-E, R-SW_Apt_ELC_HPN1-F, R-SW_Apt_ELC_HPN1-G, R-SW_Apt_GAS_HHPN1, R-SW_Apt_GAS_HPN1, R-SW_Apt_GAS_HPN2 | D5: {=SUMPRODUCT(SUMIF(caps_data!$B:$B,TRIM(MID(SUBSTITUTE($C5,", ",REPT(" ",100)),(ROW(INDIRECT("1:50"))-1)*100+1,100)),caps_data!C:C))} -> 0 | E5: {=SUMPRODUCT(SUMIF(caps_data!$B:$B,TRIM(MID(SUBSTITUTE($C5,", ",REPT(" ",100)),(ROW(INDIRECT("1:50"))-1)*100+1,100)),caps_data!D:D))} -> 0 | G5: {=SUMPRODUCT(SUMIF(caps_data!$B:$B,TRIM(MID(SUBSTITUTE($C5,", ",REPT(" ",100)),(ROW(INDIRECT("1:50"))-1)*100+1,100)),caps_data!F:F))} -> 3.8060493 | J5: {=SUMPRODUCT(SUMIF(caps_data!$B:$B,TRIM(MID(SUBSTITUTE($C5,", ",REPT(" ",100)),(ROW(INDIRECT("1:50"))-1)*100+1,100)),caps_data!I:I))} -> 20.788283 | K5: {=SUMPRODUCT(SUMIF(caps_data!$B:$B,TRIM(MID(SUBSTITUTE($C5,", ",REPT(" ",100)),(ROW(INDIRECT("1:50"))-1)*100+1,100)),caps_data!J:J))} -> 17.116404 | L5: {=SUMPRODUCT(SUMIF(caps_data!$B:$B,TRIM(MID(SUBSTITUTE($C5,", ",REPT(" ",100)),(ROW(INDIRECT("1:50"))-1)*100+1,100)),caps_data!K:K))} -> 0.10122871 | M5: {=SUMPRODUCT(SUMIF(caps_data!$B:$B,TRIM(MID(SUBSTITUTE($C5,", ",REPT(" ",100)),(ROW(INDIRECT("1:50"))-1)*100+1,100)),caps_data!L:L))} -> 0.097261719 | N5: {=SUMPRODUCT(SUMIF(caps_data!$B:$B,TRIM(MID(SUBSTITUTE($C5,", ",REPT(" ",100)),(ROW(INDIRECT("1:50"))-1)*100+1,100)),caps_data!M:M))} -> 0.091833754 | O5: {=SUMPRODUCT(SUMIF(caps_data!$B:$B,TRIM(MID(SUBSTITUTE($C5,", ",REPT(" ",100)),(ROW(INDIRECT("1:50"))-1)*100+1,100)),caps_data!N:N))} -> 0.086427549 | P5: {=SUMPRODUCT(SUMIF(caps_data!$B:$B,TRIM(MID(SUBSTITUTE($C5,", ",REPT(" ",100)),(ROW(INDIRECT("1:50"))-1)*100+1,100)),caps_data!O:O))} -> 0.0040535265 | Q5: {=SUMPRODUCT(SUMIF(caps_data!$B:$B,TRIM(MID(SUBSTITUTE($C5,", ",REPT(" ",100)),(ROW(INDIRECT("1:50"))-1)*100+1,100)),caps_data!P:P))} -> 0.32227998 | R5: {=SUMPRODUCT(SUMIF(caps_data!$B:$B,TRIM(MID(SUBSTITUTE($C5,", ",REPT(" ",100)),(ROW(INDIRECT("1:50"))-1)*100+1,100)),caps_data!Q:Q))} -> 0.13578381 | T5: {=SUMPRODUCT(SUMIF(caps_data!$B:$B,TRIM(MID(SUBSTITUTE($C5,", ",REPT(" ",100)),(ROW(INDIRECT("1:50"))-1)*100+1,100)),caps_data!S:S))} -> 0.0040533582 | AC5: {=SUMPRODUCT(SUMIF(caps_data!$B:$B,TRIM(MID(SUBSTITUTE($C5,", ",REPT(" ",100)),(ROW(INDIRECT("1:50"))-1)*100+1,100)),caps_data!AB:AB))} -> 1.521845 | AD5: {=SUMPRODUCT(SUMIF(caps_data!$B:$B,TRIM(MID(SUBSTITUTE($C5,", ",REPT(" ",100)),(ROW(INDIRECT("1:50"))-1)*100+1,100)),caps_data!AC:AC))} -> 18.024512 | AE5: {=SUMPRODUCT(SUMIF(caps_data!$B:$B,TRIM(MID(SUBSTITUTE($C5,", ",REPT(" ",100)),(ROW(INDIRECT("1:50"))-1)*100+1,100)),caps_data!AD:AD))} -> 19.424702 | AF5: {=SUMPRODUCT(SUMIF(caps_data!$B:$B,TRIM(MID(SUBSTITUTE($C5,", ",REPT(" ",100)),(ROW(INDIRECT("1:50"))-1)*100+1,100)),caps_data!AE:AE))} -> 0.25204397 | AG5: {=SUMPRODUCT(SUMIF(caps_data!$B:$B,TRIM(MID(SUBSTITUTE($C5,", ",REPT(" ",100)),(ROW(INDIRECT("1:50"))-1)*100+1,100)),caps_data!AF:AF))} -> 0.24822133 | AH5: {=SUMPRODUCT(SUMIF(caps_data!$B:$B,TRIM(MID(SUBSTITUTE($C5,", ",REPT(" ",100)),(ROW(INDIRECT("1:50"))-1)*100+1,100)),caps_data!AG:AG))} -> 0.24253002 | AI5: {=SUMPRODUCT(SUMIF(caps_data!$B:$B,TRIM(MID(SUBSTITUTE($C5,", ",REPT(" ",100)),(ROW(INDIRECT("1:50"))-1)*100+1,100)),caps_data!AH:AH))} -> 0.23673321
A6: RSD-BIOGAS | B6: Biogas | C6: R-SH_Apt_GAS_N1,R-SH_Att_GAS_N1,R-SH_Det_GAS_N1,R-SW_Apt_GAS_HHPN1,R-SW_Apt_GAS_HPN1,R-SW_Apt_GAS_HPN2,R-SW_Apt_GAS_N1,R-SW_Att_GAS_HHPN1,R-SW_Att_GAS_HPN1,R-SW_Att_GAS_HPN2,R-SW_Att_GAS_N1,R-SW_Att_GAS_N2,R-SW_Att_GAS_N3,R-SW_Det_GAS_HHPN1,R-SW_Det_GAS_HPN1,R-SW_Det_GAS_HPN2,R-SW_Det_GAS_N1,R-SW_Det_GAS_N2,R-SW_Det_GAS_N3 | D6: {=SUMPRODUCT(SUMIF(caps_data!$B:$B,TRIM(MID(SUBSTITUTE($C6,", ",REPT(" ",100)),(ROW(INDIRECT("1:50"))-1)*100+1,100)),caps_data!C:C))} -> 0 | E6: {=SUMPRODUCT(SUMIF(caps_data!$B:$B,TRIM(MID(SUBSTITUTE($C6,", ",REPT(" ",100)),(ROW(INDIRECT("1:50"))-1)*100+1,100)),caps_data!D:D))} -> 0 | F6: {=SUMPRODUCT(SUMIF(caps_data!$B:$B,TRIM(MID(SUBSTITUTE($C6,", ",REPT(" ",100)),(ROW(INDIRECT("1:50"))-1)*100+1,100)),caps_data!E:E))} -> 0 | G6: {=SUMPRODUCT(SUMIF(caps_data!$B:$B,TRIM(MID(SUBSTITUTE($C6,", ",REPT(" ",100)),(ROW(INDIRECT("1:50"))-1)*100+1,100)),caps_data!F:F))} -> 0 | H6: {=SUMPRODUCT(SUMIF(caps_data!$B:$B,TRIM(MID(SUBSTITUTE($C6,", ",REPT(" ",100)),(ROW(INDIRECT("1:50"))-1)*100+1,100)),caps_data!G:G))} -> 0 | I6: {=SUMPRODUCT(SUMIF(caps_data!$B:$B,TRIM(MID(SUBSTITUTE($C6,", ",REPT(" ",100)),(ROW(INDIRECT("1:50"))-1)*100+1,100)),caps_data!H:H))} -> 0 | J6: {=SUMPRODUCT(SUMIF(caps_data!$B:$B,TRIM(MID(SUBSTITUTE($C6,", ",REPT(" ",100)),(ROW(INDIRECT("1:50"))-1)*100+1,100)),caps_data!I:I))} -> 0 | K6: {=SUMPRODUCT(SUMIF(caps_data!$B:$B,TRIM(MID(SUBSTITUTE($C6,", ",REPT(" ",100)),(ROW(INDIRECT("1:50"))-1)*100+1,100)),caps_data!J:J))} -> 0 | L6: {=SUMPRODUCT(SUMIF(caps_data!$B:$B,TRIM(MID(SUBSTITUTE($C6,", ",REPT(" ",100)),(ROW(INDIRECT("1:50"))-1)*100+1,100)),caps_data!K:K))} -> 0 | M6: {=SUMPRODUCT(SUMIF(caps_data!$B:$B,TRIM(MID(SUBSTITUTE($C6,", ",REPT(" ",100)),(ROW(INDIRECT("1:50"))-1)*100+1,100)),caps_data!L:L))} -> 0 | N6: {=SUMPRODUCT(SUMIF(caps_data!$B:$B,TRIM(MID(SUBSTITUTE($C6,", ",REPT(" ",100)),(ROW(INDIRECT("1:50"))-1)*100+1,100)),caps_data!M:M))} -> 0 | O6: {=SUMPRODUCT(SUMIF(caps_data!$B:$B,TRIM(MID(SUBSTITUTE($C6,", ",REPT(" ",100)),(ROW(INDIRECT("1:50"))-1)*100+1,100)),caps_data!N:N))} -> 0 | P6: {=SUMPRODUCT(SUMIF(caps_data!$B:$B,TRIM(MID(SUBSTITUTE($C6,", ",REPT(" ",100)),(ROW(INDIRECT("1:50"))-1)*100+1,100)),caps_data!O:O))} -> 0 | Q6: {=SUMPRODUCT(SUMIF(caps_data!$B:$B,TRIM(MID(SUBSTITUTE($C6,", ",REPT(" ",100)),(ROW(INDIRECT("1:50"))-1)*100+1,100)),caps_data!P:P))} -> 0 | R6: {=SUMPRODUCT(SUMIF(caps_data!$B:$B,TRIM(MID(SUBSTITUTE($C6,", ",REPT(" ",100)),(ROW(INDIRECT("1:50"))-1)*100+1,100)),caps_data!Q:Q))} -> 0 | S6: {=SUMPRODUCT(SUMIF(caps_data!$B:$B,TRIM(MID(SUBSTITUTE($C6,", ",REPT(" ",100)),(ROW(INDIRECT("1:50"))-1)*100+1,100)),caps_data!R:R))} -> 0 | T6: {=SUMPRODUCT(SUMIF(caps_data!$B:$B,TRIM(MID(SUBSTITUTE($C6,", ",REPT(" ",100)),(ROW(INDIRECT("1:50"))-1)*100+1,100)),caps_data!S:S))} -> 0 | U6: {=SUMPRODUCT(SUMIF(caps_data!$B:$B,TRIM(MID(SUBSTITUTE($C6,", ",REPT(" ",100)),(ROW(INDIRECT("1:50"))-1)*100+1,100)),caps_data!T:T))} -> 0 | V6: {=SUMPRODUCT(SUMIF(caps_data!$B:$B,TRIM(MID(SUBSTITUTE($C6,", ",REPT(" ",100)),(ROW(INDIRECT("1:50"))-1)*100+1,100)),caps_data!U:U))} -> 0 | W6: {=SUMPRODUCT(SUMIF(caps_data!$B:$B,TRIM(MID(SUBSTITUTE($C6,", ",REPT(" ",100)),(ROW(INDIRECT("1:50"))-1)*100+1,100)),caps_data!V:V))} -> 0 | X6: {=SUMPRODUCT(SUMIF(caps_data!$B:$B,TRIM(MID(SUBSTITUTE($C6,", ",REPT(" ",100)),(ROW(INDIRECT("1:50"))-1)*100+1,100)),caps_data!W:W))} -> 0 | Y6: {=SUMPRODUCT(SUMIF(caps_data!$B:$B,TRIM(MID(SUBSTITUTE($C6,", ",REPT(" ",100)),(ROW(INDIRECT("1:50"))-1)*100+1,100)),caps_data!X:X))} -> 0 | Z6: {=SUMPRODUCT(SUMIF(caps_data!$B:$B,TRIM(MID(SUBSTITUTE($C6,", ",REPT(" ",100)),(ROW(INDIRECT("1:50"))-1)*100+1,100)),caps_data!Y:Y))} -> 0 | AA6: {=SUMPRODUCT(SUMIF(caps_data!$B:$B,TRIM(MID(SUBSTITUTE($C6,", ",REPT(" ",100)),(ROW(INDIRECT("1:50"))-1)*100+1,100)),caps_data!Z:Z))} -> 0 | AB6: {=SUMPRODUCT(SUMIF(caps_data!$B:$B,TRIM(MID(SUBSTITUTE($C6,", ",REPT(" ",100)),(ROW(INDIRECT("1:50"))-1)*100+1,100)),caps_data!AA:AA))} -> 0 | AC6: {=SUMPRODUCT(SUMIF(caps_data!$B:$B,TRIM(MID(SUBSTITUTE($C6,", ",REPT(" ",100)),(ROW(INDIRECT("1:50"))-1)*100+1,100)),caps_data!AB:AB))} -> 0 | AD6: {=SUMPRODUCT(SUMIF(caps_data!$B:$B,TRIM(MID(SUBSTITUTE($C6,", ",REPT(" ",100)),(ROW(INDIRECT("1:50"))-1)*100+1,100)),caps_data!AC:AC))} -> 0 | AE6: {=SUMPRODUCT(SUMIF(caps_data!$B:$B,TRIM(MID(SUBSTITUTE($C6,", ",REPT(" ",100)),(ROW(INDIRECT("1:50"))-1)*100+1,100)),caps_data!AD:AD))} -> 0 | AF6: {=SUMPRODUCT(SUMIF(caps_data!$B:$B,TRIM(MID(SUBSTITUTE($C6,", ",REPT(" ",100)),(ROW(INDIRECT("1:50"))-1)*100+1,100)),caps_data!AE:AE))} -> 0 | AG6: {=SUMPRODUCT(SUMIF(caps_data!$B:$B,TRIM(MID(SUBSTITUTE($C6,", ",REPT(" ",100)),(ROW(INDIRECT("1:50"))-1)*100+1,100)),caps_data!AF:AF))} -> 0 | AH6: {=SUMPRODUCT(SUMIF(caps_data!$B:$B,TRIM(MID(SUBSTITUTE($C6,", ",REPT(" ",100)),(ROW(INDIRECT("1:50"))-1)*100+1,100)),caps_data!AG:AG))} -> 0 | AI6: {=SUMPRODUCT(SUMIF(caps_data!$B:$B,TRIM(MID(SUBSTITUTE($C6,", ",REPT(" ",100)),(ROW(INDIRECT("1:50"))-1)*100+1,100)),caps_data!AH:AH))} -> 0
A7: RSD-ATT-HP | B7: Heat Pumps | C7: R-HC_Att_ELC_HPN1, R-HC_Att_ELC_HPN2-AB, R-HC_Att_ELC_HPN2-C, R-HC_Att_ELC_HPN2-D, R-HC_Att_ELC_HPN2-E, R-HC_Att_ELC_HPN2-F, R-HC_Att_ELC_HPN2-G, R-SH_Att_ELC_HPN1, R-SH_Att_ELC_HPN2-AB, R-SH_Att_ELC_HPN2-C, R-SH_Att_ELC_HPN2-D, R-SH_Att_ELC_HPN2-E, R-SH_Att_ELC_HPN2-F, R-SH_Att_ELC_HPN2-G, R-SH_Att_ELC_HPN3-AB, R-SH_Att_ELC_HPN3-C, R-SH_Att_ELC_HPN3-D, R-SH_Att_ELC_HPN3-E, R-SH_Att_ELC_HPN3-F, R-SH_Att_ELC_HPN3-G, R-SW_Att_ELC_HPN1-AB, R-SW_Att_ELC_HPN1-C, R-SW_Att_ELC_HPN1-D, R-SW_Att_ELC_HPN1-E, R-SW_Att_ELC_HPN1-F, R-SW_Att_ELC_HPN1-G, R-SW_Att_ELC_HPN2-AB, R-SW_Att_ELC_HPN2-C, R-SW_Att_ELC_HPN2-D, R-SW_Att_ELC_HPN2-E, R-SW_Att_ELC_HPN2-F, R-SW_Att_ELC_HPN2-G, R-SW_Att_GAS_HHPN1, R-SW_Att_GAS_HPN1, R-SW_Att_GAS_HPN2 | D7: {=SUMPRODUCT(SUMIF(caps_data!$B:$B,TRIM(MID(SUBSTITUTE($C7,", ",REPT(" ",100)),(ROW(INDIRECT("1:50"))-1)*100+1,100)),caps_data!C:C))} -> 6.1992245 | E7: {=SUMPRODUCT(SUMIF(caps_data!$B:$B,TRIM(MID(SUBSTITUTE($C7,", ",REPT(" ",100)),(ROW(INDIRECT("1:50"))-1)*100+1,100)),caps_data!D:D))} -> 52.486207 | F7: {=SUMPRODUCT(SUMIF(caps_data!$B:$B,TRIM(MID(SUBSTITUTE($C7,", ",REPT(" ",100)),(ROW(INDIRECT("1:50"))-1)*100+1,100)),caps_data!E:E))} -> 48.139253 | G7: {=SUMPRODUCT(SUMIF(caps_data!$B:$B,TRIM(MID(SUBSTITUTE($C7,", ",REPT(" ",100)),(ROW(INDIRECT("1:50"))-1)*100+1,100)),caps_data!F:F))} -> 48.176539 | H7: {=SUMPRODUCT(SUMIF(caps_data!$B:$B,TRIM(MID(SUBSTITUTE($C7,", ",REPT(" ",100)),(ROW(INDIRECT("1:50"))-1)*100+1,100)),caps_data!G:G))} -> 47.254031 | I7: {=SUMPRODUCT(SUMIF(caps_data!$B:$B,TRIM(MID(SUBSTITUTE($C7,", ",REPT(" ",100)),(ROW(INDIRECT("1:50"))-1)*100+1,100)),caps_data!H:H))} -> 36.341222 | J7: {=SUMPRODUCT(SUMIF(caps_data!$B:$B,TRIM(MID(SUBSTITUTE($C7,", ",REPT(" ",100)),(ROW(INDIRECT("1:50"))-1)*100+1,100)),caps_data!I:I))} -> 34.001223 | K7: {=SUMPRODUCT(SUMIF(caps_data!$B:$B,TRIM(MID(SUBSTITUTE($C7,", ",REPT(" ",100)),(ROW(INDIRECT("1:50"))-1)*100+1,100)),caps_data!J:J))} -> 19.83235 | L7: {=SUMPRODUCT(SUMIF(caps_data!$B:$B,TRIM(MID(SUBSTITUTE($C7,", ",REPT(" ",100)),(ROW(INDIRECT("1:50"))-1)*100+1,100)),caps_data!K:K))} -> 0.58261382 | M7: {=SUMPRODUCT(SUMIF(caps_data!$B:$B,TRIM(MID(SUBSTITUTE($C7,", ",REPT(" ",100)),(ROW(INDIRECT("1:50"))-1)*100+1,100)),caps_data!L:L))} -> 0.62415261 | N7: {=SUMPRODUCT(SUMIF(caps_data!$B:$B,TRIM(MID(SUBSTITUTE($C7,", ",REPT(" ",100)),(ROW(INDIRECT("1:50"))-1)*100+1,100)),caps_data!M:M))} -> 0.63315861 | O7: {=SUMPRODUCT(SUMIF(caps_data!$B:$B,TRIM(MID(SUBSTITUTE($C7,", ",REPT(" ",100)),(ROW(INDIRECT("1:50"))-1)*100+1,100)),caps_data!N:N))} -> 0.63217534 | P7: {=SUMPRODUCT(SUMIF(caps_data!$B:$B,TRIM(MID(SUBSTITUTE($C7,", ",REPT(" ",100)),(ROW(INDIRECT("1:50"))-1)*100+1,100)),caps_data!O:O))} -> 0.46476519 | Q7: {=SUMPRODUCT(SUMIF(caps_data!$B:$B,TRIM(MID(SUBSTITUTE($C7,", ",REPT(" ",100)),(ROW(INDIRECT("1:50"))-1)*100+1,100)),caps_data!P:P))} -> 4.7339117 | R7: {=SUMPRODUCT(SUMIF(caps_data!$B:$B,TRIM(MID(SUBSTITUTE($C7,", ",REPT(" ",100)),(ROW(INDIRECT("1:50"))-1)*100+1,100)),caps_data!Q:Q))} -> 4.4787926 | S7: {=SUMPRODUCT(SUMIF(caps_data!$B:$B,TRIM(MID(SUBSTITUTE($C7,", ",REPT(" ",100)),(ROW(INDIRECT("1:50"))-1)*100+1,100)),caps_data!R:R))} -> 0.54255293 | T7: {=SUMPRODUCT(SUMIF(caps_data!$B:$B,TRIM(MID(SUBSTITUTE($C7,", ",REPT(" ",100)),(ROW(INDIRECT("1:50"))-1)*100+1,100)),caps_data!S:S))} -> 0.51895152 | U7: {=SUMPRODUCT(SUMIF(caps_data!$B:$B,TRIM(MID(SUBSTITUTE($C7,", ",REPT(" ",100)),(ROW(INDIRECT("1:50"))-1)*100+1,100)),caps_data!T:T))} -> 10.607765 | V7: {=SUMPRODUCT(SUMIF(caps_data!$B:$B,TRIM(MID(SUBSTITUTE($C7,", ",REPT(" ",100)),(ROW(INDIRECT("1:50"))-1)*100+1,100)),caps_data!U:U))} -> 10.684082 | W7: {=SUMPRODUCT(SUMIF(caps_data!$B:$B,TRIM(MID(SUBSTITUTE($C7,", ",REPT(" ",100)),(ROW(INDIRECT("1:50"))-1)*100+1,100)),caps_data!V:V))} -> 11.39974 | X7: {=SUMPRODUCT(SUMIF(caps_data!$B:$B,TRIM(MID(SUBSTITUTE($C7,", ",REPT(" ",100)),(ROW(INDIRECT("1:50"))-1)*100+1,100)),caps_data!W:W))} -> 12.110286 | Y7: {=SUMPRODUCT(SUMIF(caps_data!$B:$B,TRIM(MID(SUBSTITUTE($C7,", ",REPT(" ",100)),(ROW(INDIRECT("1:50"))-1)*100+1,100)),caps_data!X:X))} -> 59.873935 | Z7: {=SUMPRODUCT(SUMIF(caps_data!$B:$B,TRIM(MID(SUBSTITUTE($C7,", ",REPT(" ",100)),(ROW(INDIRECT("1:50"))-1)*100+1,100)),caps_data!Y:Y))} -> 47.455386 | AA7: {=SUMPRODUCT(SUMIF(caps_data!$B:$B,TRIM(MID(SUBSTITUTE($C7,", ",REPT(" ",100)),(ROW(INDIRECT("1:50"))-1)*100+1,100)),caps_data!Z:Z))} -> 47.49267 | AB7: {=SUMPRODUCT(SUMIF(caps_data!$B:$B,TRIM(MID(SUBSTITUTE($C7,", ",REPT(" ",100)),(ROW(INDIRECT("1:50"))-1)*100+1,100)),caps_data!AA:AA))} -> 46.830457 | AC7: {=SUMPRODUCT(SUMIF(caps_data!$B:$B,TRIM(MID(SUBSTITUTE($C7,", ",REPT(" ",100)),(ROW(INDIRECT("1:50"))-1)*100+1,100)),caps_data!AB:AB))} -> 35.901575 | AD7: {=SUMPRODUCT(SUMIF(caps_data!$B:$B,TRIM(MID(SUBSTITUTE($C7,", ",REPT(" ",100)),(ROW(INDIRECT("1:50"))-1)*100+1,100)),caps_data!AC:AC))} -> 33.54466 | AE7: {=SUMPRODUCT(SUMIF(caps_data!$B:$B,TRIM(MID(SUBSTITUTE($C7,", ",REPT(" ",100)),(ROW(INDIRECT("1:50"))-1)*100+1,100)),caps_data!AD:AD))} -> 19.367589 | AF7: {=SUMPRODUCT(SUMIF(caps_data!$B:$B,TRIM(MID(SUBSTITUTE($C7,", ",REPT(" ",100)),(ROW(INDIRECT("1:50"))-1)*100+1,100)),caps_data!AE:AE))} -> 2.2877872 | AG7: {=SUMPRODUCT(SUMIF(caps_data!$B:$B,TRIM(MID(SUBSTITUTE($C7,", ",REPT(" ",100)),(ROW(INDIRECT("1:50"))-1)*100+1,100)),caps_data!AF:AF))} -> 0.92469243 | AH7: {=SUMPRODUCT(SUMIF(caps_data!$B:$B,TRIM(MID(SUBSTITUTE($C7,", ",REPT(" ",100)),(ROW(INDIRECT("1:50"))-1)*100+1,100)),caps_data!AG:AG))} -> 3.193718 | AI7: {=SUMPRODUCT(SUMIF(caps_data!$B:$B,TRIM(MID(SUBSTITUTE($C7,", ",REPT(" ",100)),(ROW(INDIRECT("1:50"))-1)*100+1,100)),caps_data!AH:AH))} -> 0.95594929
A8: RSD-DH | B8: District Heating | C8: R-SW_Apt_HET_N1, R-SW_Apt_HET_N2 | D8: {=SUMPRODUCT(SUMIF(caps_data!$B:$B,TRIM(MID(SUBSTITUTE($C8,", ",REPT(" ",100)),(ROW(INDIRECT("1:50"))-1)*100+1,100)),caps_data!C:C))} -> 0 | E8: {=SUMPRODUCT(SUMIF(caps_data!$B:$B,TRIM(MID(SUBSTITUTE($C8,", ",REPT(" ",100)),(ROW(INDIRECT("1:50"))-1)*100+1,100)),caps_data!D:D))} -> 0 | H8: {=SUMPRODUCT(SUMIF(caps_data!$B:$B,TRIM(MID(SUBSTITUTE($C8,", ",REPT(" ",100)),(ROW(INDIRECT("1:50"))-1)*100+1,100)),caps_data!G:G))} -> 0.30981051 | I8: {=SUMPRODUCT(SUMIF(caps_data!$B:$B,TRIM(MID(SUBSTITUTE($C8,", ",REPT(" ",100)),(ROW(INDIRECT("1:50"))-1)*100+1,100)),caps_data!H:H))} -> 3.5732957 | J8: {=SUMPRODUCT(SUMIF(caps_data!$B:$B,TRIM(MID(SUBSTITUTE($C8,", ",REPT(" ",100)),(ROW(INDIRECT("1:50"))-1)*100+1,100)),caps_data!I:I))} -> 1.435172 | L8: {=SUMPRODUCT(SUMIF(caps_data!$B:$B,TRIM(MID(SUBSTITUTE($C8,", ",REPT(" ",100)),(ROW(INDIRECT("1:50"))-1)*100+1,100)),caps_data!K:K))} -> 0.89317595 | M8: {=SUMPRODUCT(SUMIF(caps_data!$B:$B,TRIM(MID(SUBSTITUTE($C8,", ",REPT(" ",100)),(ROW(INDIRECT("1:50"))-1)*100+1,100)),caps_data!L:L))} -> 0.7222118 | N8: {=SUMPRODUCT(SUMIF(caps_data!$B:$B,TRIM(MID(SUBSTITUTE($C8,", ",REPT(" ",100)),(ROW(INDIRECT("1:50"))-1)*100+1,100)),caps_data!M:M))} -> 4.9216741 | O8: {=SUMPRODUCT(SUMIF(caps_data!$B:$B,TRIM(MID(SUBSTITUTE($C8,", ",REPT(" ",100)),(ROW(INDIRECT("1:50"))-1)*100+1,100)),caps_data!N:N))} -> 1.2658376 | Q8: {=SUMPRODUCT(SUMIF(caps_data!$B:$B,TRIM(MID(SUBSTITUTE($C8,", ",REPT(" ",100)),(ROW(INDIRECT("1:50"))-1)*100+1,100)),caps_data!P:P))} -> 2.6974966 | R8: {=SUMPRODUCT(SUMIF(caps_data!$B:$B,TRIM(MID(SUBSTITUTE($C8,", ",REPT(" ",100)),(ROW(INDIRECT("1:50"))-1)*100+1,100)),caps_data!Q:Q))} -> 3.5008444 | S8: {=SUMPRODUCT(SUMIF(caps_data!$B:$B,TRIM(MID(SUBSTITUTE($C8,", ",REPT(" ",100)),(ROW(INDIRECT("1:50"))-1)*100+1,100)),caps_data!R:R))} -> 3.6729575 | T8: {=SUMPRODUCT(SUMIF(caps_data!$B:$B,TRIM(MID(SUBSTITUTE($C8,", ",REPT(" ",100)),(ROW(INDIRECT("1:50"))-1)*100+1,100)),caps_data!S:S))} -> 3.6747755 | U8: {=SUMPRODUCT(SUMIF(caps_data!$B:$B,TRIM(MID(SUBSTITUTE($C8,", ",REPT(" ",100)),(ROW(INDIRECT("1:50"))-1)*100+1,100)),caps_data!T:T))} -> 3.6812978 | V8: {=SUMPRODUCT(SUMIF(caps_data!$B:$B,TRIM(MID(SUBSTITUTE($C8,", ",REPT(" ",100)),(ROW(INDIRECT("1:50"))-1)*100+1,100)),caps_data!U:U))} -> 3.697412 | W8: {=SUMPRODUCT(SUMIF(caps_data!$B:$B,TRIM(MID(SUBSTITUTE($C8,", ",REPT(" ",100)),(ROW(INDIRECT("1:50"))-1)*100+1,100)),caps_data!V:V))} -> 3.7074574 | X8: {=SUMPRODUCT(SUMIF(caps_data!$B:$B,TRIM(MID(SUBSTITUTE($C8,", ",REPT(" ",100)),(ROW(INDIRECT("1:50"))-1)*100+1,100)),caps_data!W:W))} -> 0.6289541 | Y8: {=SUMPRODUCT(SUMIF(caps_data!$B:$B,TRIM(MID(SUBSTITUTE($C8,", ",REPT(" ",100)),(ROW(INDIRECT("1:50"))-1)*100+1,100)),caps_data!X:X))} -> 0.50563414 | Z8: {=SUMPRODUCT(SUMIF(caps_data!$B:$B,TRIM(MID(SUBSTITUTE($C8,", ",REPT(" ",100)),(ROW(INDIRECT("1:50"))-1)*100+1,100)),caps_data!Y:Y))} -> 0.14565916 | AD8: {=SUMPRODUCT(SUMIF(caps_data!$B:$B,TRIM(MID(SUBSTITUTE($C8,", ",REPT(" ",100)),(ROW(INDIRECT("1:50"))-1)*100+1,100)),caps_data!AC:AC))} -> 1.3464679 | AE8: {=SUMPRODUCT(SUMIF(caps_data!$B:$B,TRIM(MID(SUBSTITUTE($C8,", ",REPT(" ",100)),(ROW(INDIRECT("1:50"))-1)*100+1,100)),caps_data!AD:AD))} -> 0.72456075 | AF8: {=SUMPRODUCT(SUMIF(caps_data!$B:$B,TRIM(MID(SUBSTITUTE($C8,", ",REPT(" ",100)),(ROW(INDIRECT("1:50"))-1)*100+1,100)),caps_data!AE:AE))} -> 1.6585341 | AG8: {=SUMPRODUCT(SUMIF(caps_data!$B:$B,TRIM(MID(SUBSTITUTE($C8,", ",REPT(" ",100)),(ROW(INDIRECT("1:50"))-1)*100+1,100)),caps_data!AF:AF))} -> 1.4650857 | AH8: {=SUMPRODUCT(SUMIF(caps_data!$B:$B,TRIM(MID(SUBSTITUTE($C8,", ",REPT(" ",100)),(ROW(INDIRECT("1:50"))-1)*100+1,100)),caps_data!AG:AG))} -> 5.6562457 | AI8: {=SUMPRODUCT(SUMIF(caps_data!$B:$B,TRIM(MID(SUBSTITUTE($C8,", ",REPT(" ",100)),(ROW(INDIRECT("1:50"))-1)*100+1,100)),caps_data!AH:AH))} -> 1.9897582
A9: RSD_BLD-DET-HP | B9: Heat Pumps | C9: R-SH_Det_ELC_HPN2-AB, R-SH_Det_ELC_HPN2-C, R-SH_Det_ELC_HPN2-D, R-SH_Det_ELC_HPN2-E, R-SH_Det_ELC_HPN2-F, R-SH_Det_ELC_HPN2-G, R-SH_Det_ELC_HPN3-AB, R-SH_Det_ELC_HPN3-C, R-SH_Det_ELC_HPN3-D, R-SH_Det_ELC_HPN3-E, R-SH_Det_ELC_HPN3-F, R-SH_Det_ELC_HPN3-G, R-SW_Det_ELC_HPN1-AB, R-SW_Det_ELC_HPN1-C, R-SW_Det_ELC_HPN1-D, R-SW_Det_ELC_HPN1-E, R-SW_Det_ELC_HPN1-F, R-SW_Det_ELC_HPN1-G, R-SW_Det_ELC_HPN2-AB, R-SW_Det_ELC_HPN2-C, R-SW_Det_ELC_HPN2-D, R-SW_Det_ELC_HPN2-E, R-SW_Det_ELC_HPN2-F, R-SW_Det_ELC_HPN2-G, R-SW_Det_GAS_HHPN1, R-SW_Det_GAS_HPN1 | D9: {=SUMPRODUCT(SUMIF(caps_data!$B:$B,TRIM(MID(SUBSTITUTE($C9,", ",REPT(" ",100)),(ROW(INDIRECT("1:50"))-1)*100+1,100)),caps_data!C:C))} -> 32.079368 | E9: {=SUMPRODUCT(SUMIF(caps_data!$B:$B,TRIM(MID(SUBSTITUTE($C9,", ",REPT(" ",100)),(ROW(INDIRECT("1:50"))-1)*100+1,100)),caps_data!D:D))} -> 42.424052 | F9: {=SUMPRODUCT(SUMIF(caps_data!$B:$B,TRIM(MID(SUBSTITUTE($C9,", ",REPT(" ",100)),(ROW(INDIRECT("1:50"))-1)*100+1,100)),caps_data!E:E))} -> 41.337958 | G9: {=SUMPRODUCT(SUMIF(caps_data!$B:$B,TRIM(MID(SUBSTITUTE($C9,", ",REPT(" ",100)),(ROW(INDIRECT("1:50"))-1)*100+1,100)),caps_data!F:F))} -> 41.860193 | H9: {=SUMPRODUCT(SUMIF(caps_data!$B:$B,TRIM(MID(SUBSTITUTE($C9,", ",REPT(" ",100)),(ROW(INDIRECT("1:50"))-1)*100+1,100)),caps_data!G:G))} -> 42.491091 | I9: {=SUMPRODUCT(SUMIF(caps_data!$B:$B,TRIM(MID(SUBSTITUTE($C9,", ",REPT(" ",100)),(ROW(INDIRECT("1:50"))-1)*100+1,100)),caps_data!H:H))} -> 42.85694 | J9: {=SUMPRODUCT(SUMIF(caps_data!$B:$B,TRIM(MID(SUBSTITUTE($C9,", ",REPT(" ",100)),(ROW(INDIRECT("1:50"))-1)*100+1,100)),caps_data!I:I))} -> 42.836404 | K9: {=SUMPRODUCT(SUMIF(caps_data!$B:$B,TRIM(MID(SUBSTITUTE($C9,", ",REPT(" ",100)),(ROW(INDIRECT("1:50"))-1)*100+1,100)),caps_data!J:J))} -> 43.332715 | L9: {=SUMPRODUCT(SUMIF(caps_data!$B:$B,TRIM(MID(SUBSTITUTE($C9,", ",REPT(" ",100)),(ROW(INDIRECT("1:50"))-1)*100+1,100)),caps_data!K:K))} -> 43.60472 | M9: {=SUMPRODUCT(SUMIF(caps_data!$B:$B,TRIM(MID(SUBSTITUTE($C9,", ",REPT(" ",100)),(ROW(INDIRECT("1:50"))-1)*100+1,100)),caps_data!L:L))} -> 41.803296 | N9: {=SUMPRODUCT(SUMIF(caps_data!$B:$B,TRIM(MID(SUBSTITUTE($C9,", ",REPT(" ",100)),(ROW(INDIRECT("1:50"))-1)*100+1,100)),caps_data!M:M))} -> 36.774871 | O9: {=SUMPRODUCT(SUMIF(caps_data!$B:$B,TRIM(MID(SUBSTITUTE($C9,", ",REPT(" ",100)),(ROW(INDIRECT("1:50"))-1)*100+1,100)),caps_data!N:N))} -> 36.645657 | P9: {=SUMPRODUCT(SUMIF(caps_data!$B:$B,TRIM(MID(SUBSTITUTE($C9,", ",REPT(" ",100)),(ROW(INDIRECT("1:50"))-1)*100+1,100)),caps_data!O:O))} -> 30.802555 | Q9: {=SUMPRODUCT(SUMIF(caps_data!$B:$B,TRIM(MID(SUBSTITUTE($C9,", ",REPT(" ",100)),(ROW(INDIRECT("1:50"))-1)*100+1,100)),caps_data!P:P))} -> 33.834227 | R9: {=SUMPRODUCT(SUMIF(caps_data!$B:$B,TRIM(MID(SUBSTITUTE($C9,", ",REPT(" ",100)),(ROW(INDIRECT("1:50"))-1)*100+1,100)),caps_data!Q:Q))} -> 34.060836 | S9: {=SUMPRODUCT(SUMIF(caps_data!$B:$B,TRIM(MID(SUBSTITUTE($C9,", ",REPT(" ",100)),(ROW(INDIRECT("1:50"))-1)*100+1,100)),caps_data!R:R))} -> 40.535006 | T9: {=SUMPRODUCT(SUMIF(caps_data!$B:$B,TRIM(MID(SUBSTITUTE($C9,", ",REPT(" ",100)),(ROW(INDIRECT("1:50"))-1)*100+1,100)),caps_data!S:S))} -> 13.811183 | U9: {=SUMPRODUCT(SUMIF(caps_data!$B:$B,TRIM(MID(SUBSTITUTE($C9,", ",REPT(" ",100)),(ROW(INDIRECT("1:50"))-1)*100+1,100)),caps_data!T:T))} -> 0.16414233 | V9: {=SUMPRODUCT(SUMIF(caps_data!$B:$B,TRIM(MID(SUBSTITUTE($C9,", ",REPT(" ",100)),(ROW(INDIRECT("1:50"))-1)*100+1,100)),caps_data!U:U))} -> 0.15744705 | W9: {=SUMPRODUCT(SUMIF(caps_data!$B:$B,TRIM(MID(SUBSTITUTE($C9,", ",REPT(" ",100)),(ROW(INDIRECT("1:50"))-1)*100+1,100)),caps_data!V:V))} -> 0.14754486 | X9: {=SUMPRODUCT(SUMIF(caps_data!$B:$B,TRIM(MID(SUBSTITUTE($C9,", ",REPT(" ",100)),(ROW(INDIRECT("1:50"))-1)*100+1,100)),caps_data!W:W))} -> 30.00265 | Y9: {=SUMPRODUCT(SUMIF(caps_data!$B:$B,TRIM(MID(SUBSTITUTE($C9,", ",REPT(" ",100)),(ROW(INDIRECT("1:50"))-1)*100+1,100)),caps_data!X:X))} -> 41.120152 | Z9: {=SUMPRODUCT(SUMIF(caps_data!$B:$B,TRIM(MID(SUBSTITUTE($C9,", ",REPT(" ",100)),(ROW(INDIRECT("1:50"))-1)*100+1,100)),caps_data!Y:Y))} -> 39.639707 | AA9: {=SUMPRODUCT(SUMIF(caps_data!$B:$B,TRIM(MID(SUBSTITUTE($C9,", ",REPT(" ",100)),(ROW(INDIRECT("1:50"))-1)*100+1,100)),caps_data!Z:Z))} -> 40.16052 | AB9: {=SUMPRODUCT(SUMIF(caps_data!$B:$B,TRIM(MID(SUBSTITUTE($C9,", ",REPT(" ",100)),(ROW(INDIRECT("1:50"))-1)*100+1,100)),caps_data!AA:AA))} -> 40.839335 | AC9: {=SUMPRODUCT(SUMIF(caps_data!$B:$B,TRIM(MID(SUBSTITUTE($C9,", ",REPT(" ",100)),(ROW(INDIRECT("1:50"))-1)*100+1,100)),caps_data!AB:AB))} -> 41.283815 | AD9: {=SUMPRODUCT(SUMIF(caps_data!$B:$B,TRIM(MID(SUBSTITUTE($C9,", ",REPT(" ",100)),(ROW(INDIRECT("1:50"))-1)*100+1,100)),caps_data!AC:AC))} -> 41.247639 | AE9: {=SUMPRODUCT(SUMIF(caps_data!$B:$B,TRIM(MID(SUBSTITUTE($C9,", ",REPT(" ",100)),(ROW(INDIRECT("1:50"))-1)*100+1,100)),caps_data!AD:AD))} -> 41.367349 | AF9: {=SUMPRODUCT(SUMIF(caps_data!$B:$B,TRIM(MID(SUBSTITUTE($C9,", ",REPT(" ",100)),(ROW(INDIRECT("1:50"))-1)*100+1,100)),caps_data!AE:AE))} -> 41.622692 | AG9: {=SUMPRODUCT(SUMIF(caps_data!$B:$B,TRIM(MID(SUBSTITUTE($C9,", ",REPT(" ",100)),(ROW(INDIRECT("1:50"))-1)*100+1,100)),caps_data!AF:AF))} -> 39.804133 | AH9: {=SUMPRODUCT(SUMIF(caps_data!$B:$B,TRIM(MID(SUBSTITUTE($C9,", ",REPT(" ",100)),(ROW(INDIRECT("1:50"))-1)*100+1,100)),caps_data!AG:AG))} -> 34.526476 | AI9: {=SUMPRODUCT(SUMIF(caps_data!$B:$B,TRIM(MID(SUBSTITUTE($C9,", ",REPT(" ",100)),(ROW(INDIRECT("1:50"))-1)*100+1,100)),caps_data!AH:AH))} -> 34.375212
N13: Coefficient | O13: 0.98
B17: UC_N | C17: Pset_Set | D17: Pset_PN | E17: Pset_CI | F17: Pset_CO | G17: Cset_CN | H17: Attribute | I17: Year | J17: LimType | K17: UC_NCAP | L17: UC_FLO | M17: AllRegions | N17: UC_RHSRT~0 | O17: UC_Desc | P17: 2022 | Q17: 2023 | R17: 2024 | S17: 2025 | T17: 2026 | U17: 2027 | V17: 2028 | W17: 2029 | X17: 2030 | Y17: 2031 | Z17: 2032 | AA17: 2033 | AB17: 2034 | AC17: 2035 | AD17: 2036 | AE17: 2037 | AF17: 2038 | AG17: 2039 | AH17: 2040 | AI17: 2041 | AJ17: 2042 | AK17: 2043 | AL17: 2044 | AM17: 2045 | AN17: 2046 | AO17: 2047 | AP17: 2048 | AQ17: 2049 | AR17: 2050
B18: =+A3 -> RSD-SHALLOW | D18: =+C3 -> R-RTFT-Apt_B3, R-RTFT-Apt_C, R-RTFT-Apt_D, R-RTFT-Att_B3, R-RTFT-Att_C, R-RTFT-Att_D, R-RTFT-Det_B3, R-RTFT-Det_C, R-RTFT-Det_D | J18: FX | K18: 1 | N18: 5 | P18: {=+SUM(D3:G3*$O$13)} -> 13.669525 | Q18: =+H3*$O$13 -> 0 | R18: =+I3*$O$13 -> 0 | S18: =+J3*$O$13 -> 0 | T18: =+K3*$O$13 -> 0 | U18: =+L3*$O$13 -> 0 | V18: =+M3*$O$13 -> 0 | W18: =+N3*$O$13 -> 0 | X18: =+O3*$O$13 -> 0 | ... AR18: =+AI3*$O$13 -> 2.3877053
B19: =+A4 -> RSD-DEEP | D19: =+C4 -> R-RTFT-Apt_E, R-RTFT-Apt_F, R-RTFT-Apt_G, R-RTFT-Att_E, R-RTFT-Att_F, R-RTFT-Att_G, R-RTFT-Det_E, R-RTFT-Det_F, R-RTFT-Det_G | J19: FX | K19: 1 | N19: 5 | P19: {=+SUM(D4:G4*$O$13)/2} -> 32.777953 | Q19: =P19 -> 32.777953 | R19: =+I4*$O$13 -> 0 | S19: =+J4*$O$13 -> 7.1022244 | T19: =+K4*$O$13 -> 21.917662 | U19: =+L4*$O$13 -> 7.2442794 | V19: =+M4*$O$13 -> 3.0506433 | W19: =+N4*$O$13 -> 3.0506433 | X19: =+O4*$O$13 -> 0.68323515 | Y19: =+P4*$O$13 -> 0 | ... AR19: =+AI4*$O$13 -> 0
B20: =+A5 -> RSD-APT-HP | D20: =+C5 -> R-HC_Apt_ELC_HPN1, R-HC_Apt_ELC_HPN2-AB, R-HC_Apt_ELC_HPN2-C, R-HC_Apt_ELC_HPN2-D, R-HC_Apt_ELC_HPN2-E, R-HC_Apt_ELC_HPN2-F, R-HC_Apt_ELC_HPN2-G, R-SH_Apt_ELC_HPN1, R-SH_Apt_ELC_HPN2-AB, R-SH_Apt_ELC_HPN2-C, R-SH_Apt_ELC_HPN2-D, R-SH_Apt_ELC_HPN2-E, R-SH_Apt_ELC_HPN2-F, R-SH_Apt_ELC_HPN2-G, R-SH_Apt_ELC_HPN3-AB, R-SH_Apt_ELC_HPN3-C, R-SH_Apt_ELC_HPN3-D, R-SH_Apt_ELC_HPN3-E, R-SH_Apt_ELC_HPN3-F, R-SH_Apt_ELC_HPN3-G, R-SW_Apt_ELC_HPN1-AB, R-SW_Apt_ELC_HPN1-C, R-SW_Apt_ELC_HPN1-D, R-SW_Apt_ELC_HPN1-E, R-SW_Apt_ELC_HPN1-F, R-SW_Apt_ELC_HPN1-G, R-SW_Apt_GAS_HHPN1, R-SW_Apt_GAS_HPN1, R-SW_Apt_GAS_HPN2 | J20: FX | K20: 1 | N20: 5 | T20: =+K5*$O$13 -> 16.774075 | U20: =+L5*$O$13 -> 0.099204134 | V20: =+M5*$O$13 -> 0.095316485 | W20: =+N5*$O$13 -> 0.089997079 | X20: =+O5*$O$13 -> 0.084698998 | Y20: =+P5*$O$13 -> 0.003972456 | Z20: =+Q5*$O$13 -> 0.31583438 | AA20: =+R5*$O$13 -> 0.13306814 | ... AR20: =+AI5*$O$13 -> 0.23199855
B21: =+A6 -> RSD-BIOGAS | D21: =+C6 -> R-SH_Apt_GAS_N1,R-SH_Att_GAS_N1,R-SH_Det_GAS_N1,R-SW_Apt_GAS_HHPN1,R-SW_Apt_GAS_HPN1,R-SW_Apt_GAS_HPN2,R-SW_Apt_GAS_N1,R-SW_Att_GAS_HHPN1,R-SW_Att_GAS_HPN1,R-SW_Att_GAS_HPN2,R-SW_Att_GAS_N1,R-SW_Att_GAS_N2,R-SW_Att_GAS_N3,R-SW_Det_GAS_HHPN1,R-SW_Det_GAS_HPN1,R-SW_Det_GAS_HPN2,R-SW_Det_GAS_N1,R-SW_Det_GAS_N2,R-SW_Det_GAS_N3 | J21: FX | K21: 1 | N21: 5 | T21: =+K6*$O$13 -> 0 | U21: =+L6*$O$13 -> 0 | V21: =+M6*$O$13 -> 0 | W21: =+N6*$O$13 -> 0 | X21: =+O6*$O$13 -> 0 | Y21: =+P6*$O$13 -> 0 | Z21: =+Q6*$O$13 -> 0 | AA21: =+R6*$O$13 -> 0 | ... AR21: =+AI6*$O$13 -> 0
B22: =+A7 -> RSD-ATT-HP | D22: =+C7 -> R-HC_Att_ELC_HPN1, R-HC_Att_ELC_HPN2-AB, R-HC_Att_ELC_HPN2-C, R-HC_Att_ELC_HPN2-D, R-HC_Att_ELC_HPN2-E, R-HC_Att_ELC_HPN2-F, R-HC_Att_ELC_HPN2-G, R-SH_Att_ELC_HPN1, R-SH_Att_ELC_HPN2-AB, R-SH_Att_ELC_HPN2-C, R-SH_Att_ELC_HPN2-D, R-SH_Att_ELC_HPN2-E, R-SH_Att_ELC_HPN2-F, R-SH_Att_ELC_HPN2-G, R-SH_Att_ELC_HPN3-AB, R-SH_Att_ELC_HPN3-C, R-SH_Att_ELC_HPN3-D, R-SH_Att_ELC_HPN3-E, R-SH_Att_ELC_HPN3-F, R-SH_Att_ELC_HPN3-G, R-SW_Att_ELC_HPN1-AB, R-SW_Att_ELC_HPN1-C, R-SW_Att_ELC_HPN1-D, R-SW_Att_ELC_HPN1-E, R-SW_Att_ELC_HPN1-F, R-SW_Att_ELC_HPN1-G, R-SW_Att_ELC_HPN2-AB, R-SW_Att_ELC_HPN2-C, R-SW_Att_ELC_HPN2-D, R-SW_Att_ELC_HPN2-E, R-SW_Att_ELC_HPN2-F, R-SW_Att_ELC_HPN2-G, R-SW_Att_GAS_HHPN1, R-SW_Att_GAS_HPN1, R-SW_Att_GAS_HPN2 | J22: FX | K22: 1 | N22: 5 | P22: =+G7*$O$13 -> 47.213008 | Q22: =+H7*$O$13 -> 46.30895 | R22: =+I7*$O$13 -> 35.614398 | S22: =+J7*$O$13 -> 33.321199 | T22: =+K7*$O$13 -> 19.435703 | U22: =+L7*$O$13 -> 0.57096155 | V22: =+M7*$O$13 -> 0.61166956 | W22: =+N7*$O$13 -> 0.62049544 | ... AR22: =+AI7*$O$13 -> 0.9368303
B23: =+A8 -> RSD-DH | D23: R-SW_Apt_HET_N1, R-SW_Apt_HET_N2, R-SW_Att_HET_N1, R-SW_Att_HET_N2, R-SW_Det_HET_N1, R-SW_Det_HET_N2 | J23: FX | K23: 1 | N23: 5 | P23: =+G8*$O$13 -> 0 | Q23: =+H8*$O$13 -> 0.3036143 | R23: =+I8*$O$13 -> 3.5018298 | S23: =+J8*$O$13 -> 1.4064685 | T23: =+K8*$O$13 -> 0 | U23: =+L8*$O$13 -> 0.87531243 | V23: =+M8*$O$13 -> 0.70776757 | W23: =+N8*$O$13 -> 4.8232406 | ... AR23: =+AI8*$O$13 -> 1.949963
B24: =+A9 -> RSD_BLD-DET-HP | D24: R-SH_Det_ELC_HPN2-AB, R-SH_Det_ELC_HPN2-C, R-SH_Det_ELC_HPN2-D, R-SH_Det_ELC_HPN2-E, R-SH_Det_ELC_HPN2-F, R-SH_Det_ELC_HPN2-G, R-SH_Det_ELC_HPN3-AB, R-SH_Det_ELC_HPN3-C, R-SH_Det_ELC_HPN3-D, R-SH_Det_ELC_HPN3-E, R-SH_Det_ELC_HPN3-F, R-SH_Det_ELC_HPN3-G, R-SW_Det_ELC_HPN1-AB, R-SW_Det_ELC_HPN1-C, R-SW_Det_ELC_HPN1-D, R-SW_Det_ELC_HPN1-E, R-SW_Det_ELC_HPN1-F, R-SW_Det_ELC_HPN1-G, R-SW_Det_ELC_HPN2-AB, R-SW_Det_ELC_HPN2-C, R-SW_Det_ELC_HPN2-D, R-SW_Det_ELC_HPN2-E, R-SW_Det_ELC_HPN2-F, R-SW_Det_ELC_HPN2-G, R-SW_Det_GAS_HHPN1, R-SW_Det_GAS_HPN1 | J24: FX | K24: 1 | N24: 5 | P24: =+G9 -> 41.860193 | Q24: =+H9 -> 42.491091 | R24: =+I9 -> 42.85694 | S24: =+J9 -> 42.836404 | T24: =+K9 -> 43.332715 | U24: =+L9 -> 43.60472 | V24: =+M9 -> 41.803296 | W24: =+N9 -> 36.774871 | ... AR24: =+AI9 -> 34.375212
C27: WAM NEP25 | E27: Units | F27: 2018 | G27: 2019 | H27: 2020 | I27: 2021 | J27: 2022 | K27: 2023 | L27: 2024 | M27: 2025 | N27: 2026 | O27: 2027 | P27: 2028 | Q27: 2029 | R27: 2030 | S27: 2031 | T27: 2032 | U27: 2033 | V27: 2034 | W27: 2035 | X27: 2036 | Y27: 2037 | Z27: 2038 | AA27: 2039 | AB27: 2040 | AC27: 2041 | AD27: 2042 | AE27: 2043 | AF27: 2044 | AG27: 2045 | AH27: 2046 | AI27: 2047 | AJ27: 2048 | AK27: 2049 | AL27: 2050
C28: BEVs | E28: # vehicles | F28: 4528 | G28: 8473 | H28: 12576 | I28: 21085 | J28: 36002 | K28: 57730 | L28: 76458.133 | M28: 101504.6 | N28: 131806.53 | O28: 168374.63 | P28: 212769.94 | Q28: 266253.76 | R28: 330739.76 | S28: 402894.63 | T28: 483270.39 | U28: 572769.39 | V28: 671364.77 | W28: 803011.77 | X28: 934123.03 | Y28: 1062667.6 | Z28: 1188757.2 | AA28: 1327958.6 | AB28: 1470126.2
C29: PHEVs | E29: # vehicles | F29: 2791 | G29: 6306 | H29: 12228 | I29: 23671 | J29: 33157 | K29: 46227 | L29: 65580.1 | M29: 88429.862 | N29: 115259.45 | O29: 146809.33 | P29: 183964.44 | Q29: 227783.37 | R29: 279411.37 | S29: 332264.2 | T29: 387049.06 | U29: 443151.33 | V29: 501364.83 | W29: 533242.83 | X29: 553528.33 | Y29: 569779.54 | Z29: 578052.05 | AA29: 577462.84 | AB29: 570363.07
C30: Electric Buses | E30: # vehicles | K30: 61 | L30: 282 | M30: 282 | N30: 282 | O30: 282 | P30: 282 | Q30: 282 | R30: 282 | S30: 282 | T30: 282 | U30: 282 | V30: 282 | W30: 282 | X30: 282 | Y30: 282 | Z30: 282 | AA30: 282 | AB30: 282
C31: PHEV LGV | E31: # vehicles | F31: 10 | G31: 57 | H31: 103 | I31: 208 | J31: 379 | K31: 675 | L31: 937.5 | M31: 1200 | N31: 2160 | O31: 3120 | P31: 4080 | Q31: 5040 | R31: 6000 | S31: 7800 | T31: 9600 | U31: 11400 | V31: 13200 | W31: 15000 | X31: 14000 | Y31: 13000 | Z31: 12000 | AA31: 11000 | AB31: 10000
C32: Battery Electric Trucks (LGV + HGV) | E32: # vehicles | F32: 167 | G32: 454 | H32: 878 | I32: 1770 | J32: 2135 | K32: 2856 | L32: 3926.2143 | M32: 4996.4286 | N32: 8917.1429 | O32: 12837.857 | P32: 16758.571 | Q32: 20679.286 | R32: 24600 | S32: 29090 | T32: 33580 | U32: 38070 | V32: 42560 | W32: 47050 | X32: 69184.875 | Y32: 91319.749 | Z32: 113454.62 | AA32: 135589.5 | AB32: 157724.37
C33: LGV | E33: # vehicles | F33: 167 | G33: 454 | H33: 878 | I33: 1770 | J33: 2135 | K33: 2821 | L33: 3810.5 | M33: 4800 | N33: 8640 | O33: 12480 | P33: 16320 | Q33: 20160 | R33: 24000 | S33: 28200 | T33: 32400 | U33: 36600 | V33: 40800 | W33: 45000 | X33: 66844.875 | Y33: 88689.749 | Z33: 110534.62 | AA33: 132379.5 | AB33: 154224.37
C34: HGV | E34: # vehicles | F34: 0 | G34: 0 | H34: 0 | I34: 0 | J34: 0 | K34: 35 | L34: 115.71429 | M34: 196.42857 | N34: 277.14286 | O34: 357.85714 | P34: 438.57143 | Q34: 519.28571 | R34: 600 | S34: 890 | T34: 1180 | U34: 1470 | V34: 1760 | W34: 2050 | X34: 2340 | Y34: 2630 | Z34: 2920 | AA34: 3210 | AB34: 3500
C35: Onshore wind | E35: MW | L35: 4740.55 | M35: 5044.2812 | N35: 5540.25 | O35: 5865.5 | P35: 6207.875 | Q35: 6579.75 | R35: 6930.625 | S35: 7281.125 | T35: 7685.25 | U35: 8093.125 | V35: 8507.5 | W35: 8927.125 | X35: 9282 | Y35: 9591.5 | Z35: 9953.25 | AA35: 10242.5 | AB35: 10550.5
C36: Offshore wind | E36: MW | L36: 25 | M36: 25 | N36: 25 | O36: 25 | P36: 25 | Q36: 231.25 | R36: 1525 | S36: 2862.5 | T36: 3500 | U36: 4000 | V36: 4500 | W36: 5175 | X36: 5875 | Y36: 6575 | Z36: 7350 | AA36: 8350 | AB36: 9325
C37: Solar | E37: MW | L37: 914.9375 | M37: 1680.75 | N37: 2789.75 | O37: 3543.375 | P37: 4296.75 | Q37: 5050.375 | R37: 5805.25 | S37: 6505.5 | T37: 7105.375 | U37: 7695.375 | V37: 8277.75 | W37: 8857.625 | X37: 9402.375 | Y37: 9880 | Z37: 10349.75 | AA37: 10812.75 | AB37: 11268.5
C38: Biofuel Blending Ethanol (transport) | E38: % share | M38: 10 | N38: 10 | O38: 10 | P38: 10 | Q38: 10 | R38: 10 | S38: 10 | T38: 10 | U38: 10 | V38: 10 | W38: 10 | X38: 10 | Y38: 10 | Z38: 10 | AA38: 10 | AB38: 10
C39: Biofuel Blending Biodiesel (transport) | E39: % share | M39: 12 | N39: 13.6 | O39: 15.2 | P39: 16.8 | Q39: 18.4 | R39: 20 | S39: 20 | T39: 20 | U39: 20 | V39: 20 | W39: 20 | X39: 20 | Y39: 20 | Z39: 20 | AA39: 20 | AB39: 20
C40: Biomethane | E40: TWh | M40: 0.25 | N40: 0.45 | O40: 0.8 | P40: 1.45 | Q40: 2.6 | R40: 4.3 | S40: 5.7 | T40: 5.7 | U40: 5.7 | V40: 5.7 | W40: 5.7 | X40: 5.7 | Y40: 5.7 | Z40: 5.7 | AA40: 5.7 | AB40: 5.7
C41: Retrofits | D41: For projected years we have provided here the number of dwellings that undertake energy efficiency measures that bring the dwelling from a BER worse than B2 to one of B2 or better, excluding solar PV. This may not align exactly with the wording of the CAP target of "B2 cost optimal or carbon equivalent". For 2024 we include an estimate of the cumulative number of dwellings that have undergone upgrade works from 2018-2024 that improved their BER rating to B2 or better through SEAI schemes or Local Authority schemes, excluding solar PV only upgrades. | E41: # Homes B2 (total) | L41: 30290 | M41: 10808 | N41: 25024.6 | O41: 39241.2 | P41: 53457.8 | Q41: 67674.4 | R41: 81891 | S41: 100657.8 | T41: 119424.6 | U41: 138191.4 | V41: 156958.2 | W41: 175725 | X41: 194491.8 | Y41: 213258.6 | Z41: 232025.4 | AA41: 250792.2 | AB41: 269559
C42: Heat Pumps (Residential) | D42: Assume that this item is for HP retrofits, excluding HP installed in new dwellings. The figure given for 2024 is the total number of HPs installed through SEAI and Local Authority retrofit schemes for 2019-2024. | E42: # Heat Pumps (total) | L42: 22594 | M42: 31445.34 | N42: 53015.01 | O42: 74768.033 | P42: 97085.801 | Q42: 119719.6 | R42: 142350.37 | S42: 165081.94 | T42: 187346.89 | U42: 210029.48 | V42: 232675.83 | W42: 254838.99 | X42: 277005.17 | Y42: 299162.27 | Z42: 321719.29 | AA42: 338758.85 | AB42: 407140.97
C43: District Heating (Residential) | E43: TWh | J43: 0.0009 | K43: 0.0009 | L43: 0.0014 | M43: 0.0014 | N43: 0.0014 | O43: 0.0014 | P43: 0.015754 | Q43: 0.030108 | R43: 0.044462 | S43: 0.0940158 | T43: 0.1435696 | U43: 0.1931234 | V43: 0.2426772 | W43: 0.292231 | X43: 0.3417848 | Y43: 0.3913386 | Z43: 0.4408924 | AA43: 0.4904462 | AB43: 0.54
C44: District Heating (Commercial) | D44: Assume includes public services | E44: TWh | J44: 0.0036 | K44: 0.0036 | L44: 0.0056 | M44: 0.0056 | N44: 0.0056 | O44: 0.0056 | P44: 0.063016 | Q44: 0.120432 | R44: 0.177848 | S44: 0.3760632 | T44: 0.5742784 | U44: 0.7724936 | V44: 0.9707088 | W44: 1.168924 | X44: 1.3671392 | Y44: 1.5653544 | Z44: 1.7635696 | AA44: 1.9617848 | AB44: 2.16
B46: ~UC_Sets: R_E: AllRegions
B47: ~UC_Sets: T_S:
J48: ~UC_T: UC_RHSRT
B49: UC_N | C49: Pset_Set | D49: Pset_PN | E49: Pset_CI | F49: Pset_CO | G49: Cset_CN | H49: Attribute | I49: Year | J49: LimType | K49: UC_CAP | L49: UC_FLO | M49: AllRegions | N49: UC_RHSRT~0 | O49: UC_Desc | P49: 2019 | Q49: 2020 | R49: 2021 | S49: 2022 | T49: 2023 | U49: 2024 | V49: 2025 | W49: 2026 | X49: 2027 | Y49: 2028 | Z49: 2029 | AA49: 2030 | AB49: 2031 | AC49: 2032 | AD49: 2033 | AE49: 2034 | AF49: 2035 | AG49: 2036 | AH49: 2037 | AI49: 2038 | AJ49: 2039 | AK49: 2040 | AL49: 2041 | AM49: 2042 | AN49: 2043 | AO49: 2044 | AP49: 2045 | AQ49: 2046 | AR49: 2047
B50: RSD-SHALLOW | D50: =_xlfn.TEXTJOIN(",",TRUE,D18:D19) -> R-RTFT-Apt_B3, R-RTFT-Apt_C, R-RTFT-Apt_D, R-RTFT-Att_B3, R-RTFT-Att_C, R-RTFT-Att_D, R-RTFT-Det_B3, R-RTFT-Det_C, R-RTFT-Det_D,R-RTFT-Apt_E, R-RTFT-Apt_F, R-RTFT-Apt_G, R-RTFT-Att_E, R-RTFT-Att_F, R-RTFT-Att_G, R-RTFT-Det_E, R-RTFT-Det_F, R-RTFT-Det_G | J50: FX | K50: 1 | N50: 5 | U50: =L41/1000 -> 30.29 | V50: =M41/1000+U50 -> 41.098 | W50: =N41/1000+$V$50 -> 66.1226 | X50: =O41/1000+$V$50 -> 80.3392 | Y50: =P41/1000+$V$50 -> 94.5558 | Z50: =Q41/1000+$V$50 -> 108.7724 | AA50: =R41/1000+$V$50 -> 122.989 | AB50: =S41/1000+$V$50 -> 141.7558 | AC50: =T41/1000+$V$50 -> 160.5226 | AD50: =U41/1000+$V$50 -> 179.2894 | ... AK50: =AB41/1000+$V$50 -> 310.657
...

Sheet caps_data
A1: Sum of Pv | C1: Period
A2: Processset | B2: Process | C2: 2019 | D2: 2020 | E2: 2021 | F2: 2022 | G2: 2023 | H2: 2024 | I2: 2025 | J2: 2026 | K2: 2027 | L2: 2028 | M2: 2029 | N2: 2030 | O2: 2031 | P2: 2032 | Q2: 2033 | R2: 2034 | S2: 2035 | T2: 2036 | U2: 2037 | V2: 2038 | W2: 2039 | X2: 2040 | Y2: 2041 | Z2: 2042 | AA2: 2043 | AB2: 2044 | AC2: 2045 | AD2: 2046 | AE2: 2047 | AF2: 2048 | AG2: 2049 | AH2: 2050 | AI2: 2051
A3: RSD_BLD-APT-GAS | B3: R-SH_Apt_GAS_N1 | C3: 1.7160034e-08 | D3: 3.8102819e-08 | E3: 12.278797 | F3: 19.825402 | G3: 24.044883 | H3: 19.758847 | I3: 1.0218077e-06 | J3: 2.7234303e-07 | K3: 17.689611 | L3: 9.7204249 | M3: 5.7371397e-07 | N3: 3.1707238e-07 | O3: 2.4137496e-07 | P3: 2.2945189e-07 | Q3: 2.2376458e-07 | R3: 2.129197e-07 | S3: 2.3655244e-07 | T3: 1.9900107e-07 | U3: 2.0624173e-07 | V3: 2.1404149e-07 | W3: 2.2503015e-07 | X3: 2.485652e-07 | Y3: 2.3921012e-07 | Z3: 2.4569638e-07 | AA3: 6.5181817e-07 | AB3: 15.748897 | AC3: 24.395097 | AD3: 22.068062 | AE3: 1.9976813 | AF3: 2.1824728 | AG3: 19.5633 | AH3: 12.036995 | AI3: 2.9276262e-07
A4: RSD_BLD-APT-GAS | B4: R-SW_Apt_GAS_HHPN1 | C4: 1.371523e-08 | D4: 1.9185486e-08 | E4: 1.3095955e-07 | F4: 1.6645494e-07 | G4: 1.6787947e-07 | H4: 1.7886392e-07 | I4: 1.8728163e-07 | J4: 1.8952866e-07 | K4: 2.3918148e-07 | L4: 2.6451057e-07 | M4: 2.8001413e-07 | N4: 2.9643338e-07 | O4: 3.1513228e-07 | P4: 3.3732519e-07 | Q4: 3.5222904e-07 | R4: 3.6693381e-07 | S4: 3.8230975e-07 | T4: 3.9889871e-07 | U4: 4.1527781e-07 | V4: 4.318309e-07 | W4: 4.4815633e-07 | X4: 4.6461563e-07 | Y4: 4.7808188e-07 | Z4: 4.93161e-07 | AA4: 5.0840053e-07 | AB4: 5.2358937e-07 | AC4: 5.3977745e-07 | AD4: 5.5647795e-07 | AE4: 5.7232389e-07 | AF4: 5.8767912e-07 | AG4: 6.0516494e-07 | AH4: 6.2108202e-07 | AI4: 6.2344681e-07
A5: RSD_BLD-APT-GAS | B5: R-SW_Apt_GAS_HPN1 | AH5: 1.1842358e-08 | AI5: 1.3872828e-08
A6: RSD_BLD-APT-GAS | B6: R-SW_Apt_GAS_N1 | C6: 1.5262237e-08 | D6: 1.5119179e-08 | E6: 14.819728 | F6: 1.1684581e-07 | G6: 1.5019322e-07 | H6: 1.3247698e-07 | I6: 1.1796547e-07 | J6: 9.4790671e-08 | K6: 3.6271754e-07 | L6: 7.8588961 | M6: 12.991167 | N6: 16.261578 | O6: 27.83524 | P6: 20.397975 | Q6: 20.012236 | R6: 20.15113 | S6: 20.21607 | T6: 20.276701 | U6: 20.453009 | V6: 20.604245 | W6: 39.198115 | X6: 30.463964 | Y6: 3.3906424 | Z6: 23.871186 | AA6: 43.062372 | AB6: 20.148851 | AC6: 16.71263 | AD6: 13.394335 | AE6: 13.697286 | AF6: 13.543874 | AG6: 13.474311 | AH6: 21.242619 | AI6: 26.34532
A7: RSD_BLD-APT-HP | B7: R-SH_Apt_ELC_HPN2-AB | E7: 1.1522513e-08 | F7: 2.7696676e-08 | G7: 5.3280628e-08 | H7: 1.2647152e-07 | I7: 17.874578 | J7: 0.10929543 | K7: 0.1012284 | L7: 0.097261508 | M7: 0.09183359 | N7: 0.08642739 | O7: 0.0040534341 | P7: 0.32227989 | Q7: 0.1357837 | R7: 7.0142981e-07 | S7: 0.0040532407 | T7: 1.8133579e-07 | U7: 1.460284e-07 | V7: 1.2174236e-07 | W7: 1.0302308e-07 | X7: 2.0039927e-07 | Y7: 7.2151308e-08 | Z7: 5.5201909e-08 | AA7: 2.0444511e-07 | AB7: 1.5218447 | AC7: 18.024425 | AD7: 0.25975663 | AE7: 0.25204195 | AF7: 0.2482208 | AG7: 0.24252953 | AH7: 0.23673272 | AI7: 2.3741752e-07
A8: RSD_BLD-APT-HP | B8: R-SH_Apt_ELC_HPN2-C | E8: 1.7445127e-08 | F8: 8.3952821e-08 | G8: 3.015709e-07 | H8: 9.6173418e-07 | I8: 2.913705 | J8: 17.007108 | K8: 2.231818e-07 | L8: 1.1336628e-07 | M8: 7.7988577e-08 | N8: 6.0213781e-08 | O8: 2.0872898e-08 | P8: 2.0392392e-08 | Q8: 1.9437913e-08 | R8: 1.726897e-08 | S8: 1.7114732e-08 | T8: 1.5765633e-08 | U8: 1.5177106e-08 | V8: 1.4582609e-08 | W8: 1.3969929e-08 | X8: 1.4933732e-08 | Y8: 1.4657026e-08 | Z8: 1.6563993e-08 | AA8: 2.5393331e-08 | AB8: 5.1464912e-08 | AC8: 8.6790911e-05 | AD8: 19.164945 | AE8: 1.7015881e-06 | AF8: 2.1302274e-07 | AG8: 1.326945e-07 | AH8: 6.8191494e-08 | AI8: 2.4130222e-08
A9: RSD_BLD-APT-HP | B9: R-SH_Apt_ELC_HPN2-D | E9: 1.0225533e-08 | F9: 2.2538505e-08 | G9: 3.9988665e-08 | H9: 9.8009634e-08 | I9: 0.13569612 | J9: 4.6175139 | K9: 2.4667234 | L9: 2.4651634 | M9: 2.4668795 | N9: 2.4668773 | O9: 2.9729468e-08 | P9: 3.1321754e-08 | Q9: 3.0949552e-08 | R9: 2.8624566e-08 | S9: 3.0530716e-08 | T9: 2.8112015e-08 | U9: 2.8374772e-08 | V9: 2.8642241e-08 | W9: 2.8845195e-08 | X9: 3.4576199e-08 | Y9: 2.8427457e-08 | Z9: 2.7561817e-08 | AA9: 4.4354145e-08 | AB9: 6.3733712e-08 | AC9: 1.0537359e-07 | AD9: 3.2492196e-07 | AE9: 1.0014549e-06 | AF9: 5.7992432e-07 | AG9: 0.36953178 | AH9: 1.1926867e-06 | AI9: 5.3692021e-08
A10: RSD_BLD-APT-HP | B10: R-SH_Apt_ELC_HPN2-E | F10: 1.0710193e-08 | G10: 1.345163e-08 | H10: 1.6704031e-08 | I10: 2.1296103e-08 | J10: 2.2859723e-08 | K10: 2.59562e-08 | L10: 2.9913098e-08 | M10: 3.4821987e-08 | N10: 4.1223326e-08 | O10: 1.9850242e-08 | P10: 2.0939981e-08 | Q10: 2.0808278e-08 | R10: 2.0068167e-08 | S10: 2.1335165e-08 | T10: 2.0513326e-08 | U10: 2.103061e-08 | V10: 2.1585586e-08 | W10: 2.2147391e-08 | X10: 2.5914932e-08 | Y10: 2.2902178e-08 | Z10: 2.240728e-08 | AA10: 3.4174003e-08 | AB10: 4.7475388e-08 | AC10: 4.9397881e-08 | AD10: 5.7179104e-08 | AE10: 6.6650391e-08 | AF10: 6.7317991e-08 | AG10: 8.1006283e-08 | AH10: 8.6238394e-08 | AI10: 3.8617672e-08
A11: RSD_BLD-APT-HP | B11: R-SH_Apt_ELC_HPN2-F | I11: 1.1359694e-08 | J11: 1.1882989e-08 | K11: 1.3735905e-08 | L11: 1.6156637e-08 | M11: 1.9096853e-08 | N11: 2.347261e-08 | O11: 1.6419987e-08 | P11: 1.7530181e-08 | Q11: 1.7722423e-08 | R11: 1.6786789e-08 | S11: 1.7767738e-08 | T11: 1.7312978e-08 | U11: 1.7786548e-08 | V11: 1.8291408e-08 | W11: 1.880657e-08 | X11: 2.1528199e-08 | Y11: 1.9578121e-08 | Z11: 1.9334896e-08 | AA11: 2.7457567e-08 | AB11: 3.5488062e-08 | AC11: 3.6932156e-08 | AD11: 4.1138986e-08 | AE11: 4.7207603e-08 | AF11: 4.8451287e-08 | AG11: 5.6213332e-08 | AH11: 6.1065318e-08 | AI11: 3.4204855e-08
A12: RSD_BLD-APT-HP | B12: R-SH_Apt_ELC_HPN2-G | L12: 1.168545e-08 | M12: 1.3459522e-08 | N12: 1.6072227e-08 | O12: 1.3878942e-08 | P12: 1.4855015e-08 | Q12: 1.5131554e-08 | R12: 1.4928419e-08 | S12: 1.5575309e-08 | T12: 1.4830742e-08 | U12: 1.5272995e-08 | V12: 1.5733524e-08 | W12: 1.6206463e-08 | X12: 1.82511e-08 | Y12: 1.6961868e-08 | Z12: 1.6880549e-08 | AA12: 2.2745665e-08 | AB12: 2.8057876e-08 | AC12: 2.9207249e-08 | AD12: 3.2026327e-08 | AE12: 3.6231745e-08 | AF12: 3.7510482e-08 | AG12: 4.2582126e-08 | AH12: 4.671666e-08 | AI12: 3.0495474e-08
A13: RSD_BLD-APT-HP | B13: R-SH_Apt_ELC_HPN3-AB | O13: 1.0182156e-08 | P13: 1.0679225e-08 | Q13: 1.0983733e-08 | R13: 1.1166793e-08 | S13: 1.1581957e-08 | T13: 1.1649851e-08 | U13: 1.1227766e-08 | V13: 1.1420625e-08 | W13: 1.1601078e-08 | X13: 1.2480939e-08 | Y13: 1.1778627e-08 | Z13: 1.1629223e-08 | AA13: 1.4518917e-08 | AB13: 1.5824996e-08 | AC13: 1.6375749e-08 | AD13: 1.6993924e-08 | AE13: 1.772529e-08 | AF13: 1.8665469e-08 | AG13: 1.9803797e-08 | AH13: 2.2134449e-08 | AI13: 2.5476864e-08
A14: RSD_BLD-APT-HP | B14: R-SH_Apt_ELC_HPN3-C | H14: 1.0068954e-08 | I14: 1.1379499e-08 | J14: 1.2513979e-08 | K14: 1.2377781e-08 | L14: 1.2117708e-08 | M14: 1.1847991e-08 | N14: 1.1553333e-08 | AA14: 1.2006217e-08 | AB14: 1.5310029e-08 | AC14: 1.9783753e-08 | AD14: 2.0581807e-08 | AE14: 2.1322781e-08 | AF14: 2.1112229e-08 | AG14: 2.1223494e-08 | AH14: 2.0470239e-08 | AI14: 1.5361089e-08
A15: RSD_BLD-APT-HP | B15: R-SH_Apt_ELC_HPN3-D | G15: 1.0914336e-08 | H15: 1.4150866e-08 | I15: 1.8507511e-08 | J15: 2.1412077e-08 | K15: 2.0808136e-08 | L15: 1.9888935e-08 | M15: 1.9006392e-08 | N15: 1.8107145e-08 | O15: 1.1149099e-08 | P15: 1.1665645e-08 | Q15: 1.1720101e-08 | R15: 1.1189731e-08 | S15: 1.1564126e-08 | T15: 1.1789667e-08 | U15: 1.2057834e-08 | V15: 1.2332616e-08 | W15: 1.2605671e-08 | X15: 1.3762086e-08 | Y15: 1.2988898e-08 | Z15: 1.2907469e-08 | AA15: 1.663394e-08 | AB15: 1.88243e-08 | AC15: 2.1311723e-08 | AD15: 2.4652708e-08 | AE15: 2.6746815e-08 | AF15: 2.7749608e-08 | AG15: 3.077405e-08 | AH15: 3.3881204e-08 | AI15: 2.5833629e-08
A16: RSD_BLD-APT-HP | B16: R-SH_Apt_ELC_HPN3-E | AA16: 1.0337097e-08 | AB16: 1.1487293e-08 | AC16: 1.1918934e-08 | AD16: 1.2619952e-08 | AE16: 1.3452823e-08 | AF16: 1.4800347e-08 | AG16: 1.6156022e-08 | AH16: 1.7587627e-08 | AI16: 1.6931259e-08
A17: RSD_BLD-APT-HP | B17: R-SH_Apt_ELC_HPN3-F | AB17: 1.0741922e-08 | AC17: 1.1151354e-08 | AD17: 1.1797137e-08 | AE17: 1.2565283e-08 | AF17: 1.3886794e-08 | AG17: 1.5138234e-08 | AH17: 1.6465629e-08 | AI17: 1.6127094e-08
A18: RSD_BLD-APT-HP | B18: R-SH_Apt_ELC_HPN3-G | AB18: 1.0046543e-08 | AC18: 1.0435773e-08 | AD18: 1.1032284e-08 | AE18: 1.1741761e-08 | AF18: 1.3037324e-08 | AG18: 1.4194962e-08 | AH18: 1.5423031e-08 | AI18: 1.5350819e-08
A19: RSD_BLD-APT-HP | B19: R-SW_Apt_ELC_HPN1-AB | E19: 3.3217029e-08 | F19: 1.913798 | K19: 1.0809348e-08 | L19: 1.0148555e-08 | Q19: 1.0181185e-08 | R19: 1.0755831e-08 | S19: 1.1354486e-08 | T19: 1.1922199e-08 | U19: 1.2589213e-08 | V19: 1.3328767e-08 | W19: 1.4074965e-08 | X19: 1.5768651e-08 | Y19: 1.6136458e-08 | Z19: 1.6646515e-08 | AA19: 1.7146538e-08 | AB19: 1.762887e-08 | AC19: 1.82441e-08 | AD19: 1.8957429e-08 | AE19: 1.9709796e-08 | AF19: 2.064242e-08 | AG19: 2.1220756e-08 | AH19: 2.3055092e-08 | AI19: 2.8556411e-08
A20: RSD_BLD-APT-HP | B20: R-SW_Apt_ELC_HPN1-C | E20: 3.3272787e-08 | F20: 1.9098509 | K20: 1.0588206e-08 | R20: 1.0502884e-08 | S20: 1.0963024e-08 | T20: 1.159206e-08 | U20: 1.2211582e-08 | V20: 1.2895831e-08 | W20: 1.3576491e-08 | X20: 1.5184876e-08 | Y20: 1.5596869e-08 | Z20: 1.6247211e-08 | AA20: 1.6904528e-08 | AB20: 1.7611255e-08 | AC20: 1.8462013e-08 | AD20: 1.9182998e-08 | AE20: 1.9934684e-08 | AF20: 2.0804588e-08 | AG20: 2.0541392e-08 | AH20: 2.2933682e-08 | AI20: 2.7281446e-08
A21: RSD_BLD-APT-HP | B21: R-SW_Apt_ELC_HPN1-D | E21: 3.3442791e-08 | F21: 1.8922512 | K21: 1.088797e-08 | L21: 1.0231433e-08 | Q21: 1.0241856e-08 | R21: 1.0703915e-08 | S21: 1.1303928e-08 | T21: 1.198249e-08 | U21: 1.2658221e-08 | V21: 1.3407686e-08 | W21: 1.4166044e-08 | X21: 1.5876528e-08 | Y21: 1.6257353e-08 | Z21: 1.6784796e-08 | AA21: 1.7306959e-08 | AB21: 1.7818335e-08 | AC21: 1.8519903e-08 | AD21: 1.9332393e-08 | AE21: 2.0126469e-08 | AF21: 1.9894059e-08 | AG21: 2.0903147e-08 | AH21: 2.3519162e-08 | AI21: 2.8583703e-08
A22: RSD_BLD-APT-HP | B22: R-SW_Apt_ELC_HPN1-E | F22: 1.0230291e-08 | X22: 1.0995252e-08 | Y22: 1.1294741e-08 | Z22: 1.1706369e-08 | AA22: 1.2106254e-08 | AB22: 1.2507718e-08 | AC22: 1.2968934e-08 | AD22: 1.351306e-08 | AE22: 1.4102348e-08 | AF22: 1.4904933e-08 | AG22: 1.4457213e-08 | AH22: 1.6554916e-08 | AI22: 2.0517308e-08
A23: RSD_BLD-APT-HP | B23: R-SW_Apt_ELC_HPN1-F | X23: 1.0279113e-08 | Y23: 1.0548419e-08 | Z23: 1.0918661e-08 | AA23: 1.1320732e-08 | AB23: 1.1728384e-08 | AC23: 1.2197475e-08 | AD23: 1.2752537e-08 | AE23: 1.3362269e-08 | AF23: 1.4093908e-08 | AG23: 1.3716583e-08 | AH23: 1.5850559e-08 | AI23: 1.9882559e-08
A24: RSD_BLD-APT-HP | B24: R-SW_Apt_ELC_HPN1-G | Y24: 1.0148622e-08 | Z24: 1.0508458e-08 | AA24: 1.0899746e-08 | AB24: 1.1297482e-08 | AC24: 1.1754515e-08 | AD24: 1.2294628e-08 | AE24: 1.288977e-08 | AF24: 1.3604944e-08 | AG24: 1.3943492e-08 | AH24: 1.5305768e-08 | AI24: 2.1258454e-08
A25: RSD_BLD-APT-HP | B25: R-SW_Apt_GAS_HHPN1 | C25: 1.371523e-08 | D25: 1.9185486e-08 | E25: 1.3095955e-07 | F25: 1.6645494e-07 | G25: 1.6787947e-07 | H25: 1.7886392e-07 | I25: 1.8728163e-07 | J25: 1.8952866e-07 | K25: 2.3918148e-07 | L25: 2.6451057e-07 | M25: 2.8001413e-07 | N25: 2.9643338e-07 | O25: 3.1513228e-07 | P25: 3.3732519e-07 | Q25: 3.5222904e-07 | R25: 3.6693381e-07 | S25: 3.8230975e-07 | T25: 3.9889871e-07 | U25: 4.1527781e-07 | V25: 4.318309e-07 | W25: 4.4815633e-07 | X25: 4.6461563e-07 | Y25: 4.7808188e-07 | Z25: 4.93161e-07 | AA25: 5.0840053e-07 | AB25: 5.2358937e-07 | AC25: 5.3977745e-07 | AD25: 5.5647795e-07 | AE25: 5.7232389e-07 | AF25: 5.8767912e-07 | AG25: 6.0516494e-07 | AH25: 6.2108202e-07 | AI25: 6.2344681e-07
A26: RSD_BLD-APT-HP | B26: R-SW_Apt_GAS_HPN1 | AH26: 1.1842358e-08 | AI26: 1.3872828e-08
A27: RSD_BLD-APT-OTH | B27: R-SH_Apt_KER_N1 | C27: 1.3145019e-08 | D27: 0.0040533675 | E27: 2.7803365e-08 | F27: 4.1719015e-08 | G27: 3.0617006e-08 | H27: 2.9260065e-08 | I27: 2.8622428e-08 | J27: 2.4715088e-08 | K27: 3.1906566e-08 | L27: 3.3166468e-08 | M27: 2.9599881e-08 | N27: 2.7511602e-08 | O27: 2.660512e-08 | P27: 2.7229718e-08 | Q27: 2.7138248e-08 | R27: 2.6809633e-08 | S27: 2.7931818e-08 | T27: 2.6279704e-08 | U27: 2.6580023e-08 | V27: 2.6865507e-08 | W27: 2.7194112e-08 | X27: 2.8091333e-08 | Y27: 2.7977668e-08 | Z27: 2.8530019e-08 | AA27: 3.8587702e-08 | AB27: 5.0696482e-08 | AC27: 5.2450165e-08 | AD27: 5.4492318e-08 | AE27: 5.6918171e-08 | AF27: 6.0160443e-08 | AG27: 6.5336329e-08 | AH27: 7.3812202e-08 | AI27: 5.503964e-08
A28: RSD_BLD-APT-OTH | B28: R-SH_Apt_LPG_N1 | E28: 1.3804496e-08 | F28: 1.479812e-08 | G28: 1.5306883e-08 | H28: 1.5603348e-08 | I28: 1.560691e-08 | J28: 1.4890607e-08 | K28: 1.6668657e-08 | L28: 1.7209451e-08 | M28: 1.6957957e-08 | N28: 1.787263e-08 | O28: 1.7580886e-08 | P28: 1.7543254e-08 | Q28: 1.7529002e-08 | R28: 1.7398182e-08 | S28: 1.7849747e-08 | T28: 1.7387882e-08 | U28: 1.7611926e-08 | V28: 1.7860115e-08 | W28: 1.8150323e-08 | X28: 1.8762592e-08 | Y28: 1.891356e-08 | Z28: 1.9438948e-08 | AA28: 2.3517899e-08 | AB28: 2.7347056e-08 | AC28: 2.8682806e-08 | AD28: 3.0292395e-08 | AE28: 3.2315583e-08 | AF28: 3.5387771e-08 | AG28: 3.9403881e-08 | AH28: 4.5661029e-08 | AI28: 4.8405508e-08
A29: RSD_BLD-APT-OTH | B29: R-SH_Apt_WOO_N1 | E29: 1.4658392e-08 | F29: 1.7035116e-08 | G29: 1.7907132e-08 | H29: 1.9062099e-08 | I29: 1.9919979e-08 | J29: 1.9792715e-08 | K29: 2.3124984e-08 | L29: 2.5279992e-08 | M29: 2.6404833e-08 | N29: 2.7572232e-08 | O29: 2.8742626e-08 | P29: 2.998377e-08 | Q29: 3.1003615e-08 | R29: 2.9264828e-08 | S29: 2.8576551e-08 | T29: 2.7700864e-08 | U29: 2.6934032e-08 | V29: 2.6231336e-08 | W29: 2.5699276e-08 | X29: 2.6444711e-08 | Y29: 2.5387821e-08 | Z29: 2.5399337e-08 | AA29: 2.8244007e-08 | AB29: 3.0124336e-08 | AC29: 3.1307576e-08 | AD29: 3.2588442e-08 | AE29: 3.3803853e-08 | AF29: 3.4299884e-08 | AG29: 3.5785293e-08 | AH29: 3.6986887e-08 | AI29: 3.2876273e-08
A30: RSD_BLD-APT-OTH | B30: R-SW_Apt_HET_N1 | E30: 9.9874947e-08 | F30: 3.0749569e-07 | G30: 0.15490526 | H30: 1.7866479 | I30: 0.71758599 | J30: 4.2566511e-07 | K30: 0.44658797 | L30: 0.3611059 | M30: 2.460837 | N30: 0.63291878 | O30: 7.8410308e-06 | P30: 1.3487483 | Q30: 1.7504222 | R30: 1.8364787 | S30: 1.8373877 | T30: 1.8406489 | U30: 1.848706 | V30: 1.8537287 | W30: 0.31447705 | X30: 0.25281707 | Y30: 0.072829581 | Z30: 8.104984e-07 | AA30: 1.0972801e-06 | AB30: 1.8663517e-06 | AC30: 0.67323394 | AD30: 0.36228037 | AE30: 0.82926706 | AF30: 0.73254284 | AG30: 2.8281228 | AH30: 0.99487908 | AI30: 0.3612481
