Workbook

Sheet Cover
A16: TIMES-Ireland Model
A19: Document type: | B19: Scenario
A20: Sector(s): | B20: Transport sector (TRA)
A21: Purpose: | B21: Retirement profile of different vehicles for existing stock
A23: Original developer(s): | B23: Vahid Aryanpur (UCC, vahid.aryanpur@ucc.ie)
B24: James Glynn (UCC, james.glynn@ucc.ie)
A26: Current maintainer(s): | B26: Vahid Aryanpur (UCC, vahid.aryanpur@ucc.ie)
A29: Part of TIM version: | B29: 1
A30: Model repository: | B30: https://github.com/MaREI-EPMG/TIMES-Ireland-model
A31: Licence: | B31: CC BY-NC-SA 4.0 (unless specified otherwise)
B32: https://creativecommons.org/licenses/by-nc-sa/4.0/

Sheet Regions
C3: {=IF(LEFT(INDEX(C5:C7,$A$4),1)<>"*",INDEX(C5:C7,$A$4),"")} -> IE | D3: {=IF(LEFT(INDEX(D5:D7,$A$4),1)<>"*",INDEX(D5:D7,$A$4),"")} | E3: {=IF(LEFT(INDEX(E5:E7,$A$4),1)<>"*",INDEX(E5:E7,$A$4),"")} -> IE-CW | F3: {=IF(LEFT(INDEX(F5:F7,$A$4),1)<>"*",INDEX(F5:F7,$A$4),"")} -> IE-D | G3: {=IF(LEFT(INDEX(G5:G7,$A$4),1)<>"*",INDEX(G5:G7,$A$4),"")} -> IE-KE | H3: {=IF(LEFT(INDEX(H5:H7,$A$4),1)<>"*",INDEX(H5:H7,$A$4),"")} -> IE-KK | I3: {=IF(LEFT(INDEX(I5:I7,$A$4),1)<>"*",INDEX(I5:I7,$A$4),"")} -> IE-LS | J3: {=IF(LEFT(INDEX(J5:J7,$A$4),1)<>"*",INDEX(J5:J7,$A$4),"")} -> IE-LD | ... AD3: {=IF(LEFT(INDEX(AD5:AD7,$A$4),1)<>"*",INDEX(AD5:AD7,$A$4),"")} -> IE-MN
A4: 1
A5: Development | C5: IE | D5: *National | E5: =Regions!A11 -> IE-CW | F5: =Regions!A16 -> IE-D | G5: =Regions!A19 -> IE-KE | H5: =Regions!A20 -> IE-KK | I5: =Regions!A21 -> IE-LS | J5: =Regions!A24 -> IE-LD | K5: =Regions!A25 -> IE-LH | L5: =Regions!A27 -> IE-MH | M5: =Regions!A29 -> IE-OY | N5: =Regions!A34 -> IE-WH | O5: =Regions!A35 -> IE-WX | P5: =Regions!A36 -> IE-WW | Q5: =Regions!A13 -> IE-CE | R5: =Regions!A14 -> IE-CO | S5: =Regions!A18 -> IE-KY | T5: =Regions!A23 -> IE-LK | U5: =Regions!A32 -> IE-TA | V5: =Regions!A33 -> IE-WD | W5: =Regions!A17 -> IE-G | X5: =Regions!A22 -> IE-LM | Y5: =Regions!A26 -> IE-MO | Z5: =Regions!A30 -> IE-RN | AA5: =Regions!A31 -> IE-SO | AB5: =Regions!A12 -> IE-CN | AC5: =Regions!A15 -> IE-DL | AD5: =Regions!A28 -> IE-MN
A6: Single-region | C6: =C5 -> IE | D6: =IF(LEFT(D5,1)<>"*","*"&D5,D5) -> *National | E6: =IF(LEFT(E5,1)<>"*","*"&E5,E5) -> *IE-CW | F6: =IF(LEFT(F5,1)<>"*","*"&F5,F5) -> *IE-D | G6: =IF(LEFT(G5,1)<>"*","*"&G5,G5) -> *IE-KE | H6: =IF(LEFT(H5,1)<>"*","*"&H5,H5) -> *IE-KK | I6: =IF(LEFT(I5,1)<>"*","*"&I5,I5) -> *IE-LS | J6: =IF(LEFT(J5,1)<>"*","*"&J5,J5) -> *IE-LD | K6: =IF(LEFT(K5,1)<>"*","*"&K5,K5) -> *IE-LH | ... AD6: =IF(LEFT(AD5,1)<>"*","*"&AD5,AD5) -> *IE-MN
A7: Multi-region | C7: ="*"&C5 -> *IE | D7: =D5 -> *National | E7: =E5 -> IE-CW | F7: =F5 -> IE-D | G7: =G5 -> IE-KE | H7: =H5 -> IE-KK | I7: =I5 -> IE-LS | J7: =J5 -> IE-LD | K7: =K5 -> IE-LH | ... AD7: =AD5 -> IE-MN
A10: Code | B10: County name
A11: IE-CW | B11: Carlow
A12: IE-CN | B12: Cavan
A13: IE-CE | B13: Clare
A14: IE-CO | B14: Cork
A15: IE-DL | B15: Donegal
A16: IE-D | B16: Dublin
A17: IE-G | B17: Galway
A18: IE-KY | B18: Kerry
A19: IE-KE | B19: Kildare
A20: IE-KK | B20: Kilkenny
A21: IE-LS | B21: Laois
... A36: IE-WW | B36: Wicklow
A37: Source: https://en.wikipedia.org/wiki/ISO_3166-2:IE

Sheet Goods Vehicle
A1: Goods vehicle (number)
A2: Year of Registration | B2: IE | C2: Carlow | D2: Dublin | E2: Kildare | F2: Kilkenny | G2: Laois | H2: Longford | I2: Louth | J2: Meath | K2: Offaly | L2: Westmeath | M2: Wexford | N2: Wicklow | O2: Clare | P2: Cork | Q2: Kerry | R2: Limerick | S2: Tipperary | T2: Waterford | U2: Galway | V2: Leitrim | W2: Mayo | X2: Roscommon | Y2: Sligo | Z2: Cavan | AA2: Donegal | AB2: Monaghan
A3: 1999 or before | B3: =SUM(C3:AB3) -> 6498 | C3: 159 | D3: 479 | E3: 236 | F3: 218 | G3: 134 | H3: 66 | I3: 103 | J3: 258 | K3: 164 | L3: 132 | M3: 371 | N3: 281 | O3: 235 | P3: 954 | Q3: 342 | R3: 317 | S3: 386 | T3: 166 | U3: 463 | V3: 89 | W3: 234 | X3: 139 | Y3: 145 | Z3: 146 | AA3: 173 | AB3: 108
A4: 2000 | B4: =SUM(C4:AB4) -> 3940 | C4: 101 | D4: 362 | E4: 142 | F4: 124 | G4: 75 | H4: 44 | I4: 70 | J4: 153 | K4: 110 | L4: 83 | M4: 186 | N4: 148 | O4: 144 | P4: 568 | Q4: 190 | R4: 171 | S4: 192 | T4: 78 | U4: 275 | V4: 51 | W4: 177 | X4: 108 | Y4: 76 | Z4: 105 | AA4: 127 | AB4: 80
A5: 2001 | B5: =SUM(C5:AB5) -> 4599 | C5: 102 | D5: 427 | E5: 176 | F5: 132 | G5: 87 | H5: 51 | I5: 76 | J5: 212 | K5: 127 | L5: 108 | M5: 207 | N5: 191 | O5: 172 | P5: 647 | Q5: 213 | R5: 192 | S5: 200 | T5: 98 | U5: 308 | V5: 75 | W5: 188 | X5: 125 | Y5: 91 | Z5: 111 | AA5: 166 | AB5: 117
A6: 2002 | B6: =SUM(C6:AB6) -> 6092 | C6: 146 | D6: 549 | E6: 234 | F6: 186 | G6: 145 | H6: 72 | I6: 103 | J6: 205 | K6: 146 | L6: 147 | M6: 277 | N6: 225 | O6: 213 | P6: 820 | Q6: 274 | R6: 243 | S6: 346 | T6: 172 | U6: 451 | V6: 84 | W6: 273 | X6: 163 | Y6: 151 | Z6: 140 | AA6: 210 | AB6: 117
A7: 2003 | B7: =SUM(C7:AB7) -> 8596 | C7: 181 | D7: 808 | E7: 370 | F7: 271 | G7: 185 | H7: 114 | I7: 147 | J7: 350 | K7: 226 | L7: 201 | M7: 422 | N7: 266 | O7: 290 | P7: 1243 | Q7: 395 | R7: 334 | S7: 430 | T7: 235 | U7: 634 | V7: 108 | W7: 361 | X7: 196 | Y7: 186 | Z7: 186 | AA7: 310 | AB7: 147
A8: 2004 | B8: =SUM(C8:AB8) -> 11434 | C8: 197 | D8: 1212 | E8: 532 | F8: 324 | G8: 254 | H8: 162 | I8: 192 | J8: 475 | K8: 280 | L8: 261 | M8: 551 | N8: 414 | O8: 402 | P8: 1555 | Q8: 468 | R8: 474 | S8: 579 | T8: 248 | U8: 740 | V8: 145 | W8: 491 | X8: 281 | Y8: 268 | Z8: 300 | AA8: 400 | AB8: 229
A9: 2005 | B9: =SUM(C9:AB9) -> 18375 | C9: 361 | D9: 2131 | E9: 859 | F9: 525 | G9: 378 | H9: 249 | I9: 368 | J9: 796 | K9: 390 | L9: 421 | M9: 851 | N9: 549 | O9: 596 | P9: 2432 | Q9: 818 | R9: 696 | S9: 860 | T9: 477 | U9: 1219 | V9: 241 | W9: 819 | X9: 414 | Y9: 395 | Z9: 463 | AA9: 708 | AB9: 359
A10: 2006 | B10: =SUM(C10:AB10) -> 24528 | C10: 477 | D10: 3009 | E10: 1112 | F10: 671 | G10: 534 | H10: 292 | I10: 521 | J10: 973 | K10: 527 | L10: 551 | M10: 1192 | N10: 748 | O10: 776 | P10: 3187 | Q10: 1045 | R10: 1016 | S10: 1199 | T10: 594 | U10: 1661 | V10: 274 | W10: 1127 | X10: 535 | Y10: 484 | Z10: 619 | AA10: 917 | AB10: 487
A11: 2007 | B11: =SUM(C11:AB11) -> 28566 | C11: 526 | D11: 3808 | E11: 1313 | F11: 778 | G11: 554 | H11: 402 | I11: 587 | J11: 1254 | K11: 618 | L11: 699 | M11: 1281 | N11: 894 | O11: 902 | P11: 3682 | Q11: 1079 | R11: 1170 | S11: 1393 | T11: 712 | U11: 1897 | V11: 316 | W11: 1246 | X11: 591 | Y11: 505 | Z11: 666 | AA11: 1113 | AB11: 580
A12: 2008 | B12: =SUM(C12:AB12) -> 22384 | C12: 393 | D12: 3249 | E12: 1030 | F12: 602 | G12: 485 | H12: 282 | I12: 493 | J12: 905 | K12: 459 | L12: 497 | M12: 878 | N12: 650 | O12: 708 | P12: 2886 | Q12: 863 | R12: 1005 | S12: 1065 | T12: 547 | U12: 1353 | V12: 242 | W12: 986 | X12: 463 | Y12: 434 | Z12: 504 | AA12: 921 | AB12: 484
A13: 2009 | B13: =SUM(C13:AB13) -> 10156 | C13: 189 | D13: 1539 | E13: 440 | F13: 208 | G13: 179 | H13: 128 | I13: 279 | J13: 402 | K13: 197 | L13: 212 | M13: 380 | N13: 265 | O13: 308 | P13: 1146 | Q13: 385 | R13: 439 | S13: 393 | T13: 243 | U13: 690 | V13: 124 | W13: 456 | X13: 217 | Y13: 246 | Z13: 271 | AA13: 607 | AB13: 213
A14: 2010 | B14: =SUM(C14:AB14) -> 9724 | C14: 123 | D14: 1505 | E14: 424 | F14: 221 | G14: 182 | H14: 120 | I14: 224 | J14: 408 | K14: 190 | L14: 230 | M14: 384 | N14: 284 | O14: 279 | P14: 1167 | Q14: 324 | R14: 413 | S14: 389 | T14: 214 | U14: 592 | V14: 94 | W14: 457 | X14: 209 | Y14: 201 | Z14: 259 | AA14: 565 | AB14: 266
A15: 2011 | B15: =SUM(C15:AB15) -> 10065 | C15: 147 | D15: 1942 | E15: 471 | F15: 232 | G15: 201 | H15: 121 | I15: 265 | J15: 433 | K15: 161 | L15: 218 | M15: 371 | N15: 258 | O15: 302 | P15: 1128 | Q15: 375 | R15: 408 | S15: 386 | T15: 239 | U15: 608 | V15: 103 | W15: 452 | X15: 171 | Y15: 201 | Z15: 212 | AA15: 403 | AB15: 257
... A23: 2019 | B23: =SUM(C23:AB23) -> 18587 | C23: 268 | D23: 6631 | E23: 866 | F23: 323 | G23: 247 | H23: 164 | I23: 432 | J23: 685 | K23: 259 | L23: 301 | M23: 627 | N23: 358 | O23: 343 | P23: 1749 | Q23: 442 | R23: 655 | S23: 511 | T23: 341 | U23: 751 | V23: 125 | W23: 478 | X23: 211 | Y23: 253 | Z23: 383 | AA23: 785 | AB23: 399
A24: Source: CSO, Table THA17
A27: =B2 -> IE
B29: 2019 | F29: Survival Rates for Small HGV
A30: Total | B30: =SUM(B31:B51) -> 362712 | F30: Vintage | G30: Sur Rates
A31: 1999 or before | B31: =B3 -> 6498 | F31: 0 | G31: 1
A32: 2000 | B32: =B4 -> 3940 | F32: 1 | G32: 1.09
A33: 2001 | B33: =B5 -> 4599 | F33: 2 | G33: 1.06
A34: 2002 | B34: =B6 -> 6092 | F34: 3 | G34: 1.04
A35: 2003 | B35: =B7 -> 8596 | F35: 4 | G35: 1.02
A36: 2004 | B36: =B8 -> 11434 | F36: 5 | G36: 1.01
A37: 2005 | B37: =B9 -> 18375 | F37: 6 | G37: 1
A38: 2006 | B38: =B10 -> 24528 | F38: 7 | G38: 1
A39: 2007 | B39: =B11 -> 28566 | F39: 8 | G39: 1
A40: 2008 | B40: =B12 -> 22384 | F40: 9 | G40: 1
A41: 2009 | B41: =B13 -> 10156 | F41: 10 | G41: 1.1
A42: 2010 | B42: =B14 -> 9724 | F42: 11 | G42: 1
A43: 2011 | B43: =B15 -> 10065 | F43: 12 | G43: 0.99
... A51: 2019 | B51: =B23 -> 18587 | F51: 20 | G51: 0.45438206
F52: 21 | G52: 0.40894385
F53: 22 | G53: 0.36804946
F54: 23 | G54: 0.33124452
F55: 24 | G55: 0.29812007
F56: 25 | G56: 0
F57: Source: Irish_TIMES 2.0
...

Sheet Buses
A1: Buses (number)
A2: Year of Registration | B2: IE | C2: Carlow | D2: Dublin | E2: Kildare | F2: Kilkenny | G2: Laois | H2: Longford | I2: Louth | J2: Meath | K2: Offaly | L2: Westmeath | M2: Wexford | N2: Wicklow | O2: Clare | P2: Cork | Q2: Kerry | R2: Limerick | S2: Tipperary | T2: Waterford | U2: Galway | V2: Leitrim | W2: Mayo | X2: Roscommon | Y2: Sligo | Z2: Cavan | AA2: Donegal | AB2: Monaghan
A3: 1999 or before | B3: =SUM(C3:AB3) -> 172 | C3: 7 | D3: 43 | E3: 4 | F3: 6 | G3: 7 | H3: 4 | I3: 2 | J3: 9 | K3: 2 | L3: 7 | M3: 4 | N3: 3 | O3: 1 | P3: 19 | Q3: 8 | R3: 5 | S3: 6 | T3: 4 | U3: 8 | V3: 2 | W3: 10 | X3: 4 | Y3: 2 | Z3: 3 | AA3: 1 | AB3: 1
A4: 2000 | B4: =SUM(C4:AB4) -> 192 | C4: 1 | D4: 72 | E4: 8 | F4: 4 | G4: 3 | H4: 1 | I4: 12 | J4: 4 | K4: 1 | L4: 8 | M4: 1 | N4: 1 | O4: 1 | P4: 16 | Q4: 11 | R4: 5 | S4: 13 | T4: 4 | U4: 7 | V4: 1 | W4: 5 | X4: 3 | Y4: 2 | Z4: 0 | AA4: 7 | AB4: 1
A5: 2001 | B5: =SUM(C5:AB5) -> 165 | C5: 5 | D5: 36 | E5: 7 | F5: 1 | G5: 6 | H5: 4 | I5: 3 | J5: 5 | K5: 4 | L5: 3 | M5: 5 | N5: 4 | O5: 6 | P5: 12 | Q5: 9 | R5: 8 | S5: 8 | T5: 4 | U5: 4 | V5: 5 | W5: 10 | X5: 3 | Y5: 0 | Z5: 2 | AA5: 9 | AB5: 2
A6: 2002 | B6: =SUM(C6:AB6) -> 181 | C6: 2 | D6: 32 | E6: 13 | F6: 4 | G6: 2 | H6: 1 | I6: 0 | J6: 10 | K6: 3 | L6: 9 | M6: 4 | N6: 2 | O6: 10 | P6: 23 | Q6: 6 | R6: 11 | S6: 11 | T6: 8 | U6: 6 | V6: 2 | W6: 9 | X6: 1 | Y6: 2 | Z6: 3 | AA6: 5 | AB6: 2
A7: 2003 | B7: =SUM(C7:AB7) -> 280 | C7: 9 | D7: 62 | E7: 7 | F7: 7 | G7: 6 | H7: 2 | I7: 8 | J7: 13 | K7: 8 | L7: 7 | M7: 5 | N7: 7 | O7: 6 | P7: 21 | Q7: 20 | R7: 10 | S7: 11 | T7: 10 | U7: 20 | V7: 5 | W7: 13 | X7: 5 | Y7: 3 | Z7: 4 | AA7: 7 | AB7: 4
A8: 2004 | B8: =SUM(C8:AB8) -> 381 | C8: 6 | D8: 98 | E8: 18 | F8: 10 | G8: 3 | H8: 6 | I8: 4 | J8: 20 | K8: 6 | L8: 5 | M8: 13 | N8: 6 | O8: 12 | P8: 39 | Q8: 16 | R8: 19 | S8: 11 | T8: 10 | U8: 26 | V8: 6 | W8: 14 | X8: 4 | Y8: 7 | Z8: 5 | AA8: 12 | AB8: 5
A9: 2005 | B9: =SUM(C9:AB9) -> 395 | C9: 7 | D9: 105 | E9: 21 | F9: 2 | G9: 2 | H9: 10 | I9: 10 | J9: 12 | K9: 8 | L9: 4 | M9: 16 | N9: 8 | O9: 13 | P9: 37 | Q9: 24 | R9: 14 | S9: 6 | T9: 13 | U9: 17 | V9: 5 | W9: 12 | X9: 4 | Y9: 7 | Z9: 14 | AA9: 19 | AB9: 5
A10: 2006 | B10: =SUM(C10:AB10) -> 732 | C10: 7 | D10: 302 | E10: 36 | F10: 12 | G10: 8 | H10: 5 | I10: 7 | J10: 26 | K10: 7 | L10: 10 | M10: 21 | N10: 23 | O10: 19 | P10: 43 | Q10: 25 | R10: 22 | S10: 32 | T10: 7 | U10: 37 | V10: 5 | W10: 24 | X10: 5 | Y10: 6 | Z10: 6 | AA10: 27 | AB10: 10
A11: 2007 | B11: =SUM(C11:AB11) -> 737 | C11: 7 | D11: 222 | E11: 39 | F11: 25 | G11: 13 | H11: 8 | I11: 20 | J11: 18 | K11: 15 | L11: 7 | M11: 16 | N11: 24 | O11: 18 | P11: 59 | Q11: 39 | R11: 26 | S11: 27 | T11: 24 | U11: 41 | V11: 4 | W11: 26 | X11: 6 | Y11: 5 | Z11: 12 | AA11: 30 | AB11: 6
A12: 2008 | B12: =SUM(C12:AB12) -> 865 | C12: 6 | D12: 282 | E12: 28 | F12: 17 | G12: 11 | H12: 11 | I12: 12 | J12: 31 | K12: 19 | L12: 10 | M12: 32 | N12: 29 | O12: 14 | P12: 68 | Q12: 38 | R12: 24 | S12: 44 | T12: 18 | U12: 57 | V12: 6 | W12: 29 | X12: 9 | Y12: 8 | Z12: 13 | AA12: 38 | AB12: 11
A13: 2009 | B13: =SUM(C13:AB13) -> 385 | C13: 6 | D13: 74 | E13: 12 | F13: 10 | G13: 6 | H13: 4 | I13: 10 | J13: 16 | K13: 8 | L13: 8 | M13: 14 | N13: 6 | O13: 12 | P13: 63 | Q13: 10 | R13: 17 | S13: 17 | T13: 5 | U13: 22 | V13: 3 | W13: 14 | X13: 5 | Y13: 2 | Z13: 8 | AA13: 28 | AB13: 5
A14: 2010 | B14: =SUM(C14:AB14) -> 196 | C14: 2 | D14: 34 | E14: 8 | F14: 6 | G14: 3 | H14: 0 | I14: 7 | J14: 16 | K14: 7 | L14: 1 | M14: 7 | N14: 3 | O14: 6 | P14: 18 | Q14: 10 | R14: 6 | S14: 7 | T14: 3 | U14: 14 | V14: 1 | W14: 8 | X14: 4 | Y14: 1 | Z14: 4 | AA14: 13 | AB14: 7
A15: 2011 | B15: =SUM(C15:AB15) -> 214 | C15: 6 | D15: 19 | E15: 28 | F15: 9 | G15: 3 | H15: 2 | I15: 9 | J15: 6 | K15: 8 | L15: 2 | M15: 8 | N15: 2 | O15: 9 | P15: 20 | Q15: 7 | R15: 9 | S15: 9 | T15: 7 | U15: 10 | V15: 1 | W15: 12 | X15: 4 | Y15: 2 | Z15: 2 | AA15: 12 | AB15: 8
... A23: 2019 | B23: =SUM(C23:AB23) -> 553 | C23: 7 | D23: 176 | E23: 23 | F23: 24 | G23: 6 | H23: 6 | I23: 10 | J23: 16 | K23: 6 | L23: 6 | M23: 16 | N23: 13 | O23: 10 | P23: 41 | Q23: 34 | R23: 15 | S23: 13 | T23: 11 | U23: 35 | V23: 6 | W23: 9 | X23: 4 | Y23: 6 | Z23: 10 | AA23: 32 | AB23: 18
A24: Source: CSO, Table THA17
A27: =B2 -> IE
B29: 2019 | F29: Survival Rates for Buses
A30: Total | B30: =SUM(B31:B51) -> 11203 | F30: Vintage | G30: Sur Rates
A31: 1999 or before | B31: =B3 -> 172 | F31: 0 | G31: 1
A32: 2000 | B32: =B4 -> 192 | F32: 1 | G32: 1
A33: 2001 | B33: =B5 -> 165 | F33: 2 | G33: 1
A34: 2002 | B34: =B6 -> 181 | F34: 3 | G34: 1
A35: 2003 | B35: =B7 -> 280 | F35: 4 | G35: 1
A36: 2004 | B36: =B8 -> 381 | F36: 5 | G36: 1
A37: 2005 | B37: =B9 -> 395 | F37: 6 | G37: 1
A38: 2006 | B38: =B10 -> 732 | F38: 7 | G38: 1
A39: 2007 | B39: =B11 -> 737 | F39: 8 | G39: 1
A40: 2008 | B40: =B12 -> 865 | F40: 9 | G40: 1
A41: 2009 | B41: =B13 -> 385 | F41: 10 | G41: 1
A42: 2010 | B42: =B14 -> 196 | F42: 11 | G42: 0.97859323
A43: 2011 | B43: =B15 -> 214 | F43: 12 | G43: 0.8937765
... A51: 2019 | B51: =B23 -> 553 | F51: 20 | G51: 0.18254159
F52: 21 | G52: 0.14603327
F53: 22 | G53: 0.10952496
F54: 23 | G54: 0.073016637
F55: 24 | G55: 0.036508318
F56: 25 | G56: 0
F57: Source: Irish_TIMES 2.0
...

Sheet Taxis
A1: Taxis (number)
A2: Year of Registration | B2: IE | C2: Carlow | D2: Dublin | E2: Kildare | F2: Kilkenny | G2: Laois | H2: Longford | I2: Louth | J2: Meath | K2: Offaly | L2: Westmeath | M2: Wexford | N2: Wicklow | O2: Clare | P2: Cork | Q2: Kerry | R2: Limerick | S2: Tipperary | T2: Waterford | U2: Galway | V2: Leitrim | W2: Mayo | X2: Roscommon | Y2: Sligo | Z2: Cavan | AA2: Donegal | AB2: Monaghan
A3: 1999 or before | B3: =SUM(C3:AB3) -> 28 | C3: 1 | D3: 16 | E3: 1 | F3: 0 | G3: 1 | H3: 0 | I3: 1 | J3: 1 | K3: 0 | L3: 0 | M3: 0 | N3: 1 | O3: 0 | P3: 0 | Q3: 2 | R3: 0 | S3: 1 | T3: 0 | U3: 0 | V3: 0 | W3: 2 | X3: 0 | Y3: 0 | Z3: 0 | AA3: 1 | AB3: 0
A4: 2000 | B4: =SUM(C4:AB4) -> 29 | C4: 1 | D4: 12 | E4: 1 | F4: 0 | G4: 0 | H4: 0 | I4: 2 | J4: 2 | K4: 0 | L4: 1 | M4: 0 | N4: 1 | O4: 0 | P4: 0 | Q4: 0 | R4: 1 | S4: 0 | T4: 2 | U4: 2 | V4: 0 | W4: 0 | X4: 1 | Y4: 1 | Z4: 0 | AA4: 2 | AB4: 0
A5: 2001 | B5: =SUM(C5:AB5) -> 33 | C5: 2 | D5: 12 | E5: 1 | F5: 0 | G5: 1 | H5: 0 | I5: 1 | J5: 1 | K5: 0 | L5: 0 | M5: 0 | N5: 2 | O5: 0 | P5: 3 | Q5: 4 | R5: 3 | S5: 0 | T5: 0 | U5: 1 | V5: 0 | W5: 1 | X5: 0 | Y5: 0 | Z5: 0 | AA5: 1 | AB5: 0
A6: 2002 | B6: =SUM(C6:AB6) -> 21 | C6: 4 | D6: 6 | E6: 0 | F6: 0 | G6: 0 | H6: 0 | I6: 0 | J6: 1 | K6: 0 | L6: 0 | M6: 0 | N6: 0 | O6: 1 | P6: 2 | Q6: 1 | R6: 1 | S6: 0 | T6: 1 | U6: 1 | V6: 0 | W6: 1 | X6: 0 | Y6: 2 | Z6: 0 | AA6: 0 | AB6: 0
A7: 2003 | B7: =SUM(C7:AB7) -> 45 | C7: 3 | D7: 17 | E7: 4 | F7: 0 | G7: 0 | H7: 0 | I7: 0 | J7: 3 | K7: 0 | L7: 1 | M7: 1 | N7: 2 | O7: 2 | P7: 5 | Q7: 1 | R7: 1 | S7: 0 | T7: 0 | U7: 4 | V7: 0 | W7: 0 | X7: 0 | Y7: 0 | Z7: 0 | AA7: 1 | AB7: 0
A8: 2004 | B8: =SUM(C8:AB8) -> 193 | C8: 4 | D8: 84 | E8: 10 | F8: 0 | G8: 1 | H8: 1 | I8: 8 | J8: 6 | K8: 3 | L8: 1 | M8: 7 | N8: 4 | O8: 5 | P8: 15 | Q8: 4 | R8: 13 | S8: 3 | T8: 1 | U8: 8 | V8: 1 | W8: 5 | X8: 1 | Y8: 1 | Z8: 2 | AA8: 3 | AB8: 2
A9: 2005 | B9: =SUM(C9:AB9) -> 444 | C9: 7 | D9: 206 | E9: 22 | F9: 3 | G9: 1 | H9: 0 | I9: 16 | J9: 21 | K9: 6 | L9: 5 | M9: 9 | N9: 8 | O9: 9 | P9: 48 | Q9: 6 | R9: 12 | S9: 9 | T9: 8 | U9: 28 | V9: 2 | W9: 2 | X9: 4 | Y9: 5 | Z9: 2 | AA9: 4 | AB9: 1
A10: 2006 | B10: =SUM(C10:AB10) -> 689 | C10: 7 | D10: 346 | E10: 19 | F10: 10 | G10: 7 | H10: 4 | I10: 17 | J10: 27 | K10: 11 | L10: 9 | M10: 14 | N10: 14 | O10: 15 | P10: 57 | Q10: 10 | R10: 34 | S10: 17 | T10: 10 | U10: 27 | V10: 0 | W10: 11 | X10: 5 | Y10: 6 | Z10: 6 | AA10: 6 | AB10: 0
A11: 2007 | B11: =SUM(C11:AB11) -> 903 | C11: 10 | D11: 438 | E11: 29 | F11: 13 | G11: 2 | H11: 5 | I11: 21 | J11: 37 | K11: 13 | L11: 8 | M11: 11 | N11: 24 | O11: 18 | P11: 96 | Q11: 21 | R11: 26 | S11: 18 | T11: 14 | U11: 37 | V11: 3 | W11: 13 | X11: 6 | Y11: 10 | Z11: 10 | AA11: 17 | AB11: 3
A12: 2008 | B12: =SUM(C12:AB12) -> 673 | C12: 13 | D12: 291 | E12: 26 | F12: 6 | G12: 8 | H12: 2 | I12: 22 | J12: 30 | K12: 10 | L12: 11 | M12: 17 | N12: 18 | O12: 10 | P12: 54 | Q12: 23 | R12: 22 | S12: 19 | T12: 18 | U12: 31 | V12: 2 | W12: 14 | X12: 4 | Y12: 10 | Z12: 1 | AA12: 6 | AB12: 5
A13: 2009 | B13: =SUM(C13:AB13) -> 498 | C13: 5 | D13: 244 | E13: 20 | F13: 5 | G13: 4 | H13: 3 | I13: 12 | J13: 20 | K13: 5 | L13: 5 | M13: 6 | N13: 6 | O13: 11 | P13: 43 | Q13: 11 | R13: 21 | S13: 8 | T13: 7 | U13: 29 | V13: 3 | W13: 5 | X13: 2 | Y13: 2 | Z13: 9 | AA13: 11 | AB13: 1
A14: 2010 | B14: =SUM(C14:AB14) -> 1056 | C14: 5 | D14: 506 | E14: 53 | F14: 5 | G14: 9 | H14: 6 | I14: 34 | J14: 49 | K14: 13 | L14: 15 | M14: 13 | N14: 18 | O14: 14 | P14: 102 | Q14: 18 | R14: 57 | S14: 14 | T14: 11 | U14: 56 | V14: 6 | W14: 15 | X14: 7 | Y14: 8 | Z14: 3 | AA14: 16 | AB14: 3
A15: 2011 | B15: =SUM(C15:AB15) -> 1316 | C15: 8 | D15: 640 | E15: 48 | F15: 8 | G15: 13 | H15: 2 | I15: 38 | J15: 65 | K15: 18 | L15: 26 | M15: 19 | N15: 18 | O15: 13 | P15: 148 | Q15: 31 | R15: 40 | S15: 20 | T15: 17 | U15: 61 | V15: 5 | W15: 18 | X15: 9 | Y15: 6 | Z15: 17 | AA15: 22 | AB15: 6
... A23: 2019 | B23: =SUM(C23:AB23) -> 1222 | C23: 11 | D23: 738 | E23: 36 | F23: 12 | G23: 13 | H23: 4 | I23: 38 | J23: 58 | K23: 5 | L23: 9 | M23: 8 | N23: 17 | O23: 15 | P23: 73 | Q23: 31 | R23: 31 | S23: 6 | T23: 17 | U23: 43 | V23: 2 | W23: 10 | X23: 6 | Y23: 5 | Z23: 10 | AA23: 18 | AB23: 6
A24: Source: CSO, Table THA17
A27: =B2 -> IE
B29: 2019 | F29: Survival Rates for small gasoline
A30: Total | B30: =SUM(B31:B51) -> 21449 | F30: Vintage | G30: Sur Rates
A31: 1999 or before | B31: =B3 -> 28 | F31: 0 | G31: 1
A32: 2000 | B32: =B4 -> 29 | F32: 1 | G32: 1
A33: 2001 | B33: =B5 -> 33 | F33: 2 | G33: 1
A34: 2002 | B34: =B6 -> 21 | F34: 3 | G34: 1
A35: 2003 | B35: =B7 -> 45 | F35: 4 | G35: 1
A36: 2004 | B36: =B8 -> 193 | F36: 5 | G36: 1
A37: 2005 | B37: =B9 -> 444 | F37: 6 | G37: 1
A38: 2006 | B38: =B10 -> 689 | F38: 7 | G38: 1
A39: 2007 | B39: =B11 -> 903 | F39: 8 | G39: 1
A40: 2008 | B40: =B12 -> 673 | F40: 9 | G40: 1
A41: 2009 | B41: =B13 -> 498 | F41: 10 | G41: 1
A42: 2010 | B42: =B14 -> 1056 | F42: 11 | G42: 0.97859323
A43: 2011 | B43: =B15 -> 1316 | F43: 12 | G43: 0.8937765
... A51: 2019 | B51: =B23 -> 1222 | F51: 20 | G51: 0.18254159
F52: 21 | G52: 0.14603327
F53: 22 | G53: 0.10952496
F54: 23 | G54: 0.073016637
F55: 24 | G55: 0.036508318
F56: 25 | G56: 0
F57: Source: Irish_TIMES 2.0
...

Sheet Diesel Cars
A1: Private Diesel Cars (number)
A2: Year of Registration | B2: IE | C2: Carlow | D2: Dublin | E2: Kildare | F2: Kilkenny | G2: Laois | H2: Longford | I2: Louth | J2: Meath | K2: Offaly | L2: Westmeath | M2: Wexford | N2: Wicklow | O2: Clare | P2: Cork | Q2: Kerry | R2: Limerick | S2: Tipperary | T2: Waterford | U2: Galway | V2: Leitrim | W2: Mayo | X2: Roscommon | Y2: Sligo | Z2: Cavan | AA2: Donegal | AB2: Monaghan
A3: 1999 or before | B3: =SUM(C3:AB3) -> 1667 | C3: 39 | D3: 153 | E3: 55 | F3: 58 | G3: 53 | H3: 18 | I3: 27 | J3: 79 | K3: 45 | L3: 36 | M3: 77 | N3: 57 | O3: 45 | P3: 228 | Q3: 108 | R3: 84 | S3: 84 | T3: 31 | U3: 129 | V3: 28 | W3: 73 | X3: 27 | Y3: 31 | Z3: 49 | AA3: 33 | AB3: 20
A4: 2000 | B4: =SUM(C4:AB4) -> 1151 | C4: 20 | D4: 113 | E4: 41 | F4: 36 | G4: 33 | H4: 11 | I4: 18 | J4: 63 | K4: 30 | L4: 30 | M4: 70 | N4: 39 | O4: 31 | P4: 136 | Q4: 56 | R4: 52 | S4: 74 | T4: 37 | U4: 71 | V4: 18 | W4: 49 | X4: 27 | Y4: 17 | Z4: 25 | AA4: 45 | AB4: 9
A5: 2001 | B5: =SUM(C5:AB5) -> 1457 | C5: 37 | D5: 148 | E5: 67 | F5: 32 | G5: 35 | H5: 29 | I5: 19 | J5: 72 | K5: 36 | L5: 27 | M5: 78 | N5: 62 | O5: 41 | P5: 182 | Q5: 67 | R5: 55 | S5: 85 | T5: 35 | U5: 102 | V5: 19 | W5: 54 | X5: 34 | Y5: 40 | Z5: 32 | AA5: 53 | AB5: 16
A6: 2002 | B6: =SUM(C6:AB6) -> 3175 | C6: 67 | D6: 316 | E6: 129 | F6: 112 | G6: 90 | H6: 40 | I6: 40 | J6: 144 | K6: 87 | L6: 84 | M6: 173 | N6: 125 | O6: 102 | P6: 397 | Q6: 142 | R6: 136 | S6: 167 | T6: 77 | U6: 246 | V6: 39 | W6: 122 | X6: 64 | Y6: 71 | Z6: 65 | AA6: 111 | AB6: 29
A7: 2003 | B7: =SUM(C7:AB7) -> 4838 | C7: 112 | D7: 557 | E7: 214 | F7: 141 | G7: 135 | H7: 64 | I7: 82 | J7: 209 | K7: 122 | L7: 126 | M7: 238 | N7: 192 | O7: 152 | P7: 572 | Q7: 248 | R7: 198 | S7: 262 | T7: 110 | U7: 333 | V7: 66 | W7: 198 | X7: 114 | Y7: 75 | Z7: 95 | AA7: 154 | AB7: 69
A8: 2004 | B8: =SUM(C8:AB8) -> 8054 | C8: 156 | D8: 1020 | E8: 396 | F8: 262 | G8: 228 | H8: 103 | I8: 134 | J8: 332 | K8: 202 | L8: 221 | M8: 457 | N8: 343 | O8: 270 | P8: 851 | Q8: 367 | R8: 304 | S8: 432 | T8: 214 | U8: 528 | V8: 106 | W8: 336 | X8: 180 | Y8: 131 | Z8: 151 | AA8: 222 | AB8: 108
A9: 2005 | B9: =SUM(C9:AB9) -> 14870 | C9: 315 | D9: 2012 | E9: 685 | F9: 397 | G9: 396 | H9: 169 | I9: 292 | J9: 700 | K9: 377 | L9: 412 | M9: 781 | N9: 589 | O9: 459 | P9: 1662 | Q9: 687 | R9: 634 | S9: 767 | T9: 427 | U9: 933 | V9: 134 | W9: 607 | X9: 294 | Y9: 213 | Z9: 289 | AA9: 435 | AB9: 204
A10: 2006 | B10: =SUM(C10:AB10) -> 23111 | C10: 483 | D10: 3508 | E10: 1076 | F10: 624 | G10: 610 | H10: 270 | I10: 475 | J10: 1071 | K10: 556 | L10: 616 | M10: 1117 | N10: 925 | O10: 662 | P10: 2581 | Q10: 1011 | R10: 1009 | S10: 1209 | T10: 635 | U10: 1385 | V10: 194 | W10: 868 | X10: 417 | Y10: 343 | Z10: 411 | AA10: 748 | AB10: 307
A11: 2007 | B11: =SUM(C11:AB11) -> 34411 | C11: 635 | D11: 5740 | E11: 1633 | F11: 847 | G11: 820 | H11: 378 | I11: 698 | J11: 1645 | K11: 775 | L11: 853 | M11: 1556 | N11: 1352 | O11: 958 | P11: 3936 | Q11: 1431 | R11: 1561 | S11: 1709 | T11: 887 | U11: 2141 | V11: 281 | W11: 1310 | X11: 598 | Y11: 540 | Z11: 675 | AA11: 1012 | AB11: 440
A12: 2008 | B12: =SUM(C12:AB12) -> 50340 | C12: 967 | D12: 8026 | E12: 2482 | F12: 1311 | G12: 1163 | H12: 526 | I12: 1097 | J12: 2346 | K12: 1189 | L12: 1233 | M12: 2496 | N12: 1754 | O12: 1440 | P12: 5734 | Q12: 2101 | R12: 2204 | S12: 2594 | T12: 1290 | U12: 3258 | V12: 437 | W12: 1904 | X12: 923 | Y12: 771 | Z12: 973 | AA12: 1474 | AB12: 647
A13: 2009 | B13: =SUM(C13:AB13) -> 43132 | C13: 739 | D13: 7426 | E13: 2021 | F13: 1028 | G13: 914 | H13: 446 | I13: 1043 | J13: 1986 | K13: 865 | L13: 1063 | M13: 1893 | N13: 1463 | O13: 1196 | P13: 5138 | Q13: 1706 | R13: 1865 | S13: 2068 | T13: 1135 | U13: 2702 | V13: 391 | W13: 1632 | X13: 757 | Y13: 695 | Z13: 751 | AA13: 1642 | AB13: 567
A14: 2010 | B14: =SUM(C14:AB14) -> 67846 | C14: 1089 | D14: 12793 | E14: 3105 | F14: 1642 | G14: 1363 | H14: 615 | I14: 1569 | J14: 3020 | K14: 1364 | L14: 1685 | M14: 2934 | N14: 2156 | O14: 1957 | P14: 8528 | Q14: 2752 | R14: 3096 | S14: 3145 | T14: 1755 | U14: 4145 | V14: 494 | W14: 2286 | X14: 1080 | Y14: 1101 | Z14: 1138 | AA14: 2248 | AB14: 786
A15: 2011 | B15: =SUM(C15:AB15) -> 80316 | C15: 1244 | D15: 15057 | E15: 3930 | F15: 1945 | G15: 1525 | H15: 755 | I15: 1842 | J15: 3639 | K15: 1606 | L15: 1945 | M15: 3344 | N15: 2435 | O15: 2460 | P15: 10242 | Q15: 3184 | R15: 3701 | S15: 3715 | T15: 2063 | U15: 5000 | V15: 675 | W15: 2750 | X15: 1305 | Y15: 1204 | Z15: 1249 | AA15: 2502 | AB15: 999
... A23: 2019 | B23: =SUM(C23:AB23) -> 69017 | C23: 960 | D23: 16754 | E23: 3351 | F23: 1426 | G23: 1237 | H23: 680 | I23: 2066 | J23: 3131 | K23: 1081 | L23: 1397 | M23: 2715 | N23: 1629 | O23: 2062 | P23: 7386 | Q23: 1921 | R23: 2691 | S23: 2460 | T23: 1793 | U23: 3667 | V23: 565 | W23: 1939 | X23: 1432 | Y23: 941 | Z23: 1340 | AA23: 3075 | AB23: 1318
A24: Source: CSO, Table THA17
A27: =B2 -> IE
B29: 2019 | F29: Survival Rates for Heavy Medium Diesel
A30: Total | B30: =SUM(B31:B51) -> 1207684 | F30: Vintage | G30: Sur Rates
A31: 1999 or before | B31: =B3 -> 1667 | F31: 0 | G31: 1
A32: 2000 | B32: =B4 -> 1151 | F32: 1 | G32: 1
A33: 2001 | B33: =B5 -> 1457 | F33: 2 | G33: 1
A34: 2002 | B34: =B6 -> 3175 | F34: 3 | G34: 1
A35: 2003 | B35: =B7 -> 4838 | F35: 4 | G35: 1
A36: 2004 | B36: =B8 -> 8054 | F36: 5 | G36: 1
A37: 2005 | B37: =B9 -> 14870 | F37: 6 | G37: 1
A38: 2006 | B38: =B10 -> 23111 | F38: 7 | G38: 1
A39: 2007 | B39: =B11 -> 34411 | F39: 8 | G39: 1
A40: 2008 | B40: =B12 -> 50340 | F40: 9 | G40: 1
A41: 2009 | B41: =B13 -> 43132 | F41: 10 | G41: 1
A42: 2010 | B42: =B14 -> 67846 | F42: 11 | G42: 1
A43: 2011 | B43: =B15 -> 80316 | F43: 12 | G43: 0.99
... A51: 2019 | B51: =B23 -> 69017 | F51: 20 | G51: 0.2
F52: 21 | G52: 0.16
F53: 22 | G53: 0.12
F54: 23 | G54: 0.08
F55: 24 | G55: 0.04
F56: 25 | G56: 0
F57: Source: Irish_TIMES 2.0
...

Sheet Gasoline Cars
A1: Private Gasoline Cars (number)
A2: Year of Registration | B2: IE | C2: Carlow | D2: Dublin | E2: Kildare | F2: Kilkenny | G2: Laois | H2: Longford | I2: Louth | J2: Meath | K2: Offaly | L2: Westmeath | M2: Wexford | N2: Wicklow | O2: Clare | P2: Cork | Q2: Kerry | R2: Limerick | S2: Tipperary | T2: Waterford | U2: Galway | V2: Leitrim | W2: Mayo | X2: Roscommon | Y2: Sligo | Z2: Cavan | AA2: Donegal | AB2: Monaghan
A3: 1999 or before | B3: =SUM(C3:AB3) -> 18684 | C3: 258 | D3: 4693 | E3: 639 | F3: 439 | G3: 266 | H3: 121 | I3: 250 | J3: 532 | K3: 340 | L3: 298 | M3: 708 | N3: 694 | O3: 568 | P3: 2759 | Q3: 958 | R3: 847 | S3: 895 | T3: 493 | U3: 996 | V3: 138 | W3: 584 | X3: 215 | Y3: 277 | Z3: 205 | AA3: 369 | AB3: 142
A4: 2000 | B4: =SUM(C4:AB4) -> 16571 | C4: 226 | D4: 4477 | E4: 619 | F4: 395 | G4: 245 | H4: 94 | I4: 229 | J4: 500 | K4: 245 | L4: 276 | M4: 570 | N4: 600 | O4: 454 | P4: 2367 | Q4: 799 | R4: 784 | S4: 685 | T4: 452 | U4: 872 | V4: 119 | W4: 501 | X4: 179 | Y4: 289 | Z4: 189 | AA4: 298 | AB4: 107
A5: 2001 | B5: =SUM(C5:AB5) -> 15829 | C5: 229 | D5: 4497 | E5: 704 | F5: 337 | G5: 228 | H5: 114 | I5: 237 | J5: 523 | K5: 233 | L5: 241 | M5: 574 | N5: 569 | O5: 398 | P5: 2110 | Q5: 717 | R5: 666 | S5: 594 | T5: 419 | U5: 809 | V5: 118 | W5: 493 | X5: 182 | Y5: 219 | Z5: 181 | AA5: 326 | AB5: 111
A6: 2002 | B6: =SUM(C6:AB6) -> 22551 | C6: 344 | D6: 5989 | E6: 1014 | F6: 483 | G6: 323 | H6: 163 | I6: 380 | J6: 740 | K6: 342 | L6: 397 | M6: 778 | N6: 875 | O6: 587 | P6: 3147 | Q6: 957 | R6: 1003 | S6: 885 | T6: 623 | U6: 1205 | V6: 143 | W6: 670 | X6: 238 | Y6: 325 | Z6: 269 | AA6: 466 | AB6: 205
A7: 2003 | B7: =SUM(C7:AB7) -> 32971 | C7: 471 | D7: 8991 | E7: 1531 | F7: 710 | G7: 559 | H7: 224 | I7: 581 | J7: 1128 | K7: 543 | L7: 572 | M7: 1179 | N7: 1174 | O7: 907 | P7: 4274 | Q7: 1341 | R7: 1478 | S7: 1328 | T7: 919 | U7: 1693 | V7: 211 | W7: 947 | X7: 438 | Y7: 431 | Z7: 407 | AA7: 639 | AB7: 295
A8: 2004 | B8: =SUM(C8:AB8) -> 50154 | C8: 630 | D8: 14220 | E8: 2356 | F8: 1011 | G8: 758 | H8: 343 | I8: 938 | J8: 1855 | K8: 779 | L8: 797 | M8: 1810 | N8: 1892 | O8: 1401 | P8: 6435 | Q8: 1949 | R8: 2185 | S8: 1846 | T8: 1411 | U8: 2589 | V8: 286 | W8: 1342 | X8: 583 | Y8: 683 | Z8: 610 | AA8: 1049 | AB8: 396
A9: 2005 | B9: =SUM(C9:AB9) -> 70808 | C9: 929 | D9: 20618 | E9: 3276 | F9: 1324 | G9: 1021 | H9: 518 | I9: 1394 | J9: 2621 | K9: 1017 | L9: 1164 | M9: 2466 | N9: 2479 | O9: 1899 | P9: 9076 | Q9: 2726 | R9: 3129 | S9: 2553 | T9: 1992 | U9: 3724 | V9: 385 | W9: 1833 | X9: 829 | Y9: 928 | Z9: 848 | AA9: 1479 | AB9: 580
A10: 2006 | B10: =SUM(C10:AB10) -> 88966 | C10: 1183 | D10: 26739 | E10: 4390 | F10: 1670 | G10: 1272 | H10: 591 | I10: 1713 | J10: 3454 | K10: 1231 | L10: 1389 | M10: 2954 | N10: 3207 | O10: 2277 | P10: 11187 | Q10: 3148 | R10: 3917 | S10: 3126 | T10: 2592 | U10: 4513 | V10: 469 | W10: 2279 | X10: 974 | Y10: 1135 | Z10: 1058 | AA10: 1827 | AB10: 671
A11: 2007 | B11: =SUM(C11:AB11) -> 104302 | C11: 1243 | D11: 32162 | E11: 5243 | F11: 1877 | G11: 1460 | H11: 629 | I11: 2148 | J11: 3976 | K11: 1408 | L11: 1642 | M11: 3320 | N11: 3822 | O11: 2745 | P11: 13166 | Q11: 3655 | R11: 4592 | S11: 3588 | T11: 2818 | U11: 5284 | V11: 496 | W11: 2494 | X11: 1113 | Y11: 1312 | Z11: 1213 | AA11: 2098 | AB11: 798
A12: 2008 | B12: =SUM(C12:AB12) -> 85461 | C12: 1031 | D12: 26722 | E12: 4148 | F12: 1498 | G12: 1185 | H12: 542 | I12: 1829 | J12: 3274 | K12: 1149 | L12: 1276 | M12: 2590 | N12: 2865 | O12: 2230 | P12: 10962 | Q12: 3048 | R12: 3805 | S12: 2825 | T12: 2411 | U12: 4384 | V12: 379 | W12: 2022 | X12: 909 | Y12: 1044 | Z12: 921 | AA12: 1754 | AB12: 658
A13: 2009 | B13: =SUM(C13:AB13) -> 24459 | C13: 287 | D13: 7982 | E13: 1135 | F13: 432 | G13: 307 | H13: 151 | I13: 529 | J13: 876 | K13: 286 | L13: 329 | M13: 708 | N13: 825 | O13: 656 | P13: 3197 | Q13: 814 | R13: 1032 | S13: 750 | T13: 677 | U13: 1159 | V13: 120 | W13: 514 | X13: 250 | Y13: 334 | Z13: 271 | AA13: 647 | AB13: 191
A14: 2010 | B14: =SUM(C14:AB14) -> 30985 | C14: 292 | D14: 10529 | E14: 1317 | F14: 585 | G14: 322 | H14: 188 | I14: 651 | J14: 1013 | K14: 333 | L14: 438 | M14: 860 | N14: 1040 | O14: 756 | P14: 4226 | Q14: 992 | R14: 1357 | S14: 927 | T14: 813 | U14: 1397 | V14: 163 | W14: 697 | X14: 341 | Y14: 395 | Z14: 332 | AA14: 741 | AB14: 280
A15: 2011 | B15: =SUM(C15:AB15) -> 26759 | C15: 234 | D15: 9685 | E15: 1134 | F15: 458 | G15: 292 | H15: 137 | I15: 654 | J15: 886 | K15: 310 | L15: 376 | M15: 723 | N15: 899 | O15: 612 | P15: 3459 | Q15: 766 | R15: 1053 | S15: 769 | T15: 748 | U15: 1167 | V15: 147 | W15: 523 | X15: 254 | Y15: 296 | Z15: 243 | AA15: 734 | AB15: 200
... A23: 2019 | B23: =SUM(C23:AB23) -> 39089 | C23: 389 | D23: 14690 | E23: 1760 | F23: 595 | G23: 384 | H23: 179 | I23: 1062 | J23: 1260 | K23: 352 | L23: 433 | M23: 1210 | N23: 1145 | O23: 834 | P23: 4918 | Q23: 802 | R23: 1372 | S23: 855 | T23: 1261 | U23: 1359 | V23: 148 | W23: 672 | X23: 1399 | Y23: 373 | Z23: 343 | AA23: 978 | AB23: 316
A24: Source: CSO, Table THA17
A27: =B2 -> IE
B29: 2019 | F29: Survival Rates for Light Medium gasoline
A30: Total | B30: =SUM(B31:B51) -> 900661 | F30: Vintage | G30: Sur Rates
A31: 1999 or before | B31: =B3 -> 18684 | F31: 0 | G31: 1 | I31: 1
A32: 2000 | B32: =B4 -> 16571 | F32: 1 | G32: 1.15 | I32: 1.08
A33: 2001 | B33: =B5 -> 15829 | F33: 2 | G33: 1.12 | I33: 1.05
A34: 2002 | B34: =B6 -> 22551 | F34: 3 | G34: 1.08 | I34: 1.02
A35: 2003 | B35: =B7 -> 32971 | F35: 4 | G35: 1.05 | I35: 1
A36: 2004 | B36: =B8 -> 50154 | F36: 5 | G36: 1.1 | I36: 1
A37: 2005 | B37: =B9 -> 70808 | F37: 6 | G37: 1 | I37: 1
A38: 2006 | B38: =B10 -> 88966 | F38: 7 | G38: 1.03 | I38: 1
A39: 2007 | B39: =B11 -> 104302 | F39: 8 | G39: 1.1 | I39: 1
A40: 2008 | B40: =B12 -> 85461 | F40: 9 | G40: 1.25 | I40: 1
A41: 2009 | B41: =B13 -> 24459 | F41: 10 | G41: 1.15 | I41: 1.1
A42: 2010 | B42: =B14 -> 30985 | F42: 11 | G42: 1.02 | I42: 1
A43: 2011 | B43: =B15 -> 26759 | F43: 12 | G43: 0.88 | I43: 0.99
... A51: 2019 | B51: =B23 -> 39089 | F51: 20 | G51: 0.1375633 | I51: 0.2
F52: 21 | G52: 0.11005064 | I52: 0.16
F53: 22 | G53: 0.082537977 | I53: 0.12
F54: 23 | G54: 0.055025318 | I54: 0.08
F55: 24 | G55: 0.027512659 | I55: 0.04
F56: 25 | G56: 0
F57: Source: Irish_TIMES 2.0
...

Sheet Motors
A1: Motorcycles (number)
A2: Year of Registration | B2: IE | C2: Carlow | D2: Dublin | E2: Kildare | F2: Kilkenny | G2: Laois | H2: Longford | I2: Louth | J2: Meath | K2: Offaly | L2: Westmeath | M2: Wexford | N2: Wicklow | O2: Clare | P2: Cork | Q2: Kerry | R2: Limerick | S2: Tipperary | T2: Waterford | U2: Galway | V2: Leitrim | W2: Mayo | X2: Roscommon | Y2: Sligo | Z2: Cavan | AA2: Donegal | AB2: Monaghan
A3: 1999 or before | B3: =SUM(C3:AB3) -> 2028 | C3: 34 | D3: 471 | E3: 103 | F3: 57 | G3: 29 | H3: 13 | I3: 39 | J3: 71 | K3: 45 | L3: 35 | M3: 91 | N3: 81 | O3: 49 | P3: 334 | Q3: 64 | R3: 85 | S3: 76 | T3: 91 | U3: 81 | V3: 9 | W3: 35 | X3: 20 | Y3: 42 | Z3: 27 | AA3: 33 | AB3: 13
A4: 2000 | B4: =SUM(C4:AB4) -> 1029 | C4: 23 | D4: 232 | E4: 52 | F4: 21 | G4: 14 | H4: 9 | I4: 16 | J4: 57 | K4: 20 | L4: 20 | M4: 40 | N4: 54 | O4: 24 | P4: 160 | Q4: 41 | R4: 45 | S4: 39 | T4: 55 | U4: 38 | V4: 8 | W4: 20 | X4: 4 | Y4: 6 | Z4: 13 | AA4: 13 | AB4: 5
A5: 2001 | B5: =SUM(C5:AB5) -> 1313 | C5: 26 | D5: 345 | E5: 81 | F5: 34 | G5: 16 | H5: 7 | I5: 32 | J5: 56 | K5: 19 | L5: 23 | M5: 58 | N5: 51 | O5: 37 | P5: 171 | Q5: 40 | R5: 52 | S5: 46 | T5: 50 | U5: 59 | V5: 7 | W5: 22 | X5: 13 | Y5: 18 | Z5: 16 | AA5: 23 | AB5: 11
A6: 2002 | B6: =SUM(C6:AB6) -> 1496 | C6: 28 | D6: 387 | E6: 82 | F6: 35 | G6: 14 | H6: 13 | I6: 25 | J6: 65 | K6: 39 | L6: 24 | M6: 70 | N6: 68 | O6: 39 | P6: 203 | Q6: 43 | R6: 62 | S6: 56 | T6: 67 | U6: 65 | V6: 4 | W6: 23 | X6: 10 | Y6: 24 | Z6: 19 | AA6: 22 | AB6: 9
A7: 2003 | B7: =SUM(C7:AB7) -> 1451 | C7: 29 | D7: 387 | E7: 87 | F7: 40 | G7: 19 | H7: 7 | I7: 32 | J7: 64 | K7: 19 | L7: 26 | M7: 77 | N7: 58 | O7: 41 | P7: 203 | Q7: 39 | R7: 59 | S7: 55 | T7: 56 | U7: 55 | V7: 6 | W7: 21 | X7: 10 | Y7: 12 | Z7: 16 | AA7: 22 | AB7: 11
A8: 2004 | B8: =SUM(C8:AB8) -> 1597 | C8: 22 | D8: 417 | E8: 106 | F8: 38 | G8: 20 | H8: 10 | I8: 38 | J8: 79 | K8: 27 | L8: 23 | M8: 70 | N8: 65 | O8: 38 | P8: 265 | Q8: 40 | R8: 54 | S8: 75 | T8: 53 | U8: 59 | V8: 6 | W8: 26 | X8: 6 | Y8: 13 | Z8: 10 | AA8: 25 | AB8: 12
A9: 2005 | B9: =SUM(C9:AB9) -> 1823 | C9: 31 | D9: 501 | E9: 112 | F9: 53 | G9: 18 | H9: 7 | I9: 33 | J9: 79 | K9: 44 | L9: 39 | M9: 74 | N9: 68 | O9: 47 | P9: 246 | Q9: 49 | R9: 83 | S9: 76 | T9: 64 | U9: 74 | V9: 3 | W9: 32 | X9: 15 | Y9: 16 | Z9: 22 | AA9: 30 | AB9: 7
A10: 2006 | B10: =SUM(C10:AB10) -> 2160 | C10: 36 | D10: 618 | E10: 102 | F10: 37 | G10: 27 | H10: 18 | I10: 46 | J10: 94 | K10: 42 | L10: 34 | M10: 88 | N10: 98 | O10: 48 | P10: 314 | Q10: 66 | R10: 89 | S10: 93 | T10: 78 | U10: 92 | V10: 10 | W10: 31 | X10: 12 | Y10: 24 | Z10: 20 | AA10: 31 | AB10: 12
A11: 2007 | B11: =SUM(C11:AB11) -> 2705 | C11: 45 | D11: 821 | E11: 142 | F11: 60 | G11: 37 | H11: 18 | I11: 66 | J11: 100 | K11: 49 | L11: 43 | M11: 110 | N11: 110 | O11: 63 | P11: 371 | Q11: 64 | R11: 82 | S11: 101 | T11: 108 | U11: 116 | V11: 4 | W11: 45 | X11: 27 | Y11: 23 | Z11: 35 | AA11: 44 | AB11: 21
A12: 2008 | B12: =SUM(C12:AB12) -> 2781 | C12: 41 | D12: 841 | E12: 142 | F12: 71 | G12: 42 | H12: 14 | I12: 51 | J12: 137 | K12: 57 | L12: 36 | M12: 103 | N12: 119 | O12: 65 | P12: 402 | Q12: 90 | R12: 109 | S12: 113 | T12: 92 | U12: 95 | V12: 11 | W12: 44 | X12: 11 | Y12: 24 | Z12: 20 | AA12: 41 | AB12: 10
A13: 2009 | B13: =SUM(C13:AB13) -> 2133 | C13: 34 | D13: 626 | E13: 121 | F13: 41 | G13: 36 | H13: 9 | I13: 37 | J13: 95 | K13: 31 | L13: 30 | M13: 78 | N13: 82 | O13: 59 | P13: 317 | Q13: 60 | R13: 75 | S13: 76 | T13: 50 | U13: 88 | V13: 10 | W13: 28 | X13: 15 | Y13: 22 | Z13: 28 | AA13: 61 | AB13: 24
A14: 2010 | B14: =SUM(C14:AB14) -> 1579 | C14: 25 | D14: 443 | E14: 71 | F14: 39 | G14: 27 | H14: 9 | I14: 28 | J14: 59 | K14: 25 | L14: 23 | M14: 76 | N14: 57 | O14: 37 | P14: 210 | Q14: 45 | R14: 71 | S14: 67 | T14: 47 | U14: 62 | V14: 10 | W14: 30 | X14: 19 | Y14: 29 | Z14: 16 | AA14: 38 | AB14: 16
A15: 2011 | B15: =SUM(C15:AB15) -> 1243 | C15: 12 | D15: 396 | E15: 76 | F15: 19 | G15: 16 | H15: 6 | I15: 26 | J15: 49 | K15: 22 | L15: 18 | M15: 33 | N15: 36 | O15: 22 | P15: 172 | Q15: 25 | R15: 46 | S15: 56 | T15: 37 | U15: 53 | V15: 8 | W15: 24 | X15: 9 | Y15: 13 | Z15: 20 | AA15: 30 | AB15: 19
... A23: 2019 | B23: =SUM(C23:AB23) -> 2568 | C23: 40 | D23: 941 | E23: 147 | F23: 44 | G23: 19 | H23: 19 | I23: 66 | J23: 127 | K23: 43 | L23: 29 | M23: 76 | N23: 99 | O23: 53 | P23: 302 | Q23: 64 | R23: 89 | S23: 68 | T23: 64 | U23: 83 | V23: 12 | W23: 34 | X23: 22 | Y23: 17 | Z23: 34 | AA23: 55 | AB23: 21
A24: Source: CSO, Table THA17
A27: =B2 -> IE
B29: 2019 | F29: Survival Rates for Heavy Medium Diesel
A30: Total | B30: =SUM(B31:B51) -> 41473 | F30: Vintage | G30: Sur Rates
A31: 1999 or before | B31: =B3 -> 2028 | F31: 0 | G31: 1
A32: 2000 | B32: =B4 -> 1029 | F32: 1 | G32: 1
A33: 2001 | B33: =B5 -> 1313 | F33: 2 | G33: 1
A34: 2002 | B34: =B6 -> 1496 | F34: 3 | G34: 1
A35: 2003 | B35: =B7 -> 1451 | F35: 4 | G35: 1
A36: 2004 | B36: =B8 -> 1597 | F36: 5 | G36: 1
A37: 2005 | B37: =B9 -> 1823 | F37: 6 | G37: 1
A38: 2006 | B38: =B10 -> 2160 | F38: 7 | G38: 1
A39: 2007 | B39: =B11 -> 2705 | F39: 8 | G39: 1
A40: 2008 | B40: =B12 -> 2781 | F40: 9 | G40: 0.98643404
A41: 2009 | B41: =B13 -> 2133 | F41: 10 | G41: 0.92357047
A42: 2010 | B42: =B14 -> 1579 | F42: 11 | G42: 0.83469918
A43: 2011 | B43: =B15 -> 1243 | F43: 12 | G43: 0.72545709
... A51: 2019 | B51: =B23 -> 2568 | F51: 20 | G51: 0.17356157
F52: 21 | G52: 0.13884926
F53: 22 | G53: 0.10413694
F54: 23 | G54: 0.069424629
F55: 24 | G55: 0.034712315
F56: 25 | G56: 0
F57: Source: Irish_TIMES 2.0
...

Sheet Stock retirement
A3: Vehicle Stock in 2018
A4: TechName | B4: *Unit | C4: Comm-IN | D4: Comm-OUT | E4: =Regions!C3 -> IE | F4: =Regions!E3 -> IE-CW | G4: =Regions!F3 -> IE-D | H4: =Regions!G3 -> IE-KE | I4: =Regions!H3 -> IE-KK | J4: =Regions!I3 -> IE-LS | K4: =Regions!J3 -> IE-LD | L4: =Regions!K3 -> IE-LH | M4: =Regions!L3 -> IE-MH | ... AE4: =Regions!AD3 -> IE-MN
A5: T-MOT-ICE_GSL00 | B5: 000_Units | C5: TRAGSL,TRAETH | D5: TRAPS,TRAPM | E5: 39.852 | F5: 0.563 | G5: 12.616 | H5: 2.168 | I5: 0.872 | J5: 0.513 | K5: 0.213 | L5: 0.855 | M5: 1.684 | N5: 0.669 | O5: 0.604 | P5: 1.506 | Q5: 1.554 | R5: 0.924 | S5: 5.452 | T5: 1.062 | U5: 1.489 | V5: 1.412 | W5: 1.293 | X5: 1.458 | Y5: 0.16 | Z5: 0.605 | AA5: 0.295 | AB5: 0.4 | AC5: 0.448 | AD5: 0.736 | AE5: 0.301
A6: T-CAR-ICE_GSL00 | B6: 000_Units | C6: TRAGSL,TRAETH | D6: TRAPS,TRAPM,TRAPL | E6: 946.86 | F6: 10.796 | G6: 299.408 | H6: 44.521 | I6: 17.346 | J6: 12.391 | K6: 5.804 | L6: 20.722 | M6: 34.216 | N6: 12.252 | O6: 14.417 | P6: 29.236 | Q6: 32.847 | R6: 24.057 | S6: 121.228 | T6: 31.727 | U6: 40.146 | V6: 30.854 | W6: 27.159 | X6: 45.82 | Y6: 4.961 | Z6: 22.404 | AA6: 11.971 | AB6: 11.761 | AC6: 10.568 | AD6: 22.398 | AE6: 7.85
A7: T-CAR-ICE_DST00 | B7: 000_Units | C7: TRADST,TRABDL | D7: TRAPS,TRAPM,TRAPL | E7: 1129.404 | F7: 17.385 | G7: 225.706 | H7: 56.834 | I7: 26.674 | J7: 22.058 | K7: 11.27 | L7: 29.947 | M7: 52.424 | N7: 21.785 | O7: 26.113 | P7: 44.971 | Q7: 34.195 | R7: 32.584 | S7: 132.295 | T7: 39.247 | U7: 47.853 | V7: 47.714 | W7: 29.674 | X7: 66.337 | Y7: 9.454 | Z7: 37.994 | AA7: 20.248 | AB7: 16.993 | AC7: 20.89 | AD7: 41.125 | AE7: 17.634
A8: T-CAR-ICE_DF00 | B8: 000_Units | C8: TRAGSL,TRACNG | D8: TRAPS,TRAPM,TRAPL | E8: 0.067 | F8: 0 | G8: 0.028 | H8: 0.001 | I8: 0.001 | J8: 0 | K8: 0.002 | L8: 0.001 | M8: 0.002 | N8: 0.003 | O8: 0.001 | P8: 0.003 | Q8: 0.005 | R8: 0.001 | S8: 0.005 | T8: 0.003 | U8: 0.002 | V8: 0 | W8: 0 | X8: 0.007 | Y8: 0 | Z8: 0 | AA8: 0 | AB8: 0 | AC8: 0 | AD8: 0.002 | AE8: 0
A9: T-CAR-ICE_E8500 | B9: 000_Units | C9: TRAGSL,TRAETH | D9: TRAPS,TRAPM,TRAPL | E9: 8.529 | F9: 0.098 | G9: 0.265 | H9: 0.281 | I9: 0.574 | J9: 0.124 | K9: 0.316 | L9: 0.041 | M9: 0.083 | N9: 0.053 | O9: 0.26 | P9: 0.177 | Q9: 0.315 | R9: 0.205 | S9: 1.162 | T9: 0.35 | U9: 0.033 | V9: 0.075 | W9: 0.229 | X9: 2.626 | Y9: 0.107 | Z9: 0.247 | AA9: 0.085 | AB9: 0.075 | AC9: 0.091 | AD9: 0.185 | AE9: 0.472
A10: T-CAR-HEV_GSL00 | B10: 000_Units | C10: TRAGSL,TRAETH | D10: TRAPS,TRAPM,TRAPL | E10: 29.8 | F10: 0.205 | G10: 1.109 | H10: 0.572 | I10: 1.428 | J10: 0.365 | K10: 0.805 | L10: 0.159 | M10: 0.457 | N10: 0.161 | O10: 0.418 | P10: 0.488 | Q10: 0.616 | R10: 0.492 | S10: 2.929 | T10: 1.663 | U10: 0.09 | V10: 0.273 | W10: 0.565 | X10: 13.569 | Y10: 0.307 | Z10: 0.583 | AA10: 0.347 | AB10: 0.265 | AC10: 0.256 | AD10: 0.573 | AE10: 1.105
A11: T-CAR-HEV_DST00 | B11: 000_Units | C11: TRADST,TRABDL | D11: TRAPS,TRAPM,TRAPL | E11: 0.773 | F11: 0.014 | G11: 0.033 | H11: 0.019 | I11: 0.043 | J11: 0.016 | K11: 0.024 | L11: 0.008 | M11: 0.013 | N11: 0.01 | O11: 0.023 | P11: 0.016 | Q11: 0.017 | R11: 0.013 | S11: 0.071 | T11: 0.032 | U11: 0.002 | V11: 0.004 | W11: 0.013 | X11: 0.287 | Y11: 0.016 | Z11: 0.017 | AA11: 0.011 | AB11: 0.005 | AC11: 0.016 | AD11: 0.012 | AE11: 0.038
A12: T-CAR-PHEV_GSL00 | B12: 000_Units | C12: TRAGSL,TRAELC | D12: TRAPS,TRAPM,TRAPL | E12: 2.759 | F12: 0.015 | G12: 0.109 | H12: 0.033 | I12: 0.15 | J12: 0.024 | K12: 0.054 | L12: 0.018 | M12: 0.023 | N12: 0.01 | O12: 0.032 | P12: 0.035 | Q12: 0.042 | R12: 0.037 | S12: 0.262 | T12: 0.152 | U12: 0.003 | V12: 0.023 | W12: 0.04 | X12: 1.43 | Y12: 0.017 | Z12: 0.047 | AA12: 0.018 | AB12: 0.016 | AC12: 0.024 | AD12: 0.037 | AE12: 0.108
A13: T-CAR-PHEV_DST00 | B13: 000_Units | C13: TRADST,TRAELC | D13: TRAPS,TRAPM,TRAPL | E13: 0.025 | F13: 0 | G13: 0.011 | H13: 0.002 | I13: 0 | J13: 0 | K13: 0.001 | L13: 0 | M13: 0.001 | N13: 0 | O13: 0 | P13: 0.001 | Q13: 0.001 | R13: 0.002 | S13: 0.002 | T13: 0 | U13: 0 | V13: 0.001 | W13: 0 | X13: 0 | Y13: 0 | Z13: 0 | AA13: 0 | AB13: 0.001 | AC13: 0 | AD13: 0.001 | AE13: 0.001
A14: T-CAR-BEV_ELC00 | B14: 000_Units | C14: TRAELC | D14: TRAPS,TRAPM,TRAPL | E14: 4.53 | F14: 0.046 | G14: 1.676 | H14: 0.292 | I14: 0.054 | J14: 0.056 | K14: 0.024 | L14: 0.103 | M14: 0.239 | N14: 0.029 | O14: 0.098 | P14: 0.141 | Q14: 0.257 | R14: 0.107 | S14: 0.514 | T14: 0.098 | U14: 0.123 | V14: 0.094 | W14: 0.1 | X14: 0.228 | Y14: 0.017 | Z14: 0.058 | AA14: 0.03 | AB14: 0.029 | AC14: 0.035 | AD14: 0.051 | AE14: 0.031
A15: T-TAX-ICE_GSL00 | B15: 000_Units | C15: TRAGSL,TRAETH | D15: TRAPS,TRAPM,TRAPL | E15: 2.5 | F15: 0.01 | G15: 1.579 | H15: 0.071 | I15: 0.01 | J15: 0.012 | K15: 0.004 | L15: 0.048 | M15: 0.095 | N15: 0.014 | O15: 0.014 | P15: 0.017 | Q15: 0.031 | R15: 0.044 | S15: 0.164 | T15: 0.028 | U15: 0.125 | V15: 0.012 | W15: 0.044 | X15: 0.115 | Y15: 0 | Z15: 0.02 | AA15: 0.003 | AB15: 0.012 | AC15: 0.007 | AD15: 0.017 | AE15: 0.004
A16: T-TAX-ICE_DST00 | B16: 000_Units | C16: TRADST,TRABDL | D16: TRAPS,TRAPM,TRAPL | E16: 17.463 | F16: 0.147 | G16: 8.514 | H16: 0.715 | I16: 0.204 | J16: 0.2 | K16: 0.083 | L16: 0.508 | M16: 0.832 | N16: 0.15 | O16: 0.259 | P16: 0.25 | Q16: 0.315 | R16: 0.301 | S16: 1.538 | T16: 0.436 | U16: 0.487 | V16: 0.241 | W16: 0.262 | X16: 0.822 | Y16: 0.065 | Z16: 0.27 | AA16: 0.129 | AB16: 0.155 | AC16: 0.157 | AD16: 0.348 | AE16: 0.075
... A22: T-HGT-ICE_DST00 | B22: 000_Units | C22: TRADST,TRABDL | D22: TRAF | E22: 21.648 | F22: 0.39 | G22: 3.883 | H22: 1.112 | I22: 0.713 | J22: 0.455 | K22: 0.276 | L22: 0.617 | M22: 1.424 | N22: 0.323 | O22: 0.316 | P22: 1.39 | Q22: 0.396 | R22: 0.397 | S22: 2.558 | T22: 0.516 | U22: 0.941 | V22: 1.05 | W22: 0.358 | X22: 1.026 | Y22: 0.135 | Z22: 0.57 | AA22: 0.326 | AB22: 0.232 | AC22: 0.488 | AD22: 0.72 | AE22: 1.036
A28: ~TFM_INS-TS
A29: Region | B29: Attribute | C29: Pset_PN | D29: 2020 | E29: 2021 | F29: 2022 | G29: 2023 | H29: 2024 | I29: 2025 | J29: 2026 | K29: 2027 | L29: 2028 | M29: 2029 | N29: 2030 | O29: 2031 | P29: 2032 | Q29: 2033 | R29: 2034 | S29: 2035 | T29: 2036 | U29: 2037 | V29: 2038 | W29: 2039 | X29: 2040 | Y29: 2041 | Z29: 2042
A30: =Regions!C3 -> IE | B30: =IF(LEFT(A30,1)="*","*","STOCK") -> STOCK | C30: =A5 -> T-MOT-ICE_GSL00 | D30: =Stock_CSO!B6 -> 41.471 | E30: =IF($D30*Motors!C1782>0.01,$D30*Motors!C1782,0) -> 31.505749 | F30: =IF($D30*Motors!D1782>0.01,$D30*Motors!D1782,0) -> 26.7704 | G30: =IF($D30*Motors!E1782>0.01,$D30*Motors!E1782,0) -> 23.670508 | H30: =IF($D30*Motors!F1782>0.01,$D30*Motors!F1782,0) -> 21.374394 | I30: =IF($D30*Motors!G1782>0.01,$D30*Motors!G1782,0) -> 19.587094 | J30: =IF($D30*Motors!H1782>0.01,$D30*Motors!H1782,0) -> 18.102451 | K30: =IF($D30*Motors!I1782>0.01,$D30*Motors!I1782,0) -> 16.71674 | L30: =IF($D30*Motors!J1782>0.01,$D30*Motors!J1782,0) -> 15.221162 | ... Z30: =IF($D30*Motors!X1782>0.01,$D30*Motors!X1782,0) -> 0
A31: =Regions!E3 -> IE-CW | B31: =IF(LEFT(A31,1)="*","*","STOCK") -> STOCK | C31: =C30 -> T-MOT-ICE_GSL00 | D31: =Stock_CSO!B7 -> 0.609 | E31: =$D31*Motors!C1783 -> 0.43347187 | F31: =$D31*Motors!D1783 -> 0.35374302 | G31: =$D31*Motors!E1783 -> 0.30408906 | H31: =$D31*Motors!F1783 -> 0.26881761 | I31: =$D31*Motors!G1783 -> 0.24241892 | J31: =$D31*Motors!H1783 -> 0.22114396 | K31: =$D31*Motors!I1783 -> 0.20223904 | L31: =$D31*Motors!J1783 -> 0.18307072 | ... Z31: =$D31*Motors!X1783 -> 2.625988e-07
A32: =Regions!F3 -> IE-D | B32: =IF(LEFT(A32,1)="*","*","STOCK") -> STOCK | C32: =C31 -> T-MOT-ICE_GSL00 | D32: =Stock_CSO!B8 -> 12.986 | E32: =$D32*Motors!C1784 -> 10.371331 | F32: =$D32*Motors!D1784 -> 9.0465297 | G32: =$D32*Motors!E1784 -> 8.145999 | H32: =$D32*Motors!F1784 -> 7.4656945 | I32: =$D32*Motors!G1784 -> 6.9263587 | J32: =$D32*Motors!H1784 -> 6.4631617 | K32: =$D32*Motors!I1784 -> 6.0089587 | L32: =$D32*Motors!J1784 -> 5.4952823 | ... Z32: =$D32*Motors!X1784 -> 6.516176e-06
A33: =Regions!G3 -> IE-KE | B33: =IF(LEFT(A33,1)="*","*","STOCK") -> STOCK | C33: =C32 -> T-MOT-ICE_GSL00 | D33: =Stock_CSO!B9 -> 2.275 | E33: =$D33*Motors!C1785 -> 1.719164 | F33: =$D33*Motors!D1785 -> 1.4591844 | G33: =$D33*Motors!E1785 -> 1.2937001 | H33: =$D33*Motors!F1785 -> 1.1721648 | I33: =$D33*Motors!G1785 -> 1.0776644 | J33: =$D33*Motors!H1785 -> 0.99920417 | K33: =$D33*Motors!I1785 -> 0.92645354 | L33: =$D33*Motors!J1785 -> 0.84833812 | ... Z33: =$D33*Motors!X1785 -> 1.0157745e-06
A34: =Regions!H3 -> IE-KK | B34: =IF(LEFT(A34,1)="*","*","STOCK") -> STOCK | C34: =C33 -> T-MOT-ICE_GSL00 | D34: =Stock_CSO!B10 -> 0.885 | E34: =$D34*Motors!C1786 -> 0.63871831 | F34: =$D34*Motors!D1786 -> 0.52738093 | G34: =$D34*Motors!E1786 -> 0.45718255 | H34: =$D34*Motors!F1786 -> 0.40568965 | I34: =$D34*Motors!G1786 -> 0.36595209 | J34: =$D34*Motors!H1786 -> 0.3334849 | K34: =$D34*Motors!I1786 -> 0.30396395 | L34: =$D34*Motors!J1786 -> 0.27332721 | ... Z34: =$D34*Motors!X1786 -> 3.0300816e-07
A35: =Regions!I3 -> IE-LS | B35: =IF(LEFT(A35,1)="*","*","STOCK") -> STOCK | C35: =C34 -> T-MOT-ICE_GSL00 | D35: =Stock_CSO!B11 -> 0.507 | E35: =$D35*Motors!C1787 -> 0.38089204 | F35: =$D35*Motors!D1787 -> 0.31903046 | G35: =$D35*Motors!E1787 -> 0.27546882 | H35: =$D35*Motors!F1787 -> 0.2418708 | I35: =$D35*Motors!G1787 -> 0.21617108 | J35: =$D35*Motors!H1787 -> 0.19626373 | K35: =$D35*Motors!I1787 -> 0.17924522 | L35: =$D35*Motors!J1787 -> 0.16182074 | ... Z35: =$D35*Motors!X1787 -> 1.3967684e-07
A36: =Regions!J3 -> IE-LD | B36: =IF(LEFT(A36,1)="*","*","STOCK") -> STOCK | C36: =C35 -> T-MOT-ICE_GSL00 | D36: =Stock_CSO!B12 -> 0.233 | E36: =$D36*Motors!C1788 -> 0.16863832 | F36: =$D36*Motors!D1788 -> 0.13941711 | G36: =$D36*Motors!E1788 -> 0.12122155 | H36: =$D36*Motors!F1788 -> 0.10880297 | I36: =$D36*Motors!G1788 -> 0.099914964 | J36: =$D36*Motors!H1788 -> 0.092930423 | K36: =$D36*Motors!I1788 -> 0.08664731 | L36: =$D36*Motors!J1788 -> 0.07984886 | ... Z36: =$D36*Motors!X1788 -> 1.2611474e-07
A37: =Regions!K3 -> IE-LH | B37: =IF(LEFT(A37,1)="*","*","STOCK") -> STOCK | C37: =C36 -> T-MOT-ICE_GSL00 | D37: =Stock_CSO!B13 -> 0.894 | E37: =$D37*Motors!C1789 -> 0.69116379 | F37: =$D37*Motors!D1789 -> 0.59394123 | G37: =$D37*Motors!E1789 -> 0.53122706 | H37: =$D37*Motors!F1789 -> 0.48629763 | I37: =$D37*Motors!G1789 -> 0.45251522 | J37: =$D37*Motors!H1789 -> 0.42446557 | K37: =$D37*Motors!I1789 -> 0.39758989 | L37: =$D37*Motors!J1789 -> 0.3671766 | ... Z37: =$D37*Motors!X1789 -> 4.5404213e-07
A38: =Regions!L3 -> IE-MH | B38: =IF(LEFT(A38,1)="*","*","STOCK") -> STOCK | C38: =C37 -> T-MOT-ICE_GSL00 | D38: =Stock_CSO!B14 -> 1.801 | E38: =$D38*Motors!C1790 -> 1.3699001 | F38: =$D38*Motors!D1790 -> 1.1628141 | G38: =$D38*Motors!E1790 -> 1.0286676 | H38: =$D38*Motors!F1790 -> 0.93063054 | I38: =$D38*Motors!G1790 -> 0.855701 | J38: =$D38*Motors!H1790 -> 0.79532006 | K38: =$D38*Motors!I1790 -> 0.73916562 | L38: =$D38*Motors!J1790 -> 0.6767716 | ... Z38: =$D38*Motors!X1790 -> 8.5893766e-07
A39: =Regions!M3 -> IE-OY | B39: =IF(LEFT(A39,1)="*","*","STOCK") -> STOCK | C39: =C38 -> T-MOT-ICE_GSL00 | D39: =Stock_CSO!B15 -> 0.692 | E39: =$D39*Motors!C1791 -> 0.49684195 | F39: =$D39*Motors!D1791 -> 0.40627938 | G39: =$D39*Motors!E1791 -> 0.34917729 | H39: =$D39*Motors!F1791 -> 0.30917369 | I39: =$D39*Motors!G1791 -> 0.28039157 | J39: =$D39*Motors!H1791 -> 0.25872702 | K39: =$D39*Motors!I1791 -> 0.24013028 | L39: =$D39*Motors!J1791 -> 0.22093616 | ... Z39: =$D39*Motors!X1791 -> 2.9336243e-07
A40: =Regions!N3 -> IE-WH | B40: =IF(LEFT(A40,1)="*","*","STOCK") -> STOCK | C40: =C39 -> T-MOT-ICE_GSL00 | D40: =Stock_CSO!B16 -> 0.622 | E40: =$D40*Motors!C1792 -> 0.45227353 | F40: =$D40*Motors!D1792 -> 0.37510674 | G40: =$D40*Motors!E1792 -> 0.32778255 | H40: =$D40*Motors!F1792 -> 0.29467273 | I40: =$D40*Motors!G1792 -> 0.2700036 | J40: =$D40*Motors!H1792 -> 0.25015303 | K40: =$D40*Motors!I1792 -> 0.23208204 | L40: =$D40*Motors!J1792 -> 0.2125529 | ... Z40: =$D40*Motors!X1792 -> 2.1288163e-07
A41: =Regions!O3 -> IE-WX | B41: =IF(LEFT(A41,1)="*","*","STOCK") -> STOCK | C41: =C40 -> T-MOT-ICE_GSL00 | D41: =Stock_CSO!B17 -> 1.571 | E41: =$D41*Motors!C1793 -> 1.1358097 | F41: =$D41*Motors!D1793 -> 0.9377869 | G41: =$D41*Motors!E1793 -> 0.81318049 | H41: =$D41*Motors!F1793 -> 0.72309832 | I41: =$D41*Motors!G1793 -> 0.6543146 | J41: =$D41*Motors!H1793 -> 0.59816174 | K41: =$D41*Motors!I1793 -> 0.54694886 | L41: =$D41*Motors!J1793 -> 0.49260927 | ... Z41: =$D41*Motors!X1793 -> 5.2202729e-07
A42: =Regions!P3 -> IE-WW | B42: =IF(LEFT(A42,1)="*","*","STOCK") -> STOCK | C42: =C41 -> T-MOT-ICE_GSL00 | D42: =Stock_CSO!B18 -> 1.646 | E42: =$D42*Motors!C1794 -> 1.2284311 | F42: =$D42*Motors!D1794 -> 1.0318673 | G42: =$D42*Motors!E1794 -> 0.90577404 | H42: =$D42*Motors!F1794 -> 0.81532584 | I42: =$D42*Motors!G1794 -> 0.74654771 | J42: =$D42*Motors!H1794 -> 0.68989101 | K42: =$D42*Motors!I1794 -> 0.63688312 | L42: =$D42*Motors!J1794 -> 0.57928673 | ... Z42: =$D42*Motors!X1794 -> 6.7893192e-07
A43: =Regions!Q3 -> IE-CE | B43: =IF(LEFT(A43,1)="*","*","STOCK") -> STOCK | C43: =C42 -> T-MOT-ICE_GSL00 | D43: =Stock_CSO!B19 -> 0.99 | E43: =$D43*Motors!C1795 -> 0.74120249 | F43: =$D43*Motors!D1795 -> 0.6249805 | G43: =$D43*Motors!E1795 -> 0.5502558 | H43: =$D43*Motors!F1795 -> 0.49541429 | I43: =$D43*Motors!G1795 -> 0.45295133 | J43: =$D43*Motors!H1795 -> 0.41718702 | K43: =$D43*Motors!I1795 -> 0.38283795 | L43: =$D43*Motors!J1795 -> 0.34506532 | ... Z43: =$D43*Motors!X1795 -> 3.6872724e-07
A44: =Regions!R3 -> IE-CO | B44: =IF(LEFT(A44,1)="*","*","STOCK") -> STOCK | C44: =C43 -> T-MOT-ICE_GSL00 | D44: =Stock_CSO!B20 -> 5.59 | E44: =$D44*Motors!C1796 -> 4.1228617 | F44: =$D44*Motors!D1796 -> 3.4437293 | G44: =$D44*Motors!E1796 -> 3.0017972 | H44: =$D44*Motors!F1796 -> 2.6752556 | I44: =$D44*Motors!G1796 -> 2.4231265 | J44: =$D44*Motors!H1796 -> 2.21932 | K44: =$D44*Motors!I1796 -> 2.0371249 | L44: =$D44*Motors!J1796 -> 1.8483398 | ... Z44: =$D44*Motors!X1796 -> 2.0972755e-06
A45: =Regions!S3 -> IE-KY | B45: =IF(LEFT(A45,1)="*","*","STOCK") -> STOCK | C45: =C44 -> T-MOT-ICE_GSL00 | D45: =Stock_CSO!B21 -> 1.112 | E45: =$D45*Motors!C1797 -> 0.81774663 | F45: =$D45*Motors!D1797 -> 0.68261423 | G45: =$D45*Motors!E1797 -> 0.59527751 | H45: =$D45*Motors!F1797 -> 0.53174001 | I45: =$D45*Motors!G1797 -> 0.48417813 | J45: =$D45*Motors!H1797 -> 0.447389 | K45: =$D45*Motors!I1797 -> 0.41451534 | L45: =$D45*Motors!J1797 -> 0.37893347 | ... Z45: =$D45*Motors!X1797 -> 4.4151304e-07
A46: =Regions!T3 -> IE-LK | B46: =IF(LEFT(A46,1)="*","*","STOCK") -> STOCK | C46: =C45 -> T-MOT-ICE_GSL00 | D46: =Stock_CSO!B22 -> 1.566 | E46: =$D46*Motors!C1798 -> 1.1673892 | F46: =$D46*Motors!D1798 -> 0.98382528 | G46: =$D46*Motors!E1798 -> 0.86644053 | H46: =$D46*Motors!F1798 -> 0.77925717 | I46: =$D46*Motors!G1798 -> 0.70978055 | J46: =$D46*Motors!H1798 -> 0.65141828 | K46: =$D46*Motors!I1798 -> 0.59753292 | L46: =$D46*Motors!J1798 -> 0.541678 | ... Z46: =$D46*Motors!X1798 -> 6.2356242e-07
A47: =Regions!U3 -> IE-TA | B47: =IF(LEFT(A47,1)="*","*","STOCK") -> STOCK | C47: =C46 -> T-MOT-ICE_GSL00 | D47: =Stock_CSO!B23 -> 1.499 | E47: =$D47*Motors!C1799 -> 1.1079679 | F47: =$D47*Motors!D1799 -> 0.91931223 | G47: =$D47*Motors!E1799 -> 0.79602758 | H47: =$D47*Motors!F1799 -> 0.70507495 | I47: =$D47*Motors!G1799 -> 0.63412559 | J47: =$D47*Motors!H1799 -> 0.57589974 | K47: =$D47*Motors!I1799 -> 0.52327616 | L47: =$D47*Motors!J1799 -> 0.46937105 | ... Z47: =$D47*Motors!X1799 -> 4.7307851e-07
A48: =Regions!V3 -> IE-WD | B48: =IF(LEFT(A48,1)="*","*","STOCK") -> STOCK | C48: =C47 -> T-MOT-ICE_GSL00 | D48: =Stock_CSO!B24 -> 1.342 | E48: =$D48*Motors!C1800 -> 0.94243145 | F48: =$D48*Motors!D1800 -> 0.76845132 | G48: =$D48*Motors!E1800 -> 0.66280747 | H48: =$D48*Motors!F1800 -> 0.58960177 | I48: =$D48*Motors!G1800 -> 0.53563556 | J48: =$D48*Motors!H1800 -> 0.49187479 | K48: =$D48*Motors!I1800 -> 0.45156376 | L48: =$D48*Motors!J1800 -> 0.40929103 | ... Z48: =$D48*Motors!X1800 -> 4.4740368e-07
A49: =Regions!W3 -> IE-G | B49: =IF(LEFT(A49,1)="*","*","STOCK") -> STOCK | C49: =C48 -> T-MOT-ICE_GSL00 | D49: =Stock_CSO!B25 -> 1.538 | E49: =$D49*Motors!C1801 -> 1.1367395 | F49: =$D49*Motors!D1801 -> 0.94666099 | G49: =$D49*Motors!E1801 -> 0.82331103 | H49: =$D49*Motors!F1801 -> 0.73309442 | I49: =$D49*Motors!G1801 -> 0.66374885 | J49: =$D49*Motors!H1801 -> 0.6065585 | K49: =$D49*Motors!I1801 -> 0.55433854 | L49: =$D49*Motors!J1801 -> 0.50034361 | ... Z49: =$D49*Motors!X1801 -> 5.688264e-07
A50: =Regions!X3 -> IE-LM | B50: =IF(LEFT(A50,1)="*","*","STOCK") -> STOCK | C50: =C49 -> T-MOT-ICE_GSL00 | D50: =Stock_CSO!B26 -> 0.175 | E50: =$D50*Motors!C1802 -> 0.13536253 | F50: =$D50*Motors!D1802 -> 0.11834876 | G50: =$D50*Motors!E1802 -> 0.10673739 | H50: =$D50*Motors!F1802 -> 0.097079327 | I50: =$D50*Motors!G1802 -> 0.088304657 | J50: =$D50*Motors!H1802 -> 0.080227254 | K50: =$D50*Motors!I1802 -> 0.072631779 | L50: =$D50*Motors!J1802 -> 0.065171133 | ... Z50: =$D50*Motors!X1802 -> 8.2698839e-08
A51: =Regions!Y3 -> IE-MO | B51: =IF(LEFT(A51,1)="*","*","STOCK") -> STOCK | C51: =C50 -> T-MOT-ICE_GSL00 | D51: =Stock_CSO!B27 -> 0.648 | E51: =$D51*Motors!C1803 -> 0.4847651 | F51: =$D51*Motors!D1803 -> 0.40908641 | G51: =$D51*Motors!E1803 -> 0.35997501 | H51: =$D51*Motors!F1803 -> 0.32339268 | I51: =$D51*Motors!G1803 -> 0.29460096 | J51: =$D51*Motors!H1803 -> 0.27064082 | K51: =$D51*Motors!I1803 -> 0.24885657 | L51: =$D51*Motors!J1803 -> 0.22668094 | ... Z51: =$D51*Motors!X1803 -> 2.4827712e-07
A52: =Regions!Z3 -> IE-RN | B52: =IF(LEFT(A52,1)="*","*","STOCK") -> STOCK | C52: =C51 -> T-MOT-ICE_GSL00 | D52: =Stock_CSO!B28 -> 0.315 | E52: =$D52*Motors!C1804 -> 0.24185838 | F52: =$D52*Motors!D1804 -> 0.208436 | G52: =$D52*Motors!E1804 -> 0.18613289 | H52: =$D52*Motors!F1804 -> 0.16888696 | I52: =$D52*Motors!G1804 -> 0.15486451 | J52: =$D52*Motors!H1804 -> 0.14276717 | K52: =$D52*Motors!I1804 -> 0.13157296 | L52: =$D52*Motors!J1804 -> 0.11987657 | ... Z52: =$D52*Motors!X1804 -> 1.5025134e-07
...

Sheet Stock_CSO
A4: Vehicle population in 2019
A5: Region | B5: Motor | C5: T-TAX-ICE_GSL00 | D5: T-TAX-ICE_DST00 | E5: T-TAX-HEV_GSL00 | F5: T-BUS-ICE_DST00 | G5: T-CAR-ICE_GSL00 | H5: T-CAR-ICE_DST00 | I5: T-LGT-ICE_DST00 | J5: T-MGT-ICE_DST00 | K5: T-HGT-ICE_DST00
A6: ='Stock retirement'!A30 -> IE | B6: 41.471 | C6: 1.691 | D6: 17.634 | E6: 2.132 | F6: 11.206 | G6: 861.396 | H6: 1267.787 | I6: 370.708 | J6: 11.207 | K6: 22.797
A7: ='Stock retirement'!A31 -> IE-CW | B7: 0.609 | C7: 0.01 | D7: 0.152 | E7: 0.006 | F7: 0.149 | G7: 9.436 | H7: 19.614 | I7: 5.907 | J7: 0.138 | K7: 0.412
A8: ='Stock retirement'!A32 -> IE-D | B8: 12.986 | C8: 1.045 | D8: 8.654 | E8: 1.674 | F8: 3.262 | G8: 278.007 | H8: 244.097 | I8: 80.75 | J8: 3.015 | K8: 4.177
A9: ='Stock retirement'!A33 -> IE-KE | B9: 2.275 | C9: 0.056 | D9: 0.697 | E9: 0.06 | F9: 0.525 | G9: 41.228 | H9: 64.718 | I9: 17.131 | J9: 0.588 | K9: 1.177
A10: ='Stock retirement'!A34 -> IE-KK | B10: 0.885 | C10: 0.007 | D10: 0.195 | E10: 0.002 | F10: 0.334 | G10: 15.522 | H10: 30.097 | I10: 8.485 | J10: 0.252 | K10: 0.749
A11: ='Stock retirement'!A35 -> IE-LS | B11: 0.507 | C11: 0.009 | D11: 0.196 | E11: 0.021 | F11: 0.211 | G11: 10.818 | H11: 25.468 | I11: 6.336 | J11: 0.21 | K11: 0.471
A12: ='Stock retirement'!A36 -> IE-LD | B12: 0.233 | C12: 0.001 | D12: 0.086 | E12: 0 | F12: 0.101 | G12: 5.06 | H12: 12.664 | I12: 4.183 | J12: 0.145 | K12: 0.293
A13: ='Stock retirement'!A37 -> IE-LH | B13: 0.894 | C13: 0.037 | D13: 0.488 | E13: 0.051 | F13: 0.246 | G13: 19.492 | H13: 33.583 | I13: 8.319 | J13: 0.385 | K13: 0.644
A14: ='Stock retirement'!A38 -> IE-MH | B14: 1.801 | C14: 0.064 | D14: 0.853 | E14: 0.076 | F14: 0.399 | G14: 31.619 | H14: 60.193 | I14: 15.941 | J14: 0.506 | K14: 1.478
A15: ='Stock retirement'!A39 -> IE-OY | B15: 0.692 | C15: 0.011 | D15: 0.146 | E15: 0.004 | F15: 0.219 | G15: 10.542 | H15: 24.713 | I15: 6.708 | J15: 0.163 | K15: 0.346
A16: ='Stock retirement'!A40 -> IE-WH | B16: 0.622 | C16: 0.01 | D16: 0.248 | E16: 0.012 | F16: 0.154 | G16: 12.463 | H16: 29.417 | I16: 8.421 | J16: 0.198 | K16: 0.343
A17: ='Stock retirement'!A41 -> IE-WX | B17: 1.571 | C17: 0.01 | D17: 0.238 | E17: 0.008 | F17: 0.302 | G17: 25.875 | H17: 51.429 | I17: 14.337 | J17: 0.396 | K17: 1.416
... A32: ='Stock retirement'!A56 -> IE-MN | B32: 0.304 | C32: 0.003 | D32: 0.073 | E32: 0 | F32: 0.232 | G32: 6.907 | H32: 19.933 | I32: 8.461 | J32: 0.247 | K32: 1.088
A33: Source: CSO, Table THA17
